Workbook
Name CargaPorProfesor: 'Auxiliar'!$F$1:$J$30
Name AsignaturaNuevaProfesor: 'Auxiliar'!$M$1:$M$30
Name ProfesoresValidos: OFFSET('Profesores'!$A$2,0,0,COUNTA('Profesores'!$A$2:$A$11),1)
Name ProfesoresTabla: OFFSET('Profesores'!$A$2,0,0,COUNTA('Profesores'!$A$2:$A$11),4)
Name AsignaturasValidas: OFFSET('Asignaturas'!$A$2,0,0,COUNTA('Asignaturas'!$A$2:$A$15),1)
Name AsignaturasTabla: OFFSET('Asignaturas'!$A$2,0,0,COUNTA('Asignaturas'!$A$2:$A$15),7)

Sheet Portada
A2: Gestión del departamento
A3: Matemática Aplicada · Semestre 2026-2027 / 1
A4: Generado desde | B4: config/departamento.yaml
A5: Fecha | B5: 07/09/2026 16:52
A7: Donde se cambian los datos
A8: Las casillas de fondo blanco se escriben a mano. Las demás se calculan solas y están bloqueadas: si necesitas tocarlas, quita la protección de la hoja desde el menú de Excel o de Calc.
A9: Las listas que el índice marca «se escribe» admiten filas nuevas al final, en las líneas libres que ya vienen preparadas. No dejes filas en blanco en medio: la lista se corta ahí y lo que quede debajo desaparece de los desplegables. Las demás hojas de datos son copia del YAML y están bloqueadas.
A11: Las hojas de este libro
A12: Profesores | B12: Los profesores del departamento, con su grado y su tope | C12: se escribe
A13: Asignaturas | B13: Las asignaturas del semestre y sus horas; aquí se añaden las nuevas | C13: se escribe
A14: Asignación | B14: Quién imparte cada conferencia y cada grupo de CP | C14: se escribe
A15: Carga por profesor | B15: Cuántas horas acumula cada uno y si pasa su tope | C15: se calcula
A16: Cobertura por asignatura | B16: Qué asignaturas están cubiertas y qué les falta | C16: se calcula

Sheet Profesores
A1: Id | B1: Nombre | C1: Grado | D1: Tope horas | E1: Origen del tope
A2: PIAD | B2: Pedro I. Alonso Diaz | C2: Dr. | D2: 160 | E2: =IF(A2="","",IF(D2="","Sin tope",IF(D2=160,"Del departamento","Propio")))
A3: MARA | B3: Maria Ramirez | C3: MSc. | D3: 160 | E3: =IF(A3="","",IF(D3="","Sin tope",IF(D3=160,"Del departamento","Propio")))
A4: LGOM | B4: Luis Gomez | C4: Dr. | D4: 160 | E4: =IF(A4="","",IF(D4="","Sin tope",IF(D4=160,"Del departamento","Propio")))
A5: ANSU | B5: Ana Suarez | C5: MSc. | D5: 80 | E5: =IF(A5="","",IF(D5="","Sin tope",IF(D5=160,"Del departamento","Propio")))
A6: RTOR | B6: Raul Torres | C6: Dr. | D6: 160 | E6: =IF(A6="","",IF(D6="","Sin tope",IF(D6=160,"Del departamento","Propio")))
E7: =IF(A7="","",IF(D7="","Sin tope",IF(D7=160,"Del departamento","Propio")))
E8: =IF(A8="","",IF(D8="","Sin tope",IF(D8=160,"Del departamento","Propio")))
E9: =IF(A9="","",IF(D9="","Sin tope",IF(D9=160,"Del departamento","Propio")))
E10: =IF(A10="","",IF(D10="","Sin tope",IF(D10=160,"Del departamento","Propio")))
E11: =IF(A11="","",IF(D11="","Sin tope",IF(D11=160,"Del departamento","Propio")))

Sheet Asignaturas
A1: Id | B1: Nombre | C1: Carrera | D1: Horas Conf | E1: Horas CP por grupo | F1: Grupos CP | G1: Total
A2: EST-CC | B2: Estadística (CC) | C2: Ciencia de la Computación | D2: 32 | E2: 32 | F2: 2 | G2: =IF(A2="","",D2+E2*F2)
A3: EST-MAT | B3: Estadística (Mat) | C3: Matemática | D3: 32 | E3: 32 | F3: 1 | G3: =IF(A3="","",D3+E3*F3)
A4: AN-CD | B4: Análisis Numérico (CD) | C4: Ciencia de Datos | D4: 48 | E4: 32 | F4: 3 | G4: =IF(A4="","",D4+E4*F4)
A5: SEM-MAT | B5: Seminario de Matemática | C5: Matemática | D5: 16 | E5: 0 | F5: 0 | G5: =IF(A5="","",D5+E5*F5)
G6: =IF(A6="","",D6+E6*F6)
G7: =IF(A7="","",D7+E7*F7)
G8: =IF(A8="","",D8+E8*F8)
G9: =IF(A9="","",D9+E9*F9)
G10: =IF(A10="","",D10+E10*F10)
G11: =IF(A11="","",D11+E11*F11)
G12: =IF(A12="","",D12+E12*F12)
G13: =IF(A13="","",D13+E13*F13)
G14: =IF(A14="","",D14+E14*F14)
G15: =IF(A15="","",D15+E15*F15)

Sheet Asignación
A1: Asignación — Matemática Aplicada — 2026-2027 / 1
A3: Id | B3: Asignatura | C3: Carrera | D3: Tipo | E3: Grupo | F3: Horas | G3: Profesor | H3: Nombre | J3: Id | K3: Nombre | L3: Horas | M3: Asignaturas | N3: Tope
A4: EST-CC | B4: =IF($A4="","",IFERROR(VLOOKUP($A4,AsignaturasTabla,2,0),"")) | C4: =IF($A4="","",IFERROR(VLOOKUP($A4,AsignaturasTabla,3,0),"")) | D4: Conf | E4: - | F4: =IF($A4="","",IFERROR(IF($D4="Conf",VLOOKUP($A4,AsignaturasTabla,4,0),VLOOKUP($A4,AsignaturasTabla,5,0)),"")) | H4: =IF($G4="","",IFERROR(VLOOKUP($G4,ProfesoresTabla,2,0),"(desconocido)")) | J4: =IF(Profesores!A2="","",Profesores!A2) | K4: =IF(Profesores!A2="","",Profesores!B2) | L4: =IF($J4="","",SUMIF($G$4:$G$33,$J4,$F$4:$F$33)) | M4: =IF($J4="","",SUMIF($G$4:$G$33,$J4,AsignaturaNuevaProfesor)) | N4: =IF(Profesores!A2="","",Profesores!D2)
A5: EST-CC | B5: =IF($A5="","",IFERROR(VLOOKUP($A5,AsignaturasTabla,2,0),"")) | C5: =IF($A5="","",IFERROR(VLOOKUP($A5,AsignaturasTabla,3,0),"")) | D5: CP | E5: 1 | F5: =IF($A5="","",IFERROR(IF($D5="Conf",VLOOKUP($A5,AsignaturasTabla,4,0),VLOOKUP($A5,AsignaturasTabla,5,0)),"")) | H5: =IF($G5="","",IFERROR(VLOOKUP($G5,ProfesoresTabla,2,0),"(desconocido)")) | J5: =IF(Profesores!A3="","",Profesores!A3) | K5: =IF(Profesores!A3="","",Profesores!B3) | L5: =IF($J5="","",SUMIF($G$4:$G$33,$J5,$F$4:$F$33)) | M5: =IF($J5="","",SUMIF($G$4:$G$33,$J5,AsignaturaNuevaProfesor)) | N5: =IF(Profesores!A3="","",Profesores!D3)
A6: EST-CC | B6: =IF($A6="","",IFERROR(VLOOKUP($A6,AsignaturasTabla,2,0),"")) | C6: =IF($A6="","",IFERROR(VLOOKUP($A6,AsignaturasTabla,3,0),"")) | D6: CP | E6: 2 | F6: =IF($A6="","",IFERROR(IF($D6="Conf",VLOOKUP($A6,AsignaturasTabla,4,0),VLOOKUP($A6,AsignaturasTabla,5,0)),"")) | H6: =IF($G6="","",IFERROR(VLOOKUP($G6,ProfesoresTabla,2,0),"(desconocido)")) | J6: =IF(Profesores!A4="","",Profesores!A4) | K6: =IF(Profesores!A4="","",Profesores!B4) | L6: =IF($J6="","",SUMIF($G$4:$G$33,$J6,$F$4:$F$33)) | M6: =IF($J6="","",SUMIF($G$4:$G$33,$J6,AsignaturaNuevaProfesor)) | N6: =IF(Profesores!A4="","",Profesores!D4)
A7: EST-MAT | B7: =IF($A7="","",IFERROR(VLOOKUP($A7,AsignaturasTabla,2,0),"")) | C7: =IF($A7="","",IFERROR(VLOOKUP($A7,AsignaturasTabla,3,0),"")) | D7: Conf | E7: - | F7: =IF($A7="","",IFERROR(IF($D7="Conf",VLOOKUP($A7,AsignaturasTabla,4,0),VLOOKUP($A7,AsignaturasTabla,5,0)),"")) | H7: =IF($G7="","",IFERROR(VLOOKUP($G7,ProfesoresTabla,2,0),"(desconocido)")) | J7: =IF(Profesores!A5="","",Profesores!A5) | K7: =IF(Profesores!A5="","",Profesores!B5) | L7: =IF($J7="","",SUMIF($G$4:$G$33,$J7,$F$4:$F$33)) | M7: =IF($J7="","",SUMIF($G$4:$G$33,$J7,AsignaturaNuevaProfesor)) | N7: =IF(Profesores!A5="","",Profesores!D5)
A8: EST-MAT | B8: =IF($A8="","",IFERROR(VLOOKUP($A8,AsignaturasTabla,2,0),"")) | C8: =IF($A8="","",IFERROR(VLOOKUP($A8,AsignaturasTabla,3,0),"")) | D8: CP | E8: 1 | F8: =IF($A8="","",IFERROR(IF($D8="Conf",VLOOKUP($A8,AsignaturasTabla,4,0),VLOOKUP($A8,AsignaturasTabla,5,0)),"")) | H8: =IF($G8="","",IFERROR(VLOOKUP($G8,ProfesoresTabla,2,0),"(desconocido)")) | J8: =IF(Profesores!A6="","",Profesores!A6) | K8: =IF(Profesores!A6="","",Profesores!B6) | L8: =IF($J8="","",SUMIF($G$4:$G$33,$J8,$F$4:$F$33)) | M8: =IF($J8="","",SUMIF($G$4:$G$33,$J8,AsignaturaNuevaProfesor)) | N8: =IF(Profesores!A6="","",Profesores!D6)
A9: AN-CD | B9: =IF($A9="","",IFERROR(VLOOKUP($A9,AsignaturasTabla,2,0),"")) | C9: =IF($A9="","",IFERROR(VLOOKUP($A9,AsignaturasTabla,3,0),"")) | D9: Conf | E9: - | F9: =IF($A9="","",IFERROR(IF($D9="Conf",VLOOKUP($A9,AsignaturasTabla,4,0),VLOOKUP($A9,AsignaturasTabla,5,0)),"")) | H9: =IF($G9="","",IFERROR(VLOOKUP($G9,ProfesoresTabla,2,0),"(desconocido)")) | J9: =IF(Profesores!A7="","",Profesores!A7) | K9: =IF(Profesores!A7="","",Profesores!B7) | L9: =IF($J9="","",SUMIF($G$4:$G$33,$J9,$F$4:$F$33)) | M9: =IF($J9="","",SUMIF($G$4:$G$33,$J9,AsignaturaNuevaProfesor)) | N9: =IF(Profesores!A7="","",Profesores!D7)
A10: AN-CD | B10: =IF($A10="","",IFERROR(VLOOKUP($A10,AsignaturasTabla,2,0),"")) | C10: =IF($A10="","",IFERROR(VLOOKUP($A10,AsignaturasTabla,3,0),"")) | D10: CP | E10: 1 | F10: =IF($A10="","",IFERROR(IF($D10="Conf",VLOOKUP($A10,AsignaturasTabla,4,0),VLOOKUP($A10,AsignaturasTabla,5,0)),"")) | H10: =IF($G10="","",IFERROR(VLOOKUP($G10,ProfesoresTabla,2,0),"(desconocido)")) | J10: =IF(Profesores!A8="","",Profesores!A8) | K10: =IF(Profesores!A8="","",Profesores!B8) | L10: =IF($J10="","",SUMIF($G$4:$G$33,$J10,$F$4:$F$33)) | M10: =IF($J10="","",SUMIF($G$4:$G$33,$J10,AsignaturaNuevaProfesor)) | N10: =IF(Profesores!A8="","",Profesores!D8)
A11: AN-CD | B11: =IF($A11="","",IFERROR(VLOOKUP($A11,AsignaturasTabla,2,0),"")) | C11: =IF($A11="","",IFERROR(VLOOKUP($A11,AsignaturasTabla,3,0),"")) | D11: CP | E11: 2 | F11: =IF($A11="","",IFERROR(IF($D11="Conf",VLOOKUP($A11,AsignaturasTabla,4,0),VLOOKUP($A11,AsignaturasTabla,5,0)),"")) | H11: =IF($G11="","",IFERROR(VLOOKUP($G11,ProfesoresTabla,2,0),"(desconocido)")) | J11: =IF(Profesores!A9="","",Profesores!A9) | K11: =IF(Profesores!A9="","",Profesores!B9) | L11: =IF($J11="","",SUMIF($G$4:$G$33,$J11,$F$4:$F$33)) | M11: =IF($J11="","",SUMIF($G$4:$G$33,$J11,AsignaturaNuevaProfesor)) | N11: =IF(Profesores!A9="","",Profesores!D9)
A12: AN-CD | B12: =IF($A12="","",IFERROR(VLOOKUP($A12,AsignaturasTabla,2,0),"")) | C12: =IF($A12="","",IFERROR(VLOOKUP($A12,AsignaturasTabla,3,0),"")) | D12: CP | E12: 3 | F12: =IF($A12="","",IFERROR(IF($D12="Conf",VLOOKUP($A12,AsignaturasTabla,4,0),VLOOKUP($A12,AsignaturasTabla,5,0)),"")) | H12: =IF($G12="","",IFERROR(VLOOKUP($G12,ProfesoresTabla,2,0),"(desconocido)")) | J12: =IF(Profesores!A10="","",Profesores!A10) | K12: =IF(Profesores!A10="","",Profesores!B10) | L12: =IF($J12="","",SUMIF($G$4:$G$33,$J12,$F$4:$F$33)) | M12: =IF($J12="","",SUMIF($G$4:$G$33,$J12,AsignaturaNuevaProfesor)) | N12: =IF(Profesores!A10="","",Profesores!D10)
A13: SEM-MAT | B13: =IF($A13="","",IFERROR(VLOOKUP($A13,AsignaturasTabla,2,0),"")) | C13: =IF($A13="","",IFERROR(VLOOKUP($A13,AsignaturasTabla,3,0),"")) | D13: Conf | E13: - | F13: =IF($A13="","",IFERROR(IF($D13="Conf",VLOOKUP($A13,AsignaturasTabla,4,0),VLOOKUP($A13,AsignaturasTabla,5,0)),"")) | H13: =IF($G13="","",IFERROR(VLOOKUP($G13,ProfesoresTabla,2,0),"(desconocido)")) | J13: =IF(Profesores!A11="","",Profesores!A11) | K13: =IF(Profesores!A11="","",Profesores!B11) | L13: =IF($J13="","",SUMIF($G$4:$G$33,$J13,$F$4:$F$33)) | M13: =IF($J13="","",SUMIF($G$4:$G$33,$J13,AsignaturaNuevaProfesor)) | N13: =IF(Profesores!A11="","",Profesores!D11)
B14: =IF($A14="","",IFERROR(VLOOKUP($A14,AsignaturasTabla,2,0),"")) | C14: =IF($A14="","",IFERROR(VLOOKUP($A14,AsignaturasTabla,3,0),"")) | F14: =IF($A14="","",IFERROR(IF($D14="Conf",VLOOKUP($A14,AsignaturasTabla,4,0),VLOOKUP($A14,AsignaturasTabla,5,0)),"")) | H14: =IF($G14="","",IFERROR(VLOOKUP($G14,ProfesoresTabla,2,0),"(desconocido)"))
B15: =IF($A15="","",IFERROR(VLOOKUP($A15,AsignaturasTabla,2,0),"")) | C15: =IF($A15="","",IFERROR(VLOOKUP($A15,AsignaturasTabla,3,0),"")) | F15: =IF($A15="","",IFERROR(IF($D15="Conf",VLOOKUP($A15,AsignaturasTabla,4,0),VLOOKUP($A15,AsignaturasTabla,5,0)),"")) | H15: =IF($G15="","",IFERROR(VLOOKUP($G15,ProfesoresTabla,2,0),"(desconocido)"))
B16: =IF($A16="","",IFERROR(VLOOKUP($A16,AsignaturasTabla,2,0),"")) | C16: =IF($A16="","",IFERROR(VLOOKUP($A16,AsignaturasTabla,3,0),"")) | F16: =IF($A16="","",IFERROR(IF($D16="Conf",VLOOKUP($A16,AsignaturasTabla,4,0),VLOOKUP($A16,AsignaturasTabla,5,0)),"")) | H16: =IF($G16="","",IFERROR(VLOOKUP($G16,ProfesoresTabla,2,0),"(desconocido)"))
B17: =IF($A17="","",IFERROR(VLOOKUP($A17,AsignaturasTabla,2,0),"")) | C17: =IF($A17="","",IFERROR(VLOOKUP($A17,AsignaturasTabla,3,0),"")) | F17: =IF($A17="","",IFERROR(IF($D17="Conf",VLOOKUP($A17,AsignaturasTabla,4,0),VLOOKUP($A17,AsignaturasTabla,5,0)),"")) | H17: =IF($G17="","",IFERROR(VLOOKUP($G17,ProfesoresTabla,2,0),"(desconocido)"))
B18: =IF($A18="","",IFERROR(VLOOKUP($A18,AsignaturasTabla,2,0),"")) | C18: =IF($A18="","",IFERROR(VLOOKUP($A18,AsignaturasTabla,3,0),"")) | F18: =IF($A18="","",IFERROR(IF($D18="Conf",VLOOKUP($A18,AsignaturasTabla,4,0),VLOOKUP($A18,AsignaturasTabla,5,0)),"")) | H18: =IF($G18="","",IFERROR(VLOOKUP($G18,ProfesoresTabla,2,0),"(desconocido)"))
B19: =IF($A19="","",IFERROR(VLOOKUP($A19,AsignaturasTabla,2,0),"")) | C19: =IF($A19="","",IFERROR(VLOOKUP($A19,AsignaturasTabla,3,0),"")) | F19: =IF($A19="","",IFERROR(IF($D19="Conf",VLOOKUP($A19,AsignaturasTabla,4,0),VLOOKUP($A19,AsignaturasTabla,5,0)),"")) | H19: =IF($G19="","",IFERROR(VLOOKUP($G19,ProfesoresTabla,2,0),"(desconocido)"))
B20: =IF($A20="","",IFERROR(VLOOKUP($A20,AsignaturasTabla,2,0),"")) | C20: =IF($A20="","",IFERROR(VLOOKUP($A20,AsignaturasTabla,3,0),"")) | F20: =IF($A20="","",IFERROR(IF($D20="Conf",VLOOKUP($A20,AsignaturasTabla,4,0),VLOOKUP($A20,AsignaturasTabla,5,0)),"")) | H20: =IF($G20="","",IFERROR(VLOOKUP($G20,ProfesoresTabla,2,0),"(desconocido)"))
B21: =IF($A21="","",IFERROR(VLOOKUP($A21,AsignaturasTabla,2,0),"")) | C21: =IF($A21="","",IFERROR(VLOOKUP($A21,AsignaturasTabla,3,0),"")) | F21: =IF($A21="","",IFERROR(IF($D21="Conf",VLOOKUP($A21,AsignaturasTabla,4,0),VLOOKUP($A21,AsignaturasTabla,5,0)),"")) | H21: =IF($G21="","",IFERROR(VLOOKUP($G21,ProfesoresTabla,2,0),"(desconocido)"))
B22: =IF($A22="","",IFERROR(VLOOKUP($A22,AsignaturasTabla,2,0),"")) | C22: =IF($A22="","",IFERROR(VLOOKUP($A22,AsignaturasTabla,3,0),"")) | F22: =IF($A22="","",IFERROR(IF($D22="Conf",VLOOKUP($A22,AsignaturasTabla,4,0),VLOOKUP($A22,AsignaturasTabla,5,0)),"")) | H22: =IF($G22="","",IFERROR(VLOOKUP($G22,ProfesoresTabla,2,0),"(desconocido)"))
B23: =IF($A23="","",IFERROR(VLOOKUP($A23,AsignaturasTabla,2,0),"")) | C23: =IF($A23="","",IFERROR(VLOOKUP($A23,AsignaturasTabla,3,0),"")) | F23: =IF($A23="","",IFERROR(IF($D23="Conf",VLOOKUP($A23,AsignaturasTabla,4,0),VLOOKUP($A23,AsignaturasTabla,5,0)),"")) | H23: =IF($G23="","",IFERROR(VLOOKUP($G23,ProfesoresTabla,2,0),"(desconocido)"))
B24: =IF($A24="","",IFERROR(VLOOKUP($A24,AsignaturasTabla,2,0),"")) | C24: =IF($A24="","",IFERROR(VLOOKUP($A24,AsignaturasTabla,3,0),"")) | F24: =IF($A24="","",IFERROR(IF($D24="Conf",VLOOKUP($A24,AsignaturasTabla,4,0),VLOOKUP($A24,AsignaturasTabla,5,0)),"")) | H24: =IF($G24="","",IFERROR(VLOOKUP($G24,ProfesoresTabla,2,0),"(desconocido)"))
B25: =IF($A25="","",IFERROR(VLOOKUP($A25,AsignaturasTabla,2,0),"")) | C25: =IF($A25="","",IFERROR(VLOOKUP($A25,AsignaturasTabla,3,0),"")) | F25: =IF($A25="","",IFERROR(IF($D25="Conf",VLOOKUP($A25,AsignaturasTabla,4,0),VLOOKUP($A25,AsignaturasTabla,5,0)),"")) | H25: =IF($G25="","",IFERROR(VLOOKUP($G25,ProfesoresTabla,2,0),"(desconocido)"))
... B33: =IF($A33="","",IFERROR(VLOOKUP($A33,AsignaturasTabla,2,0),"")) | C33: =IF($A33="","",IFERROR(VLOOKUP($A33,AsignaturasTabla,3,0),"")) | F33: =IF($A33="","",IFERROR(IF($D33="Conf",VLOOKUP($A33,AsignaturasTabla,4,0),VLOOKUP($A33,AsignaturasTabla,5,0)),"")) | H33: =IF($G33="","",IFERROR(VLOOKUP($G33,ProfesoresTabla,2,0),"(desconocido)"))
B35: Falta asignar profesor
B36: Id fuera de la lista (profesor o asignatura)
B37: Profesor por encima de su tope (panel de la derecha)

Sheet Carga por profesor
A1: Carga por profesor — Matemática Aplicada — 2026-2027 / 1
A3: Id | B3: Nombre | C3: Grado | D3: Tope horas
A4: =IF(Profesores!A2="","",Profesores!A2) | B4: =IF($A$4="","",IFERROR(VLOOKUP($A$4,ProfesoresTabla,2,0),"")) | C4: =IF($A$4="","",IFERROR(VLOOKUP($A$4,ProfesoresTabla,3,0),"")) | D4: =IF($A$4="","",IFERROR(VLOOKUP($A$4,ProfesoresTabla,4,0),""))
A5: Asignatura | B5: Tipo | C5: Grupo | D5: Horas
A6: =IF($A$4="","",IFERROR(VLOOKUP($A$4&"#1",CargaPorProfesor,2,0),"")) | B6: =IF($A$4="","",IFERROR(VLOOKUP($A$4&"#1",CargaPorProfesor,3,0),"")) | C6: =IF($A$4="","",IFERROR(VLOOKUP($A$4&"#1",CargaPorProfesor,4,0),"")) | D6: =IF($A$4="","",IFERROR(VLOOKUP($A$4&"#1",CargaPorProfesor,5,0),""))
A7: =IF($A$4="","",IFERROR(VLOOKUP($A$4&"#2",CargaPorProfesor,2,0),"")) | B7: =IF($A$4="","",IFERROR(VLOOKUP($A$4&"#2",CargaPorProfesor,3,0),"")) | C7: =IF($A$4="","",IFERROR(VLOOKUP($A$4&"#2",CargaPorProfesor,4,0),"")) | D7: =IF($A$4="","",IFERROR(VLOOKUP($A$4&"#2",CargaPorProfesor,5,0),""))
A8: =IF($A$4="","",IFERROR(VLOOKUP($A$4&"#3",CargaPorProfesor,2,0),"")) | B8: =IF($A$4="","",IFERROR(VLOOKUP($A$4&"#3",CargaPorProfesor,3,0),"")) | C8: =IF($A$4="","",IFERROR(VLOOKUP($A$4&"#3",CargaPorProfesor,4,0),"")) | D8: =IF($A$4="","",IFERROR(VLOOKUP($A$4&"#3",CargaPorProfesor,5,0),""))
A9: =IF($A$4="","",IFERROR(VLOOKUP($A$4&"#4",CargaPorProfesor,2,0),"")) | B9: =IF($A$4="","",IFERROR(VLOOKUP($A$4&"#4",CargaPorProfesor,3,0),"")) | C9: =IF($A$4="","",IFERROR(VLOOKUP($A$4&"#4",CargaPorProfesor,4,0),"")) | D9: =IF($A$4="","",IFERROR(VLOOKUP($A$4&"#4",CargaPorProfesor,5,0),""))
A10: =IF($A$4="","",IFERROR(VLOOKUP($A$4&"#5",CargaPorProfesor,2,0),"")) | B10: =IF($A$4="","",IFERROR(VLOOKUP($A$4&"#5",CargaPorProfesor,3,0),"")) | C10: =IF($A$4="","",IFERROR(VLOOKUP($A$4&"#5",CargaPorProfesor,4,0),"")) | D10: =IF($A$4="","",IFERROR(VLOOKUP($A$4&"#5",CargaPorProfesor,5,0),""))
A11: =IF($A$4="","",IFERROR(VLOOKUP($A$4&"#6",CargaPorProfesor,2,0),"")) | B11: =IF($A$4="","",IFERROR(VLOOKUP($A$4&"#6",CargaPorProfesor,3,0),"")) | C11: =IF($A$4="","",IFERROR(VLOOKUP($A$4&"#6",CargaPorProfesor,4,0),"")) | D11: =IF($A$4="","",IFERROR(VLOOKUP($A$4&"#6",CargaPorProfesor,5,0),""))
A12: =IF($A$4="","",IFERROR(VLOOKUP($A$4&"#7",CargaPorProfesor,2,0),"")) | B12: =IF($A$4="","",IFERROR(VLOOKUP($A$4&"#7",CargaPorProfesor,3,0),"")) | C12: =IF($A$4="","",IFERROR(VLOOKUP($A$4&"#7",CargaPorProfesor,4,0),"")) | D12: =IF($A$4="","",IFERROR(VLOOKUP($A$4&"#7",CargaPorProfesor,5,0),""))
A13: =IF($A$4="","",IF(COUNTIF('Asignación'!$G$4:$G$33,$A$4)>8,"(+"&(COUNTIF('Asignación'!$G$4:$G$33,$A$4)-8+1)&" más)",IFERROR(VLOOKUP($A$4&"#8",CargaPorProfesor,2,0),""))) | B13: =IF($A$4="","",IFERROR(VLOOKUP($A$4&"#8",CargaPorProfesor,3,0),"")) | C13: =IF($A$4="","",IFERROR(VLOOKUP($A$4&"#8",CargaPorProfesor,4,0),"")) | D13: =IF($A$4="","",IFERROR(VLOOKUP($A$4&"#8",CargaPorProfesor,5,0),""))
A14: TOTAL | D14: =IF($A$4="","",SUMIF('Asignación'!$G$4:$G$33,$A$4,'Asignación'!$F$4:$F$33))
A16: Id | B16: Nombre | C16: Grado | D16: Tope horas
A17: =IF(Profesores!A3="","",Profesores!A3) | B17: =IF($A$17="","",IFERROR(VLOOKUP($A$17,ProfesoresTabla,2,0),"")) | C17: =IF($A$17="","",IFERROR(VLOOKUP($A$17,ProfesoresTabla,3,0),"")) | D17: =IF($A$17="","",IFERROR(VLOOKUP($A$17,ProfesoresTabla,4,0),""))
A18: Asignatura | B18: Tipo | C18: Grupo | D18: Horas
A19: =IF($A$17="","",IFERROR(VLOOKUP($A$17&"#1",CargaPorProfesor,2,0),"")) | B19: =IF($A$17="","",IFERROR(VLOOKUP($A$17&"#1",CargaPorProfesor,3,0),"")) | C19: =IF($A$17="","",IFERROR(VLOOKUP($A$17&"#1",CargaPorProfesor,4,0),"")) | D19: =IF($A$17="","",IFERROR(VLOOKUP($A$17&"#1",CargaPorProfesor,5,0),""))
A20: =IF($A$17="","",IFERROR(VLOOKUP($A$17&"#2",CargaPorProfesor,2,0),"")) | B20: =IF($A$17="","",IFERROR(VLOOKUP($A$17&"#2",CargaPorProfesor,3,0),"")) | C20: =IF($A$17="","",IFERROR(VLOOKUP($A$17&"#2",CargaPorProfesor,4,0),"")) | D20: =IF($A$17="","",IFERROR(VLOOKUP($A$17&"#2",CargaPorProfesor,5,0),""))
A21: =IF($A$17="","",IFERROR(VLOOKUP($A$17&"#3",CargaPorProfesor,2,0),"")) | B21: =IF($A$17="","",IFERROR(VLOOKUP($A$17&"#3",CargaPorProfesor,3,0),"")) | C21: =IF($A$17="","",IFERROR(VLOOKUP($A$17&"#3",CargaPorProfesor,4,0),"")) | D21: =IF($A$17="","",IFERROR(VLOOKUP($A$17&"#3",CargaPorProfesor,5,0),""))
A22: =IF($A$17="","",IFERROR(VLOOKUP($A$17&"#4",CargaPorProfesor,2,0),"")) | B22: =IF($A$17="","",IFERROR(VLOOKUP($A$17&"#4",CargaPorProfesor,3,0),"")) | C22: =IF($A$17="","",IFERROR(VLOOKUP($A$17&"#4",CargaPorProfesor,4,0),"")) | D22: =IF($A$17="","",IFERROR(VLOOKUP($A$17&"#4",CargaPorProfesor,5,0),""))
A23: =IF($A$17="","",IFERROR(VLOOKUP($A$17&"#5",CargaPorProfesor,2,0),"")) | B23: =IF($A$17="","",IFERROR(VLOOKUP($A$17&"#5",CargaPorProfesor,3,0),"")) | C23: =IF($A$17="","",IFERROR(VLOOKUP($A$17&"#5",CargaPorProfesor,4,0),"")) | D23: =IF($A$17="","",IFERROR(VLOOKUP($A$17&"#5",CargaPorProfesor,5,0),""))
A24: =IF($A$17="","",IFERROR(VLOOKUP($A$17&"#6",CargaPorProfesor,2,0),"")) | B24: =IF($A$17="","",IFERROR(VLOOKUP($A$17&"#6",CargaPorProfesor,3,0),"")) | C24: =IF($A$17="","",IFERROR(VLOOKUP($A$17&"#6",CargaPorProfesor,4,0),"")) | D24: =IF($A$17="","",IFERROR(VLOOKUP($A$17&"#6",CargaPorProfesor,5,0),""))
A25: =IF($A$17="","",IFERROR(VLOOKUP($A$17&"#7",CargaPorProfesor,2,0),"")) | B25: =IF($A$17="","",IFERROR(VLOOKUP($A$17&"#7",CargaPorProfesor,3,0),"")) | C25: =IF($A$17="","",IFERROR(VLOOKUP($A$17&"#7",CargaPorProfesor,4,0),"")) | D25: =IF($A$17="","",IFERROR(VLOOKUP($A$17&"#7",CargaPorProfesor,5,0),""))
A26: =IF($A$17="","",IF(COUNTIF('Asignación'!$G$4:$G$33,$A$17)>8,"(+"&(COUNTIF('Asignación'!$G$4:$G$33,$A$17)-8+1)&" más)",IFERROR(VLOOKUP($A$17&"#8",CargaPorProfesor,2,0),""))) | B26: =IF($A$17="","",IFERROR(VLOOKUP($A$17&"#8",CargaPorProfesor,3,0),"")) | C26: =IF($A$17="","",IFERROR(VLOOKUP($A$17&"#8",CargaPorProfesor,4,0),"")) | D26: =IF($A$17="","",IFERROR(VLOOKUP($A$17&"#8",CargaPorProfesor,5,0),""))
A27: TOTAL | D27: =IF($A$17="","",SUMIF('Asignación'!$G$4:$G$33,$A$17,'Asignación'!$F$4:$F$33))
A29: Id | B29: Nombre | C29: Grado | D29: Tope horas
A30: =IF(Profesores!A4="","",Profesores!A4) | B30: =IF($A$30="","",IFERROR(VLOOKUP($A$30,ProfesoresTabla,2,0),"")) | C30: =IF($A$30="","",IFERROR(VLOOKUP($A$30,ProfesoresTabla,3,0),"")) | D30: =IF($A$30="","",IFERROR(VLOOKUP($A$30,ProfesoresTabla,4,0),""))
A31: Asignatura | B31: Tipo | C31: Grupo | D31: Horas
A32: =IF($A$30="","",IFERROR(VLOOKUP($A$30&"#1",CargaPorProfesor,2,0),"")) | B32: =IF($A$30="","",IFERROR(VLOOKUP($A$30&"#1",CargaPorProfesor,3,0),"")) | C32: =IF($A$30="","",IFERROR(VLOOKUP($A$30&"#1",CargaPorProfesor,4,0),"")) | D32: =IF($A$30="","",IFERROR(VLOOKUP($A$30&"#1",CargaPorProfesor,5,0),""))
A33: =IF($A$30="","",IFERROR(VLOOKUP($A$30&"#2",CargaPorProfesor,2,0),"")) | B33: =IF($A$30="","",IFERROR(VLOOKUP($A$30&"#2",CargaPorProfesor,3,0),"")) | C33: =IF($A$30="","",IFERROR(VLOOKUP($A$30&"#2",CargaPorProfesor,4,0),"")) | D33: =IF($A$30="","",IFERROR(VLOOKUP($A$30&"#2",CargaPorProfesor,5,0),""))
A34: =IF($A$30="","",IFERROR(VLOOKUP($A$30&"#3",CargaPorProfesor,2,0),"")) | B34: =IF($A$30="","",IFERROR(VLOOKUP($A$30&"#3",CargaPorProfesor,3,0),"")) | C34: =IF($A$30="","",IFERROR(VLOOKUP($A$30&"#3",CargaPorProfesor,4,0),"")) | D34: =IF($A$30="","",IFERROR(VLOOKUP($A$30&"#3",CargaPorProfesor,5,0),""))
A35: =IF($A$30="","",IFERROR(VLOOKUP($A$30&"#4",CargaPorProfesor,2,0),"")) | B35: =IF($A$30="","",IFERROR(VLOOKUP($A$30&"#4",CargaPorProfesor,3,0),"")) | C35: =IF($A$30="","",IFERROR(VLOOKUP($A$30&"#4",CargaPorProfesor,4,0),"")) | D35: =IF($A$30="","",IFERROR(VLOOKUP($A$30&"#4",CargaPorProfesor,5,0),""))
A36: =IF($A$30="","",IFERROR(VLOOKUP($A$30&"#5",CargaPorProfesor,2,0),"")) | B36: =IF($A$30="","",IFERROR(VLOOKUP($A$30&"#5",CargaPorProfesor,3,0),"")) | C36: =IF($A$30="","",IFERROR(VLOOKUP($A$30&"#5",CargaPorProfesor,4,0),"")) | D36: =IF($A$30="","",IFERROR(VLOOKUP($A$30&"#5",CargaPorProfesor,5,0),""))
A37: =IF($A$30="","",IFERROR(VLOOKUP($A$30&"#6",CargaPorProfesor,2,0),"")) | B37: =IF($A$30="","",IFERROR(VLOOKUP($A$30&"#6",CargaPorProfesor,3,0),"")) | C37: =IF($A$30="","",IFERROR(VLOOKUP($A$30&"#6",CargaPorProfesor,4,0),"")) | D37: =IF($A$30="","",IFERROR(VLOOKUP($A$30&"#6",CargaPorProfesor,5,0),""))
A38: =IF($A$30="","",IFERROR(VLOOKUP($A$30&"#7",CargaPorProfesor,2,0),"")) | B38: =IF($A$30="","",IFERROR(VLOOKUP($A$30&"#7",CargaPorProfesor,3,0),"")) | C38: =IF($A$30="","",IFERROR(VLOOKUP($A$30&"#7",CargaPorProfesor,4,0),"")) | D38: =IF($A$30="","",IFERROR(VLOOKUP($A$30&"#7",CargaPorProfesor,5,0),""))
A39: =IF($A$30="","",IF(COUNTIF('Asignación'!$G$4:$G$33,$A$30)>8,"(+"&(COUNTIF('Asignación'!$G$4:$G$33,$A$30)-8+1)&" más)",IFERROR(VLOOKUP($A$30&"#8",CargaPorProfesor,2,0),""))) | B39: =IF($A$30="","",IFERROR(VLOOKUP($A$30&"#8",CargaPorProfesor,3,0),"")) | C39: =IF($A$30="","",IFERROR(VLOOKUP($A$30&"#8",CargaPorProfesor,4,0),"")) | D39: =IF($A$30="","",IFERROR(VLOOKUP($A$30&"#8",CargaPorProfesor,5,0),""))
A40: TOTAL | D40: =IF($A$30="","",SUMIF('Asignación'!$G$4:$G$33,$A$30,'Asignación'!$F$4:$F$33))
A42: Id | B42: Nombre | C42: Grado | D42: Tope horas
A43: =IF(Profesores!A5="","",Profesores!A5) | B43: =IF($A$43="","",IFERROR(VLOOKUP($A$43,ProfesoresTabla,2,0),"")) | C43: =IF($A$43="","",IFERROR(VLOOKUP($A$43,ProfesoresTabla,3,0),"")) | D43: =IF($A$43="","",IFERROR(VLOOKUP($A$43,ProfesoresTabla,4,0),""))
A44: Asignatura | B44: Tipo | C44: Grupo | D44: Horas
...

Sheet Cobertura por asignatura
A1: Cobertura por asignatura — Matemática Aplicada — 2026-2027 / 1
A2: Id | B2: Asignatura | C2: Carrera | D2: Horas planificadas | E2: Filas de carga | F2: Horas en filas | G2: Horas asignadas | H2: Filas sin profesor | I2: Estado
A3: =IF(Asignaturas!A2="","",Asignaturas!A2) | B3: =IF(Asignaturas!A2="","",Asignaturas!B2) | C3: =IF(Asignaturas!A2="","",Asignaturas!C2) | D3: =IF(Asignaturas!A2="","",Asignaturas!G2) | E3: =IF($A3="","",COUNTIF('Asignación'!$A$4:$A$33,$A3)) | F3: =IF($A3="","",SUMIF('Asignación'!$A$4:$A$33,$A3,'Asignación'!$F$4:$F$33)) | G3: =IF($A3="","",SUMIFS('Asignación'!$F$4:$F$33,'Asignación'!$A$4:$A$33,$A3,'Asignación'!$G$4:$G$33,"<>")) | H3: =IF($A3="","",COUNTIFS('Asignación'!$A$4:$A$33,$A3,'Asignación'!$G$4:$G$33,"")) | I3: =IF($A3="","",IF($E3=0,"Sin filas de carga",IF($F3<$D3,IF($D3-$F3=1,"Falta 1 hora de carga","Faltan "&($D3-$F3)&" horas de carga"),IF($H3>0,IF($H3=1,"Falta 1 profesor","Faltan "&$H3&" profesores"),"Completa"))))
A4: =IF(Asignaturas!A3="","",Asignaturas!A3) | B4: =IF(Asignaturas!A3="","",Asignaturas!B3) | C4: =IF(Asignaturas!A3="","",Asignaturas!C3) | D4: =IF(Asignaturas!A3="","",Asignaturas!G3) | E4: =IF($A4="","",COUNTIF('Asignación'!$A$4:$A$33,$A4)) | F4: =IF($A4="","",SUMIF('Asignación'!$A$4:$A$33,$A4,'Asignación'!$F$4:$F$33)) | G4: =IF($A4="","",SUMIFS('Asignación'!$F$4:$F$33,'Asignación'!$A$4:$A$33,$A4,'Asignación'!$G$4:$G$33,"<>")) | H4: =IF($A4="","",COUNTIFS('Asignación'!$A$4:$A$33,$A4,'Asignación'!$G$4:$G$33,"")) | I4: =IF($A4="","",IF($E4=0,"Sin filas de carga",IF($F4<$D4,IF($D4-$F4=1,"Falta 1 hora de carga","Faltan "&($D4-$F4)&" horas de carga"),IF($H4>0,IF($H4=1,"Falta 1 profesor","Faltan "&$H4&" profesores"),"Completa"))))
A5: =IF(Asignaturas!A4="","",Asignaturas!A4) | B5: =IF(Asignaturas!A4="","",Asignaturas!B4) | C5: =IF(Asignaturas!A4="","",Asignaturas!C4) | D5: =IF(Asignaturas!A4="","",Asignaturas!G4) | E5: =IF($A5="","",COUNTIF('Asignación'!$A$4:$A$33,$A5)) | F5: =IF($A5="","",SUMIF('Asignación'!$A$4:$A$33,$A5,'Asignación'!$F$4:$F$33)) | G5: =IF($A5="","",SUMIFS('Asignación'!$F$4:$F$33,'Asignación'!$A$4:$A$33,$A5,'Asignación'!$G$4:$G$33,"<>")) | H5: =IF($A5="","",COUNTIFS('Asignación'!$A$4:$A$33,$A5,'Asignación'!$G$4:$G$33,"")) | I5: =IF($A5="","",IF($E5=0,"Sin filas de carga",IF($F5<$D5,IF($D5-$F5=1,"Falta 1 hora de carga","Faltan "&($D5-$F5)&" horas de carga"),IF($H5>0,IF($H5=1,"Falta 1 profesor","Faltan "&$H5&" profesores"),"Completa"))))
A6: =IF(Asignaturas!A5="","",Asignaturas!A5) | B6: =IF(Asignaturas!A5="","",Asignaturas!B5) | C6: =IF(Asignaturas!A5="","",Asignaturas!C5) | D6: =IF(Asignaturas!A5="","",Asignaturas!G5) | E6: =IF($A6="","",COUNTIF('Asignación'!$A$4:$A$33,$A6)) | F6: =IF($A6="","",SUMIF('Asignación'!$A$4:$A$33,$A6,'Asignación'!$F$4:$F$33)) | G6: =IF($A6="","",SUMIFS('Asignación'!$F$4:$F$33,'Asignación'!$A$4:$A$33,$A6,'Asignación'!$G$4:$G$33,"<>")) | H6: =IF($A6="","",COUNTIFS('Asignación'!$A$4:$A$33,$A6,'Asignación'!$G$4:$G$33,"")) | I6: =IF($A6="","",IF($E6=0,"Sin filas de carga",IF($F6<$D6,IF($D6-$F6=1,"Falta 1 hora de carga","Faltan "&($D6-$F6)&" horas de carga"),IF($H6>0,IF($H6=1,"Falta 1 profesor","Faltan "&$H6&" profesores"),"Completa"))))
A7: =IF(Asignaturas!A6="","",Asignaturas!A6) | B7: =IF(Asignaturas!A6="","",Asignaturas!B6) | C7: =IF(Asignaturas!A6="","",Asignaturas!C6) | D7: =IF(Asignaturas!A6="","",Asignaturas!G6) | E7: =IF($A7="","",COUNTIF('Asignación'!$A$4:$A$33,$A7)) | F7: =IF($A7="","",SUMIF('Asignación'!$A$4:$A$33,$A7,'Asignación'!$F$4:$F$33)) | G7: =IF($A7="","",SUMIFS('Asignación'!$F$4:$F$33,'Asignación'!$A$4:$A$33,$A7,'Asignación'!$G$4:$G$33,"<>")) | H7: =IF($A7="","",COUNTIFS('Asignación'!$A$4:$A$33,$A7,'Asignación'!$G$4:$G$33,"")) | I7: =IF($A7="","",IF($E7=0,"Sin filas de carga",IF($F7<$D7,IF($D7-$F7=1,"Falta 1 hora de carga","Faltan "&($D7-$F7)&" horas de carga"),IF($H7>0,IF($H7=1,"Falta 1 profesor","Faltan "&$H7&" profesores"),"Completa"))))
A8: =IF(Asignaturas!A7="","",Asignaturas!A7) | B8: =IF(Asignaturas!A7="","",Asignaturas!B7) | C8: =IF(Asignaturas!A7="","",Asignaturas!C7) | D8: =IF(Asignaturas!A7="","",Asignaturas!G7) | E8: =IF($A8="","",COUNTIF('Asignación'!$A$4:$A$33,$A8)) | F8: =IF($A8="","",SUMIF('Asignación'!$A$4:$A$33,$A8,'Asignación'!$F$4:$F$33)) | G8: =IF($A8="","",SUMIFS('Asignación'!$F$4:$F$33,'Asignación'!$A$4:$A$33,$A8,'Asignación'!$G$4:$G$33,"<>")) | H8: =IF($A8="","",COUNTIFS('Asignación'!$A$4:$A$33,$A8,'Asignación'!$G$4:$G$33,"")) | I8: =IF($A8="","",IF($E8=0,"Sin filas de carga",IF($F8<$D8,IF($D8-$F8=1,"Falta 1 hora de carga","Faltan "&($D8-$F8)&" horas de carga"),IF($H8>0,IF($H8=1,"Falta 1 profesor","Faltan "&$H8&" profesores"),"Completa"))))
A9: =IF(Asignaturas!A8="","",Asignaturas!A8) | B9: =IF(Asignaturas!A8="","",Asignaturas!B8) | C9: =IF(Asignaturas!A8="","",Asignaturas!C8) | D9: =IF(Asignaturas!A8="","",Asignaturas!G8) | E9: =IF($A9="","",COUNTIF('Asignación'!$A$4:$A$33,$A9)) | F9: =IF($A9="","",SUMIF('Asignación'!$A$4:$A$33,$A9,'Asignación'!$F$4:$F$33)) | G9: =IF($A9="","",SUMIFS('Asignación'!$F$4:$F$33,'Asignación'!$A$4:$A$33,$A9,'Asignación'!$G$4:$G$33,"<>")) | H9: =IF($A9="","",COUNTIFS('Asignación'!$A$4:$A$33,$A9,'Asignación'!$G$4:$G$33,"")) | I9: =IF($A9="","",IF($E9=0,"Sin filas de carga",IF($F9<$D9,IF($D9-$F9=1,"Falta 1 hora de carga","Faltan "&($D9-$F9)&" horas de carga"),IF($H9>0,IF($H9=1,"Falta 1 profesor","Faltan "&$H9&" profesores"),"Completa"))))
A10: =IF(Asignaturas!A9="","",Asignaturas!A9) | B10: =IF(Asignaturas!A9="","",Asignaturas!B9) | C10: =IF(Asignaturas!A9="","",Asignaturas!C9) | D10: =IF(Asignaturas!A9="","",Asignaturas!G9) | E10: =IF($A10="","",COUNTIF('Asignación'!$A$4:$A$33,$A10)) | F10: =IF($A10="","",SUMIF('Asignación'!$A$4:$A$33,$A10,'Asignación'!$F$4:$F$33)) | G10: =IF($A10="","",SUMIFS('Asignación'!$F$4:$F$33,'Asignación'!$A$4:$A$33,$A10,'Asignación'!$G$4:$G$33,"<>")) | H10: =IF($A10="","",COUNTIFS('Asignación'!$A$4:$A$33,$A10,'Asignación'!$G$4:$G$33,"")) | I10: =IF($A10="","",IF($E10=0,"Sin filas de carga",IF($F10<$D10,IF($D10-$F10=1,"Falta 1 hora de carga","Faltan "&($D10-$F10)&" horas de carga"),IF($H10>0,IF($H10=1,"Falta 1 profesor","Faltan "&$H10&" profesores"),"Completa"))))
A11: =IF(Asignaturas!A10="","",Asignaturas!A10) | B11: =IF(Asignaturas!A10="","",Asignaturas!B10) | C11: =IF(Asignaturas!A10="","",Asignaturas!C10) | D11: =IF(Asignaturas!A10="","",Asignaturas!G10) | E11: =IF($A11="","",COUNTIF('Asignación'!$A$4:$A$33,$A11)) | F11: =IF($A11="","",SUMIF('Asignación'!$A$4:$A$33,$A11,'Asignación'!$F$4:$F$33)) | G11: =IF($A11="","",SUMIFS('Asignación'!$F$4:$F$33,'Asignación'!$A$4:$A$33,$A11,'Asignación'!$G$4:$G$33,"<>")) | H11: =IF($A11="","",COUNTIFS('Asignación'!$A$4:$A$33,$A11,'Asignación'!$G$4:$G$33,"")) | I11: =IF($A11="","",IF($E11=0,"Sin filas de carga",IF($F11<$D11,IF($D11-$F11=1,"Falta 1 hora de carga","Faltan "&($D11-$F11)&" horas de carga"),IF($H11>0,IF($H11=1,"Falta 1 profesor","Faltan "&$H11&" profesores"),"Completa"))))
A12: =IF(Asignaturas!A11="","",Asignaturas!A11) | B12: =IF(Asignaturas!A11="","",Asignaturas!B11) | C12: =IF(Asignaturas!A11="","",Asignaturas!C11) | D12: =IF(Asignaturas!A11="","",Asignaturas!G11) | E12: =IF($A12="","",COUNTIF('Asignación'!$A$4:$A$33,$A12)) | F12: =IF($A12="","",SUMIF('Asignación'!$A$4:$A$33,$A12,'Asignación'!$F$4:$F$33)) | G12: =IF($A12="","",SUMIFS('Asignación'!$F$4:$F$33,'Asignación'!$A$4:$A$33,$A12,'Asignación'!$G$4:$G$33,"<>")) | H12: =IF($A12="","",COUNTIFS('Asignación'!$A$4:$A$33,$A12,'Asignación'!$G$4:$G$33,"")) | I12: =IF($A12="","",IF($E12=0,"Sin filas de carga",IF($F12<$D12,IF($D12-$F12=1,"Falta 1 hora de carga","Faltan "&($D12-$F12)&" horas de carga"),IF($H12>0,IF($H12=1,"Falta 1 profesor","Faltan "&$H12&" profesores"),"Completa"))))
A13: =IF(Asignaturas!A12="","",Asignaturas!A12) | B13: =IF(Asignaturas!A12="","",Asignaturas!B12) | C13: =IF(Asignaturas!A12="","",Asignaturas!C12) | D13: =IF(Asignaturas!A12="","",Asignaturas!G12) | E13: =IF($A13="","",COUNTIF('Asignación'!$A$4:$A$33,$A13)) | F13: =IF($A13="","",SUMIF('Asignación'!$A$4:$A$33,$A13,'Asignación'!$F$4:$F$33)) | G13: =IF($A13="","",SUMIFS('Asignación'!$F$4:$F$33,'Asignación'!$A$4:$A$33,$A13,'Asignación'!$G$4:$G$33,"<>")) | H13: =IF($A13="","",COUNTIFS('Asignación'!$A$4:$A$33,$A13,'Asignación'!$G$4:$G$33,"")) | I13: =IF($A13="","",IF($E13=0,"Sin filas de carga",IF($F13<$D13,IF($D13-$F13=1,"Falta 1 hora de carga","Faltan "&($D13-$F13)&" horas de carga"),IF($H13>0,IF($H13=1,"Falta 1 profesor","Faltan "&$H13&" profesores"),"Completa"))))
A14: =IF(Asignaturas!A13="","",Asignaturas!A13) | B14: =IF(Asignaturas!A13="","",Asignaturas!B13) | C14: =IF(Asignaturas!A13="","",Asignaturas!C13) | D14: =IF(Asignaturas!A13="","",Asignaturas!G13) | E14: =IF($A14="","",COUNTIF('Asignación'!$A$4:$A$33,$A14)) | F14: =IF($A14="","",SUMIF('Asignación'!$A$4:$A$33,$A14,'Asignación'!$F$4:$F$33)) | G14: =IF($A14="","",SUMIFS('Asignación'!$F$4:$F$33,'Asignación'!$A$4:$A$33,$A14,'Asignación'!$G$4:$G$33,"<>")) | H14: =IF($A14="","",COUNTIFS('Asignación'!$A$4:$A$33,$A14,'Asignación'!$G$4:$G$33,"")) | I14: =IF($A14="","",IF($E14=0,"Sin filas de carga",IF($F14<$D14,IF($D14-$F14=1,"Falta 1 hora de carga","Faltan "&($D14-$F14)&" horas de carga"),IF($H14>0,IF($H14=1,"Falta 1 profesor","Faltan "&$H14&" profesores"),"Completa"))))
... A16: =IF(Asignaturas!A15="","",Asignaturas!A15) | B16: =IF(Asignaturas!A15="","",Asignaturas!B15) | C16: =IF(Asignaturas!A15="","",Asignaturas!C15) | D16: =IF(Asignaturas!A15="","",Asignaturas!G15) | E16: =IF($A16="","",COUNTIF('Asignación'!$A$4:$A$33,$A16)) | F16: =IF($A16="","",SUMIF('Asignación'!$A$4:$A$33,$A16,'Asignación'!$F$4:$F$33)) | G16: =IF($A16="","",SUMIFS('Asignación'!$F$4:$F$33,'Asignación'!$A$4:$A$33,$A16,'Asignación'!$G$4:$G$33,"<>")) | H16: =IF($A16="","",COUNTIFS('Asignación'!$A$4:$A$33,$A16,'Asignación'!$G$4:$G$33,"")) | I16: =IF($A16="","",IF($E16=0,"Sin filas de carga",IF($F16<$D16,IF($D16-$F16=1,"Falta 1 hora de carga","Faltan "&($D16-$F16)&" horas de carga"),IF($H16>0,IF($H16=1,"Falta 1 profesor","Faltan "&$H16&" profesores"),"Completa"))))
B18: Asignatura completa (todo creado y asignado)
B19: Asignatura incompleta (ver la columna Estado)

Sheet Auxiliar
F1: =IF('Asignación'!$G$4="","",'Asignación'!$G$4&"#"&COUNTIF('Asignación'!$G$4:$G$4,'Asignación'!$G$4)) | G1: ='Asignación'!B4 | H1: ='Asignación'!D4 | I1: ='Asignación'!E4 | J1: ='Asignación'!F4 | L1: =IF('Asignación'!$G$4="","",'Asignación'!$G$4&"|"&'Asignación'!$A$4) | M1: =IF(L1="",0,IF(COUNTIF($L$1:$L1,L1)=1,1,0))
F2: =IF('Asignación'!$G$5="","",'Asignación'!$G$5&"#"&COUNTIF('Asignación'!$G$4:$G$5,'Asignación'!$G$5)) | G2: ='Asignación'!B5 | H2: ='Asignación'!D5 | I2: ='Asignación'!E5 | J2: ='Asignación'!F5 | L2: =IF('Asignación'!$G$5="","",'Asignación'!$G$5&"|"&'Asignación'!$A$5) | M2: =IF(L2="",0,IF(COUNTIF($L$1:$L2,L2)=1,1,0))
F3: =IF('Asignación'!$G$6="","",'Asignación'!$G$6&"#"&COUNTIF('Asignación'!$G$4:$G$6,'Asignación'!$G$6)) | G3: ='Asignación'!B6 | H3: ='Asignación'!D6 | I3: ='Asignación'!E6 | J3: ='Asignación'!F6 | L3: =IF('Asignación'!$G$6="","",'Asignación'!$G$6&"|"&'Asignación'!$A$6) | M3: =IF(L3="",0,IF(COUNTIF($L$1:$L3,L3)=1,1,0))
F4: =IF('Asignación'!$G$7="","",'Asignación'!$G$7&"#"&COUNTIF('Asignación'!$G$4:$G$7,'Asignación'!$G$7)) | G4: ='Asignación'!B7 | H4: ='Asignación'!D7 | I4: ='Asignación'!E7 | J4: ='Asignación'!F7 | L4: =IF('Asignación'!$G$7="","",'Asignación'!$G$7&"|"&'Asignación'!$A$7) | M4: =IF(L4="",0,IF(COUNTIF($L$1:$L4,L4)=1,1,0))
F5: =IF('Asignación'!$G$8="","",'Asignación'!$G$8&"#"&COUNTIF('Asignación'!$G$4:$G$8,'Asignación'!$G$8)) | G5: ='Asignación'!B8 | H5: ='Asignación'!D8 | I5: ='Asignación'!E8 | J5: ='Asignación'!F8 | L5: =IF('Asignación'!$G$8="","",'Asignación'!$G$8&"|"&'Asignación'!$A$8) | M5: =IF(L5="",0,IF(COUNTIF($L$1:$L5,L5)=1,1,0))
F6: =IF('Asignación'!$G$9="","",'Asignación'!$G$9&"#"&COUNTIF('Asignación'!$G$4:$G$9,'Asignación'!$G$9)) | G6: ='Asignación'!B9 | H6: ='Asignación'!D9 | I6: ='Asignación'!E9 | J6: ='Asignación'!F9 | L6: =IF('Asignación'!$G$9="","",'Asignación'!$G$9&"|"&'Asignación'!$A$9) | M6: =IF(L6="",0,IF(COUNTIF($L$1:$L6,L6)=1,1,0))
F7: =IF('Asignación'!$G$10="","",'Asignación'!$G$10&"#"&COUNTIF('Asignación'!$G$4:$G$10,'Asignación'!$G$10)) | G7: ='Asignación'!B10 | H7: ='Asignación'!D10 | I7: ='Asignación'!E10 | J7: ='Asignación'!F10 | L7: =IF('Asignación'!$G$10="","",'Asignación'!$G$10&"|"&'Asignación'!$A$10) | M7: =IF(L7="",0,IF(COUNTIF($L$1:$L7,L7)=1,1,0))
F8: =IF('Asignación'!$G$11="","",'Asignación'!$G$11&"#"&COUNTIF('Asignación'!$G$4:$G$11,'Asignación'!$G$11)) | G8: ='Asignación'!B11 | H8: ='Asignación'!D11 | I8: ='Asignación'!E11 | J8: ='Asignación'!F11 | L8: =IF('Asignación'!$G$11="","",'Asignación'!$G$11&"|"&'Asignación'!$A$11) | M8: =IF(L8="",0,IF(COUNTIF($L$1:$L8,L8)=1,1,0))
F9: =IF('Asignación'!$G$12="","",'Asignación'!$G$12&"#"&COUNTIF('Asignación'!$G$4:$G$12,'Asignación'!$G$12)) | G9: ='Asignación'!B12 | H9: ='Asignación'!D12 | I9: ='Asignación'!E12 | J9: ='Asignación'!F12 | L9: =IF('Asignación'!$G$12="","",'Asignación'!$G$12&"|"&'Asignación'!$A$12) | M9: =IF(L9="",0,IF(COUNTIF($L$1:$L9,L9)=1,1,0))
F10: =IF('Asignación'!$G$13="","",'Asignación'!$G$13&"#"&COUNTIF('Asignación'!$G$4:$G$13,'Asignación'!$G$13)) | G10: ='Asignación'!B13 | H10: ='Asignación'!D13 | I10: ='Asignación'!E13 | J10: ='Asignación'!F13 | L10: =IF('Asignación'!$G$13="","",'Asignación'!$G$13&"|"&'Asignación'!$A$13) | M10: =IF(L10="",0,IF(COUNTIF($L$1:$L10,L10)=1,1,0))
F11: =IF('Asignación'!$G$14="","",'Asignación'!$G$14&"#"&COUNTIF('Asignación'!$G$4:$G$14,'Asignación'!$G$14)) | G11: ='Asignación'!B14 | H11: ='Asignación'!D14 | I11: ='Asignación'!E14 | J11: ='Asignación'!F14 | L11: =IF('Asignación'!$G$14="","",'Asignación'!$G$14&"|"&'Asignación'!$A$14) | M11: =IF(L11="",0,IF(COUNTIF($L$1:$L11,L11)=1,1,0))
F12: =IF('Asignación'!$G$15="","",'Asignación'!$G$15&"#"&COUNTIF('Asignación'!$G$4:$G$15,'Asignación'!$G$15)) | G12: ='Asignación'!B15 | H12: ='Asignación'!D15 | I12: ='Asignación'!E15 | J12: ='Asignación'!F15 | L12: =IF('Asignación'!$G$15="","",'Asignación'!$G$15&"|"&'Asignación'!$A$15) | M12: =IF(L12="",0,IF(COUNTIF($L$1:$L12,L12)=1,1,0))
F13: =IF('Asignación'!$G$16="","",'Asignación'!$G$16&"#"&COUNTIF('Asignación'!$G$4:$G$16,'Asignación'!$G$16)) | G13: ='Asignación'!B16 | H13: ='Asignación'!D16 | I13: ='Asignación'!E16 | J13: ='Asignación'!F16 | L13: =IF('Asignación'!$G$16="","",'Asignación'!$G$16&"|"&'Asignación'!$A$16) | M13: =IF(L13="",0,IF(COUNTIF($L$1:$L13,L13)=1,1,0))
F14: =IF('Asignación'!$G$17="","",'Asignación'!$G$17&"#"&COUNTIF('Asignación'!$G$4:$G$17,'Asignación'!$G$17)) | G14: ='Asignación'!B17 | H14: ='Asignación'!D17 | I14: ='Asignación'!E17 | J14: ='Asignación'!F17 | L14: =IF('Asignación'!$G$17="","",'Asignación'!$G$17&"|"&'Asignación'!$A$17) | M14: =IF(L14="",0,IF(COUNTIF($L$1:$L14,L14)=1,1,0))
F15: =IF('Asignación'!$G$18="","",'Asignación'!$G$18&"#"&COUNTIF('Asignación'!$G$4:$G$18,'Asignación'!$G$18)) | G15: ='Asignación'!B18 | H15: ='Asignación'!D18 | I15: ='Asignación'!E18 | J15: ='Asignación'!F18 | L15: =IF('Asignación'!$G$18="","",'Asignación'!$G$18&"|"&'Asignación'!$A$18) | M15: =IF(L15="",0,IF(COUNTIF($L$1:$L15,L15)=1,1,0))
F16: =IF('Asignación'!$G$19="","",'Asignación'!$G$19&"#"&COUNTIF('Asignación'!$G$4:$G$19,'Asignación'!$G$19)) | G16: ='Asignación'!B19 | H16: ='Asignación'!D19 | I16: ='Asignación'!E19 | J16: ='Asignación'!F19 | L16: =IF('Asignación'!$G$19="","",'Asignación'!$G$19&"|"&'Asignación'!$A$19) | M16: =IF(L16="",0,IF(COUNTIF($L$1:$L16,L16)=1,1,0))
F17: =IF('Asignación'!$G$20="","",'Asignación'!$G$20&"#"&COUNTIF('Asignación'!$G$4:$G$20,'Asignación'!$G$20)) | G17: ='Asignación'!B20 | H17: ='Asignación'!D20 | I17: ='Asignación'!E20 | J17: ='Asignación'!F20 | L17: =IF('Asignación'!$G$20="","",'Asignación'!$G$20&"|"&'Asignación'!$A$20) | M17: =IF(L17="",0,IF(COUNTIF($L$1:$L17,L17)=1,1,0))
F18: =IF('Asignación'!$G$21="","",'Asignación'!$G$21&"#"&COUNTIF('Asignación'!$G$4:$G$21,'Asignación'!$G$21)) | G18: ='Asignación'!B21 | H18: ='Asignación'!D21 | I18: ='Asignación'!E21 | J18: ='Asignación'!F21 | L18: =IF('Asignación'!$G$21="","",'Asignación'!$G$21&"|"&'Asignación'!$A$21) | M18: =IF(L18="",0,IF(COUNTIF($L$1:$L18,L18)=1,1,0))
F19: =IF('Asignación'!$G$22="","",'Asignación'!$G$22&"#"&COUNTIF('Asignación'!$G$4:$G$22,'Asignación'!$G$22)) | G19: ='Asignación'!B22 | H19: ='Asignación'!D22 | I19: ='Asignación'!E22 | J19: ='Asignación'!F22 | L19: =IF('Asignación'!$G$22="","",'Asignación'!$G$22&"|"&'Asignación'!$A$22) | M19: =IF(L19="",0,IF(COUNTIF($L$1:$L19,L19)=1,1,0))
F20: =IF('Asignación'!$G$23="","",'Asignación'!$G$23&"#"&COUNTIF('Asignación'!$G$4:$G$23,'Asignación'!$G$23)) | G20: ='Asignación'!B23 | H20: ='Asignación'!D23 | I20: ='Asignación'!E23 | J20: ='Asignación'!F23 | L20: =IF('Asignación'!$G$23="","",'Asignación'!$G$23&"|"&'Asignación'!$A$23) | M20: =IF(L20="",0,IF(COUNTIF($L$1:$L20,L20)=1,1,0))
F21: =IF('Asignación'!$G$24="","",'Asignación'!$G$24&"#"&COUNTIF('Asignación'!$G$4:$G$24,'Asignación'!$G$24)) | G21: ='Asignación'!B24 | H21: ='Asignación'!D24 | I21: ='Asignación'!E24 | J21: ='Asignación'!F24 | L21: =IF('Asignación'!$G$24="","",'Asignación'!$G$24&"|"&'Asignación'!$A$24) | M21: =IF(L21="",0,IF(COUNTIF($L$1:$L21,L21)=1,1,0))
F22: =IF('Asignación'!$G$25="","",'Asignación'!$G$25&"#"&COUNTIF('Asignación'!$G$4:$G$25,'Asignación'!$G$25)) | G22: ='Asignación'!B25 | H22: ='Asignación'!D25 | I22: ='Asignación'!E25 | J22: ='Asignación'!F25 | L22: =IF('Asignación'!$G$25="","",'Asignación'!$G$25&"|"&'Asignación'!$A$25) | M22: =IF(L22="",0,IF(COUNTIF($L$1:$L22,L22)=1,1,0))
F23: =IF('Asignación'!$G$26="","",'Asignación'!$G$26&"#"&COUNTIF('Asignación'!$G$4:$G$26,'Asignación'!$G$26)) | G23: ='Asignación'!B26 | H23: ='Asignación'!D26 | I23: ='Asignación'!E26 | J23: ='Asignación'!F26 | L23: =IF('Asignación'!$G$26="","",'Asignación'!$G$26&"|"&'Asignación'!$A$26) | M23: =IF(L23="",0,IF(COUNTIF($L$1:$L23,L23)=1,1,0))
F24: =IF('Asignación'!$G$27="","",'Asignación'!$G$27&"#"&COUNTIF('Asignación'!$G$4:$G$27,'Asignación'!$G$27)) | G24: ='Asignación'!B27 | H24: ='Asignación'!D27 | I24: ='Asignación'!E27 | J24: ='Asignación'!F27 | L24: =IF('Asignación'!$G$27="","",'Asignación'!$G$27&"|"&'Asignación'!$A$27) | M24: =IF(L24="",0,IF(COUNTIF($L$1:$L24,L24)=1,1,0))
F25: =IF('Asignación'!$G$28="","",'Asignación'!$G$28&"#"&COUNTIF('Asignación'!$G$4:$G$28,'Asignación'!$G$28)) | G25: ='Asignación'!B28 | H25: ='Asignación'!D28 | I25: ='Asignación'!E28 | J25: ='Asignación'!F28 | L25: =IF('Asignación'!$G$28="","",'Asignación'!$G$28&"|"&'Asignación'!$A$28) | M25: =IF(L25="",0,IF(COUNTIF($L$1:$L25,L25)=1,1,0))
F26: =IF('Asignación'!$G$29="","",'Asignación'!$G$29&"#"&COUNTIF('Asignación'!$G$4:$G$29,'Asignación'!$G$29)) | G26: ='Asignación'!B29 | H26: ='Asignación'!D29 | I26: ='Asignación'!E29 | J26: ='Asignación'!F29 | L26: =IF('Asignación'!$G$29="","",'Asignación'!$G$29&"|"&'Asignación'!$A$29) | M26: =IF(L26="",0,IF(COUNTIF($L$1:$L26,L26)=1,1,0))
F27: =IF('Asignación'!$G$30="","",'Asignación'!$G$30&"#"&COUNTIF('Asignación'!$G$4:$G$30,'Asignación'!$G$30)) | G27: ='Asignación'!B30 | H27: ='Asignación'!D30 | I27: ='Asignación'!E30 | J27: ='Asignación'!F30 | L27: =IF('Asignación'!$G$30="","",'Asignación'!$G$30&"|"&'Asignación'!$A$30) | M27: =IF(L27="",0,IF(COUNTIF($L$1:$L27,L27)=1,1,0))
F28: =IF('Asignación'!$G$31="","",'Asignación'!$G$31&"#"&COUNTIF('Asignación'!$G$4:$G$31,'Asignación'!$G$31)) | G28: ='Asignación'!B31 | H28: ='Asignación'!D31 | I28: ='Asignación'!E31 | J28: ='Asignación'!F31 | L28: =IF('Asignación'!$G$31="","",'Asignación'!$G$31&"|"&'Asignación'!$A$31) | M28: =IF(L28="",0,IF(COUNTIF($L$1:$L28,L28)=1,1,0))
F29: =IF('Asignación'!$G$32="","",'Asignación'!$G$32&"#"&COUNTIF('Asignación'!$G$4:$G$32,'Asignación'!$G$32)) | G29: ='Asignación'!B32 | H29: ='Asignación'!D32 | I29: ='Asignación'!E32 | J29: ='Asignación'!F32 | L29: =IF('Asignación'!$G$32="","",'Asignación'!$G$32&"|"&'Asignación'!$A$32) | M29: =IF(L29="",0,IF(COUNTIF($L$1:$L29,L29)=1,1,0))
F30: =IF('Asignación'!$G$33="","",'Asignación'!$G$33&"#"&COUNTIF('Asignación'!$G$4:$G$33,'Asignación'!$G$33)) | G30: ='Asignación'!B33 | H30: ='Asignación'!D33 | I30: ='Asignación'!E33 | J30: ='Asignación'!F33 | L30: =IF('Asignación'!$G$33="","",'Asignación'!$G$33&"|"&'Asignación'!$A$33) | M30: =IF(L30="",0,IF(COUNTIF($L$1:$L30,L30)=1,1,0))
