Workbook
Name AulasValidas: 'Datos'!$A$1:$A$15

Sheet Aulas
A1: Lunes | B1: Aula 1 | C1: Aula 2 | D1: Aula 3 | E1: Aula 4 | F1: Aula 5 | G1: Aula 6 | H1: Aula 7 | I1: Aula 8 | J1: Aula 9 | K1: Aula 10 | L1: Aula 11 | M1: Aula 12 | N1: Lab 1 | O1: Lab 2 | P1: Salón
A2: Turno 1 | B2: =SUBSTITUTE(TRIM(IF('C111'!B5="Aula 1","C111 ","")&IF('C112'!B5="Aula 1","C112 ","")&IF('C113'!B5="Aula 1","C113 ","")&IF('C121'!B5="Aula 1","C121 ","")&IF('C122'!B5="Aula 1","C122 ","")&IF('C211'!B5="Aula 1","C211 ","")&IF('C212'!B5="Aula 1","C212 ","")&IF('C311'!B5="Aula 1","C311 ","")&IF('C312'!B5="Aula 1","C312 ","")&IF('C411'!B5="Aula 1","C411 ","")&IF('C412'!B5="Aula 1","C412 ","")&IF('M111'!B5="Aula 1","M111 ","")&IF('M112'!B5="Aula 1","M112 ","")&IF('M211'!B5="Aula 1","M211 ","")&IF('M212'!B5="Aula 1","M212 ","")&IF('M311'!B5="Aula 1","M311 ","")&IF('M411'!B5="Aula 1","M411 ","")&IF('D111'!B5="Aula 1","D111 ","")&IF('D112'!B5="Aula 1","D112 ","")&IF('D211'!B5="Aula 1","D211 ","")&IF('D311'!B5="Aula 1","D311 ","")&IF('D411'!B5="Aula 1","D411 ",""))," ",",") | C2: =SUBSTITUTE(TRIM(IF('C111'!B5="Aula 2","C111 ","")&IF('C112'!B5="Aula 2","C112 ","")&IF('C113'!B5="Aula 2","C113 ","")&IF('C121'!B5="Aula 2","C121 ","")&IF('C122'!B5="Aula 2","C122 ","")&IF('C211'!B5="Aula 2","C211 ","")&IF('C212'!B5="Aula 2","C212 ","")&IF('C311'!B5="Aula 2","C311 ","")&IF('C312'!B5="Aula 2","C312 ","")&IF('C411'!B5="Aula 2","C411 ","")&IF('C412'!B5="Aula 2","C412 ","")&IF('M111'!B5="Aula 2","M111 ","")&IF('M112'!B5="Aula 2","M112 ","")&IF('M211'!B5="Aula 2","M211 ","")&IF('M212'!B5="Aula 2","M212 ","")&IF('M311'!B5="Aula 2","M311 ","")&IF('M411'!B5="Aula 2","M411 ","")&IF('D111'!B5="Aula 2","D111 ","")&IF('D112'!B5="Aula 2","D112 ","")&IF('D211'!B5="Aula 2","D211 ","")&IF('D311'!B5="Aula 2","D311 ","")&IF('D411'!B5="Aula 2","D411 ",""))," ",",") | D2: =SUBSTITUTE(TRIM(IF('C111'!B5="Aula 3","C111 ","")&IF('C112'!B5="Aula 3","C112 ","")&IF('C113'!B5="Aula 3","C113 ","")&IF('C121'!B5="Aula 3","C121 ","")&IF('C122'!B5="Aula 3","C122 ","")&IF('C211'!B5="Aula 3","C211 ","")&IF('C212'!B5="Aula 3","C212 ","")&IF('C311'!B5="Aula 3","C311 ","")&IF('C312'!B5="Aula 3","C312 ","")&IF('C411'!B5="Aula 3","C411 ","")&IF('C412'!B5="Aula 3","C412 ","")&IF('M111'!B5="Aula 3","M111 ","")&IF('M112'!B5="Aula 3","M112 ","")&IF('M211'!B5="Aula 3","M211 ","")&IF('M212'!B5="Aula 3","M212 ","")&IF('M311'!B5="Aula 3","M311 ","")&IF('M411'!B5="Aula 3","M411 ","")&IF('D111'!B5="Aula 3","D111 ","")&IF('D112'!B5="Aula 3","D112 ","")&IF('D211'!B5="Aula 3","D211 ","")&IF('D311'!B5="Aula 3","D311 ","")&IF('D411'!B5="Aula 3","D411 ",""))," ",",") | E2: =SUBSTITUTE(TRIM(IF('C111'!B5="Aula 4","C111 ","")&IF('C112'!B5="Aula 4","C112 ","")&IF('C113'!B5="Aula 4","C113 ","")&IF('C121'!B5="Aula 4","C121 ","")&IF('C122'!B5="Aula 4","C122 ","")&IF('C211'!B5="Aula 4","C211 ","")&IF('C212'!B5="Aula 4","C212 ","")&IF('C311'!B5="Aula 4","C311 ","")&IF('C312'!B5="Aula 4","C312 ","")&IF('C411'!B5="Aula 4","C411 ","")&IF('C412'!B5="Aula 4","C412 ","")&IF('M111'!B5="Aula 4","M111 ","")&IF('M112'!B5="Aula 4","M112 ","")&IF('M211'!B5="Aula 4","M211 ","")&IF('M212'!B5="Aula 4","M212 ","")&IF('M311'!B5="Aula 4","M311 ","")&IF('M411'!B5="Aula 4","M411 ","")&IF('D111'!B5="Aula 4","D111 ","")&IF('D112'!B5="Aula 4","D112 ","")&IF('D211'!B5="Aula 4","D211 ","")&IF('D311'!B5="Aula 4","D311 ","")&IF('D411'!B5="Aula 4","D411 ",""))," ",",") | F2: =SUBSTITUTE(TRIM(IF('C111'!B5="Aula 5","C111 ","")&IF('C112'!B5="Aula 5","C112 ","")&IF('C113'!B5="Aula 5","C113 ","")&IF('C121'!B5="Aula 5","C121 ","")&IF('C122'!B5="Aula 5","C122 ","")&IF('C211'!B5="Aula 5","C211 ","")&IF('C212'!B5="Aula 5","C212 ","")&IF('C311'!B5="Aula 5","C311 ","")&IF('C312'!B5="Aula 5","C312 ","")&IF('C411'!B5="Aula 5","C411 ","")&IF('C412'!B5="Aula 5","C412 ","")&IF('M111'!B5="Aula 5","M111 ","")&IF('M112'!B5="Aula 5","M112 ","")&IF('M211'!B5="Aula 5","M211 ","")&IF('M212'!B5="Aula 5","M212 ","")&IF('M311'!B5="Aula 5","M311 ","")&IF('M411'!B5="Aula 5","M411 ","")&IF('D111'!B5="Aula 5","D111 ","")&IF('D112'!B5="Aula 5","D112 ","")&IF('D211'!B5="Aula 5","D211 ","")&IF('D311'!B5="Aula 5","D311 ","")&IF('D411'!B5="Aula 5","D411 ",""))," ",",") | G2: =SUBSTITUTE(TRIM(IF('C111'!B5="Aula 6","C111 ","")&IF('C112'!B5="Aula 6","C112 ","")&IF('C113'!B5="Aula 6","C113 ","")&IF('C121'!B5="Aula 6","C121 ","")&IF('C122'!B5="Aula 6","C122 ","")&IF('C211'!B5="Aula 6","C211 ","")&IF('C212'!B5="Aula 6","C212 ","")&IF('C311'!B5="Aula 6","C311 ","")&IF('C312'!B5="Aula 6","C312 ","")&IF('C411'!B5="Aula 6","C411 ","")&IF('C412'!B5="Aula 6","C412 ","")&IF('M111'!B5="Aula 6","M111 ","")&IF('M112'!B5="Aula 6","M112 ","")&IF('M211'!B5="Aula 6","M211 ","")&IF('M212'!B5="Aula 6","M212 ","")&IF('M311'!B5="Aula 6","M311 ","")&IF('M411'!B5="Aula 6","M411 ","")&IF('D111'!B5="Aula 6","D111 ","")&IF('D112'!B5="Aula 6","D112 ","")&IF('D211'!B5="Aula 6","D211 ","")&IF('D311'!B5="Aula 6","D311 ","")&IF('D411'!B5="Aula 6","D411 ",""))," ",",") | H2: =SUBSTITUTE(TRIM(IF('C111'!B5="Aula 7","C111 ","")&IF('C112'!B5="Aula 7","C112 ","")&IF('C113'!B5="Aula 7","C113 ","")&IF('C121'!B5="Aula 7","C121 ","")&IF('C122'!B5="Aula 7","C122 ","")&IF('C211'!B5="Aula 7","C211 ","")&IF('C212'!B5="Aula 7","C212 ","")&IF('C311'!B5="Aula 7","C311 ","")&IF('C312'!B5="Aula 7","C312 ","")&IF('C411'!B5="Aula 7","C411 ","")&IF('C412'!B5="Aula 7","C412 ","")&IF('M111'!B5="Aula 7","M111 ","")&IF('M112'!B5="Aula 7","M112 ","")&IF('M211'!B5="Aula 7","M211 ","")&IF('M212'!B5="Aula 7","M212 ","")&IF('M311'!B5="Aula 7","M311 ","")&IF('M411'!B5="Aula 7","M411 ","")&IF('D111'!B5="Aula 7","D111 ","")&IF('D112'!B5="Aula 7","D112 ","")&IF('D211'!B5="Aula 7","D211 ","")&IF('D311'!B5="Aula 7","D311 ","")&IF('D411'!B5="Aula 7","D411 ",""))," ",",") | I2: =SUBSTITUTE(TRIM(IF('C111'!B5="Aula 8","C111 ","")&IF('C112'!B5="Aula 8","C112 ","")&IF('C113'!B5="Aula 8","C113 ","")&IF('C121'!B5="Aula 8","C121 ","")&IF('C122'!B5="Aula 8","C122 ","")&IF('C211'!B5="Aula 8","C211 ","")&IF('C212'!B5="Aula 8","C212 ","")&IF('C311'!B5="Aula 8","C311 ","")&IF('C312'!B5="Aula 8","C312 ","")&IF('C411'!B5="Aula 8","C411 ","")&IF('C412'!B5="Aula 8","C412 ","")&IF('M111'!B5="Aula 8","M111 ","")&IF('M112'!B5="Aula 8","M112 ","")&IF('M211'!B5="Aula 8","M211 ","")&IF('M212'!B5="Aula 8","M212 ","")&IF('M311'!B5="Aula 8","M311 ","")&IF('M411'!B5="Aula 8","M411 ","")&IF('D111'!B5="Aula 8","D111 ","")&IF('D112'!B5="Aula 8","D112 ","")&IF('D211'!B5="Aula 8","D211 ","")&IF('D311'!B5="Aula 8","D311 ","")&IF('D411'!B5="Aula 8","D411 ",""))," ",",") | J2: =SUBSTITUTE(TRIM(IF('C111'!B5="Aula 9","C111 ","")&IF('C112'!B5="Aula 9","C112 ","")&IF('C113'!B5="Aula 9","C113 ","")&IF('C121'!B5="Aula 9","C121 ","")&IF('C122'!B5="Aula 9","C122 ","")&IF('C211'!B5="Aula 9","C211 ","")&IF('C212'!B5="Aula 9","C212 ","")&IF('C311'!B5="Aula 9","C311 ","")&IF('C312'!B5="Aula 9","C312 ","")&IF('C411'!B5="Aula 9","C411 ","")&IF('C412'!B5="Aula 9","C412 ","")&IF('M111'!B5="Aula 9","M111 ","")&IF('M112'!B5="Aula 9","M112 ","")&IF('M211'!B5="Aula 9","M211 ","")&IF('M212'!B5="Aula 9","M212 ","")&IF('M311'!B5="Aula 9","M311 ","")&IF('M411'!B5="Aula 9","M411 ","")&IF('D111'!B5="Aula 9","D111 ","")&IF('D112'!B5="Aula 9","D112 ","")&IF('D211'!B5="Aula 9","D211 ","")&IF('D311'!B5="Aula 9","D311 ","")&IF('D411'!B5="Aula 9","D411 ",""))," ",",") | K2: =SUBSTITUTE(TRIM(IF('C111'!B5="Aula 10","C111 ","")&IF('C112'!B5="Aula 10","C112 ","")&IF('C113'!B5="Aula 10","C113 ","")&IF('C121'!B5="Aula 10","C121 ","")&IF('C122'!B5="Aula 10","C122 ","")&IF('C211'!B5="Aula 10","C211 ","")&IF('C212'!B5="Aula 10","C212 ","")&IF('C311'!B5="Aula 10","C311 ","")&IF('C312'!B5="Aula 10","C312 ","")&IF('C411'!B5="Aula 10","C411 ","")&IF('C412'!B5="Aula 10","C412 ","")&IF('M111'!B5="Aula 10","M111 ","")&IF('M112'!B5="Aula 10","M112 ","")&IF('M211'!B5="Aula 10","M211 ","")&IF('M212'!B5="Aula 10","M212 ","")&IF('M311'!B5="Aula 10","M311 ","")&IF('M411'!B5="Aula 10","M411 ","")&IF('D111'!B5="Aula 10","D111 ","")&IF('D112'!B5="Aula 10","D112 ","")&IF('D211'!B5="Aula 10","D211 ","")&IF('D311'!B5="Aula 10","D311 ","")&IF('D411'!B5="Aula 10","D411 ",""))," ",",") | L2: =SUBSTITUTE(TRIM(IF('C111'!B5="Aula 11","C111 ","")&IF('C112'!B5="Aula 11","C112 ","")&IF('C113'!B5="Aula 11","C113 ","")&IF('C121'!B5="Aula 11","C121 ","")&IF('C122'!B5="Aula 11","C122 ","")&IF('C211'!B5="Aula 11","C211 ","")&IF('C212'!B5="Aula 11","C212 ","")&IF('C311'!B5="Aula 11","C311 ","")&IF('C312'!B5="Aula 11","C312 ","")&IF('C411'!B5="Aula 11","C411 ","")&IF('C412'!B5="Aula 11","C412 ","")&IF('M111'!B5="Aula 11","M111 ","")&IF('M112'!B5="Aula 11","M112 ","")&IF('M211'!B5="Aula 11","M211 ","")&IF('M212'!B5="Aula 11","M212 ","")&IF('M311'!B5="Aula 11","M311 ","")&IF('M411'!B5="Aula 11","M411 ","")&IF('D111'!B5="Aula 11","D111 ","")&IF('D112'!B5="Aula 11","D112 ","")&IF('D211'!B5="Aula 11","D211 ","")&IF('D311'!B5="Aula 11","D311 ","")&IF('D411'!B5="Aula 11","D411 ",""))," ",",") | M2: =SUBSTITUTE(TRIM(IF('C111'!B5="Aula 12","C111 ","")&IF('C112'!B5="Aula 12","C112 ","")&IF('C113'!B5="Aula 12","C113 ","")&IF('C121'!B5="Aula 12","C121 ","")&IF('C122'!B5="Aula 12","C122 ","")&IF('C211'!B5="Aula 12","C211 ","")&IF('C212'!B5="Aula 12","C212 ","")&IF('C311'!B5="Aula 12","C311 ","")&IF('C312'!B5="Aula 12","C312 ","")&IF('C411'!B5="Aula 12","C411 ","")&IF('C412'!B5="Aula 12","C412 ","")&IF('M111'!B5="Aula 12","M111 ","")&IF('M112'!B5="Aula 12","M112 ","")&IF('M211'!B5="Aula 12","M211 ","")&IF('M212'!B5="Aula 12","M212 ","")&IF('M311'!B5="Aula 12","M311 ","")&IF('M411'!B5="Aula 12","M411 ","")&IF('D111'!B5="Aula 12","D111 ","")&IF('D112'!B5="Aula 12","D112 ","")&IF('D211'!B5="Aula 12","D211 ","")&IF('D311'!B5="Aula 12","D311 ","")&IF('D411'!B5="Aula 12","D411 ",""))," ",",") | N2: =SUBSTITUTE(TRIM(IF('C111'!B5="Lab 1","C111 ","")&IF('C112'!B5="Lab 1","C112 ","")&IF('C113'!B5="Lab 1","C113 ","")&IF('C121'!B5="Lab 1","C121 ","")&IF('C122'!B5="Lab 1","C122 ","")&IF('C211'!B5="Lab 1","C211 ","")&IF('C212'!B5="Lab 1","C212 ","")&IF('C311'!B5="Lab 1","C311 ","")&IF('C312'!B5="Lab 1","C312 ","")&IF('C411'!B5="Lab 1","C411 ","")&IF('C412'!B5="Lab 1","C412 ","")&IF('M111'!B5="Lab 1","M111 ","")&IF('M112'!B5="Lab 1","M112 ","")&IF('M211'!B5="Lab 1","M211 ","")&IF('M212'!B5="Lab 1","M212 ","")&IF('M311'!B5="Lab 1","M311 ","")&IF('M411'!B5="Lab 1","M411 ","")&IF('D111'!B5="Lab 1","D111 ","")&IF('D112'!B5="Lab 1","D112 ","")&IF('D211'!B5="Lab 1","D211 ","")&IF('D311'!B5="Lab 1","D311 ","")&IF('D411'!B5="Lab 1","D411 ",""))," ",",") | O2: =SUBSTITUTE(TRIM(IF('C111'!B5="Lab 2","C111 ","")&IF('C112'!B5="Lab 2","C112 ","")&IF('C113'!B5="Lab 2","C113 ","")&IF('C121'!B5="Lab 2","C121 ","")&IF('C122'!B5="Lab 2","C122 ","")&IF('C211'!B5="Lab 2","C211 ","")&IF('C212'!B5="Lab 2","C212 ","")&IF('C311'!B5="Lab 2","C311 ","")&IF('C312'!B5="Lab 2","C312 ","")&IF('C411'!B5="Lab 2","C411 ","")&IF('C412'!B5="Lab 2","C412 ","")&IF('M111'!B5="Lab 2","M111 ","")&IF('M112'!B5="Lab 2","M112 ","")&IF('M211'!B5="Lab 2","M211 ","")&IF('M212'!B5="Lab 2","M212 ","")&IF('M311'!B5="Lab 2","M311 ","")&IF('M411'!B5="Lab 2","M411 ","")&IF('D111'!B5="Lab 2","D111 ","")&IF('D112'!B5="Lab 2","D112 ","")&IF('D211'!B5="Lab 2","D211 ","")&IF('D311'!B5="Lab 2","D311 ","")&IF('D411'!B5="Lab 2","D411 ",""))," ",",") | P2: =SUBSTITUTE(TRIM(IF('C111'!B5="Salón","C111 ","")&IF('C112'!B5="Salón","C112 ","")&IF('C113'!B5="Salón","C113 ","")&IF('C121'!B5="Salón","C121 ","")&IF('C122'!B5="Salón","C122 ","")&IF('C211'!B5="Salón","C211 ","")&IF('C212'!B5="Salón","C212 ","")&IF('C311'!B5="Salón","C311 ","")&IF('C312'!B5="Salón","C312 ","")&IF('C411'!B5="Salón","C411 ","")&IF('C412'!B5="Salón","C412 ","")&IF('M111'!B5="Salón","M111 ","")&IF('M112'!B5="Salón","M112 ","")&IF('M211'!B5="Salón","M211 ","")&IF('M212'!B5="Salón","M212 ","")&IF('M311'!B5="Salón","M311 ","")&IF('M411'!B5="Salón","M411 ","")&IF('D111'!B5="Salón","D111 ","")&IF('D112'!B5="Salón","D112 ","")&IF('D211'!B5="Salón","D211 ","")&IF('D311'!B5="Salón","D311 ","")&IF('D411'!B5="Salón","D411 ",""))," ",",")
A3: Turno 2 | B3: =SUBSTITUTE(TRIM(IF('C111'!B7="Aula 1","C111 ","")&IF('C112'!B7="Aula 1","C112 ","")&IF('C113'!B7="Aula 1","C113 ","")&IF('C121'!B7="Aula 1","C121 ","")&IF('C122'!B7="Aula 1","C122 ","")&IF('C211'!B7="Aula 1","C211 ","")&IF('C212'!B7="Aula 1","C212 ","")&IF('C311'!B7="Aula 1","C311 ","")&IF('C312'!B7="Aula 1","C312 ","")&IF('C411'!B7="Aula 1","C411 ","")&IF('C412'!B7="Aula 1","C412 ","")&IF('M111'!B7="Aula 1","M111 ","")&IF('M112'!B7="Aula 1","M112 ","")&IF('M211'!B7="Aula 1","M211 ","")&IF('M212'!B7="Aula 1","M212 ","")&IF('M311'!B7="Aula 1","M311 ","")&IF('M411'!B7="Aula 1","M411 ","")&IF('D111'!B7="Aula 1","D111 ","")&IF('D112'!B7="Aula 1","D112 ","")&IF('D211'!B7="Aula 1","D211 ","")&IF('D311'!B7="Aula 1","D311 ","")&IF('D411'!B7="Aula 1","D411 ",""))," ",",") | C3: =SUBSTITUTE(TRIM(IF('C111'!B7="Aula 2","C111 ","")&IF('C112'!B7="Aula 2","C112 ","")&IF('C113'!B7="Aula 2","C113 ","")&IF('C121'!B7="Aula 2","C121 ","")&IF('C122'!B7="Aula 2","C122 ","")&IF('C211'!B7="Aula 2","C211 ","")&IF('C212'!B7="Aula 2","C212 ","")&IF('C311'!B7="Aula 2","C311 ","")&IF('C312'!B7="Aula 2","C312 ","")&IF('C411'!B7="Aula 2","C411 ","")&IF('C412'!B7="Aula 2","C412 ","")&IF('M111'!B7="Aula 2","M111 ","")&IF('M112'!B7="Aula 2","M112 ","")&IF('M211'!B7="Aula 2","M211 ","")&IF('M212'!B7="Aula 2","M212 ","")&IF('M311'!B7="Aula 2","M311 ","")&IF('M411'!B7="Aula 2","M411 ","")&IF('D111'!B7="Aula 2","D111 ","")&IF('D112'!B7="Aula 2","D112 ","")&IF('D211'!B7="Aula 2","D211 ","")&IF('D311'!B7="Aula 2","D311 ","")&IF('D411'!B7="Aula 2","D411 ",""))," ",",") | D3: =SUBSTITUTE(TRIM(IF('C111'!B7="Aula 3","C111 ","")&IF('C112'!B7="Aula 3","C112 ","")&IF('C113'!B7="Aula 3","C113 ","")&IF('C121'!B7="Aula 3","C121 ","")&IF('C122'!B7="Aula 3","C122 ","")&IF('C211'!B7="Aula 3","C211 ","")&IF('C212'!B7="Aula 3","C212 ","")&IF('C311'!B7="Aula 3","C311 ","")&IF('C312'!B7="Aula 3","C312 ","")&IF('C411'!B7="Aula 3","C411 ","")&IF('C412'!B7="Aula 3","C412 ","")&IF('M111'!B7="Aula 3","M111 ","")&IF('M112'!B7="Aula 3","M112 ","")&IF('M211'!B7="Aula 3","M211 ","")&IF('M212'!B7="Aula 3","M212 ","")&IF('M311'!B7="Aula 3","M311 ","")&IF('M411'!B7="Aula 3","M411 ","")&IF('D111'!B7="Aula 3","D111 ","")&IF('D112'!B7="Aula 3","D112 ","")&IF('D211'!B7="Aula 3","D211 ","")&IF('D311'!B7="Aula 3","D311 ","")&IF('D411'!B7="Aula 3","D411 ",""))," ",",") | E3: =SUBSTITUTE(TRIM(IF('C111'!B7="Aula 4","C111 ","")&IF('C112'!B7="Aula 4","C112 ","")&IF('C113'!B7="Aula 4","C113 ","")&IF('C121'!B7="Aula 4","C121 ","")&IF('C122'!B7="Aula 4","C122 ","")&IF('C211'!B7="Aula 4","C211 ","")&IF('C212'!B7="Aula 4","C212 ","")&IF('C311'!B7="Aula 4","C311 ","")&IF('C312'!B7="Aula 4","C312 ","")&IF('C411'!B7="Aula 4","C411 ","")&IF('C412'!B7="Aula 4","C412 ","")&IF('M111'!B7="Aula 4","M111 ","")&IF('M112'!B7="Aula 4","M112 ","")&IF('M211'!B7="Aula 4","M211 ","")&IF('M212'!B7="Aula 4","M212 ","")&IF('M311'!B7="Aula 4","M311 ","")&IF('M411'!B7="Aula 4","M411 ","")&IF('D111'!B7="Aula 4","D111 ","")&IF('D112'!B7="Aula 4","D112 ","")&IF('D211'!B7="Aula 4","D211 ","")&IF('D311'!B7="Aula 4","D311 ","")&IF('D411'!B7="Aula 4","D411 ",""))," ",",") | F3: =SUBSTITUTE(TRIM(IF('C111'!B7="Aula 5","C111 ","")&IF('C112'!B7="Aula 5","C112 ","")&IF('C113'!B7="Aula 5","C113 ","")&IF('C121'!B7="Aula 5","C121 ","")&IF('C122'!B7="Aula 5","C122 ","")&IF('C211'!B7="Aula 5","C211 ","")&IF('C212'!B7="Aula 5","C212 ","")&IF('C311'!B7="Aula 5","C311 ","")&IF('C312'!B7="Aula 5","C312 ","")&IF('C411'!B7="Aula 5","C411 ","")&IF('C412'!B7="Aula 5","C412 ","")&IF('M111'!B7="Aula 5","M111 ","")&IF('M112'!B7="Aula 5","M112 ","")&IF('M211'!B7="Aula 5","M211 ","")&IF('M212'!B7="Aula 5","M212 ","")&IF('M311'!B7="Aula 5","M311 ","")&IF('M411'!B7="Aula 5","M411 ","")&IF('D111'!B7="Aula 5","D111 ","")&IF('D112'!B7="Aula 5","D112 ","")&IF('D211'!B7="Aula 5","D211 ","")&IF('D311'!B7="Aula 5","D311 ","")&IF('D411'!B7="Aula 5","D411 ",""))," ",",") | G3: =SUBSTITUTE(TRIM(IF('C111'!B7="Aula 6","C111 ","")&IF('C112'!B7="Aula 6","C112 ","")&IF('C113'!B7="Aula 6","C113 ","")&IF('C121'!B7="Aula 6","C121 ","")&IF('C122'!B7="Aula 6","C122 ","")&IF('C211'!B7="Aula 6","C211 ","")&IF('C212'!B7="Aula 6","C212 ","")&IF('C311'!B7="Aula 6","C311 ","")&IF('C312'!B7="Aula 6","C312 ","")&IF('C411'!B7="Aula 6","C411 ","")&IF('C412'!B7="Aula 6","C412 ","")&IF('M111'!B7="Aula 6","M111 ","")&IF('M112'!B7="Aula 6","M112 ","")&IF('M211'!B7="Aula 6","M211 ","")&IF('M212'!B7="Aula 6","M212 ","")&IF('M311'!B7="Aula 6","M311 ","")&IF('M411'!B7="Aula 6","M411 ","")&IF('D111'!B7="Aula 6","D111 ","")&IF('D112'!B7="Aula 6","D112 ","")&IF('D211'!B7="Aula 6","D211 ","")&IF('D311'!B7="Aula 6","D311 ","")&IF('D411'!B7="Aula 6","D411 ",""))," ",",") | H3: =SUBSTITUTE(TRIM(IF('C111'!B7="Aula 7","C111 ","")&IF('C112'!B7="Aula 7","C112 ","")&IF('C113'!B7="Aula 7","C113 ","")&IF('C121'!B7="Aula 7","C121 ","")&IF('C122'!B7="Aula 7","C122 ","")&IF('C211'!B7="Aula 7","C211 ","")&IF('C212'!B7="Aula 7","C212 ","")&IF('C311'!B7="Aula 7","C311 ","")&IF('C312'!B7="Aula 7","C312 ","")&IF('C411'!B7="Aula 7","C411 ","")&IF('C412'!B7="Aula 7","C412 ","")&IF('M111'!B7="Aula 7","M111 ","")&IF('M112'!B7="Aula 7","M112 ","")&IF('M211'!B7="Aula 7","M211 ","")&IF('M212'!B7="Aula 7","M212 ","")&IF('M311'!B7="Aula 7","M311 ","")&IF('M411'!B7="Aula 7","M411 ","")&IF('D111'!B7="Aula 7","D111 ","")&IF('D112'!B7="Aula 7","D112 ","")&IF('D211'!B7="Aula 7","D211 ","")&IF('D311'!B7="Aula 7","D311 ","")&IF('D411'!B7="Aula 7","D411 ",""))," ",",") | I3: =SUBSTITUTE(TRIM(IF('C111'!B7="Aula 8","C111 ","")&IF('C112'!B7="Aula 8","C112 ","")&IF('C113'!B7="Aula 8","C113 ","")&IF('C121'!B7="Aula 8","C121 ","")&IF('C122'!B7="Aula 8","C122 ","")&IF('C211'!B7="Aula 8","C211 ","")&IF('C212'!B7="Aula 8","C212 ","")&IF('C311'!B7="Aula 8","C311 ","")&IF('C312'!B7="Aula 8","C312 ","")&IF('C411'!B7="Aula 8","C411 ","")&IF('C412'!B7="Aula 8","C412 ","")&IF('M111'!B7="Aula 8","M111 ","")&IF('M112'!B7="Aula 8","M112 ","")&IF('M211'!B7="Aula 8","M211 ","")&IF('M212'!B7="Aula 8","M212 ","")&IF('M311'!B7="Aula 8","M311 ","")&IF('M411'!B7="Aula 8","M411 ","")&IF('D111'!B7="Aula 8","D111 ","")&IF('D112'!B7="Aula 8","D112 ","")&IF('D211'!B7="Aula 8","D211 ","")&IF('D311'!B7="Aula 8","D311 ","")&IF('D411'!B7="Aula 8","D411 ",""))," ",",") | J3: =SUBSTITUTE(TRIM(IF('C111'!B7="Aula 9","C111 ","")&IF('C112'!B7="Aula 9","C112 ","")&IF('C113'!B7="Aula 9","C113 ","")&IF('C121'!B7="Aula 9","C121 ","")&IF('C122'!B7="Aula 9","C122 ","")&IF('C211'!B7="Aula 9","C211 ","")&IF('C212'!B7="Aula 9","C212 ","")&IF('C311'!B7="Aula 9","C311 ","")&IF('C312'!B7="Aula 9","C312 ","")&IF('C411'!B7="Aula 9","C411 ","")&IF('C412'!B7="Aula 9","C412 ","")&IF('M111'!B7="Aula 9","M111 ","")&IF('M112'!B7="Aula 9","M112 ","")&IF('M211'!B7="Aula 9","M211 ","")&IF('M212'!B7="Aula 9","M212 ","")&IF('M311'!B7="Aula 9","M311 ","")&IF('M411'!B7="Aula 9","M411 ","")&IF('D111'!B7="Aula 9","D111 ","")&IF('D112'!B7="Aula 9","D112 ","")&IF('D211'!B7="Aula 9","D211 ","")&IF('D311'!B7="Aula 9","D311 ","")&IF('D411'!B7="Aula 9","D411 ",""))," ",",") | K3: =SUBSTITUTE(TRIM(IF('C111'!B7="Aula 10","C111 ","")&IF('C112'!B7="Aula 10","C112 ","")&IF('C113'!B7="Aula 10","C113 ","")&IF('C121'!B7="Aula 10","C121 ","")&IF('C122'!B7="Aula 10","C122 ","")&IF('C211'!B7="Aula 10","C211 ","")&IF('C212'!B7="Aula 10","C212 ","")&IF('C311'!B7="Aula 10","C311 ","")&IF('C312'!B7="Aula 10","C312 ","")&IF('C411'!B7="Aula 10","C411 ","")&IF('C412'!B7="Aula 10","C412 ","")&IF('M111'!B7="Aula 10","M111 ","")&IF('M112'!B7="Aula 10","M112 ","")&IF('M211'!B7="Aula 10","M211 ","")&IF('M212'!B7="Aula 10","M212 ","")&IF('M311'!B7="Aula 10","M311 ","")&IF('M411'!B7="Aula 10","M411 ","")&IF('D111'!B7="Aula 10","D111 ","")&IF('D112'!B7="Aula 10","D112 ","")&IF('D211'!B7="Aula 10","D211 ","")&IF('D311'!B7="Aula 10","D311 ","")&IF('D411'!B7="Aula 10","D411 ",""))," ",",") | L3: =SUBSTITUTE(TRIM(IF('C111'!B7="Aula 11","C111 ","")&IF('C112'!B7="Aula 11","C112 ","")&IF('C113'!B7="Aula 11","C113 ","")&IF('C121'!B7="Aula 11","C121 ","")&IF('C122'!B7="Aula 11","C122 ","")&IF('C211'!B7="Aula 11","C211 ","")&IF('C212'!B7="Aula 11","C212 ","")&IF('C311'!B7="Aula 11","C311 ","")&IF('C312'!B7="Aula 11","C312 ","")&IF('C411'!B7="Aula 11","C411 ","")&IF('C412'!B7="Aula 11","C412 ","")&IF('M111'!B7="Aula 11","M111 ","")&IF('M112'!B7="Aula 11","M112 ","")&IF('M211'!B7="Aula 11","M211 ","")&IF('M212'!B7="Aula 11","M212 ","")&IF('M311'!B7="Aula 11","M311 ","")&IF('M411'!B7="Aula 11","M411 ","")&IF('D111'!B7="Aula 11","D111 ","")&IF('D112'!B7="Aula 11","D112 ","")&IF('D211'!B7="Aula 11","D211 ","")&IF('D311'!B7="Aula 11","D311 ","")&IF('D411'!B7="Aula 11","D411 ",""))," ",",") | M3: =SUBSTITUTE(TRIM(IF('C111'!B7="Aula 12","C111 ","")&IF('C112'!B7="Aula 12","C112 ","")&IF('C113'!B7="Aula 12","C113 ","")&IF('C121'!B7="Aula 12","C121 ","")&IF('C122'!B7="Aula 12","C122 ","")&IF('C211'!B7="Aula 12","C211 ","")&IF('C212'!B7="Aula 12","C212 ","")&IF('C311'!B7="Aula 12","C311 ","")&IF('C312'!B7="Aula 12","C312 ","")&IF('C411'!B7="Aula 12","C411 ","")&IF('C412'!B7="Aula 12","C412 ","")&IF('M111'!B7="Aula 12","M111 ","")&IF('M112'!B7="Aula 12","M112 ","")&IF('M211'!B7="Aula 12","M211 ","")&IF('M212'!B7="Aula 12","M212 ","")&IF('M311'!B7="Aula 12","M311 ","")&IF('M411'!B7="Aula 12","M411 ","")&IF('D111'!B7="Aula 12","D111 ","")&IF('D112'!B7="Aula 12","D112 ","")&IF('D211'!B7="Aula 12","D211 ","")&IF('D311'!B7="Aula 12","D311 ","")&IF('D411'!B7="Aula 12","D411 ",""))," ",",") | N3: =SUBSTITUTE(TRIM(IF('C111'!B7="Lab 1","C111 ","")&IF('C112'!B7="Lab 1","C112 ","")&IF('C113'!B7="Lab 1","C113 ","")&IF('C121'!B7="Lab 1","C121 ","")&IF('C122'!B7="Lab 1","C122 ","")&IF('C211'!B7="Lab 1","C211 ","")&IF('C212'!B7="Lab 1","C212 ","")&IF('C311'!B7="Lab 1","C311 ","")&IF('C312'!B7="Lab 1","C312 ","")&IF('C411'!B7="Lab 1","C411 ","")&IF('C412'!B7="Lab 1","C412 ","")&IF('M111'!B7="Lab 1","M111 ","")&IF('M112'!B7="Lab 1","M112 ","")&IF('M211'!B7="Lab 1","M211 ","")&IF('M212'!B7="Lab 1","M212 ","")&IF('M311'!B7="Lab 1","M311 ","")&IF('M411'!B7="Lab 1","M411 ","")&IF('D111'!B7="Lab 1","D111 ","")&IF('D112'!B7="Lab 1","D112 ","")&IF('D211'!B7="Lab 1","D211 ","")&IF('D311'!B7="Lab 1","D311 ","")&IF('D411'!B7="Lab 1","D411 ",""))," ",",") | O3: =SUBSTITUTE(TRIM(IF('C111'!B7="Lab 2","C111 ","")&IF('C112'!B7="Lab 2","C112 ","")&IF('C113'!B7="Lab 2","C113 ","")&IF('C121'!B7="Lab 2","C121 ","")&IF('C122'!B7="Lab 2","C122 ","")&IF('C211'!B7="Lab 2","C211 ","")&IF('C212'!B7="Lab 2","C212 ","")&IF('C311'!B7="Lab 2","C311 ","")&IF('C312'!B7="Lab 2","C312 ","")&IF('C411'!B7="Lab 2","C411 ","")&IF('C412'!B7="Lab 2","C412 ","")&IF('M111'!B7="Lab 2","M111 ","")&IF('M112'!B7="Lab 2","M112 ","")&IF('M211'!B7="Lab 2","M211 ","")&IF('M212'!B7="Lab 2","M212 ","")&IF('M311'!B7="Lab 2","M311 ","")&IF('M411'!B7="Lab 2","M411 ","")&IF('D111'!B7="Lab 2","D111 ","")&IF('D112'!B7="Lab 2","D112 ","")&IF('D211'!B7="Lab 2","D211 ","")&IF('D311'!B7="Lab 2","D311 ","")&IF('D411'!B7="Lab 2","D411 ",""))," ",",") | P3: =SUBSTITUTE(TRIM(IF('C111'!B7="Salón","C111 ","")&IF('C112'!B7="Salón","C112 ","")&IF('C113'!B7="Salón","C113 ","")&IF('C121'!B7="Salón","C121 ","")&IF('C122'!B7="Salón","C122 ","")&IF('C211'!B7="Salón","C211 ","")&IF('C212'!B7="Salón","C212 ","")&IF('C311'!B7="Salón","C311 ","")&IF('C312'!B7="Salón","C312 ","")&IF('C411'!B7="Salón","C411 ","")&IF('C412'!B7="Salón","C412 ","")&IF('M111'!B7="Salón","M111 ","")&IF('M112'!B7="Salón","M112 ","")&IF('M211'!B7="Salón","M211 ","")&IF('M212'!B7="Salón","M212 ","")&IF('M311'!B7="Salón","M311 ","")&IF('M411'!B7="Salón","M411 ","")&IF('D111'!B7="Salón","D111 ","")&IF('D112'!B7="Salón","D112 ","")&IF('D211'!B7="Salón","D211 ","")&IF('D311'!B7="Salón","D311 ","")&IF('D411'!B7="Salón","D411 ",""))," ",",")
A4: Turno 3 | B4: =SUBSTITUTE(TRIM(IF('C111'!B9="Aula 1","C111 ","")&IF('C112'!B9="Aula 1","C112 ","")&IF('C113'!B9="Aula 1","C113 ","")&IF('C121'!B9="Aula 1","C121 ","")&IF('C122'!B9="Aula 1","C122 ","")&IF('C211'!B9="Aula 1","C211 ","")&IF('C212'!B9="Aula 1","C212 ","")&IF('C311'!B9="Aula 1","C311 ","")&IF('C312'!B9="Aula 1","C312 ","")&IF('C411'!B9="Aula 1","C411 ","")&IF('C412'!B9="Aula 1","C412 ","")&IF('M111'!B9="Aula 1","M111 ","")&IF('M112'!B9="Aula 1","M112 ","")&IF('M211'!B9="Aula 1","M211 ","")&IF('M212'!B9="Aula 1","M212 ","")&IF('M311'!B9="Aula 1","M311 ","")&IF('M411'!B9="Aula 1","M411 ","")&IF('D111'!B9="Aula 1","D111 ","")&IF('D112'!B9="Aula 1","D112 ","")&IF('D211'!B9="Aula 1","D211 ","")&IF('D311'!B9="Aula 1","D311 ","")&IF('D411'!B9="Aula 1","D411 ",""))," ",",") | C4: =SUBSTITUTE(TRIM(IF('C111'!B9="Aula 2","C111 ","")&IF('C112'!B9="Aula 2","C112 ","")&IF('C113'!B9="Aula 2","C113 ","")&IF('C121'!B9="Aula 2","C121 ","")&IF('C122'!B9="Aula 2","C122 ","")&IF('C211'!B9="Aula 2","C211 ","")&IF('C212'!B9="Aula 2","C212 ","")&IF('C311'!B9="Aula 2","C311 ","")&IF('C312'!B9="Aula 2","C312 ","")&IF('C411'!B9="Aula 2","C411 ","")&IF('C412'!B9="Aula 2","C412 ","")&IF('M111'!B9="Aula 2","M111 ","")&IF('M112'!B9="Aula 2","M112 ","")&IF('M211'!B9="Aula 2","M211 ","")&IF('M212'!B9="Aula 2","M212 ","")&IF('M311'!B9="Aula 2","M311 ","")&IF('M411'!B9="Aula 2","M411 ","")&IF('D111'!B9="Aula 2","D111 ","")&IF('D112'!B9="Aula 2","D112 ","")&IF('D211'!B9="Aula 2","D211 ","")&IF('D311'!B9="Aula 2","D311 ","")&IF('D411'!B9="Aula 2","D411 ",""))," ",",") | D4: =SUBSTITUTE(TRIM(IF('C111'!B9="Aula 3","C111 ","")&IF('C112'!B9="Aula 3","C112 ","")&IF('C113'!B9="Aula 3","C113 ","")&IF('C121'!B9="Aula 3","C121 ","")&IF('C122'!B9="Aula 3","C122 ","")&IF('C211'!B9="Aula 3","C211 ","")&IF('C212'!B9="Aula 3","C212 ","")&IF('C311'!B9="Aula 3","C311 ","")&IF('C312'!B9="Aula 3","C312 ","")&IF('C411'!B9="Aula 3","C411 ","")&IF('C412'!B9="Aula 3","C412 ","")&IF('M111'!B9="Aula 3","M111 ","")&IF('M112'!B9="Aula 3","M112 ","")&IF('M211'!B9="Aula 3","M211 ","")&IF('M212'!B9="Aula 3","M212 ","")&IF('M311'!B9="Aula 3","M311 ","")&IF('M411'!B9="Aula 3","M411 ","")&IF('D111'!B9="Aula 3","D111 ","")&IF('D112'!B9="Aula 3","D112 ","")&IF('D211'!B9="Aula 3","D211 ","")&IF('D311'!B9="Aula 3","D311 ","")&IF('D411'!B9="Aula 3","D411 ",""))," ",",") | E4: =SUBSTITUTE(TRIM(IF('C111'!B9="Aula 4","C111 ","")&IF('C112'!B9="Aula 4","C112 ","")&IF('C113'!B9="Aula 4","C113 ","")&IF('C121'!B9="Aula 4","C121 ","")&IF('C122'!B9="Aula 4","C122 ","")&IF('C211'!B9="Aula 4","C211 ","")&IF('C212'!B9="Aula 4","C212 ","")&IF('C311'!B9="Aula 4","C311 ","")&IF('C312'!B9="Aula 4","C312 ","")&IF('C411'!B9="Aula 4","C411 ","")&IF('C412'!B9="Aula 4","C412 ","")&IF('M111'!B9="Aula 4","M111 ","")&IF('M112'!B9="Aula 4","M112 ","")&IF('M211'!B9="Aula 4","M211 ","")&IF('M212'!B9="Aula 4","M212 ","")&IF('M311'!B9="Aula 4","M311 ","")&IF('M411'!B9="Aula 4","M411 ","")&IF('D111'!B9="Aula 4","D111 ","")&IF('D112'!B9="Aula 4","D112 ","")&IF('D211'!B9="Aula 4","D211 ","")&IF('D311'!B9="Aula 4","D311 ","")&IF('D411'!B9="Aula 4","D411 ",""))," ",",") | F4: =SUBSTITUTE(TRIM(IF('C111'!B9="Aula 5","C111 ","")&IF('C112'!B9="Aula 5","C112 ","")&IF('C113'!B9="Aula 5","C113 ","")&IF('C121'!B9="Aula 5","C121 ","")&IF('C122'!B9="Aula 5","C122 ","")&IF('C211'!B9="Aula 5","C211 ","")&IF('C212'!B9="Aula 5","C212 ","")&IF('C311'!B9="Aula 5","C311 ","")&IF('C312'!B9="Aula 5","C312 ","")&IF('C411'!B9="Aula 5","C411 ","")&IF('C412'!B9="Aula 5","C412 ","")&IF('M111'!B9="Aula 5","M111 ","")&IF('M112'!B9="Aula 5","M112 ","")&IF('M211'!B9="Aula 5","M211 ","")&IF('M212'!B9="Aula 5","M212 ","")&IF('M311'!B9="Aula 5","M311 ","")&IF('M411'!B9="Aula 5","M411 ","")&IF('D111'!B9="Aula 5","D111 ","")&IF('D112'!B9="Aula 5","D112 ","")&IF('D211'!B9="Aula 5","D211 ","")&IF('D311'!B9="Aula 5","D311 ","")&IF('D411'!B9="Aula 5","D411 ",""))," ",",") | G4: =SUBSTITUTE(TRIM(IF('C111'!B9="Aula 6","C111 ","")&IF('C112'!B9="Aula 6","C112 ","")&IF('C113'!B9="Aula 6","C113 ","")&IF('C121'!B9="Aula 6","C121 ","")&IF('C122'!B9="Aula 6","C122 ","")&IF('C211'!B9="Aula 6","C211 ","")&IF('C212'!B9="Aula 6","C212 ","")&IF('C311'!B9="Aula 6","C311 ","")&IF('C312'!B9="Aula 6","C312 ","")&IF('C411'!B9="Aula 6","C411 ","")&IF('C412'!B9="Aula 6","C412 ","")&IF('M111'!B9="Aula 6","M111 ","")&IF('M112'!B9="Aula 6","M112 ","")&IF('M211'!B9="Aula 6","M211 ","")&IF('M212'!B9="Aula 6","M212 ","")&IF('M311'!B9="Aula 6","M311 ","")&IF('M411'!B9="Aula 6","M411 ","")&IF('D111'!B9="Aula 6","D111 ","")&IF('D112'!B9="Aula 6","D112 ","")&IF('D211'!B9="Aula 6","D211 ","")&IF('D311'!B9="Aula 6","D311 ","")&IF('D411'!B9="Aula 6","D411 ",""))," ",",") | H4: =SUBSTITUTE(TRIM(IF('C111'!B9="Aula 7","C111 ","")&IF('C112'!B9="Aula 7","C112 ","")&IF('C113'!B9="Aula 7","C113 ","")&IF('C121'!B9="Aula 7","C121 ","")&IF('C122'!B9="Aula 7","C122 ","")&IF('C211'!B9="Aula 7","C211 ","")&IF('C212'!B9="Aula 7","C212 ","")&IF('C311'!B9="Aula 7","C311 ","")&IF('C312'!B9="Aula 7","C312 ","")&IF('C411'!B9="Aula 7","C411 ","")&IF('C412'!B9="Aula 7","C412 ","")&IF('M111'!B9="Aula 7","M111 ","")&IF('M112'!B9="Aula 7","M112 ","")&IF('M211'!B9="Aula 7","M211 ","")&IF('M212'!B9="Aula 7","M212 ","")&IF('M311'!B9="Aula 7","M311 ","")&IF('M411'!B9="Aula 7","M411 ","")&IF('D111'!B9="Aula 7","D111 ","")&IF('D112'!B9="Aula 7","D112 ","")&IF('D211'!B9="Aula 7","D211 ","")&IF('D311'!B9="Aula 7","D311 ","")&IF('D411'!B9="Aula 7","D411 ",""))," ",",") | I4: =SUBSTITUTE(TRIM(IF('C111'!B9="Aula 8","C111 ","")&IF('C112'!B9="Aula 8","C112 ","")&IF('C113'!B9="Aula 8","C113 ","")&IF('C121'!B9="Aula 8","C121 ","")&IF('C122'!B9="Aula 8","C122 ","")&IF('C211'!B9="Aula 8","C211 ","")&IF('C212'!B9="Aula 8","C212 ","")&IF('C311'!B9="Aula 8","C311 ","")&IF('C312'!B9="Aula 8","C312 ","")&IF('C411'!B9="Aula 8","C411 ","")&IF('C412'!B9="Aula 8","C412 ","")&IF('M111'!B9="Aula 8","M111 ","")&IF('M112'!B9="Aula 8","M112 ","")&IF('M211'!B9="Aula 8","M211 ","")&IF('M212'!B9="Aula 8","M212 ","")&IF('M311'!B9="Aula 8","M311 ","")&IF('M411'!B9="Aula 8","M411 ","")&IF('D111'!B9="Aula 8","D111 ","")&IF('D112'!B9="Aula 8","D112 ","")&IF('D211'!B9="Aula 8","D211 ","")&IF('D311'!B9="Aula 8","D311 ","")&IF('D411'!B9="Aula 8","D411 ",""))," ",",") | J4: =SUBSTITUTE(TRIM(IF('C111'!B9="Aula 9","C111 ","")&IF('C112'!B9="Aula 9","C112 ","")&IF('C113'!B9="Aula 9","C113 ","")&IF('C121'!B9="Aula 9","C121 ","")&IF('C122'!B9="Aula 9","C122 ","")&IF('C211'!B9="Aula 9","C211 ","")&IF('C212'!B9="Aula 9","C212 ","")&IF('C311'!B9="Aula 9","C311 ","")&IF('C312'!B9="Aula 9","C312 ","")&IF('C411'!B9="Aula 9","C411 ","")&IF('C412'!B9="Aula 9","C412 ","")&IF('M111'!B9="Aula 9","M111 ","")&IF('M112'!B9="Aula 9","M112 ","")&IF('M211'!B9="Aula 9","M211 ","")&IF('M212'!B9="Aula 9","M212 ","")&IF('M311'!B9="Aula 9","M311 ","")&IF('M411'!B9="Aula 9","M411 ","")&IF('D111'!B9="Aula 9","D111 ","")&IF('D112'!B9="Aula 9","D112 ","")&IF('D211'!B9="Aula 9","D211 ","")&IF('D311'!B9="Aula 9","D311 ","")&IF('D411'!B9="Aula 9","D411 ",""))," ",",") | K4: =SUBSTITUTE(TRIM(IF('C111'!B9="Aula 10","C111 ","")&IF('C112'!B9="Aula 10","C112 ","")&IF('C113'!B9="Aula 10","C113 ","")&IF('C121'!B9="Aula 10","C121 ","")&IF('C122'!B9="Aula 10","C122 ","")&IF('C211'!B9="Aula 10","C211 ","")&IF('C212'!B9="Aula 10","C212 ","")&IF('C311'!B9="Aula 10","C311 ","")&IF('C312'!B9="Aula 10","C312 ","")&IF('C411'!B9="Aula 10","C411 ","")&IF('C412'!B9="Aula 10","C412 ","")&IF('M111'!B9="Aula 10","M111 ","")&IF('M112'!B9="Aula 10","M112 ","")&IF('M211'!B9="Aula 10","M211 ","")&IF('M212'!B9="Aula 10","M212 ","")&IF('M311'!B9="Aula 10","M311 ","")&IF('M411'!B9="Aula 10","M411 ","")&IF('D111'!B9="Aula 10","D111 ","")&IF('D112'!B9="Aula 10","D112 ","")&IF('D211'!B9="Aula 10","D211 ","")&IF('D311'!B9="Aula 10","D311 ","")&IF('D411'!B9="Aula 10","D411 ",""))," ",",") | L4: =SUBSTITUTE(TRIM(IF('C111'!B9="Aula 11","C111 ","")&IF('C112'!B9="Aula 11","C112 ","")&IF('C113'!B9="Aula 11","C113 ","")&IF('C121'!B9="Aula 11","C121 ","")&IF('C122'!B9="Aula 11","C122 ","")&IF('C211'!B9="Aula 11","C211 ","")&IF('C212'!B9="Aula 11","C212 ","")&IF('C311'!B9="Aula 11","C311 ","")&IF('C312'!B9="Aula 11","C312 ","")&IF('C411'!B9="Aula 11","C411 ","")&IF('C412'!B9="Aula 11","C412 ","")&IF('M111'!B9="Aula 11","M111 ","")&IF('M112'!B9="Aula 11","M112 ","")&IF('M211'!B9="Aula 11","M211 ","")&IF('M212'!B9="Aula 11","M212 ","")&IF('M311'!B9="Aula 11","M311 ","")&IF('M411'!B9="Aula 11","M411 ","")&IF('D111'!B9="Aula 11","D111 ","")&IF('D112'!B9="Aula 11","D112 ","")&IF('D211'!B9="Aula 11","D211 ","")&IF('D311'!B9="Aula 11","D311 ","")&IF('D411'!B9="Aula 11","D411 ",""))," ",",") | M4: =SUBSTITUTE(TRIM(IF('C111'!B9="Aula 12","C111 ","")&IF('C112'!B9="Aula 12","C112 ","")&IF('C113'!B9="Aula 12","C113 ","")&IF('C121'!B9="Aula 12","C121 ","")&IF('C122'!B9="Aula 12","C122 ","")&IF('C211'!B9="Aula 12","C211 ","")&IF('C212'!B9="Aula 12","C212 ","")&IF('C311'!B9="Aula 12","C311 ","")&IF('C312'!B9="Aula 12","C312 ","")&IF('C411'!B9="Aula 12","C411 ","")&IF('C412'!B9="Aula 12","C412 ","")&IF('M111'!B9="Aula 12","M111 ","")&IF('M112'!B9="Aula 12","M112 ","")&IF('M211'!B9="Aula 12","M211 ","")&IF('M212'!B9="Aula 12","M212 ","")&IF('M311'!B9="Aula 12","M311 ","")&IF('M411'!B9="Aula 12","M411 ","")&IF('D111'!B9="Aula 12","D111 ","")&IF('D112'!B9="Aula 12","D112 ","")&IF('D211'!B9="Aula 12","D211 ","")&IF('D311'!B9="Aula 12","D311 ","")&IF('D411'!B9="Aula 12","D411 ",""))," ",",") | N4: =SUBSTITUTE(TRIM(IF('C111'!B9="Lab 1","C111 ","")&IF('C112'!B9="Lab 1","C112 ","")&IF('C113'!B9="Lab 1","C113 ","")&IF('C121'!B9="Lab 1","C121 ","")&IF('C122'!B9="Lab 1","C122 ","")&IF('C211'!B9="Lab 1","C211 ","")&IF('C212'!B9="Lab 1","C212 ","")&IF('C311'!B9="Lab 1","C311 ","")&IF('C312'!B9="Lab 1","C312 ","")&IF('C411'!B9="Lab 1","C411 ","")&IF('C412'!B9="Lab 1","C412 ","")&IF('M111'!B9="Lab 1","M111 ","")&IF('M112'!B9="Lab 1","M112 ","")&IF('M211'!B9="Lab 1","M211 ","")&IF('M212'!B9="Lab 1","M212 ","")&IF('M311'!B9="Lab 1","M311 ","")&IF('M411'!B9="Lab 1","M411 ","")&IF('D111'!B9="Lab 1","D111 ","")&IF('D112'!B9="Lab 1","D112 ","")&IF('D211'!B9="Lab 1","D211 ","")&IF('D311'!B9="Lab 1","D311 ","")&IF('D411'!B9="Lab 1","D411 ",""))," ",",") | O4: =SUBSTITUTE(TRIM(IF('C111'!B9="Lab 2","C111 ","")&IF('C112'!B9="Lab 2","C112 ","")&IF('C113'!B9="Lab 2","C113 ","")&IF('C121'!B9="Lab 2","C121 ","")&IF('C122'!B9="Lab 2","C122 ","")&IF('C211'!B9="Lab 2","C211 ","")&IF('C212'!B9="Lab 2","C212 ","")&IF('C311'!B9="Lab 2","C311 ","")&IF('C312'!B9="Lab 2","C312 ","")&IF('C411'!B9="Lab 2","C411 ","")&IF('C412'!B9="Lab 2","C412 ","")&IF('M111'!B9="Lab 2","M111 ","")&IF('M112'!B9="Lab 2","M112 ","")&IF('M211'!B9="Lab 2","M211 ","")&IF('M212'!B9="Lab 2","M212 ","")&IF('M311'!B9="Lab 2","M311 ","")&IF('M411'!B9="Lab 2","M411 ","")&IF('D111'!B9="Lab 2","D111 ","")&IF('D112'!B9="Lab 2","D112 ","")&IF('D211'!B9="Lab 2","D211 ","")&IF('D311'!B9="Lab 2","D311 ","")&IF('D411'!B9="Lab 2","D411 ",""))," ",",") | P4: =SUBSTITUTE(TRIM(IF('C111'!B9="Salón","C111 ","")&IF('C112'!B9="Salón","C112 ","")&IF('C113'!B9="Salón","C113 ","")&IF('C121'!B9="Salón","C121 ","")&IF('C122'!B9="Salón","C122 ","")&IF('C211'!B9="Salón","C211 ","")&IF('C212'!B9="Salón","C212 ","")&IF('C311'!B9="Salón","C311 ","")&IF('C312'!B9="Salón","C312 ","")&IF('C411'!B9="Salón","C411 ","")&IF('C412'!B9="Salón","C412 ","")&IF('M111'!B9="Salón","M111 ","")&IF('M112'!B9="Salón","M112 ","")&IF('M211'!B9="Salón","M211 ","")&IF('M212'!B9="Salón","M212 ","")&IF('M311'!B9="Salón","M311 ","")&IF('M411'!B9="Salón","M411 ","")&IF('D111'!B9="Salón","D111 ","")&IF('D112'!B9="Salón","D112 ","")&IF('D211'!B9="Salón","D211 ","")&IF('D311'!B9="Salón","D311 ","")&IF('D411'!B9="Salón","D411 ",""))," ",",")
A5: Turno 4 | B5: =SUBSTITUTE(TRIM(IF('C111'!B11="Aula 1","C111 ","")&IF('C112'!B11="Aula 1","C112 ","")&IF('C113'!B11="Aula 1","C113 ","")&IF('C121'!B11="Aula 1","C121 ","")&IF('C122'!B11="Aula 1","C122 ","")&IF('C211'!B11="Aula 1","C211 ","")&IF('C212'!B11="Aula 1","C212 ","")&IF('C311'!B11="Aula 1","C311 ","")&IF('C312'!B11="Aula 1","C312 ","")&IF('C411'!B11="Aula 1","C411 ","")&IF('C412'!B11="Aula 1","C412 ","")&IF('M111'!B11="Aula 1","M111 ","")&IF('M112'!B11="Aula 1","M112 ","")&IF('M211'!B11="Aula 1","M211 ","")&IF('M212'!B11="Aula 1","M212 ","")&IF('M311'!B11="Aula 1","M311 ","")&IF('M411'!B11="Aula 1","M411 ","")&IF('D111'!B11="Aula 1","D111 ","")&IF('D112'!B11="Aula 1","D112 ","")&IF('D211'!B11="Aula 1","D211 ","")&IF('D311'!B11="Aula 1","D311 ","")&IF('D411'!B11="Aula 1","D411 ",""))," ",",") | C5: =SUBSTITUTE(TRIM(IF('C111'!B11="Aula 2","C111 ","")&IF('C112'!B11="Aula 2","C112 ","")&IF('C113'!B11="Aula 2","C113 ","")&IF('C121'!B11="Aula 2","C121 ","")&IF('C122'!B11="Aula 2","C122 ","")&IF('C211'!B11="Aula 2","C211 ","")&IF('C212'!B11="Aula 2","C212 ","")&IF('C311'!B11="Aula 2","C311 ","")&IF('C312'!B11="Aula 2","C312 ","")&IF('C411'!B11="Aula 2","C411 ","")&IF('C412'!B11="Aula 2","C412 ","")&IF('M111'!B11="Aula 2","M111 ","")&IF('M112'!B11="Aula 2","M112 ","")&IF('M211'!B11="Aula 2","M211 ","")&IF('M212'!B11="Aula 2","M212 ","")&IF('M311'!B11="Aula 2","M311 ","")&IF('M411'!B11="Aula 2","M411 ","")&IF('D111'!B11="Aula 2","D111 ","")&IF('D112'!B11="Aula 2","D112 ","")&IF('D211'!B11="Aula 2","D211 ","")&IF('D311'!B11="Aula 2","D311 ","")&IF('D411'!B11="Aula 2","D411 ",""))," ",",") | D5: =SUBSTITUTE(TRIM(IF('C111'!B11="Aula 3","C111 ","")&IF('C112'!B11="Aula 3","C112 ","")&IF('C113'!B11="Aula 3","C113 ","")&IF('C121'!B11="Aula 3","C121 ","")&IF('C122'!B11="Aula 3","C122 ","")&IF('C211'!B11="Aula 3","C211 ","")&IF('C212'!B11="Aula 3","C212 ","")&IF('C311'!B11="Aula 3","C311 ","")&IF('C312'!B11="Aula 3","C312 ","")&IF('C411'!B11="Aula 3","C411 ","")&IF('C412'!B11="Aula 3","C412 ","")&IF('M111'!B11="Aula 3","M111 ","")&IF('M112'!B11="Aula 3","M112 ","")&IF('M211'!B11="Aula 3","M211 ","")&IF('M212'!B11="Aula 3","M212 ","")&IF('M311'!B11="Aula 3","M311 ","")&IF('M411'!B11="Aula 3","M411 ","")&IF('D111'!B11="Aula 3","D111 ","")&IF('D112'!B11="Aula 3","D112 ","")&IF('D211'!B11="Aula 3","D211 ","")&IF('D311'!B11="Aula 3","D311 ","")&IF('D411'!B11="Aula 3","D411 ",""))," ",",") | E5: =SUBSTITUTE(TRIM(IF('C111'!B11="Aula 4","C111 ","")&IF('C112'!B11="Aula 4","C112 ","")&IF('C113'!B11="Aula 4","C113 ","")&IF('C121'!B11="Aula 4","C121 ","")&IF('C122'!B11="Aula 4","C122 ","")&IF('C211'!B11="Aula 4","C211 ","")&IF('C212'!B11="Aula 4","C212 ","")&IF('C311'!B11="Aula 4","C311 ","")&IF('C312'!B11="Aula 4","C312 ","")&IF('C411'!B11="Aula 4","C411 ","")&IF('C412'!B11="Aula 4","C412 ","")&IF('M111'!B11="Aula 4","M111 ","")&IF('M112'!B11="Aula 4","M112 ","")&IF('M211'!B11="Aula 4","M211 ","")&IF('M212'!B11="Aula 4","M212 ","")&IF('M311'!B11="Aula 4","M311 ","")&IF('M411'!B11="Aula 4","M411 ","")&IF('D111'!B11="Aula 4","D111 ","")&IF('D112'!B11="Aula 4","D112 ","")&IF('D211'!B11="Aula 4","D211 ","")&IF('D311'!B11="Aula 4","D311 ","")&IF('D411'!B11="Aula 4","D411 ",""))," ",",") | F5: =SUBSTITUTE(TRIM(IF('C111'!B11="Aula 5","C111 ","")&IF('C112'!B11="Aula 5","C112 ","")&IF('C113'!B11="Aula 5","C113 ","")&IF('C121'!B11="Aula 5","C121 ","")&IF('C122'!B11="Aula 5","C122 ","")&IF('C211'!B11="Aula 5","C211 ","")&IF('C212'!B11="Aula 5","C212 ","")&IF('C311'!B11="Aula 5","C311 ","")&IF('C312'!B11="Aula 5","C312 ","")&IF('C411'!B11="Aula 5","C411 ","")&IF('C412'!B11="Aula 5","C412 ","")&IF('M111'!B11="Aula 5","M111 ","")&IF('M112'!B11="Aula 5","M112 ","")&IF('M211'!B11="Aula 5","M211 ","")&IF('M212'!B11="Aula 5","M212 ","")&IF('M311'!B11="Aula 5","M311 ","")&IF('M411'!B11="Aula 5","M411 ","")&IF('D111'!B11="Aula 5","D111 ","")&IF('D112'!B11="Aula 5","D112 ","")&IF('D211'!B11="Aula 5","D211 ","")&IF('D311'!B11="Aula 5","D311 ","")&IF('D411'!B11="Aula 5","D411 ",""))," ",",") | G5: =SUBSTITUTE(TRIM(IF('C111'!B11="Aula 6","C111 ","")&IF('C112'!B11="Aula 6","C112 ","")&IF('C113'!B11="Aula 6","C113 ","")&IF('C121'!B11="Aula 6","C121 ","")&IF('C122'!B11="Aula 6","C122 ","")&IF('C211'!B11="Aula 6","C211 ","")&IF('C212'!B11="Aula 6","C212 ","")&IF('C311'!B11="Aula 6","C311 ","")&IF('C312'!B11="Aula 6","C312 ","")&IF('C411'!B11="Aula 6","C411 ","")&IF('C412'!B11="Aula 6","C412 ","")&IF('M111'!B11="Aula 6","M111 ","")&IF('M112'!B11="Aula 6","M112 ","")&IF('M211'!B11="Aula 6","M211 ","")&IF('M212'!B11="Aula 6","M212 ","")&IF('M311'!B11="Aula 6","M311 ","")&IF('M411'!B11="Aula 6","M411 ","")&IF('D111'!B11="Aula 6","D111 ","")&IF('D112'!B11="Aula 6","D112 ","")&IF('D211'!B11="Aula 6","D211 ","")&IF('D311'!B11="Aula 6","D311 ","")&IF('D411'!B11="Aula 6","D411 ",""))," ",",") | H5: =SUBSTITUTE(TRIM(IF('C111'!B11="Aula 7","C111 ","")&IF('C112'!B11="Aula 7","C112 ","")&IF('C113'!B11="Aula 7","C113 ","")&IF('C121'!B11="Aula 7","C121 ","")&IF('C122'!B11="Aula 7","C122 ","")&IF('C211'!B11="Aula 7","C211 ","")&IF('C212'!B11="Aula 7","C212 ","")&IF('C311'!B11="Aula 7","C311 ","")&IF('C312'!B11="Aula 7","C312 ","")&IF('C411'!B11="Aula 7","C411 ","")&IF('C412'!B11="Aula 7","C412 ","")&IF('M111'!B11="Aula 7","M111 ","")&IF('M112'!B11="Aula 7","M112 ","")&IF('M211'!B11="Aula 7","M211 ","")&IF('M212'!B11="Aula 7","M212 ","")&IF('M311'!B11="Aula 7","M311 ","")&IF('M411'!B11="Aula 7","M411 ","")&IF('D111'!B11="Aula 7","D111 ","")&IF('D112'!B11="Aula 7","D112 ","")&IF('D211'!B11="Aula 7","D211 ","")&IF('D311'!B11="Aula 7","D311 ","")&IF('D411'!B11="Aula 7","D411 ",""))," ",",") | I5: =SUBSTITUTE(TRIM(IF('C111'!B11="Aula 8","C111 ","")&IF('C112'!B11="Aula 8","C112 ","")&IF('C113'!B11="Aula 8","C113 ","")&IF('C121'!B11="Aula 8","C121 ","")&IF('C122'!B11="Aula 8","C122 ","")&IF('C211'!B11="Aula 8","C211 ","")&IF('C212'!B11="Aula 8","C212 ","")&IF('C311'!B11="Aula 8","C311 ","")&IF('C312'!B11="Aula 8","C312 ","")&IF('C411'!B11="Aula 8","C411 ","")&IF('C412'!B11="Aula 8","C412 ","")&IF('M111'!B11="Aula 8","M111 ","")&IF('M112'!B11="Aula 8","M112 ","")&IF('M211'!B11="Aula 8","M211 ","")&IF('M212'!B11="Aula 8","M212 ","")&IF('M311'!B11="Aula 8","M311 ","")&IF('M411'!B11="Aula 8","M411 ","")&IF('D111'!B11="Aula 8","D111 ","")&IF('D112'!B11="Aula 8","D112 ","")&IF('D211'!B11="Aula 8","D211 ","")&IF('D311'!B11="Aula 8","D311 ","")&IF('D411'!B11="Aula 8","D411 ",""))," ",",") | J5: =SUBSTITUTE(TRIM(IF('C111'!B11="Aula 9","C111 ","")&IF('C112'!B11="Aula 9","C112 ","")&IF('C113'!B11="Aula 9","C113 ","")&IF('C121'!B11="Aula 9","C121 ","")&IF('C122'!B11="Aula 9","C122 ","")&IF('C211'!B11="Aula 9","C211 ","")&IF('C212'!B11="Aula 9","C212 ","")&IF('C311'!B11="Aula 9","C311 ","")&IF('C312'!B11="Aula 9","C312 ","")&IF('C411'!B11="Aula 9","C411 ","")&IF('C412'!B11="Aula 9","C412 ","")&IF('M111'!B11="Aula 9","M111 ","")&IF('M112'!B11="Aula 9","M112 ","")&IF('M211'!B11="Aula 9","M211 ","")&IF('M212'!B11="Aula 9","M212 ","")&IF('M311'!B11="Aula 9","M311 ","")&IF('M411'!B11="Aula 9","M411 ","")&IF('D111'!B11="Aula 9","D111 ","")&IF('D112'!B11="Aula 9","D112 ","")&IF('D211'!B11="Aula 9","D211 ","")&IF('D311'!B11="Aula 9","D311 ","")&IF('D411'!B11="Aula 9","D411 ",""))," ",",") | K5: =SUBSTITUTE(TRIM(IF('C111'!B11="Aula 10","C111 ","")&IF('C112'!B11="Aula 10","C112 ","")&IF('C113'!B11="Aula 10","C113 ","")&IF('C121'!B11="Aula 10","C121 ","")&IF('C122'!B11="Aula 10","C122 ","")&IF('C211'!B11="Aula 10","C211 ","")&IF('C212'!B11="Aula 10","C212 ","")&IF('C311'!B11="Aula 10","C311 ","")&IF('C312'!B11="Aula 10","C312 ","")&IF('C411'!B11="Aula 10","C411 ","")&IF('C412'!B11="Aula 10","C412 ","")&IF('M111'!B11="Aula 10","M111 ","")&IF('M112'!B11="Aula 10","M112 ","")&IF('M211'!B11="Aula 10","M211 ","")&IF('M212'!B11="Aula 10","M212 ","")&IF('M311'!B11="Aula 10","M311 ","")&IF('M411'!B11="Aula 10","M411 ","")&IF('D111'!B11="Aula 10","D111 ","")&IF('D112'!B11="Aula 10","D112 ","")&IF('D211'!B11="Aula 10","D211 ","")&IF('D311'!B11="Aula 10","D311 ","")&IF('D411'!B11="Aula 10","D411 ",""))," ",",") | L5: =SUBSTITUTE(TRIM(IF('C111'!B11="Aula 11","C111 ","")&IF('C112'!B11="Aula 11","C112 ","")&IF('C113'!B11="Aula 11","C113 ","")&IF('C121'!B11="Aula 11","C121 ","")&IF('C122'!B11="Aula 11","C122 ","")&IF('C211'!B11="Aula 11","C211 ","")&IF('C212'!B11="Aula 11","C212 ","")&IF('C311'!B11="Aula 11","C311 ","")&IF('C312'!B11="Aula 11","C312 ","")&IF('C411'!B11="Aula 11","C411 ","")&IF('C412'!B11="Aula 11","C412 ","")&IF('M111'!B11="Aula 11","M111 ","")&IF('M112'!B11="Aula 11","M112 ","")&IF('M211'!B11="Aula 11","M211 ","")&IF('M212'!B11="Aula 11","M212 ","")&IF('M311'!B11="Aula 11","M311 ","")&IF('M411'!B11="Aula 11","M411 ","")&IF('D111'!B11="Aula 11","D111 ","")&IF('D112'!B11="Aula 11","D112 ","")&IF('D211'!B11="Aula 11","D211 ","")&IF('D311'!B11="Aula 11","D311 ","")&IF('D411'!B11="Aula 11","D411 ",""))," ",",") | M5: =SUBSTITUTE(TRIM(IF('C111'!B11="Aula 12","C111 ","")&IF('C112'!B11="Aula 12","C112 ","")&IF('C113'!B11="Aula 12","C113 ","")&IF('C121'!B11="Aula 12","C121 ","")&IF('C122'!B11="Aula 12","C122 ","")&IF('C211'!B11="Aula 12","C211 ","")&IF('C212'!B11="Aula 12","C212 ","")&IF('C311'!B11="Aula 12","C311 ","")&IF('C312'!B11="Aula 12","C312 ","")&IF('C411'!B11="Aula 12","C411 ","")&IF('C412'!B11="Aula 12","C412 ","")&IF('M111'!B11="Aula 12","M111 ","")&IF('M112'!B11="Aula 12","M112 ","")&IF('M211'!B11="Aula 12","M211 ","")&IF('M212'!B11="Aula 12","M212 ","")&IF('M311'!B11="Aula 12","M311 ","")&IF('M411'!B11="Aula 12","M411 ","")&IF('D111'!B11="Aula 12","D111 ","")&IF('D112'!B11="Aula 12","D112 ","")&IF('D211'!B11="Aula 12","D211 ","")&IF('D311'!B11="Aula 12","D311 ","")&IF('D411'!B11="Aula 12","D411 ",""))," ",",") | N5: =SUBSTITUTE(TRIM(IF('C111'!B11="Lab 1","C111 ","")&IF('C112'!B11="Lab 1","C112 ","")&IF('C113'!B11="Lab 1","C113 ","")&IF('C121'!B11="Lab 1","C121 ","")&IF('C122'!B11="Lab 1","C122 ","")&IF('C211'!B11="Lab 1","C211 ","")&IF('C212'!B11="Lab 1","C212 ","")&IF('C311'!B11="Lab 1","C311 ","")&IF('C312'!B11="Lab 1","C312 ","")&IF('C411'!B11="Lab 1","C411 ","")&IF('C412'!B11="Lab 1","C412 ","")&IF('M111'!B11="Lab 1","M111 ","")&IF('M112'!B11="Lab 1","M112 ","")&IF('M211'!B11="Lab 1","M211 ","")&IF('M212'!B11="Lab 1","M212 ","")&IF('M311'!B11="Lab 1","M311 ","")&IF('M411'!B11="Lab 1","M411 ","")&IF('D111'!B11="Lab 1","D111 ","")&IF('D112'!B11="Lab 1","D112 ","")&IF('D211'!B11="Lab 1","D211 ","")&IF('D311'!B11="Lab 1","D311 ","")&IF('D411'!B11="Lab 1","D411 ",""))," ",",") | O5: =SUBSTITUTE(TRIM(IF('C111'!B11="Lab 2","C111 ","")&IF('C112'!B11="Lab 2","C112 ","")&IF('C113'!B11="Lab 2","C113 ","")&IF('C121'!B11="Lab 2","C121 ","")&IF('C122'!B11="Lab 2","C122 ","")&IF('C211'!B11="Lab 2","C211 ","")&IF('C212'!B11="Lab 2","C212 ","")&IF('C311'!B11="Lab 2","C311 ","")&IF('C312'!B11="Lab 2","C312 ","")&IF('C411'!B11="Lab 2","C411 ","")&IF('C412'!B11="Lab 2","C412 ","")&IF('M111'!B11="Lab 2","M111 ","")&IF('M112'!B11="Lab 2","M112 ","")&IF('M211'!B11="Lab 2","M211 ","")&IF('M212'!B11="Lab 2","M212 ","")&IF('M311'!B11="Lab 2","M311 ","")&IF('M411'!B11="Lab 2","M411 ","")&IF('D111'!B11="Lab 2","D111 ","")&IF('D112'!B11="Lab 2","D112 ","")&IF('D211'!B11="Lab 2","D211 ","")&IF('D311'!B11="Lab 2","D311 ","")&IF('D411'!B11="Lab 2","D411 ",""))," ",",") | P5: =SUBSTITUTE(TRIM(IF('C111'!B11="Salón","C111 ","")&IF('C112'!B11="Salón","C112 ","")&IF('C113'!B11="Salón","C113 ","")&IF('C121'!B11="Salón","C121 ","")&IF('C122'!B11="Salón","C122 ","")&IF('C211'!B11="Salón","C211 ","")&IF('C212'!B11="Salón","C212 ","")&IF('C311'!B11="Salón","C311 ","")&IF('C312'!B11="Salón","C312 ","")&IF('C411'!B11="Salón","C411 ","")&IF('C412'!B11="Salón","C412 ","")&IF('M111'!B11="Salón","M111 ","")&IF('M112'!B11="Salón","M112 ","")&IF('M211'!B11="Salón","M211 ","")&IF('M212'!B11="Salón","M212 ","")&IF('M311'!B11="Salón","M311 ","")&IF('M411'!B11="Salón","M411 ","")&IF('D111'!B11="Salón","D111 ","")&IF('D112'!B11="Salón","D112 ","")&IF('D211'!B11="Salón","D211 ","")&IF('D311'!B11="Salón","D311 ","")&IF('D411'!B11="Salón","D411 ",""))," ",",")
A6: Turno 5 | B6: =SUBSTITUTE(TRIM(IF('C111'!B13="Aula 1","C111 ","")&IF('C112'!B13="Aula 1","C112 ","")&IF('C113'!B13="Aula 1","C113 ","")&IF('C121'!B13="Aula 1","C121 ","")&IF('C122'!B13="Aula 1","C122 ","")&IF('C211'!B13="Aula 1","C211 ","")&IF('C212'!B13="Aula 1","C212 ","")&IF('C311'!B13="Aula 1","C311 ","")&IF('C312'!B13="Aula 1","C312 ","")&IF('C411'!B13="Aula 1","C411 ","")&IF('C412'!B13="Aula 1","C412 ","")&IF('M111'!B13="Aula 1","M111 ","")&IF('M112'!B13="Aula 1","M112 ","")&IF('M211'!B13="Aula 1","M211 ","")&IF('M212'!B13="Aula 1","M212 ","")&IF('M311'!B13="Aula 1","M311 ","")&IF('M411'!B13="Aula 1","M411 ","")&IF('D111'!B13="Aula 1","D111 ","")&IF('D112'!B13="Aula 1","D112 ","")&IF('D211'!B13="Aula 1","D211 ","")&IF('D311'!B13="Aula 1","D311 ","")&IF('D411'!B13="Aula 1","D411 ",""))," ",",") | C6: =SUBSTITUTE(TRIM(IF('C111'!B13="Aula 2","C111 ","")&IF('C112'!B13="Aula 2","C112 ","")&IF('C113'!B13="Aula 2","C113 ","")&IF('C121'!B13="Aula 2","C121 ","")&IF('C122'!B13="Aula 2","C122 ","")&IF('C211'!B13="Aula 2","C211 ","")&IF('C212'!B13="Aula 2","C212 ","")&IF('C311'!B13="Aula 2","C311 ","")&IF('C312'!B13="Aula 2","C312 ","")&IF('C411'!B13="Aula 2","C411 ","")&IF('C412'!B13="Aula 2","C412 ","")&IF('M111'!B13="Aula 2","M111 ","")&IF('M112'!B13="Aula 2","M112 ","")&IF('M211'!B13="Aula 2","M211 ","")&IF('M212'!B13="Aula 2","M212 ","")&IF('M311'!B13="Aula 2","M311 ","")&IF('M411'!B13="Aula 2","M411 ","")&IF('D111'!B13="Aula 2","D111 ","")&IF('D112'!B13="Aula 2","D112 ","")&IF('D211'!B13="Aula 2","D211 ","")&IF('D311'!B13="Aula 2","D311 ","")&IF('D411'!B13="Aula 2","D411 ",""))," ",",") | D6: =SUBSTITUTE(TRIM(IF('C111'!B13="Aula 3","C111 ","")&IF('C112'!B13="Aula 3","C112 ","")&IF('C113'!B13="Aula 3","C113 ","")&IF('C121'!B13="Aula 3","C121 ","")&IF('C122'!B13="Aula 3","C122 ","")&IF('C211'!B13="Aula 3","C211 ","")&IF('C212'!B13="Aula 3","C212 ","")&IF('C311'!B13="Aula 3","C311 ","")&IF('C312'!B13="Aula 3","C312 ","")&IF('C411'!B13="Aula 3","C411 ","")&IF('C412'!B13="Aula 3","C412 ","")&IF('M111'!B13="Aula 3","M111 ","")&IF('M112'!B13="Aula 3","M112 ","")&IF('M211'!B13="Aula 3","M211 ","")&IF('M212'!B13="Aula 3","M212 ","")&IF('M311'!B13="Aula 3","M311 ","")&IF('M411'!B13="Aula 3","M411 ","")&IF('D111'!B13="Aula 3","D111 ","")&IF('D112'!B13="Aula 3","D112 ","")&IF('D211'!B13="Aula 3","D211 ","")&IF('D311'!B13="Aula 3","D311 ","")&IF('D411'!B13="Aula 3","D411 ",""))," ",",") | E6: =SUBSTITUTE(TRIM(IF('C111'!B13="Aula 4","C111 ","")&IF('C112'!B13="Aula 4","C112 ","")&IF('C113'!B13="Aula 4","C113 ","")&IF('C121'!B13="Aula 4","C121 ","")&IF('C122'!B13="Aula 4","C122 ","")&IF('C211'!B13="Aula 4","C211 ","")&IF('C212'!B13="Aula 4","C212 ","")&IF('C311'!B13="Aula 4","C311 ","")&IF('C312'!B13="Aula 4","C312 ","")&IF('C411'!B13="Aula 4","C411 ","")&IF('C412'!B13="Aula 4","C412 ","")&IF('M111'!B13="Aula 4","M111 ","")&IF('M112'!B13="Aula 4","M112 ","")&IF('M211'!B13="Aula 4","M211 ","")&IF('M212'!B13="Aula 4","M212 ","")&IF('M311'!B13="Aula 4","M311 ","")&IF('M411'!B13="Aula 4","M411 ","")&IF('D111'!B13="Aula 4","D111 ","")&IF('D112'!B13="Aula 4","D112 ","")&IF('D211'!B13="Aula 4","D211 ","")&IF('D311'!B13="Aula 4","D311 ","")&IF('D411'!B13="Aula 4","D411 ",""))," ",",") | F6: =SUBSTITUTE(TRIM(IF('C111'!B13="Aula 5","C111 ","")&IF('C112'!B13="Aula 5","C112 ","")&IF('C113'!B13="Aula 5","C113 ","")&IF('C121'!B13="Aula 5","C121 ","")&IF('C122'!B13="Aula 5","C122 ","")&IF('C211'!B13="Aula 5","C211 ","")&IF('C212'!B13="Aula 5","C212 ","")&IF('C311'!B13="Aula 5","C311 ","")&IF('C312'!B13="Aula 5","C312 ","")&IF('C411'!B13="Aula 5","C411 ","")&IF('C412'!B13="Aula 5","C412 ","")&IF('M111'!B13="Aula 5","M111 ","")&IF('M112'!B13="Aula 5","M112 ","")&IF('M211'!B13="Aula 5","M211 ","")&IF('M212'!B13="Aula 5","M212 ","")&IF('M311'!B13="Aula 5","M311 ","")&IF('M411'!B13="Aula 5","M411 ","")&IF('D111'!B13="Aula 5","D111 ","")&IF('D112'!B13="Aula 5","D112 ","")&IF('D211'!B13="Aula 5","D211 ","")&IF('D311'!B13="Aula 5","D311 ","")&IF('D411'!B13="Aula 5","D411 ",""))," ",",") | G6: =SUBSTITUTE(TRIM(IF('C111'!B13="Aula 6","C111 ","")&IF('C112'!B13="Aula 6","C112 ","")&IF('C113'!B13="Aula 6","C113 ","")&IF('C121'!B13="Aula 6","C121 ","")&IF('C122'!B13="Aula 6","C122 ","")&IF('C211'!B13="Aula 6","C211 ","")&IF('C212'!B13="Aula 6","C212 ","")&IF('C311'!B13="Aula 6","C311 ","")&IF('C312'!B13="Aula 6","C312 ","")&IF('C411'!B13="Aula 6","C411 ","")&IF('C412'!B13="Aula 6","C412 ","")&IF('M111'!B13="Aula 6","M111 ","")&IF('M112'!B13="Aula 6","M112 ","")&IF('M211'!B13="Aula 6","M211 ","")&IF('M212'!B13="Aula 6","M212 ","")&IF('M311'!B13="Aula 6","M311 ","")&IF('M411'!B13="Aula 6","M411 ","")&IF('D111'!B13="Aula 6","D111 ","")&IF('D112'!B13="Aula 6","D112 ","")&IF('D211'!B13="Aula 6","D211 ","")&IF('D311'!B13="Aula 6","D311 ","")&IF('D411'!B13="Aula 6","D411 ",""))," ",",") | H6: =SUBSTITUTE(TRIM(IF('C111'!B13="Aula 7","C111 ","")&IF('C112'!B13="Aula 7","C112 ","")&IF('C113'!B13="Aula 7","C113 ","")&IF('C121'!B13="Aula 7","C121 ","")&IF('C122'!B13="Aula 7","C122 ","")&IF('C211'!B13="Aula 7","C211 ","")&IF('C212'!B13="Aula 7","C212 ","")&IF('C311'!B13="Aula 7","C311 ","")&IF('C312'!B13="Aula 7","C312 ","")&IF('C411'!B13="Aula 7","C411 ","")&IF('C412'!B13="Aula 7","C412 ","")&IF('M111'!B13="Aula 7","M111 ","")&IF('M112'!B13="Aula 7","M112 ","")&IF('M211'!B13="Aula 7","M211 ","")&IF('M212'!B13="Aula 7","M212 ","")&IF('M311'!B13="Aula 7","M311 ","")&IF('M411'!B13="Aula 7","M411 ","")&IF('D111'!B13="Aula 7","D111 ","")&IF('D112'!B13="Aula 7","D112 ","")&IF('D211'!B13="Aula 7","D211 ","")&IF('D311'!B13="Aula 7","D311 ","")&IF('D411'!B13="Aula 7","D411 ",""))," ",",") | I6: =SUBSTITUTE(TRIM(IF('C111'!B13="Aula 8","C111 ","")&IF('C112'!B13="Aula 8","C112 ","")&IF('C113'!B13="Aula 8","C113 ","")&IF('C121'!B13="Aula 8","C121 ","")&IF('C122'!B13="Aula 8","C122 ","")&IF('C211'!B13="Aula 8","C211 ","")&IF('C212'!B13="Aula 8","C212 ","")&IF('C311'!B13="Aula 8","C311 ","")&IF('C312'!B13="Aula 8","C312 ","")&IF('C411'!B13="Aula 8","C411 ","")&IF('C412'!B13="Aula 8","C412 ","")&IF('M111'!B13="Aula 8","M111 ","")&IF('M112'!B13="Aula 8","M112 ","")&IF('M211'!B13="Aula 8","M211 ","")&IF('M212'!B13="Aula 8","M212 ","")&IF('M311'!B13="Aula 8","M311 ","")&IF('M411'!B13="Aula 8","M411 ","")&IF('D111'!B13="Aula 8","D111 ","")&IF('D112'!B13="Aula 8","D112 ","")&IF('D211'!B13="Aula 8","D211 ","")&IF('D311'!B13="Aula 8","D311 ","")&IF('D411'!B13="Aula 8","D411 ",""))," ",",") | J6: =SUBSTITUTE(TRIM(IF('C111'!B13="Aula 9","C111 ","")&IF('C112'!B13="Aula 9","C112 ","")&IF('C113'!B13="Aula 9","C113 ","")&IF('C121'!B13="Aula 9","C121 ","")&IF('C122'!B13="Aula 9","C122 ","")&IF('C211'!B13="Aula 9","C211 ","")&IF('C212'!B13="Aula 9","C212 ","")&IF('C311'!B13="Aula 9","C311 ","")&IF('C312'!B13="Aula 9","C312 ","")&IF('C411'!B13="Aula 9","C411 ","")&IF('C412'!B13="Aula 9","C412 ","")&IF('M111'!B13="Aula 9","M111 ","")&IF('M112'!B13="Aula 9","M112 ","")&IF('M211'!B13="Aula 9","M211 ","")&IF('M212'!B13="Aula 9","M212 ","")&IF('M311'!B13="Aula 9","M311 ","")&IF('M411'!B13="Aula 9","M411 ","")&IF('D111'!B13="Aula 9","D111 ","")&IF('D112'!B13="Aula 9","D112 ","")&IF('D211'!B13="Aula 9","D211 ","")&IF('D311'!B13="Aula 9","D311 ","")&IF('D411'!B13="Aula 9","D411 ",""))," ",",") | K6: =SUBSTITUTE(TRIM(IF('C111'!B13="Aula 10","C111 ","")&IF('C112'!B13="Aula 10","C112 ","")&IF('C113'!B13="Aula 10","C113 ","")&IF('C121'!B13="Aula 10","C121 ","")&IF('C122'!B13="Aula 10","C122 ","")&IF('C211'!B13="Aula 10","C211 ","")&IF('C212'!B13="Aula 10","C212 ","")&IF('C311'!B13="Aula 10","C311 ","")&IF('C312'!B13="Aula 10","C312 ","")&IF('C411'!B13="Aula 10","C411 ","")&IF('C412'!B13="Aula 10","C412 ","")&IF('M111'!B13="Aula 10","M111 ","")&IF('M112'!B13="Aula 10","M112 ","")&IF('M211'!B13="Aula 10","M211 ","")&IF('M212'!B13="Aula 10","M212 ","")&IF('M311'!B13="Aula 10","M311 ","")&IF('M411'!B13="Aula 10","M411 ","")&IF('D111'!B13="Aula 10","D111 ","")&IF('D112'!B13="Aula 10","D112 ","")&IF('D211'!B13="Aula 10","D211 ","")&IF('D311'!B13="Aula 10","D311 ","")&IF('D411'!B13="Aula 10","D411 ",""))," ",",") | L6: =SUBSTITUTE(TRIM(IF('C111'!B13="Aula 11","C111 ","")&IF('C112'!B13="Aula 11","C112 ","")&IF('C113'!B13="Aula 11","C113 ","")&IF('C121'!B13="Aula 11","C121 ","")&IF('C122'!B13="Aula 11","C122 ","")&IF('C211'!B13="Aula 11","C211 ","")&IF('C212'!B13="Aula 11","C212 ","")&IF('C311'!B13="Aula 11","C311 ","")&IF('C312'!B13="Aula 11","C312 ","")&IF('C411'!B13="Aula 11","C411 ","")&IF('C412'!B13="Aula 11","C412 ","")&IF('M111'!B13="Aula 11","M111 ","")&IF('M112'!B13="Aula 11","M112 ","")&IF('M211'!B13="Aula 11","M211 ","")&IF('M212'!B13="Aula 11","M212 ","")&IF('M311'!B13="Aula 11","M311 ","")&IF('M411'!B13="Aula 11","M411 ","")&IF('D111'!B13="Aula 11","D111 ","")&IF('D112'!B13="Aula 11","D112 ","")&IF('D211'!B13="Aula 11","D211 ","")&IF('D311'!B13="Aula 11","D311 ","")&IF('D411'!B13="Aula 11","D411 ",""))," ",",") | M6: =SUBSTITUTE(TRIM(IF('C111'!B13="Aula 12","C111 ","")&IF('C112'!B13="Aula 12","C112 ","")&IF('C113'!B13="Aula 12","C113 ","")&IF('C121'!B13="Aula 12","C121 ","")&IF('C122'!B13="Aula 12","C122 ","")&IF('C211'!B13="Aula 12","C211 ","")&IF('C212'!B13="Aula 12","C212 ","")&IF('C311'!B13="Aula 12","C311 ","")&IF('C312'!B13="Aula 12","C312 ","")&IF('C411'!B13="Aula 12","C411 ","")&IF('C412'!B13="Aula 12","C412 ","")&IF('M111'!B13="Aula 12","M111 ","")&IF('M112'!B13="Aula 12","M112 ","")&IF('M211'!B13="Aula 12","M211 ","")&IF('M212'!B13="Aula 12","M212 ","")&IF('M311'!B13="Aula 12","M311 ","")&IF('M411'!B13="Aula 12","M411 ","")&IF('D111'!B13="Aula 12","D111 ","")&IF('D112'!B13="Aula 12","D112 ","")&IF('D211'!B13="Aula 12","D211 ","")&IF('D311'!B13="Aula 12","D311 ","")&IF('D411'!B13="Aula 12","D411 ",""))," ",",") | N6: =SUBSTITUTE(TRIM(IF('C111'!B13="Lab 1","C111 ","")&IF('C112'!B13="Lab 1","C112 ","")&IF('C113'!B13="Lab 1","C113 ","")&IF('C121'!B13="Lab 1","C121 ","")&IF('C122'!B13="Lab 1","C122 ","")&IF('C211'!B13="Lab 1","C211 ","")&IF('C212'!B13="Lab 1","C212 ","")&IF('C311'!B13="Lab 1","C311 ","")&IF('C312'!B13="Lab 1","C312 ","")&IF('C411'!B13="Lab 1","C411 ","")&IF('C412'!B13="Lab 1","C412 ","")&IF('M111'!B13="Lab 1","M111 ","")&IF('M112'!B13="Lab 1","M112 ","")&IF('M211'!B13="Lab 1","M211 ","")&IF('M212'!B13="Lab 1","M212 ","")&IF('M311'!B13="Lab 1","M311 ","")&IF('M411'!B13="Lab 1","M411 ","")&IF('D111'!B13="Lab 1","D111 ","")&IF('D112'!B13="Lab 1","D112 ","")&IF('D211'!B13="Lab 1","D211 ","")&IF('D311'!B13="Lab 1","D311 ","")&IF('D411'!B13="Lab 1","D411 ",""))," ",",") | O6: =SUBSTITUTE(TRIM(IF('C111'!B13="Lab 2","C111 ","")&IF('C112'!B13="Lab 2","C112 ","")&IF('C113'!B13="Lab 2","C113 ","")&IF('C121'!B13="Lab 2","C121 ","")&IF('C122'!B13="Lab 2","C122 ","")&IF('C211'!B13="Lab 2","C211 ","")&IF('C212'!B13="Lab 2","C212 ","")&IF('C311'!B13="Lab 2","C311 ","")&IF('C312'!B13="Lab 2","C312 ","")&IF('C411'!B13="Lab 2","C411 ","")&IF('C412'!B13="Lab 2","C412 ","")&IF('M111'!B13="Lab 2","M111 ","")&IF('M112'!B13="Lab 2","M112 ","")&IF('M211'!B13="Lab 2","M211 ","")&IF('M212'!B13="Lab 2","M212 ","")&IF('M311'!B13="Lab 2","M311 ","")&IF('M411'!B13="Lab 2","M411 ","")&IF('D111'!B13="Lab 2","D111 ","")&IF('D112'!B13="Lab 2","D112 ","")&IF('D211'!B13="Lab 2","D211 ","")&IF('D311'!B13="Lab 2","D311 ","")&IF('D411'!B13="Lab 2","D411 ",""))," ",",") | P6: =SUBSTITUTE(TRIM(IF('C111'!B13="Salón","C111 ","")&IF('C112'!B13="Salón","C112 ","")&IF('C113'!B13="Salón","C113 ","")&IF('C121'!B13="Salón","C121 ","")&IF('C122'!B13="Salón","C122 ","")&IF('C211'!B13="Salón","C211 ","")&IF('C212'!B13="Salón","C212 ","")&IF('C311'!B13="Salón","C311 ","")&IF('C312'!B13="Salón","C312 ","")&IF('C411'!B13="Salón","C411 ","")&IF('C412'!B13="Salón","C412 ","")&IF('M111'!B13="Salón","M111 ","")&IF('M112'!B13="Salón","M112 ","")&IF('M211'!B13="Salón","M211 ","")&IF('M212'!B13="Salón","M212 ","")&IF('M311'!B13="Salón","M311 ","")&IF('M411'!B13="Salón","M411 ","")&IF('D111'!B13="Salón","D111 ","")&IF('D112'!B13="Salón","D112 ","")&IF('D211'!B13="Salón","D211 ","")&IF('D311'!B13="Salón","D311 ","")&IF('D411'!B13="Salón","D411 ",""))," ",",")
