Workbook
Name AulasValidas: 'Datos'!$A$1:$A$10

Sheet Aulas
A1: Lunes | B1: Aula 1 | C1: Aula 2 | D1: Aula 3 | E1: Aula 4 | F1: Aula 5 | G1: Aula 6 | H1: Aula 7 | I1: Aula 8 | J1: Aula 9 | K1: Lab
A2: Turno 1 | B2: =SUBSTITUTE(TRIM(IF('C111'!B5="Aula 1","C111 ","")&IF('C112'!B5="Aula 1","C112 ","")&IF('C113'!B5="Aula 1","C113 ","")&IF('C121'!B5="Aula 1","C121 ","")&IF('C122'!B5="Aula 1","C122 ",""))," ",",") | C2: =SUBSTITUTE(TRIM(IF('C111'!B5="Aula 2","C111 ","")&IF('C112'!B5="Aula 2","C112 ","")&IF('C113'!B5="Aula 2","C113 ","")&IF('C121'!B5="Aula 2","C121 ","")&IF('C122'!B5="Aula 2","C122 ",""))," ",",") | D2: =SUBSTITUTE(TRIM(IF('C111'!B5="Aula 3","C111 ","")&IF('C112'!B5="Aula 3","C112 ","")&IF('C113'!B5="Aula 3","C113 ","")&IF('C121'!B5="Aula 3","C121 ","")&IF('C122'!B5="Aula 3","C122 ",""))," ",",") | E2: =SUBSTITUTE(TRIM(IF('C111'!B5="Aula 4","C111 ","")&IF('C112'!B5="Aula 4","C112 ","")&IF('C113'!B5="Aula 4","C113 ","")&IF('C121'!B5="Aula 4","C121 ","")&IF('C122'!B5="Aula 4","C122 ",""))," ",",") | F2: =SUBSTITUTE(TRIM(IF('C111'!B5="Aula 5","C111 ","")&IF('C112'!B5="Aula 5","C112 ","")&IF('C113'!B5="Aula 5","C113 ","")&IF('C121'!B5="Aula 5","C121 ","")&IF('C122'!B5="Aula 5","C122 ",""))," ",",") | G2: =SUBSTITUTE(TRIM(IF('C111'!B5="Aula 6","C111 ","")&IF('C112'!B5="Aula 6","C112 ","")&IF('C113'!B5="Aula 6","C113 ","")&IF('C121'!B5="Aula 6","C121 ","")&IF('C122'!B5="Aula 6","C122 ",""))," ",",") | H2: =SUBSTITUTE(TRIM(IF('C111'!B5="Aula 7","C111 ","")&IF('C112'!B5="Aula 7","C112 ","")&IF('C113'!B5="Aula 7","C113 ","")&IF('C121'!B5="Aula 7","C121 ","")&IF('C122'!B5="Aula 7","C122 ",""))," ",",") | I2: =SUBSTITUTE(TRIM(IF('C111'!B5="Aula 8","C111 ","")&IF('C112'!B5="Aula 8","C112 ","")&IF('C113'!B5="Aula 8","C113 ","")&IF('C121'!B5="Aula 8","C121 ","")&IF('C122'!B5="Aula 8","C122 ",""))," ",",") | J2: =SUBSTITUTE(TRIM(IF('C111'!B5="Aula 9","C111 ","")&IF('C112'!B5="Aula 9","C112 ","")&IF('C113'!B5="Aula 9","C113 ","")&IF('C121'!B5="Aula 9","C121 ","")&IF('C122'!B5="Aula 9","C122 ",""))," ",",") | K2: =SUBSTITUTE(TRIM(IF('C111'!B5="Lab","C111 ","")&IF('C112'!B5="Lab","C112 ","")&IF('C113'!B5="Lab","C113 ","")&IF('C121'!B5="Lab","C121 ","")&IF('C122'!B5="Lab","C122 ",""))," ",",")
A3: Turno 2 | B3: =SUBSTITUTE(TRIM(IF('C111'!B7="Aula 1","C111 ","")&IF('C112'!B7="Aula 1","C112 ","")&IF('C113'!B7="Aula 1","C113 ","")&IF('C121'!B7="Aula 1","C121 ","")&IF('C122'!B7="Aula 1","C122 ",""))," ",",") | C3: =SUBSTITUTE(TRIM(IF('C111'!B7="Aula 2","C111 ","")&IF('C112'!B7="Aula 2","C112 ","")&IF('C113'!B7="Aula 2","C113 ","")&IF('C121'!B7="Aula 2","C121 ","")&IF('C122'!B7="Aula 2","C122 ",""))," ",",") | D3: =SUBSTITUTE(TRIM(IF('C111'!B7="Aula 3","C111 ","")&IF('C112'!B7="Aula 3","C112 ","")&IF('C113'!B7="Aula 3","C113 ","")&IF('C121'!B7="Aula 3","C121 ","")&IF('C122'!B7="Aula 3","C122 ",""))," ",",") | E3: =SUBSTITUTE(TRIM(IF('C111'!B7="Aula 4","C111 ","")&IF('C112'!B7="Aula 4","C112 ","")&IF('C113'!B7="Aula 4","C113 ","")&IF('C121'!B7="Aula 4","C121 ","")&IF('C122'!B7="Aula 4","C122 ",""))," ",",") | F3: =SUBSTITUTE(TRIM(IF('C111'!B7="Aula 5","C111 ","")&IF('C112'!B7="Aula 5","C112 ","")&IF('C113'!B7="Aula 5","C113 ","")&IF('C121'!B7="Aula 5","C121 ","")&IF('C122'!B7="Aula 5","C122 ",""))," ",",") | G3: =SUBSTITUTE(TRIM(IF('C111'!B7="Aula 6","C111 ","")&IF('C112'!B7="Aula 6","C112 ","")&IF('C113'!B7="Aula 6","C113 ","")&IF('C121'!B7="Aula 6","C121 ","")&IF('C122'!B7="Aula 6","C122 ",""))," ",",") | H3: =SUBSTITUTE(TRIM(IF('C111'!B7="Aula 7","C111 ","")&IF('C112'!B7="Aula 7","C112 ","")&IF('C113'!B7="Aula 7","C113 ","")&IF('C121'!B7="Aula 7","C121 ","")&IF('C122'!B7="Aula 7","C122 ",""))," ",",") | I3: =SUBSTITUTE(TRIM(IF('C111'!B7="Aula 8","C111 ","")&IF('C112'!B7="Aula 8","C112 ","")&IF('C113'!B7="Aula 8","C113 ","")&IF('C121'!B7="Aula 8","C121 ","")&IF('C122'!B7="Aula 8","C122 ",""))," ",",") | J3: =SUBSTITUTE(TRIM(IF('C111'!B7="Aula 9","C111 ","")&IF('C112'!B7="Aula 9","C112 ","")&IF('C113'!B7="Aula 9","C113 ","")&IF('C121'!B7="Aula 9","C121 ","")&IF('C122'!B7="Aula 9","C122 ",""))," ",",") | K3: =SUBSTITUTE(TRIM(IF('C111'!B7="Lab","C111 ","")&IF('C112'!B7="Lab","C112 ","")&IF('C113'!B7="Lab","C113 ","")&IF('C121'!B7="Lab","C121 ","")&IF('C122'!B7="Lab","C122 ",""))," ",",")
A4: Turno 3 | B4: =SUBSTITUTE(TRIM(IF('C111'!B9="Aula 1","C111 ","")&IF('C112'!B9="Aula 1","C112 ","")&IF('C113'!B9="Aula 1","C113 ","")&IF('C121'!B9="Aula 1","C121 ","")&IF('C122'!B9="Aula 1","C122 ",""))," ",",") | C4: =SUBSTITUTE(TRIM(IF('C111'!B9="Aula 2","C111 ","")&IF('C112'!B9="Aula 2","C112 ","")&IF('C113'!B9="Aula 2","C113 ","")&IF('C121'!B9="Aula 2","C121 ","")&IF('C122'!B9="Aula 2","C122 ",""))," ",",") | D4: =SUBSTITUTE(TRIM(IF('C111'!B9="Aula 3","C111 ","")&IF('C112'!B9="Aula 3","C112 ","")&IF('C113'!B9="Aula 3","C113 ","")&IF('C121'!B9="Aula 3","C121 ","")&IF('C122'!B9="Aula 3","C122 ",""))," ",",") | E4: =SUBSTITUTE(TRIM(IF('C111'!B9="Aula 4","C111 ","")&IF('C112'!B9="Aula 4","C112 ","")&IF('C113'!B9="Aula 4","C113 ","")&IF('C121'!B9="Aula 4","C121 ","")&IF('C122'!B9="Aula 4","C122 ",""))," ",",") | F4: =SUBSTITUTE(TRIM(IF('C111'!B9="Aula 5","C111 ","")&IF('C112'!B9="Aula 5","C112 ","")&IF('C113'!B9="Aula 5","C113 ","")&IF('C121'!B9="Aula 5","C121 ","")&IF('C122'!B9="Aula 5","C122 ",""))," ",",") | G4: =SUBSTITUTE(TRIM(IF('C111'!B9="Aula 6","C111 ","")&IF('C112'!B9="Aula 6","C112 ","")&IF('C113'!B9="Aula 6","C113 ","")&IF('C121'!B9="Aula 6","C121 ","")&IF('C122'!B9="Aula 6","C122 ",""))," ",",") | H4: =SUBSTITUTE(TRIM(IF('C111'!B9="Aula 7","C111 ","")&IF('C112'!B9="Aula 7","C112 ","")&IF('C113'!B9="Aula 7","C113 ","")&IF('C121'!B9="Aula 7","C121 ","")&IF('C122'!B9="Aula 7","C122 ",""))," ",",") | I4: =SUBSTITUTE(TRIM(IF('C111'!B9="Aula 8","C111 ","")&IF('C112'!B9="Aula 8","C112 ","")&IF('C113'!B9="Aula 8","C113 ","")&IF('C121'!B9="Aula 8","C121 ","")&IF('C122'!B9="Aula 8","C122 ",""))," ",",") | J4: =SUBSTITUTE(TRIM(IF('C111'!B9="Aula 9","C111 ","")&IF('C112'!B9="Aula 9","C112 ","")&IF('C113'!B9="Aula 9","C113 ","")&IF('C121'!B9="Aula 9","C121 ","")&IF('C122'!B9="Aula 9","C122 ",""))," ",",") | K4: =SUBSTITUTE(TRIM(IF('C111'!B9="Lab","C111 ","")&IF('C112'!B9="Lab","C112 ","")&IF('C113'!B9="Lab","C113 ","")&IF('C121'!B9="Lab","C121 ","")&IF('C122'!B9="Lab","C122 ",""))," ",",")
A5: Turno 4 | B5: =SUBSTITUTE(TRIM(IF('C111'!B11="Aula 1","C111 ","")&IF('C112'!B11="Aula 1","C112 ","")&IF('C113'!B11="Aula 1","C113 ","")&IF('C121'!B11="Aula 1","C121 ","")&IF('C122'!B11="Aula 1","C122 ",""))," ",",") | C5: =SUBSTITUTE(TRIM(IF('C111'!B11="Aula 2","C111 ","")&IF('C112'!B11="Aula 2","C112 ","")&IF('C113'!B11="Aula 2","C113 ","")&IF('C121'!B11="Aula 2","C121 ","")&IF('C122'!B11="Aula 2","C122 ",""))," ",",") | D5: =SUBSTITUTE(TRIM(IF('C111'!B11="Aula 3","C111 ","")&IF('C112'!B11="Aula 3","C112 ","")&IF('C113'!B11="Aula 3","C113 ","")&IF('C121'!B11="Aula 3","C121 ","")&IF('C122'!B11="Aula 3","C122 ",""))," ",",") | E5: =SUBSTITUTE(TRIM(IF('C111'!B11="Aula 4","C111 ","")&IF('C112'!B11="Aula 4","C112 ","")&IF('C113'!B11="Aula 4","C113 ","")&IF('C121'!B11="Aula 4","C121 ","")&IF('C122'!B11="Aula 4","C122 ",""))," ",",") | F5: =SUBSTITUTE(TRIM(IF('C111'!B11="Aula 5","C111 ","")&IF('C112'!B11="Aula 5","C112 ","")&IF('C113'!B11="Aula 5","C113 ","")&IF('C121'!B11="Aula 5","C121 ","")&IF('C122'!B11="Aula 5","C122 ",""))," ",",") | G5: =SUBSTITUTE(TRIM(IF('C111'!B11="Aula 6","C111 ","")&IF('C112'!B11="Aula 6","C112 ","")&IF('C113'!B11="Aula 6","C113 ","")&IF('C121'!B11="Aula 6","C121 ","")&IF('C122'!B11="Aula 6","C122 ",""))," ",",") | H5: =SUBSTITUTE(TRIM(IF('C111'!B11="Aula 7","C111 ","")&IF('C112'!B11="Aula 7","C112 ","")&IF('C113'!B11="Aula 7","C113 ","")&IF('C121'!B11="Aula 7","C121 ","")&IF('C122'!B11="Aula 7","C122 ",""))," ",",") | I5: =SUBSTITUTE(TRIM(IF('C111'!B11="Aula 8","C111 ","")&IF('C112'!B11="Aula 8","C112 ","")&IF('C113'!B11="Aula 8","C113 ","")&IF('C121'!B11="Aula 8","C121 ","")&IF('C122'!B11="Aula 8","C122 ",""))," ",",") | J5: =SUBSTITUTE(TRIM(IF('C111'!B11="Aula 9","C111 ","")&IF('C112'!B11="Aula 9","C112 ","")&IF('C113'!B11="Aula 9","C113 ","")&IF('C121'!B11="Aula 9","C121 ","")&IF('C122'!B11="Aula 9","C122 ",""))," ",",") | K5: =SUBSTITUTE(TRIM(IF('C111'!B11="Lab","C111 ","")&IF('C112'!B11="Lab","C112 ","")&IF('C113'!B11="Lab","C113 ","")&IF('C121'!B11="Lab","C121 ","")&IF('C122'!B11="Lab","C122 ",""))," ",",")
A6: Turno 5 | B6: =SUBSTITUTE(TRIM(IF('C111'!B13="Aula 1","C111 ","")&IF('C112'!B13="Aula 1","C112 ","")&IF('C113'!B13="Aula 1","C113 ","")&IF('C121'!B13="Aula 1","C121 ","")&IF('C122'!B13="Aula 1","C122 ",""))," ",",") | C6: =SUBSTITUTE(TRIM(IF('C111'!B13="Aula 2","C111 ","")&IF('C112'!B13="Aula 2","C112 ","")&IF('C113'!B13="Aula 2","C113 ","")&IF('C121'!B13="Aula 2","C121 ","")&IF('C122'!B13="Aula 2","C122 ",""))," ",",") | D6: =SUBSTITUTE(TRIM(IF('C111'!B13="Aula 3","C111 ","")&IF('C112'!B13="Aula 3","C112 ","")&IF('C113'!B13="Aula 3","C113 ","")&IF('C121'!B13="Aula 3","C121 ","")&IF('C122'!B13="Aula 3","C122 ",""))," ",",") | E6: =SUBSTITUTE(TRIM(IF('C111'!B13="Aula 4","C111 ","")&IF('C112'!B13="Aula 4","C112 ","")&IF('C113'!B13="Aula 4","C113 ","")&IF('C121'!B13="Aula 4","C121 ","")&IF('C122'!B13="Aula 4","C122 ",""))," ",",") | F6: =SUBSTITUTE(TRIM(IF('C111'!B13="Aula 5","C111 ","")&IF('C112'!B13="Aula 5","C112 ","")&IF('C113'!B13="Aula 5","C113 ","")&IF('C121'!B13="Aula 5","C121 ","")&IF('C122'!B13="Aula 5","C122 ",""))," ",",") | G6: =SUBSTITUTE(TRIM(IF('C111'!B13="Aula 6","C111 ","")&IF('C112'!B13="Aula 6","C112 ","")&IF('C113'!B13="Aula 6","C113 ","")&IF('C121'!B13="Aula 6","C121 ","")&IF('C122'!B13="Aula 6","C122 ",""))," ",",") | H6: =SUBSTITUTE(TRIM(IF('C111'!B13="Aula 7","C111 ","")&IF('C112'!B13="Aula 7","C112 ","")&IF('C113'!B13="Aula 7","C113 ","")&IF('C121'!B13="Aula 7","C121 ","")&IF('C122'!B13="Aula 7","C122 ",""))," ",",") | I6: =SUBSTITUTE(TRIM(IF('C111'!B13="Aula 8","C111 ","")&IF('C112'!B13="Aula 8","C112 ","")&IF('C113'!B13="Aula 8","C113 ","")&IF('C121'!B13="Aula 8","C121 ","")&IF('C122'!B13="Aula 8","C122 ",""))," ",",") | J6: =SUBSTITUTE(TRIM(IF('C111'!B13="Aula 9","C111 ","")&IF('C112'!B13="Aula 9","C112 ","")&IF('C113'!B13="Aula 9","C113 ","")&IF('C121'!B13="Aula 9","C121 ","")&IF('C122'!B13="Aula 9","C122 ",""))," ",",") | K6: =SUBSTITUTE(TRIM(IF('C111'!B13="Lab","C111 ","")&IF('C112'!B13="Lab","C112 ","")&IF('C113'!B13="Lab","C113 ","")&IF('C121'!B13="Lab","C121 ","")&IF('C122'!B13="Lab","C122 ",""))," ",",")
A7: Turno 6 | B7: =SUBSTITUTE(TRIM(IF('C111'!B15="Aula 1","C111 ","")&IF('C112'!B15="Aula 1","C112 ","")&IF('C113'!B15="Aula 1","C113 ","")&IF('C121'!B15="Aula 1","C121 ","")&IF('C122'!B15="Aula 1","C122 ",""))," ",",") | C7: =SUBSTITUTE(TRIM(IF('C111'!B15="Aula 2","C111 ","")&IF('C112'!B15="Aula 2","C112 ","")&IF('C113'!B15="Aula 2","C113 ","")&IF('C121'!B15="Aula 2","C121 ","")&IF('C122'!B15="Aula 2","C122 ",""))," ",",") | D7: =SUBSTITUTE(TRIM(IF('C111'!B15="Aula 3","C111 ","")&IF('C112'!B15="Aula 3","C112 ","")&IF('C113'!B15="Aula 3","C113 ","")&IF('C121'!B15="Aula 3","C121 ","")&IF('C122'!B15="Aula 3","C122 ",""))," ",",") | E7: =SUBSTITUTE(TRIM(IF('C111'!B15="Aula 4","C111 ","")&IF('C112'!B15="Aula 4","C112 ","")&IF('C113'!B15="Aula 4","C113 ","")&IF('C121'!B15="Aula 4","C121 ","")&IF('C122'!B15="Aula 4","C122 ",""))," ",",") | F7: =SUBSTITUTE(TRIM(IF('C111'!B15="Aula 5","C111 ","")&IF('C112'!B15="Aula 5","C112 ","")&IF('C113'!B15="Aula 5","C113 ","")&IF('C121'!B15="Aula 5","C121 ","")&IF('C122'!B15="Aula 5","C122 ",""))," ",",") | G7: =SUBSTITUTE(TRIM(IF('C111'!B15="Aula 6","C111 ","")&IF('C112'!B15="Aula 6","C112 ","")&IF('C113'!B15="Aula 6","C113 ","")&IF('C121'!B15="Aula 6","C121 ","")&IF('C122'!B15="Aula 6","C122 ",""))," ",",") | H7: =SUBSTITUTE(TRIM(IF('C111'!B15="Aula 7","C111 ","")&IF('C112'!B15="Aula 7","C112 ","")&IF('C113'!B15="Aula 7","C113 ","")&IF('C121'!B15="Aula 7","C121 ","")&IF('C122'!B15="Aula 7","C122 ",""))," ",",") | I7: =SUBSTITUTE(TRIM(IF('C111'!B15="Aula 8","C111 ","")&IF('C112'!B15="Aula 8","C112 ","")&IF('C113'!B15="Aula 8","C113 ","")&IF('C121'!B15="Aula 8","C121 ","")&IF('C122'!B15="Aula 8","C122 ",""))," ",",") | J7: =SUBSTITUTE(TRIM(IF('C111'!B15="Aula 9","C111 ","")&IF('C112'!B15="Aula 9","C112 ","")&IF('C113'!B15="Aula 9","C113 ","")&IF('C121'!B15="Aula 9","C121 ","")&IF('C122'!B15="Aula 9","C122 ",""))," ",",") | K7: =SUBSTITUTE(TRIM(IF('C111'!B15="Lab","C111 ","")&IF('C112'!B15="Lab","C112 ","")&IF('C113'!B15="Lab","C113 ","")&IF('C121'!B15="Lab","C121 ","")&IF('C122'!B15="Lab","C122 ",""))," ",",")
A9: Martes | B9: Aula 1 | C9: Aula 2 | D9: Aula 3 | E9: Aula 4 | F9: Aula 5 | G9: Aula 6 | H9: Aula 7 | I9: Aula 8 | J9: Aula 9 | K9: Lab
A10: Turno 1 | B10: =SUBSTITUTE(TRIM(IF('C111'!C5="Aula 1","C111 ","")&IF('C112'!C5="Aula 1","C112 ","")&IF('C113'!C5="Aula 1","C113 ","")&IF('C121'!C5="Aula 1","C121 ","")&IF('C122'!C5="Aula 1","C122 ",""))," ",",") | C10: =SUBSTITUTE(TRIM(IF('C111'!C5="Aula 2","C111 ","")&IF('C112'!C5="Aula 2","C112 ","")&IF('C113'!C5="Aula 2","C113 ","")&IF('C121'!C5="Aula 2","C121 ","")&IF('C122'!C5="Aula 2","C122 ",""))," ",",") | D10: =SUBSTITUTE(TRIM(IF('C111'!C5="Aula 3","C111 ","")&IF('C112'!C5="Aula 3","C112 ","")&IF('C113'!C5="Aula 3","C113 ","")&IF('C121'!C5="Aula 3","C121 ","")&IF('C122'!C5="Aula 3","C122 ",""))," ",",") | E10: =SUBSTITUTE(TRIM(IF('C111'!C5="Aula 4","C111 ","")&IF('C112'!C5="Aula 4","C112 ","")&IF('C113'!C5="Aula 4","C113 ","")&IF('C121'!C5="Aula 4","C121 ","")&IF('C122'!C5="Aula 4","C122 ",""))," ",",") | F10: =SUBSTITUTE(TRIM(IF('C111'!C5="Aula 5","C111 ","")&IF('C112'!C5="Aula 5","C112 ","")&IF('C113'!C5="Aula 5","C113 ","")&IF('C121'!C5="Aula 5","C121 ","")&IF('C122'!C5="Aula 5","C122 ",""))," ",",") | G10: =SUBSTITUTE(TRIM(IF('C111'!C5="Aula 6","C111 ","")&IF('C112'!C5="Aula 6","C112 ","")&IF('C113'!C5="Aula 6","C113 ","")&IF('C121'!C5="Aula 6","C121 ","")&IF('C122'!C5="Aula 6","C122 ",""))," ",",") | H10: =SUBSTITUTE(TRIM(IF('C111'!C5="Aula 7","C111 ","")&IF('C112'!C5="Aula 7","C112 ","")&IF('C113'!C5="Aula 7","C113 ","")&IF('C121'!C5="Aula 7","C121 ","")&IF('C122'!C5="Aula 7","C122 ",""))," ",",") | I10: =SUBSTITUTE(TRIM(IF('C111'!C5="Aula 8","C111 ","")&IF('C112'!C5="Aula 8","C112 ","")&IF('C113'!C5="Aula 8","C113 ","")&IF('C121'!C5="Aula 8","C121 ","")&IF('C122'!C5="Aula 8","C122 ",""))," ",",") | J10: =SUBSTITUTE(TRIM(IF('C111'!C5="Aula 9","C111 ","")&IF('C112'!C5="Aula 9","C112 ","")&IF('C113'!C5="Aula 9","C113 ","")&IF('C121'!C5="Aula 9","C121 ","")&IF('C122'!C5="Aula 9","C122 ",""))," ",",") | K10: =SUBSTITUTE(TRIM(IF('C111'!C5="Lab","C111 ","")&IF('C112'!C5="Lab","C112 ","")&IF('C113'!C5="Lab","C113 ","")&IF('C121'!C5="Lab","C121 ","")&IF('C122'!C5="Lab","C122 ",""))," ",",")
A11: Turno 2 | B11: =SUBSTITUTE(TRIM(IF('C111'!C7="Aula 1","C111 ","")&IF('C112'!C7="Aula 1","C112 ","")&IF('C113'!C7="Aula 1","C113 ","")&IF('C121'!C7="Aula 1","C121 ","")&IF('C122'!C7="Aula 1","C122 ",""))," ",",") | C11: =SUBSTITUTE(TRIM(IF('C111'!C7="Aula 2","C111 ","")&IF('C112'!C7="Aula 2","C112 ","")&IF('C113'!C7="Aula 2","C113 ","")&IF('C121'!C7="Aula 2","C121 ","")&IF('C122'!C7="Aula 2","C122 ",""))," ",",") | D11: =SUBSTITUTE(TRIM(IF('C111'!C7="Aula 3","C111 ","")&IF('C112'!C7="Aula 3","C112 ","")&IF('C113'!C7="Aula 3","C113 ","")&IF('C121'!C7="Aula 3","C121 ","")&IF('C122'!C7="Aula 3","C122 ",""))," ",",") | E11: =SUBSTITUTE(TRIM(IF('C111'!C7="Aula 4","C111 ","")&IF('C112'!C7="Aula 4","C112 ","")&IF('C113'!C7="Aula 4","C113 ","")&IF('C121'!C7="Aula 4","C121 ","")&IF('C122'!C7="Aula 4","C122 ",""))," ",",") | F11: =SUBSTITUTE(TRIM(IF('C111'!C7="Aula 5","C111 ","")&IF('C112'!C7="Aula 5","C112 ","")&IF('C113'!C7="Aula 5","C113 ","")&IF('C121'!C7="Aula 5","C121 ","")&IF('C122'!C7="Aula 5","C122 ",""))," ",",") | G11: =SUBSTITUTE(TRIM(IF('C111'!C7="Aula 6","C111 ","")&IF('C112'!C7="Aula 6","C112 ","")&IF('C113'!C7="Aula 6","C113 ","")&IF('C121'!C7="Aula 6","C121 ","")&IF('C122'!C7="Aula 6","C122 ",""))," ",",") | H11: =SUBSTITUTE(TRIM(IF('C111'!C7="Aula 7","C111 ","")&IF('C112'!C7="Aula 7","C112 ","")&IF('C113'!C7="Aula 7","C113 ","")&IF('C121'!C7="Aula 7","C121 ","")&IF('C122'!C7="Aula 7","C122 ",""))," ",",") | I11: =SUBSTITUTE(TRIM(IF('C111'!C7="Aula 8","C111 ","")&IF('C112'!C7="Aula 8","C112 ","")&IF('C113'!C7="Aula 8","C113 ","")&IF('C121'!C7="Aula 8","C121 ","")&IF('C122'!C7="Aula 8","C122 ",""))," ",",") | J11: =SUBSTITUTE(TRIM(IF('C111'!C7="Aula 9","C111 ","")&IF('C112'!C7="Aula 9","C112 ","")&IF('C113'!C7="Aula 9","C113 ","")&IF('C121'!C7="Aula 9","C121 ","")&IF('C122'!C7="Aula 9","C122 ",""))," ",",") | K11: =SUBSTITUTE(TRIM(IF('C111'!C7="Lab","C111 ","")&IF('C112'!C7="Lab","C112 ","")&IF('C113'!C7="Lab","C113 ","")&IF('C121'!C7="Lab","C121 ","")&IF('C122'!C7="Lab","C122 ",""))," ",",")
A12: Turno 3 | B12: =SUBSTITUTE(TRIM(IF('C111'!C9="Aula 1","C111 ","")&IF('C112'!C9="Aula 1","C112 ","")&IF('C113'!C9="Aula 1","C113 ","")&IF('C121'!C9="Aula 1","C121 ","")&IF('C122'!C9="Aula 1","C122 ",""))," ",",") | C12: =SUBSTITUTE(TRIM(IF('C111'!C9="Aula 2","C111 ","")&IF('C112'!C9="Aula 2","C112 ","")&IF('C113'!C9="Aula 2","C113 ","")&IF('C121'!C9="Aula 2","C121 ","")&IF('C122'!C9="Aula 2","C122 ",""))," ",",") | D12: =SUBSTITUTE(TRIM(IF('C111'!C9="Aula 3","C111 ","")&IF('C112'!C9="Aula 3","C112 ","")&IF('C113'!C9="Aula 3","C113 ","")&IF('C121'!C9="Aula 3","C121 ","")&IF('C122'!C9="Aula 3","C122 ",""))," ",",") | E12: =SUBSTITUTE(TRIM(IF('C111'!C9="Aula 4","C111 ","")&IF('C112'!C9="Aula 4","C112 ","")&IF('C113'!C9="Aula 4","C113 ","")&IF('C121'!C9="Aula 4","C121 ","")&IF('C122'!C9="Aula 4","C122 ",""))," ",",") | F12: =SUBSTITUTE(TRIM(IF('C111'!C9="Aula 5","C111 ","")&IF('C112'!C9="Aula 5","C112 ","")&IF('C113'!C9="Aula 5","C113 ","")&IF('C121'!C9="Aula 5","C121 ","")&IF('C122'!C9="Aula 5","C122 ",""))," ",",") | G12: =SUBSTITUTE(TRIM(IF('C111'!C9="Aula 6","C111 ","")&IF('C112'!C9="Aula 6","C112 ","")&IF('C113'!C9="Aula 6","C113 ","")&IF('C121'!C9="Aula 6","C121 ","")&IF('C122'!C9="Aula 6","C122 ",""))," ",",") | H12: =SUBSTITUTE(TRIM(IF('C111'!C9="Aula 7","C111 ","")&IF('C112'!C9="Aula 7","C112 ","")&IF('C113'!C9="Aula 7","C113 ","")&IF('C121'!C9="Aula 7","C121 ","")&IF('C122'!C9="Aula 7","C122 ",""))," ",",") | I12: =SUBSTITUTE(TRIM(IF('C111'!C9="Aula 8","C111 ","")&IF('C112'!C9="Aula 8","C112 ","")&IF('C113'!C9="Aula 8","C113 ","")&IF('C121'!C9="Aula 8","C121 ","")&IF('C122'!C9="Aula 8","C122 ",""))," ",",") | J12: =SUBSTITUTE(TRIM(IF('C111'!C9="Aula 9","C111 ","")&IF('C112'!C9="Aula 9","C112 ","")&IF('C113'!C9="Aula 9","C113 ","")&IF('C121'!C9="Aula 9","C121 ","")&IF('C122'!C9="Aula 9","C122 ",""))," ",",") | K12: =SUBSTITUTE(TRIM(IF('C111'!C9="Lab","C111 ","")&IF('C112'!C9="Lab","C112 ","")&IF('C113'!C9="Lab","C113 ","")&IF('C121'!C9="Lab","C121 ","")&IF('C122'!C9="Lab","C122 ",""))," ",",")
A13: Turno 4 | B13: =SUBSTITUTE(TRIM(IF('C111'!C11="Aula 1","C111 ","")&IF('C112'!C11="Aula 1","C112 ","")&IF('C113'!C11="Aula 1","C113 ","")&IF('C121'!C11="Aula 1","C121 ","")&IF('C122'!C11="Aula 1","C122 ",""))," ",",") | C13: =SUBSTITUTE(TRIM(IF('C111'!C11="Aula 2","C111 ","")&IF('C112'!C11="Aula 2","C112 ","")&IF('C113'!C11="Aula 2","C113 ","")&IF('C121'!C11="Aula 2","C121 ","")&IF('C122'!C11="Aula 2","C122 ",""))," ",",") | D13: =SUBSTITUTE(TRIM(IF('C111'!C11="Aula 3","C111 ","")&IF('C112'!C11="Aula 3","C112 ","")&IF('C113'!C11="Aula 3","C113 ","")&IF('C121'!C11="Aula 3","C121 ","")&IF('C122'!C11="Aula 3","C122 ",""))," ",",") | E13: =SUBSTITUTE(TRIM(IF('C111'!C11="Aula 4","C111 ","")&IF('C112'!C11="Aula 4","C112 ","")&IF('C113'!C11="Aula 4","C113 ","")&IF('C121'!C11="Aula 4","C121 ","")&IF('C122'!C11="Aula 4","C122 ",""))," ",",") | F13: =SUBSTITUTE(TRIM(IF('C111'!C11="Aula 5","C111 ","")&IF('C112'!C11="Aula 5","C112 ","")&IF('C113'!C11="Aula 5","C113 ","")&IF('C121'!C11="Aula 5","C121 ","")&IF('C122'!C11="Aula 5","C122 ",""))," ",",") | G13: =SUBSTITUTE(TRIM(IF('C111'!C11="Aula 6","C111 ","")&IF('C112'!C11="Aula 6","C112 ","")&IF('C113'!C11="Aula 6","C113 ","")&IF('C121'!C11="Aula 6","C121 ","")&IF('C122'!C11="Aula 6","C122 ",""))," ",",") | H13: =SUBSTITUTE(TRIM(IF('C111'!C11="Aula 7","C111 ","")&IF('C112'!C11="Aula 7","C112 ","")&IF('C113'!C11="Aula 7","C113 ","")&IF('C121'!C11="Aula 7","C121 ","")&IF('C122'!C11="Aula 7","C122 ",""))," ",",") | I13: =SUBSTITUTE(TRIM(IF('C111'!C11="Aula 8","C111 ","")&IF('C112'!C11="Aula 8","C112 ","")&IF('C113'!C11="Aula 8","C113 ","")&IF('C121'!C11="Aula 8","C121 ","")&IF('C122'!C11="Aula 8","C122 ",""))," ",",") | J13: =SUBSTITUTE(TRIM(IF('C111'!C11="Aula 9","C111 ","")&IF('C112'!C11="Aula 9","C112 ","")&IF('C113'!C11="Aula 9","C113 ","")&IF('C121'!C11="Aula 9","C121 ","")&IF('C122'!C11="Aula 9","C122 ",""))," ",",") | K13: =SUBSTITUTE(TRIM(IF('C111'!C11="Lab","C111 ","")&IF('C112'!C11="Lab","C112 ","")&IF('C113'!C11="Lab","C113 ","")&IF('C121'!C11="Lab","C121 ","")&IF('C122'!C11="Lab","C122 ",""))," ",",")
A14: Turno 5 | B14: =SUBSTITUTE(TRIM(IF('C111'!C13="Aula 1","C111 ","")&IF('C112'!C13="Aula 1","C112 ","")&IF('C113'!C13="Aula 1","C113 ","")&IF('C121'!C13="Aula 1","C121 ","")&IF('C122'!C13="Aula 1","C122 ",""))," ",",") | C14: =SUBSTITUTE(TRIM(IF('C111'!C13="Aula 2","C111 ","")&IF('C112'!C13="Aula 2","C112 ","")&IF('C113'!C13="Aula 2","C113 ","")&IF('C121'!C13="Aula 2","C121 ","")&IF('C122'!C13="Aula 2","C122 ",""))," ",",") | D14: =SUBSTITUTE(TRIM(IF('C111'!C13="Aula 3","C111 ","")&IF('C112'!C13="Aula 3","C112 ","")&IF('C113'!C13="Aula 3","C113 ","")&IF('C121'!C13="Aula 3","C121 ","")&IF('C122'!C13="Aula 3","C122 ",""))," ",",") | E14: =SUBSTITUTE(TRIM(IF('C111'!C13="Aula 4","C111 ","")&IF('C112'!C13="Aula 4","C112 ","")&IF('C113'!C13="Aula 4","C113 ","")&IF('C121'!C13="Aula 4","C121 ","")&IF('C122'!C13="Aula 4","C122 ",""))," ",",") | F14: =SUBSTITUTE(TRIM(IF('C111'!C13="Aula 5","C111 ","")&IF('C112'!C13="Aula 5","C112 ","")&IF('C113'!C13="Aula 5","C113 ","")&IF('C121'!C13="Aula 5","C121 ","")&IF('C122'!C13="Aula 5","C122 ",""))," ",",") | G14: =SUBSTITUTE(TRIM(IF('C111'!C13="Aula 6","C111 ","")&IF('C112'!C13="Aula 6","C112 ","")&IF('C113'!C13="Aula 6","C113 ","")&IF('C121'!C13="Aula 6","C121 ","")&IF('C122'!C13="Aula 6","C122 ",""))," ",",") | H14: =SUBSTITUTE(TRIM(IF('C111'!C13="Aula 7","C111 ","")&IF('C112'!C13="Aula 7","C112 ","")&IF('C113'!C13="Aula 7","C113 ","")&IF('C121'!C13="Aula 7","C121 ","")&IF('C122'!C13="Aula 7","C122 ",""))," ",",") | I14: =SUBSTITUTE(TRIM(IF('C111'!C13="Aula 8","C111 ","")&IF('C112'!C13="Aula 8","C112 ","")&IF('C113'!C13="Aula 8","C113 ","")&IF('C121'!C13="Aula 8","C121 ","")&IF('C122'!C13="Aula 8","C122 ",""))," ",",") | J14: =SUBSTITUTE(TRIM(IF('C111'!C13="Aula 9","C111 ","")&IF('C112'!C13="Aula 9","C112 ","")&IF('C113'!C13="Aula 9","C113 ","")&IF('C121'!C13="Aula 9","C121 ","")&IF('C122'!C13="Aula 9","C122 ",""))," ",",") | K14: =SUBSTITUTE(TRIM(IF('C111'!C13="Lab","C111 ","")&IF('C112'!C13="Lab","C112 ","")&IF('C113'!C13="Lab","C113 ","")&IF('C121'!C13="Lab","C121 ","")&IF('C122'!C13="Lab","C122 ",""))," ",",")
A15: Turno 6 | B15: =SUBSTITUTE(TRIM(IF('C111'!C15="Aula 1","C111 ","")&IF('C112'!C15="Aula 1","C112 ","")&IF('C113'!C15="Aula 1","C113 ","")&IF('C121'!C15="Aula 1","C121 ","")&IF('C122'!C15="Aula 1","C122 ",""))," ",",") | C15: =SUBSTITUTE(TRIM(IF('C111'!C15="Aula 2","C111 ","")&IF('C112'!C15="Aula 2","C112 ","")&IF('C113'!C15="Aula 2","C113 ","")&IF('C121'!C15="Aula 2","C121 ","")&IF('C122'!C15="Aula 2","C122 ",""))," ",",") | D15: =SUBSTITUTE(TRIM(IF('C111'!C15="Aula 3","C111 ","")&IF('C112'!C15="Aula 3","C112 ","")&IF('C113'!C15="Aula 3","C113 ","")&IF('C121'!C15="Aula 3","C121 ","")&IF('C122'!C15="Aula 3","C122 ",""))," ",",") | E15: =SUBSTITUTE(TRIM(IF('C111'!C15="Aula 4","C111 ","")&IF('C112'!C15="Aula 4","C112 ","")&IF('C113'!C15="Aula 4","C113 ","")&IF('C121'!C15="Aula 4","C121 ","")&IF('C122'!C15="Aula 4","C122 ",""))," ",",") | F15: =SUBSTITUTE(TRIM(IF('C111'!C15="Aula 5","C111 ","")&IF('C112'!C15="Aula 5","C112 ","")&IF('C113'!C15="Aula 5","C113 ","")&IF('C121'!C15="Aula 5","C121 ","")&IF('C122'!C15="Aula 5","C122 ",""))," ",",") | G15: =SUBSTITUTE(TRIM(IF('C111'!C15="Aula 6","C111 ","")&IF('C112'!C15="Aula 6","C112 ","")&IF('C113'!C15="Aula 6","C113 ","")&IF('C121'!C15="Aula 6","C121 ","")&IF('C122'!C15="Aula 6","C122 ",""))," ",",") | H15: =SUBSTITUTE(TRIM(IF('C111'!C15="Aula 7","C111 ","")&IF('C112'!C15="Aula 7","C112 ","")&IF('C113'!C15="Aula 7","C113 ","")&IF('C121'!C15="Aula 7","C121 ","")&IF('C122'!C15="Aula 7","C122 ",""))," ",",") | I15: =SUBSTITUTE(TRIM(IF('C111'!C15="Aula 8","C111 ","")&IF('C112'!C15="Aula 8","C112 ","")&IF('C113'!C15="Aula 8","C113 ","")&IF('C121'!C15="Aula 8","C121 ","")&IF('C122'!C15="Aula 8","C122 ",""))," ",",") | J15: =SUBSTITUTE(TRIM(IF('C111'!C15="Aula 9","C111 ","")&IF('C112'!C15="Aula 9","C112 ","")&IF('C113'!C15="Aula 9","C113 ","")&IF('C121'!C15="Aula 9","C121 ","")&IF('C122'!C15="Aula 9","C122 ",""))," ",",") | K15: =SUBSTITUTE(TRIM(IF('C111'!C15="Lab","C111 ","")&IF('C112'!C15="Lab","C112 ","")&IF('C113'!C15="Lab","C113 ","")&IF('C121'!C15="Lab","C121 ","")&IF('C122'!C15="Lab","C122 ",""))," ",",")
A17: Miércoles | B17: Aula 1 | C17: Aula 2 | D17: Aula 3 | E17: Aula 4 | F17: Aula 5 | G17: Aula 6 | H17: Aula 7 | I17: Aula 8 | J17: Aula 9 | K17: Lab
A18: Turno 1 | B18: =SUBSTITUTE(TRIM(IF('C111'!D5="Aula 1","C111 ","")&IF('C112'!D5="Aula 1","C112 ","")&IF('C113'!D5="Aula 1","C113 ","")&IF('C121'!D5="Aula 1","C121 ","")&IF('C122'!D5="Aula 1","C122 ",""))," ",",") | C18: =SUBSTITUTE(TRIM(IF('C111'!D5="Aula 2","C111 ","")&IF('C112'!D5="Aula 2","C112 ","")&IF('C113'!D5="Aula 2","C113 ","")&IF('C121'!D5="Aula 2","C121 ","")&IF('C122'!D5="Aula 2","C122 ",""))," ",",") | D18: =SUBSTITUTE(TRIM(IF('C111'!D5="Aula 3","C111 ","")&IF('C112'!D5="Aula 3","C112 ","")&IF('C113'!D5="Aula 3","C113 ","")&IF('C121'!D5="Aula 3","C121 ","")&IF('C122'!D5="Aula 3","C122 ",""))," ",",") | E18: =SUBSTITUTE(TRIM(IF('C111'!D5="Aula 4","C111 ","")&IF('C112'!D5="Aula 4","C112 ","")&IF('C113'!D5="Aula 4","C113 ","")&IF('C121'!D5="Aula 4","C121 ","")&IF('C122'!D5="Aula 4","C122 ",""))," ",",") | F18: =SUBSTITUTE(TRIM(IF('C111'!D5="Aula 5","C111 ","")&IF('C112'!D5="Aula 5","C112 ","")&IF('C113'!D5="Aula 5","C113 ","")&IF('C121'!D5="Aula 5","C121 ","")&IF('C122'!D5="Aula 5","C122 ",""))," ",",") | G18: =SUBSTITUTE(TRIM(IF('C111'!D5="Aula 6","C111 ","")&IF('C112'!D5="Aula 6","C112 ","")&IF('C113'!D5="Aula 6","C113 ","")&IF('C121'!D5="Aula 6","C121 ","")&IF('C122'!D5="Aula 6","C122 ",""))," ",",") | H18: =SUBSTITUTE(TRIM(IF('C111'!D5="Aula 7","C111 ","")&IF('C112'!D5="Aula 7","C112 ","")&IF('C113'!D5="Aula 7","C113 ","")&IF('C121'!D5="Aula 7","C121 ","")&IF('C122'!D5="Aula 7","C122 ",""))," ",",") | I18: =SUBSTITUTE(TRIM(IF('C111'!D5="Aula 8","C111 ","")&IF('C112'!D5="Aula 8","C112 ","")&IF('C113'!D5="Aula 8","C113 ","")&IF('C121'!D5="Aula 8","C121 ","")&IF('C122'!D5="Aula 8","C122 ",""))," ",",") | J18: =SUBSTITUTE(TRIM(IF('C111'!D5="Aula 9","C111 ","")&IF('C112'!D5="Aula 9","C112 ","")&IF('C113'!D5="Aula 9","C113 ","")&IF('C121'!D5="Aula 9","C121 ","")&IF('C122'!D5="Aula 9","C122 ",""))," ",",") | K18: =SUBSTITUTE(TRIM(IF('C111'!D5="Lab","C111 ","")&IF('C112'!D5="Lab","C112 ","")&IF('C113'!D5="Lab","C113 ","")&IF('C121'!D5="Lab","C121 ","")&IF('C122'!D5="Lab","C122 ",""))," ",",")
A19: Turno 2 | B19: =SUBSTITUTE(TRIM(IF('C111'!D7="Aula 1","C111 ","")&IF('C112'!D7="Aula 1","C112 ","")&IF('C113'!D7="Aula 1","C113 ","")&IF('C121'!D7="Aula 1","C121 ","")&IF('C122'!D7="Aula 1","C122 ",""))," ",",") | C19: =SUBSTITUTE(TRIM(IF('C111'!D7="Aula 2","C111 ","")&IF('C112'!D7="Aula 2","C112 ","")&IF('C113'!D7="Aula 2","C113 ","")&IF('C121'!D7="Aula 2","C121 ","")&IF('C122'!D7="Aula 2","C122 ",""))," ",",") | D19: =SUBSTITUTE(TRIM(IF('C111'!D7="Aula 3","C111 ","")&IF('C112'!D7="Aula 3","C112 ","")&IF('C113'!D7="Aula 3","C113 ","")&IF('C121'!D7="Aula 3","C121 ","")&IF('C122'!D7="Aula 3","C122 ",""))," ",",") | E19: =SUBSTITUTE(TRIM(IF('C111'!D7="Aula 4","C111 ","")&IF('C112'!D7="Aula 4","C112 ","")&IF('C113'!D7="Aula 4","C113 ","")&IF('C121'!D7="Aula 4","C121 ","")&IF('C122'!D7="Aula 4","C122 ",""))," ",",") | F19: =SUBSTITUTE(TRIM(IF('C111'!D7="Aula 5","C111 ","")&IF('C112'!D7="Aula 5","C112 ","")&IF('C113'!D7="Aula 5","C113 ","")&IF('C121'!D7="Aula 5","C121 ","")&IF('C122'!D7="Aula 5","C122 ",""))," ",",") | G19: =SUBSTITUTE(TRIM(IF('C111'!D7="Aula 6","C111 ","")&IF('C112'!D7="Aula 6","C112 ","")&IF('C113'!D7="Aula 6","C113 ","")&IF('C121'!D7="Aula 6","C121 ","")&IF('C122'!D7="Aula 6","C122 ",""))," ",",") | H19: =SUBSTITUTE(TRIM(IF('C111'!D7="Aula 7","C111 ","")&IF('C112'!D7="Aula 7","C112 ","")&IF('C113'!D7="Aula 7","C113 ","")&IF('C121'!D7="Aula 7","C121 ","")&IF('C122'!D7="Aula 7","C122 ",""))," ",",") | I19: =SUBSTITUTE(TRIM(IF('C111'!D7="Aula 8","C111 ","")&IF('C112'!D7="Aula 8","C112 ","")&IF('C113'!D7="Aula 8","C113 ","")&IF('C121'!D7="Aula 8","C121 ","")&IF('C122'!D7="Aula 8","C122 ",""))," ",",") | J19: =SUBSTITUTE(TRIM(IF('C111'!D7="Aula 9","C111 ","")&IF('C112'!D7="Aula 9","C112 ","")&IF('C113'!D7="Aula 9","C113 ","")&IF('C121'!D7="Aula 9","C121 ","")&IF('C122'!D7="Aula 9","C122 ",""))," ",",") | K19: =SUBSTITUTE(TRIM(IF('C111'!D7="Lab","C111 ","")&IF('C112'!D7="Lab","C112 ","")&IF('C113'!D7="Lab","C113 ","")&IF('C121'!D7="Lab","C121 ","")&IF('C122'!D7="Lab","C122 ",""))," ",",")
A20: Turno 3 | B20: =SUBSTITUTE(TRIM(IF('C111'!D9="Aula 1","C111 ","")&IF('C112'!D9="Aula 1","C112 ","")&IF('C113'!D9="Aula 1","C113 ","")&IF('C121'!D9="Aula 1","C121 ","")&IF('C122'!D9="Aula 1","C122 ",""))," ",",") | C20: =SUBSTITUTE(TRIM(IF('C111'!D9="Aula 2","C111 ","")&IF('C112'!D9="Aula 2","C112 ","")&IF('C113'!D9="Aula 2","C113 ","")&IF('C121'!D9="Aula 2","C121 ","")&IF('C122'!D9="Aula 2","C122 ",""))," ",",") | D20: =SUBSTITUTE(TRIM(IF('C111'!D9="Aula 3","C111 ","")&IF('C112'!D9="Aula 3","C112 ","")&IF('C113'!D9="Aula 3","C113 ","")&IF('C121'!D9="Aula 3","C121 ","")&IF('C122'!D9="Aula 3","C122 ",""))," ",",") | E20: =SUBSTITUTE(TRIM(IF('C111'!D9="Aula 4","C111 ","")&IF('C112'!D9="Aula 4","C112 ","")&IF('C113'!D9="Aula 4","C113 ","")&IF('C121'!D9="Aula 4","C121 ","")&IF('C122'!D9="Aula 4","C122 ",""))," ",",") | F20: =SUBSTITUTE(TRIM(IF('C111'!D9="Aula 5","C111 ","")&IF('C112'!D9="Aula 5","C112 ","")&IF('C113'!D9="Aula 5","C113 ","")&IF('C121'!D9="Aula 5","C121 ","")&IF('C122'!D9="Aula 5","C122 ",""))," ",",") | G20: =SUBSTITUTE(TRIM(IF('C111'!D9="Aula 6","C111 ","")&IF('C112'!D9="Aula 6","C112 ","")&IF('C113'!D9="Aula 6","C113 ","")&IF('C121'!D9="Aula 6","C121 ","")&IF('C122'!D9="Aula 6","C122 ",""))," ",",") | H20: =SUBSTITUTE(TRIM(IF('C111'!D9="Aula 7","C111 ","")&IF('C112'!D9="Aula 7","C112 ","")&IF('C113'!D9="Aula 7","C113 ","")&IF('C121'!D9="Aula 7","C121 ","")&IF('C122'!D9="Aula 7","C122 ",""))," ",",") | I20: =SUBSTITUTE(TRIM(IF('C111'!D9="Aula 8","C111 ","")&IF('C112'!D9="Aula 8","C112 ","")&IF('C113'!D9="Aula 8","C113 ","")&IF('C121'!D9="Aula 8","C121 ","")&IF('C122'!D9="Aula 8","C122 ",""))," ",",") | J20: =SUBSTITUTE(TRIM(IF('C111'!D9="Aula 9","C111 ","")&IF('C112'!D9="Aula 9","C112 ","")&IF('C113'!D9="Aula 9","C113 ","")&IF('C121'!D9="Aula 9","C121 ","")&IF('C122'!D9="Aula 9","C122 ",""))," ",",") | K20: =SUBSTITUTE(TRIM(IF('C111'!D9="Lab","C111 ","")&IF('C112'!D9="Lab","C112 ","")&IF('C113'!D9="Lab","C113 ","")&IF('C121'!D9="Lab","C121 ","")&IF('C122'!D9="Lab","C122 ",""))," ",",")
A21: Turno 4 | B21: =SUBSTITUTE(TRIM(IF('C111'!D11="Aula 1","C111 ","")&IF('C112'!D11="Aula 1","C112 ","")&IF('C113'!D11="Aula 1","C113 ","")&IF('C121'!D11="Aula 1","C121 ","")&IF('C122'!D11="Aula 1","C122 ",""))," ",",") | C21: =SUBSTITUTE(TRIM(IF('C111'!D11="Aula 2","C111 ","")&IF('C112'!D11="Aula 2","C112 ","")&IF('C113'!D11="Aula 2","C113 ","")&IF('C121'!D11="Aula 2","C121 ","")&IF('C122'!D11="Aula 2","C122 ",""))," ",",") | D21: =SUBSTITUTE(TRIM(IF('C111'!D11="Aula 3","C111 ","")&IF('C112'!D11="Aula 3","C112 ","")&IF('C113'!D11="Aula 3","C113 ","")&IF('C121'!D11="Aula 3","C121 ","")&IF('C122'!D11="Aula 3","C122 ",""))," ",",") | E21: =SUBSTITUTE(TRIM(IF('C111'!D11="Aula 4","C111 ","")&IF('C112'!D11="Aula 4","C112 ","")&IF('C113'!D11="Aula 4","C113 ","")&IF('C121'!D11="Aula 4","C121 ","")&IF('C122'!D11="Aula 4","C122 ",""))," ",",") | F21: =SUBSTITUTE(TRIM(IF('C111'!D11="Aula 5","C111 ","")&IF('C112'!D11="Aula 5","C112 ","")&IF('C113'!D11="Aula 5","C113 ","")&IF('C121'!D11="Aula 5","C121 ","")&IF('C122'!D11="Aula 5","C122 ",""))," ",",") | G21: =SUBSTITUTE(TRIM(IF('C111'!D11="Aula 6","C111 ","")&IF('C112'!D11="Aula 6","C112 ","")&IF('C113'!D11="Aula 6","C113 ","")&IF('C121'!D11="Aula 6","C121 ","")&IF('C122'!D11="Aula 6","C122 ",""))," ",",") | H21: =SUBSTITUTE(TRIM(IF('C111'!D11="Aula 7","C111 ","")&IF('C112'!D11="Aula 7","C112 ","")&IF('C113'!D11="Aula 7","C113 ","")&IF('C121'!D11="Aula 7","C121 ","")&IF('C122'!D11="Aula 7","C122 ",""))," ",",") | I21: =SUBSTITUTE(TRIM(IF('C111'!D11="Aula 8","C111 ","")&IF('C112'!D11="Aula 8","C112 ","")&IF('C113'!D11="Aula 8","C113 ","")&IF('C121'!D11="Aula 8","C121 ","")&IF('C122'!D11="Aula 8","C122 ",""))," ",",") | J21: =SUBSTITUTE(TRIM(IF('C111'!D11="Aula 9","C111 ","")&IF('C112'!D11="Aula 9","C112 ","")&IF('C113'!D11="Aula 9","C113 ","")&IF('C121'!D11="Aula 9","C121 ","")&IF('C122'!D11="Aula 9","C122 ",""))," ",",") | K21: =SUBSTITUTE(TRIM(IF('C111'!D11="Lab","C111 ","")&IF('C112'!D11="Lab","C112 ","")&IF('C113'!D11="Lab","C113 ","")&IF('C121'!D11="Lab","C121 ","")&IF('C122'!D11="Lab","C122 ",""))," ",",")
A22: Turno 5 | B22: =SUBSTITUTE(TRIM(IF('C111'!D13="Aula 1","C111 ","")&IF('C112'!D13="Aula 1","C112 ","")&IF('C113'!D13="Aula 1","C113 ","")&IF('C121'!D13="Aula 1","C121 ","")&IF('C122'!D13="Aula 1","C122 ",""))," ",",") | C22: =SUBSTITUTE(TRIM(IF('C111'!D13="Aula 2","C111 ","")&IF('C112'!D13="Aula 2","C112 ","")&IF('C113'!D13="Aula 2","C113 ","")&IF('C121'!D13="Aula 2","C121 ","")&IF('C122'!D13="Aula 2","C122 ",""))," ",",") | D22: =SUBSTITUTE(TRIM(IF('C111'!D13="Aula 3","C111 ","")&IF('C112'!D13="Aula 3","C112 ","")&IF('C113'!D13="Aula 3","C113 ","")&IF('C121'!D13="Aula 3","C121 ","")&IF('C122'!D13="Aula 3","C122 ",""))," ",",") | E22: =SUBSTITUTE(TRIM(IF('C111'!D13="Aula 4","C111 ","")&IF('C112'!D13="Aula 4","C112 ","")&IF('C113'!D13="Aula 4","C113 ","")&IF('C121'!D13="Aula 4","C121 ","")&IF('C122'!D13="Aula 4","C122 ",""))," ",",") | F22: =SUBSTITUTE(TRIM(IF('C111'!D13="Aula 5","C111 ","")&IF('C112'!D13="Aula 5","C112 ","")&IF('C113'!D13="Aula 5","C113 ","")&IF('C121'!D13="Aula 5","C121 ","")&IF('C122'!D13="Aula 5","C122 ",""))," ",",") | G22: =SUBSTITUTE(TRIM(IF('C111'!D13="Aula 6","C111 ","")&IF('C112'!D13="Aula 6","C112 ","")&IF('C113'!D13="Aula 6","C113 ","")&IF('C121'!D13="Aula 6","C121 ","")&IF('C122'!D13="Aula 6","C122 ",""))," ",",") | H22: =SUBSTITUTE(TRIM(IF('C111'!D13="Aula 7","C111 ","")&IF('C112'!D13="Aula 7","C112 ","")&IF('C113'!D13="Aula 7","C113 ","")&IF('C121'!D13="Aula 7","C121 ","")&IF('C122'!D13="Aula 7","C122 ",""))," ",",") | I22: =SUBSTITUTE(TRIM(IF('C111'!D13="Aula 8","C111 ","")&IF('C112'!D13="Aula 8","C112 ","")&IF('C113'!D13="Aula 8","C113 ","")&IF('C121'!D13="Aula 8","C121 ","")&IF('C122'!D13="Aula 8","C122 ",""))," ",",") | J22: =SUBSTITUTE(TRIM(IF('C111'!D13="Aula 9","C111 ","")&IF('C112'!D13="Aula 9","C112 ","")&IF('C113'!D13="Aula 9","C113 ","")&IF('C121'!D13="Aula 9","C121 ","")&IF('C122'!D13="Aula 9","C122 ",""))," ",",") | K22: =SUBSTITUTE(TRIM(IF('C111'!D13="Lab","C111 ","")&IF('C112'!D13="Lab","C112 ","")&IF('C113'!D13="Lab","C113 ","")&IF('C121'!D13="Lab","C121 ","")&IF('C122'!D13="Lab","C122 ",""))," ",",")
A23: Turno 6 | B23: =SUBSTITUTE(TRIM(IF('C111'!D15="Aula 1","C111 ","")&IF('C112'!D15="Aula 1","C112 ","")&IF('C113'!D15="Aula 1","C113 ","")&IF('C121'!D15="Aula 1","C121 ","")&IF('C122'!D15="Aula 1","C122 ",""))," ",",") | C23: =SUBSTITUTE(TRIM(IF('C111'!D15="Aula 2","C111 ","")&IF('C112'!D15="Aula 2","C112 ","")&IF('C113'!D15="Aula 2","C113 ","")&IF('C121'!D15="Aula 2","C121 ","")&IF('C122'!D15="Aula 2","C122 ",""))," ",",") | D23: =SUBSTITUTE(TRIM(IF('C111'!D15="Aula 3","C111 ","")&IF('C112'!D15="Aula 3","C112 ","")&IF('C113'!D15="Aula 3","C113 ","")&IF('C121'!D15="Aula 3","C121 ","")&IF('C122'!D15="Aula 3","C122 ",""))," ",",") | E23: =SUBSTITUTE(TRIM(IF('C111'!D15="Aula 4","C111 ","")&IF('C112'!D15="Aula 4","C112 ","")&IF('C113'!D15="Aula 4","C113 ","")&IF('C121'!D15="Aula 4","C121 ","")&IF('C122'!D15="Aula 4","C122 ",""))," ",",") | F23: =SUBSTITUTE(TRIM(IF('C111'!D15="Aula 5","C111 ","")&IF('C112'!D15="Aula 5","C112 ","")&IF('C113'!D15="Aula 5","C113 ","")&IF('C121'!D15="Aula 5","C121 ","")&IF('C122'!D15="Aula 5","C122 ",""))," ",",") | G23: =SUBSTITUTE(TRIM(IF('C111'!D15="Aula 6","C111 ","")&IF('C112'!D15="Aula 6","C112 ","")&IF('C113'!D15="Aula 6","C113 ","")&IF('C121'!D15="Aula 6","C121 ","")&IF('C122'!D15="Aula 6","C122 ",""))," ",",") | H23: =SUBSTITUTE(TRIM(IF('C111'!D15="Aula 7","C111 ","")&IF('C112'!D15="Aula 7","C112 ","")&IF('C113'!D15="Aula 7","C113 ","")&IF('C121'!D15="Aula 7","C121 ","")&IF('C122'!D15="Aula 7","C122 ",""))," ",",") | I23: =SUBSTITUTE(TRIM(IF('C111'!D15="Aula 8","C111 ","")&IF('C112'!D15="Aula 8","C112 ","")&IF('C113'!D15="Aula 8","C113 ","")&IF('C121'!D15="Aula 8","C121 ","")&IF('C122'!D15="Aula 8","C122 ",""))," ",",") | J23: =SUBSTITUTE(TRIM(IF('C111'!D15="Aula 9","C111 ","")&IF('C112'!D15="Aula 9","C112 ","")&IF('C113'!D15="Aula 9","C113 ","")&IF('C121'!D15="Aula 9","C121 ","")&IF('C122'!D15="Aula 9","C122 ",""))," ",",") | K23: =SUBSTITUTE(TRIM(IF('C111'!D15="Lab","C111 ","")&IF('C112'!D15="Lab","C112 ","")&IF('C113'!D15="Lab","C113 ","")&IF('C121'!D15="Lab","C121 ","")&IF('C122'!D15="Lab","C122 ",""))," ",",")
A25: Jueves | B25: Aula 1 | C25: Aula 2 | D25: Aula 3 | E25: Aula 4 | F25: Aula 5 | G25: Aula 6 | H25: Aula 7 | I25: Aula 8 | J25: Aula 9 | K25: Lab
A26: Turno 1 | B26: =SUBSTITUTE(TRIM(IF('C111'!E5="Aula 1","C111 ","")&IF('C112'!E5="Aula 1","C112 ","")&IF('C113'!E5="Aula 1","C113 ","")&IF('C121'!E5="Aula 1","C121 ","")&IF('C122'!E5="Aula 1","C122 ",""))," ",",") | C26: =SUBSTITUTE(TRIM(IF('C111'!E5="Aula 2","C111 ","")&IF('C112'!E5="Aula 2","C112 ","")&IF('C113'!E5="Aula 2","C113 ","")&IF('C121'!E5="Aula 2","C121 ","")&IF('C122'!E5="Aula 2","C122 ",""))," ",",") | D26: =SUBSTITUTE(TRIM(IF('C111'!E5="Aula 3","C111 ","")&IF('C112'!E5="Aula 3","C112 ","")&IF('C113'!E5="Aula 3","C113 ","")&IF('C121'!E5="Aula 3","C121 ","")&IF('C122'!E5="Aula 3","C122 ",""))," ",",") | E26: =SUBSTITUTE(TRIM(IF('C111'!E5="Aula 4","C111 ","")&IF('C112'!E5="Aula 4","C112 ","")&IF('C113'!E5="Aula 4","C113 ","")&IF('C121'!E5="Aula 4","C121 ","")&IF('C122'!E5="Aula 4","C122 ",""))," ",",") | F26: =SUBSTITUTE(TRIM(IF('C111'!E5="Aula 5","C111 ","")&IF('C112'!E5="Aula 5","C112 ","")&IF('C113'!E5="Aula 5","C113 ","")&IF('C121'!E5="Aula 5","C121 ","")&IF('C122'!E5="Aula 5","C122 ",""))," ",",") | G26: =SUBSTITUTE(TRIM(IF('C111'!E5="Aula 6","C111 ","")&IF('C112'!E5="Aula 6","C112 ","")&IF('C113'!E5="Aula 6","C113 ","")&IF('C121'!E5="Aula 6","C121 ","")&IF('C122'!E5="Aula 6","C122 ",""))," ",",") | H26: =SUBSTITUTE(TRIM(IF('C111'!E5="Aula 7","C111 ","")&IF('C112'!E5="Aula 7","C112 ","")&IF('C113'!E5="Aula 7","C113 ","")&IF('C121'!E5="Aula 7","C121 ","")&IF('C122'!E5="Aula 7","C122 ",""))," ",",") | I26: =SUBSTITUTE(TRIM(IF('C111'!E5="Aula 8","C111 ","")&IF('C112'!E5="Aula 8","C112 ","")&IF('C113'!E5="Aula 8","C113 ","")&IF('C121'!E5="Aula 8","C121 ","")&IF('C122'!E5="Aula 8","C122 ",""))," ",",") | J26: =SUBSTITUTE(TRIM(IF('C111'!E5="Aula 9","C111 ","")&IF('C112'!E5="Aula 9","C112 ","")&IF('C113'!E5="Aula 9","C113 ","")&IF('C121'!E5="Aula 9","C121 ","")&IF('C122'!E5="Aula 9","C122 ",""))," ",",") | K26: =SUBSTITUTE(TRIM(IF('C111'!E5="Lab","C111 ","")&IF('C112'!E5="Lab","C112 ","")&IF('C113'!E5="Lab","C113 ","")&IF('C121'!E5="Lab","C121 ","")&IF('C122'!E5="Lab","C122 ",""))," ",",")
A27: Turno 2 | B27: =SUBSTITUTE(TRIM(IF('C111'!E7="Aula 1","C111 ","")&IF('C112'!E7="Aula 1","C112 ","")&IF('C113'!E7="Aula 1","C113 ","")&IF('C121'!E7="Aula 1","C121 ","")&IF('C122'!E7="Aula 1","C122 ",""))," ",",") | C27: =SUBSTITUTE(TRIM(IF('C111'!E7="Aula 2","C111 ","")&IF('C112'!E7="Aula 2","C112 ","")&IF('C113'!E7="Aula 2","C113 ","")&IF('C121'!E7="Aula 2","C121 ","")&IF('C122'!E7="Aula 2","C122 ",""))," ",",") | D27: =SUBSTITUTE(TRIM(IF('C111'!E7="Aula 3","C111 ","")&IF('C112'!E7="Aula 3","C112 ","")&IF('C113'!E7="Aula 3","C113 ","")&IF('C121'!E7="Aula 3","C121 ","")&IF('C122'!E7="Aula 3","C122 ",""))," ",",") | E27: =SUBSTITUTE(TRIM(IF('C111'!E7="Aula 4","C111 ","")&IF('C112'!E7="Aula 4","C112 ","")&IF('C113'!E7="Aula 4","C113 ","")&IF('C121'!E7="Aula 4","C121 ","")&IF('C122'!E7="Aula 4","C122 ",""))," ",",") | F27: =SUBSTITUTE(TRIM(IF('C111'!E7="Aula 5","C111 ","")&IF('C112'!E7="Aula 5","C112 ","")&IF('C113'!E7="Aula 5","C113 ","")&IF('C121'!E7="Aula 5","C121 ","")&IF('C122'!E7="Aula 5","C122 ",""))," ",",") | G27: =SUBSTITUTE(TRIM(IF('C111'!E7="Aula 6","C111 ","")&IF('C112'!E7="Aula 6","C112 ","")&IF('C113'!E7="Aula 6","C113 ","")&IF('C121'!E7="Aula 6","C121 ","")&IF('C122'!E7="Aula 6","C122 ",""))," ",",") | H27: =SUBSTITUTE(TRIM(IF('C111'!E7="Aula 7","C111 ","")&IF('C112'!E7="Aula 7","C112 ","")&IF('C113'!E7="Aula 7","C113 ","")&IF('C121'!E7="Aula 7","C121 ","")&IF('C122'!E7="Aula 7","C122 ",""))," ",",") | I27: =SUBSTITUTE(TRIM(IF('C111'!E7="Aula 8","C111 ","")&IF('C112'!E7="Aula 8","C112 ","")&IF('C113'!E7="Aula 8","C113 ","")&IF('C121'!E7="Aula 8","C121 ","")&IF('C122'!E7="Aula 8","C122 ",""))," ",",") | J27: =SUBSTITUTE(TRIM(IF('C111'!E7="Aula 9","C111 ","")&IF('C112'!E7="Aula 9","C112 ","")&IF('C113'!E7="Aula 9","C113 ","")&IF('C121'!E7="Aula 9","C121 ","")&IF('C122'!E7="Aula 9","C122 ",""))," ",",") | K27: =SUBSTITUTE(TRIM(IF('C111'!E7="Lab","C111 ","")&IF('C112'!E7="Lab","C112 ","")&IF('C113'!E7="Lab","C113 ","")&IF('C121'!E7="Lab","C121 ","")&IF('C122'!E7="Lab","C122 ",""))," ",",")
A28: Turno 3 | B28: =SUBSTITUTE(TRIM(IF('C111'!E9="Aula 1","C111 ","")&IF('C112'!E9="Aula 1","C112 ","")&IF('C113'!E9="Aula 1","C113 ","")&IF('C121'!E9="Aula 1","C121 ","")&IF('C122'!E9="Aula 1","C122 ",""))," ",",") | C28: =SUBSTITUTE(TRIM(IF('C111'!E9="Aula 2","C111 ","")&IF('C112'!E9="Aula 2","C112 ","")&IF('C113'!E9="Aula 2","C113 ","")&IF('C121'!E9="Aula 2","C121 ","")&IF('C122'!E9="Aula 2","C122 ",""))," ",",") | D28: =SUBSTITUTE(TRIM(IF('C111'!E9="Aula 3","C111 ","")&IF('C112'!E9="Aula 3","C112 ","")&IF('C113'!E9="Aula 3","C113 ","")&IF('C121'!E9="Aula 3","C121 ","")&IF('C122'!E9="Aula 3","C122 ",""))," ",",") | E28: =SUBSTITUTE(TRIM(IF('C111'!E9="Aula 4","C111 ","")&IF('C112'!E9="Aula 4","C112 ","")&IF('C113'!E9="Aula 4","C113 ","")&IF('C121'!E9="Aula 4","C121 ","")&IF('C122'!E9="Aula 4","C122 ",""))," ",",") | F28: =SUBSTITUTE(TRIM(IF('C111'!E9="Aula 5","C111 ","")&IF('C112'!E9="Aula 5","C112 ","")&IF('C113'!E9="Aula 5","C113 ","")&IF('C121'!E9="Aula 5","C121 ","")&IF('C122'!E9="Aula 5","C122 ",""))," ",",") | G28: =SUBSTITUTE(TRIM(IF('C111'!E9="Aula 6","C111 ","")&IF('C112'!E9="Aula 6","C112 ","")&IF('C113'!E9="Aula 6","C113 ","")&IF('C121'!E9="Aula 6","C121 ","")&IF('C122'!E9="Aula 6","C122 ",""))," ",",") | H28: =SUBSTITUTE(TRIM(IF('C111'!E9="Aula 7","C111 ","")&IF('C112'!E9="Aula 7","C112 ","")&IF('C113'!E9="Aula 7","C113 ","")&IF('C121'!E9="Aula 7","C121 ","")&IF('C122'!E9="Aula 7","C122 ",""))," ",",") | I28: =SUBSTITUTE(TRIM(IF('C111'!E9="Aula 8","C111 ","")&IF('C112'!E9="Aula 8","C112 ","")&IF('C113'!E9="Aula 8","C113 ","")&IF('C121'!E9="Aula 8","C121 ","")&IF('C122'!E9="Aula 8","C122 ",""))," ",",") | J28: =SUBSTITUTE(TRIM(IF('C111'!E9="Aula 9","C111 ","")&IF('C112'!E9="Aula 9","C112 ","")&IF('C113'!E9="Aula 9","C113 ","")&IF('C121'!E9="Aula 9","C121 ","")&IF('C122'!E9="Aula 9","C122 ",""))," ",",") | K28: =SUBSTITUTE(TRIM(IF('C111'!E9="Lab","C111 ","")&IF('C112'!E9="Lab","C112 ","")&IF('C113'!E9="Lab","C113 ","")&IF('C121'!E9="Lab","C121 ","")&IF('C122'!E9="Lab","C122 ",""))," ",",")
A29: Turno 4 | B29: =SUBSTITUTE(TRIM(IF('C111'!E11="Aula 1","C111 ","")&IF('C112'!E11="Aula 1","C112 ","")&IF('C113'!E11="Aula 1","C113 ","")&IF('C121'!E11="Aula 1","C121 ","")&IF('C122'!E11="Aula 1","C122 ",""))," ",",") | C29: =SUBSTITUTE(TRIM(IF('C111'!E11="Aula 2","C111 ","")&IF('C112'!E11="Aula 2","C112 ","")&IF('C113'!E11="Aula 2","C113 ","")&IF('C121'!E11="Aula 2","C121 ","")&IF('C122'!E11="Aula 2","C122 ",""))," ",",") | D29: =SUBSTITUTE(TRIM(IF('C111'!E11="Aula 3","C111 ","")&IF('C112'!E11="Aula 3","C112 ","")&IF('C113'!E11="Aula 3","C113 ","")&IF('C121'!E11="Aula 3","C121 ","")&IF('C122'!E11="Aula 3","C122 ",""))," ",",") | E29: =SUBSTITUTE(TRIM(IF('C111'!E11="Aula 4","C111 ","")&IF('C112'!E11="Aula 4","C112 ","")&IF('C113'!E11="Aula 4","C113 ","")&IF('C121'!E11="Aula 4","C121 ","")&IF('C122'!E11="Aula 4","C122 ",""))," ",",") | F29: =SUBSTITUTE(TRIM(IF('C111'!E11="Aula 5","C111 ","")&IF('C112'!E11="Aula 5","C112 ","")&IF('C113'!E11="Aula 5","C113 ","")&IF('C121'!E11="Aula 5","C121 ","")&IF('C122'!E11="Aula 5","C122 ",""))," ",",") | G29: =SUBSTITUTE(TRIM(IF('C111'!E11="Aula 6","C111 ","")&IF('C112'!E11="Aula 6","C112 ","")&IF('C113'!E11="Aula 6","C113 ","")&IF('C121'!E11="Aula 6","C121 ","")&IF('C122'!E11="Aula 6","C122 ",""))," ",",") | H29: =SUBSTITUTE(TRIM(IF('C111'!E11="Aula 7","C111 ","")&IF('C112'!E11="Aula 7","C112 ","")&IF('C113'!E11="Aula 7","C113 ","")&IF('C121'!E11="Aula 7","C121 ","")&IF('C122'!E11="Aula 7","C122 ",""))," ",",") | I29: =SUBSTITUTE(TRIM(IF('C111'!E11="Aula 8","C111 ","")&IF('C112'!E11="Aula 8","C112 ","")&IF('C113'!E11="Aula 8","C113 ","")&IF('C121'!E11="Aula 8","C121 ","")&IF('C122'!E11="Aula 8","C122 ",""))," ",",") | J29: =SUBSTITUTE(TRIM(IF('C111'!E11="Aula 9","C111 ","")&IF('C112'!E11="Aula 9","C112 ","")&IF('C113'!E11="Aula 9","C113 ","")&IF('C121'!E11="Aula 9","C121 ","")&IF('C122'!E11="Aula 9","C122 ",""))," ",",") | K29: =SUBSTITUTE(TRIM(IF('C111'!E11="Lab","C111 ","")&IF('C112'!E11="Lab","C112 ","")&IF('C113'!E11="Lab","C113 ","")&IF('C121'!E11="Lab","C121 ","")&IF('C122'!E11="Lab","C122 ",""))," ",",")
A30: Turno 5 | B30: =SUBSTITUTE(TRIM(IF('C111'!E13="Aula 1","C111 ","")&IF('C112'!E13="Aula 1","C112 ","")&IF('C113'!E13="Aula 1","C113 ","")&IF('C121'!E13="Aula 1","C121 ","")&IF('C122'!E13="Aula 1","C122 ",""))," ",",") | C30: =SUBSTITUTE(TRIM(IF('C111'!E13="Aula 2","C111 ","")&IF('C112'!E13="Aula 2","C112 ","")&IF('C113'!E13="Aula 2","C113 ","")&IF('C121'!E13="Aula 2","C121 ","")&IF('C122'!E13="Aula 2","C122 ",""))," ",",") | D30: =SUBSTITUTE(TRIM(IF('C111'!E13="Aula 3","C111 ","")&IF('C112'!E13="Aula 3","C112 ","")&IF('C113'!E13="Aula 3","C113 ","")&IF('C121'!E13="Aula 3","C121 ","")&IF('C122'!E13="Aula 3","C122 ",""))," ",",") | E30: =SUBSTITUTE(TRIM(IF('C111'!E13="Aula 4","C111 ","")&IF('C112'!E13="Aula 4","C112 ","")&IF('C113'!E13="Aula 4","C113 ","")&IF('C121'!E13="Aula 4","C121 ","")&IF('C122'!E13="Aula 4","C122 ",""))," ",",") | F30: =SUBSTITUTE(TRIM(IF('C111'!E13="Aula 5","C111 ","")&IF('C112'!E13="Aula 5","C112 ","")&IF('C113'!E13="Aula 5","C113 ","")&IF('C121'!E13="Aula 5","C121 ","")&IF('C122'!E13="Aula 5","C122 ",""))," ",",") | G30: =SUBSTITUTE(TRIM(IF('C111'!E13="Aula 6","C111 ","")&IF('C112'!E13="Aula 6","C112 ","")&IF('C113'!E13="Aula 6","C113 ","")&IF('C121'!E13="Aula 6","C121 ","")&IF('C122'!E13="Aula 6","C122 ",""))," ",",") | H30: =SUBSTITUTE(TRIM(IF('C111'!E13="Aula 7","C111 ","")&IF('C112'!E13="Aula 7","C112 ","")&IF('C113'!E13="Aula 7","C113 ","")&IF('C121'!E13="Aula 7","C121 ","")&IF('C122'!E13="Aula 7","C122 ",""))," ",",") | I30: =SUBSTITUTE(TRIM(IF('C111'!E13="Aula 8","C111 ","")&IF('C112'!E13="Aula 8","C112 ","")&IF('C113'!E13="Aula 8","C113 ","")&IF('C121'!E13="Aula 8","C121 ","")&IF('C122'!E13="Aula 8","C122 ",""))," ",",") | J30: =SUBSTITUTE(TRIM(IF('C111'!E13="Aula 9","C111 ","")&IF('C112'!E13="Aula 9","C112 ","")&IF('C113'!E13="Aula 9","C113 ","")&IF('C121'!E13="Aula 9","C121 ","")&IF('C122'!E13="Aula 9","C122 ",""))," ",",") | K30: =SUBSTITUTE(TRIM(IF('C111'!E13="Lab","C111 ","")&IF('C112'!E13="Lab","C112 ","")&IF('C113'!E13="Lab","C113 ","")&IF('C121'!E13="Lab","C121 ","")&IF('C122'!E13="Lab","C122 ",""))," ",",")
A31: Turno 6 | B31: =SUBSTITUTE(TRIM(IF('C111'!E15="Aula 1","C111 ","")&IF('C112'!E15="Aula 1","C112 ","")&IF('C113'!E15="Aula 1","C113 ","")&IF('C121'!E15="Aula 1","C121 ","")&IF('C122'!E15="Aula 1","C122 ",""))," ",",") | C31: =SUBSTITUTE(TRIM(IF('C111'!E15="Aula 2","C111 ","")&IF('C112'!E15="Aula 2","C112 ","")&IF('C113'!E15="Aula 2","C113 ","")&IF('C121'!E15="Aula 2","C121 ","")&IF('C122'!E15="Aula 2","C122 ",""))," ",",") | D31: =SUBSTITUTE(TRIM(IF('C111'!E15="Aula 3","C111 ","")&IF('C112'!E15="Aula 3","C112 ","")&IF('C113'!E15="Aula 3","C113 ","")&IF('C121'!E15="Aula 3","C121 ","")&IF('C122'!E15="Aula 3","C122 ",""))," ",",") | E31: =SUBSTITUTE(TRIM(IF('C111'!E15="Aula 4","C111 ","")&IF('C112'!E15="Aula 4","C112 ","")&IF('C113'!E15="Aula 4","C113 ","")&IF('C121'!E15="Aula 4","C121 ","")&IF('C122'!E15="Aula 4","C122 ",""))," ",",") | F31: =SUBSTITUTE(TRIM(IF('C111'!E15="Aula 5","C111 ","")&IF('C112'!E15="Aula 5","C112 ","")&IF('C113'!E15="Aula 5","C113 ","")&IF('C121'!E15="Aula 5","C121 ","")&IF('C122'!E15="Aula 5","C122 ",""))," ",",") | G31: =SUBSTITUTE(TRIM(IF('C111'!E15="Aula 6","C111 ","")&IF('C112'!E15="Aula 6","C112 ","")&IF('C113'!E15="Aula 6","C113 ","")&IF('C121'!E15="Aula 6","C121 ","")&IF('C122'!E15="Aula 6","C122 ",""))," ",",") | H31: =SUBSTITUTE(TRIM(IF('C111'!E15="Aula 7","C111 ","")&IF('C112'!E15="Aula 7","C112 ","")&IF('C113'!E15="Aula 7","C113 ","")&IF('C121'!E15="Aula 7","C121 ","")&IF('C122'!E15="Aula 7","C122 ",""))," ",",") | I31: =SUBSTITUTE(TRIM(IF('C111'!E15="Aula 8","C111 ","")&IF('C112'!E15="Aula 8","C112 ","")&IF('C113'!E15="Aula 8","C113 ","")&IF('C121'!E15="Aula 8","C121 ","")&IF('C122'!E15="Aula 8","C122 ",""))," ",",") | J31: =SUBSTITUTE(TRIM(IF('C111'!E15="Aula 9","C111 ","")&IF('C112'!E15="Aula 9","C112 ","")&IF('C113'!E15="Aula 9","C113 ","")&IF('C121'!E15="Aula 9","C121 ","")&IF('C122'!E15="Aula 9","C122 ",""))," ",",") | K31: =SUBSTITUTE(TRIM(IF('C111'!E15="Lab","C111 ","")&IF('C112'!E15="Lab","C112 ","")&IF('C113'!E15="Lab","C113 ","")&IF('C121'!E15="Lab","C121 ","")&IF('C122'!E15="Lab","C122 ",""))," ",",")
A33: Viernes | B33: Aula 1 | C33: Aula 2 | D33: Aula 3 | E33: Aula 4 | F33: Aula 5 | G33: Aula 6 | H33: Aula 7 | I33: Aula 8 | J33: Aula 9 | K33: Lab
A34: Turno 1 | B34: =SUBSTITUTE(TRIM(IF('C111'!F5="Aula 1","C111 ","")&IF('C112'!F5="Aula 1","C112 ","")&IF('C113'!F5="Aula 1","C113 ","")&IF('C121'!F5="Aula 1","C121 ","")&IF('C122'!F5="Aula 1","C122 ",""))," ",",") | C34: =SUBSTITUTE(TRIM(IF('C111'!F5="Aula 2","C111 ","")&IF('C112'!F5="Aula 2","C112 ","")&IF('C113'!F5="Aula 2","C113 ","")&IF('C121'!F5="Aula 2","C121 ","")&IF('C122'!F5="Aula 2","C122 ",""))," ",",") | D34: =SUBSTITUTE(TRIM(IF('C111'!F5="Aula 3","C111 ","")&IF('C112'!F5="Aula 3","C112 ","")&IF('C113'!F5="Aula 3","C113 ","")&IF('C121'!F5="Aula 3","C121 ","")&IF('C122'!F5="Aula 3","C122 ",""))," ",",") | E34: =SUBSTITUTE(TRIM(IF('C111'!F5="Aula 4","C111 ","")&IF('C112'!F5="Aula 4","C112 ","")&IF('C113'!F5="Aula 4","C113 ","")&IF('C121'!F5="Aula 4","C121 ","")&IF('C122'!F5="Aula 4","C122 ",""))," ",",") | F34: =SUBSTITUTE(TRIM(IF('C111'!F5="Aula 5","C111 ","")&IF('C112'!F5="Aula 5","C112 ","")&IF('C113'!F5="Aula 5","C113 ","")&IF('C121'!F5="Aula 5","C121 ","")&IF('C122'!F5="Aula 5","C122 ",""))," ",",") | G34: =SUBSTITUTE(TRIM(IF('C111'!F5="Aula 6","C111 ","")&IF('C112'!F5="Aula 6","C112 ","")&IF('C113'!F5="Aula 6","C113 ","")&IF('C121'!F5="Aula 6","C121 ","")&IF('C122'!F5="Aula 6","C122 ",""))," ",",") | H34: =SUBSTITUTE(TRIM(IF('C111'!F5="Aula 7","C111 ","")&IF('C112'!F5="Aula 7","C112 ","")&IF('C113'!F5="Aula 7","C113 ","")&IF('C121'!F5="Aula 7","C121 ","")&IF('C122'!F5="Aula 7","C122 ",""))," ",",") | I34: =SUBSTITUTE(TRIM(IF('C111'!F5="Aula 8","C111 ","")&IF('C112'!F5="Aula 8","C112 ","")&IF('C113'!F5="Aula 8","C113 ","")&IF('C121'!F5="Aula 8","C121 ","")&IF('C122'!F5="Aula 8","C122 ",""))," ",",") | J34: =SUBSTITUTE(TRIM(IF('C111'!F5="Aula 9","C111 ","")&IF('C112'!F5="Aula 9","C112 ","")&IF('C113'!F5="Aula 9","C113 ","")&IF('C121'!F5="Aula 9","C121 ","")&IF('C122'!F5="Aula 9","C122 ",""))," ",",") | K34: =SUBSTITUTE(TRIM(IF('C111'!F5="Lab","C111 ","")&IF('C112'!F5="Lab","C112 ","")&IF('C113'!F5="Lab","C113 ","")&IF('C121'!F5="Lab","C121 ","")&IF('C122'!F5="Lab","C122 ",""))," ",",")
A35: Turno 2 | B35: =SUBSTITUTE(TRIM(IF('C111'!F7="Aula 1","C111 ","")&IF('C112'!F7="Aula 1","C112 ","")&IF('C113'!F7="Aula 1","C113 ","")&IF('C121'!F7="Aula 1","C121 ","")&IF('C122'!F7="Aula 1","C122 ",""))," ",",") | C35: =SUBSTITUTE(TRIM(IF('C111'!F7="Aula 2","C111 ","")&IF('C112'!F7="Aula 2","C112 ","")&IF('C113'!F7="Aula 2","C113 ","")&IF('C121'!F7="Aula 2","C121 ","")&IF('C122'!F7="Aula 2","C122 ",""))," ",",") | D35: =SUBSTITUTE(TRIM(IF('C111'!F7="Aula 3","C111 ","")&IF('C112'!F7="Aula 3","C112 ","")&IF('C113'!F7="Aula 3","C113 ","")&IF('C121'!F7="Aula 3","C121 ","")&IF('C122'!F7="Aula 3","C122 ",""))," ",",") | E35: =SUBSTITUTE(TRIM(IF('C111'!F7="Aula 4","C111 ","")&IF('C112'!F7="Aula 4","C112 ","")&IF('C113'!F7="Aula 4","C113 ","")&IF('C121'!F7="Aula 4","C121 ","")&IF('C122'!F7="Aula 4","C122 ",""))," ",",") | F35: =SUBSTITUTE(TRIM(IF('C111'!F7="Aula 5","C111 ","")&IF('C112'!F7="Aula 5","C112 ","")&IF('C113'!F7="Aula 5","C113 ","")&IF('C121'!F7="Aula 5","C121 ","")&IF('C122'!F7="Aula 5","C122 ",""))," ",",") | G35: =SUBSTITUTE(TRIM(IF('C111'!F7="Aula 6","C111 ","")&IF('C112'!F7="Aula 6","C112 ","")&IF('C113'!F7="Aula 6","C113 ","")&IF('C121'!F7="Aula 6","C121 ","")&IF('C122'!F7="Aula 6","C122 ",""))," ",",") | H35: =SUBSTITUTE(TRIM(IF('C111'!F7="Aula 7","C111 ","")&IF('C112'!F7="Aula 7","C112 ","")&IF('C113'!F7="Aula 7","C113 ","")&IF('C121'!F7="Aula 7","C121 ","")&IF('C122'!F7="Aula 7","C122 ",""))," ",",") | I35: =SUBSTITUTE(TRIM(IF('C111'!F7="Aula 8","C111 ","")&IF('C112'!F7="Aula 8","C112 ","")&IF('C113'!F7="Aula 8","C113 ","")&IF('C121'!F7="Aula 8","C121 ","")&IF('C122'!F7="Aula 8","C122 ",""))," ",",") | J35: =SUBSTITUTE(TRIM(IF('C111'!F7="Aula 9","C111 ","")&IF('C112'!F7="Aula 9","C112 ","")&IF('C113'!F7="Aula 9","C113 ","")&IF('C121'!F7="Aula 9","C121 ","")&IF('C122'!F7="Aula 9","C122 ",""))," ",",") | K35: =SUBSTITUTE(TRIM(IF('C111'!F7="Lab","C111 ","")&IF('C112'!F7="Lab","C112 ","")&IF('C113'!F7="Lab","C113 ","")&IF('C121'!F7="Lab","C121 ","")&IF('C122'!F7="Lab","C122 ",""))," ",",")
A36: Turno 3 | B36: =SUBSTITUTE(TRIM(IF('C111'!F9="Aula 1","C111 ","")&IF('C112'!F9="Aula 1","C112 ","")&IF('C113'!F9="Aula 1","C113 ","")&IF('C121'!F9="Aula 1","C121 ","")&IF('C122'!F9="Aula 1","C122 ",""))," ",",") | C36: =SUBSTITUTE(TRIM(IF('C111'!F9="Aula 2","C111 ","")&IF('C112'!F9="Aula 2","C112 ","")&IF('C113'!F9="Aula 2","C113 ","")&IF('C121'!F9="Aula 2","C121 ","")&IF('C122'!F9="Aula 2","C122 ",""))," ",",") | D36: =SUBSTITUTE(TRIM(IF('C111'!F9="Aula 3","C111 ","")&IF('C112'!F9="Aula 3","C112 ","")&IF('C113'!F9="Aula 3","C113 ","")&IF('C121'!F9="Aula 3","C121 ","")&IF('C122'!F9="Aula 3","C122 ",""))," ",",") | E36: =SUBSTITUTE(TRIM(IF('C111'!F9="Aula 4","C111 ","")&IF('C112'!F9="Aula 4","C112 ","")&IF('C113'!F9="Aula 4","C113 ","")&IF('C121'!F9="Aula 4","C121 ","")&IF('C122'!F9="Aula 4","C122 ",""))," ",",") | F36: =SUBSTITUTE(TRIM(IF('C111'!F9="Aula 5","C111 ","")&IF('C112'!F9="Aula 5","C112 ","")&IF('C113'!F9="Aula 5","C113 ","")&IF('C121'!F9="Aula 5","C121 ","")&IF('C122'!F9="Aula 5","C122 ",""))," ",",") | G36: =SUBSTITUTE(TRIM(IF('C111'!F9="Aula 6","C111 ","")&IF('C112'!F9="Aula 6","C112 ","")&IF('C113'!F9="Aula 6","C113 ","")&IF('C121'!F9="Aula 6","C121 ","")&IF('C122'!F9="Aula 6","C122 ",""))," ",",") | H36: =SUBSTITUTE(TRIM(IF('C111'!F9="Aula 7","C111 ","")&IF('C112'!F9="Aula 7","C112 ","")&IF('C113'!F9="Aula 7","C113 ","")&IF('C121'!F9="Aula 7","C121 ","")&IF('C122'!F9="Aula 7","C122 ",""))," ",",") | I36: =SUBSTITUTE(TRIM(IF('C111'!F9="Aula 8","C111 ","")&IF('C112'!F9="Aula 8","C112 ","")&IF('C113'!F9="Aula 8","C113 ","")&IF('C121'!F9="Aula 8","C121 ","")&IF('C122'!F9="Aula 8","C122 ",""))," ",",") | J36: =SUBSTITUTE(TRIM(IF('C111'!F9="Aula 9","C111 ","")&IF('C112'!F9="Aula 9","C112 ","")&IF('C113'!F9="Aula 9","C113 ","")&IF('C121'!F9="Aula 9","C121 ","")&IF('C122'!F9="Aula 9","C122 ",""))," ",",") | K36: =SUBSTITUTE(TRIM(IF('C111'!F9="Lab","C111 ","")&IF('C112'!F9="Lab","C112 ","")&IF('C113'!F9="Lab","C113 ","")&IF('C121'!F9="Lab","C121 ","")&IF('C122'!F9="Lab","C122 ",""))," ",",")
A37: Turno 4 | B37: =SUBSTITUTE(TRIM(IF('C111'!F11="Aula 1","C111 ","")&IF('C112'!F11="Aula 1","C112 ","")&IF('C113'!F11="Aula 1","C113 ","")&IF('C121'!F11="Aula 1","C121 ","")&IF('C122'!F11="Aula 1","C122 ",""))," ",",") | C37: =SUBSTITUTE(TRIM(IF('C111'!F11="Aula 2","C111 ","")&IF('C112'!F11="Aula 2","C112 ","")&IF('C113'!F11="Aula 2","C113 ","")&IF('C121'!F11="Aula 2","C121 ","")&IF('C122'!F11="Aula 2","C122 ",""))," ",",") | D37: =SUBSTITUTE(TRIM(IF('C111'!F11="Aula 3","C111 ","")&IF('C112'!F11="Aula 3","C112 ","")&IF('C113'!F11="Aula 3","C113 ","")&IF('C121'!F11="Aula 3","C121 ","")&IF('C122'!F11="Aula 3","C122 ",""))," ",",") | E37: =SUBSTITUTE(TRIM(IF('C111'!F11="Aula 4","C111 ","")&IF('C112'!F11="Aula 4","C112 ","")&IF('C113'!F11="Aula 4","C113 ","")&IF('C121'!F11="Aula 4","C121 ","")&IF('C122'!F11="Aula 4","C122 ",""))," ",",") | F37: =SUBSTITUTE(TRIM(IF('C111'!F11="Aula 5","C111 ","")&IF('C112'!F11="Aula 5","C112 ","")&IF('C113'!F11="Aula 5","C113 ","")&IF('C121'!F11="Aula 5","C121 ","")&IF('C122'!F11="Aula 5","C122 ",""))," ",",") | G37: =SUBSTITUTE(TRIM(IF('C111'!F11="Aula 6","C111 ","")&IF('C112'!F11="Aula 6","C112 ","")&IF('C113'!F11="Aula 6","C113 ","")&IF('C121'!F11="Aula 6","C121 ","")&IF('C122'!F11="Aula 6","C122 ",""))," ",",") | H37: =SUBSTITUTE(TRIM(IF('C111'!F11="Aula 7","C111 ","")&IF('C112'!F11="Aula 7","C112 ","")&IF('C113'!F11="Aula 7","C113 ","")&IF('C121'!F11="Aula 7","C121 ","")&IF('C122'!F11="Aula 7","C122 ",""))," ",",") | I37: =SUBSTITUTE(TRIM(IF('C111'!F11="Aula 8","C111 ","")&IF('C112'!F11="Aula 8","C112 ","")&IF('C113'!F11="Aula 8","C113 ","")&IF('C121'!F11="Aula 8","C121 ","")&IF('C122'!F11="Aula 8","C122 ",""))," ",",") | J37: =SUBSTITUTE(TRIM(IF('C111'!F11="Aula 9","C111 ","")&IF('C112'!F11="Aula 9","C112 ","")&IF('C113'!F11="Aula 9","C113 ","")&IF('C121'!F11="Aula 9","C121 ","")&IF('C122'!F11="Aula 9","C122 ",""))," ",",") | K37: =SUBSTITUTE(TRIM(IF('C111'!F11="Lab","C111 ","")&IF('C112'!F11="Lab","C112 ","")&IF('C113'!F11="Lab","C113 ","")&IF('C121'!F11="Lab","C121 ","")&IF('C122'!F11="Lab","C122 ",""))," ",",")
