Workbook
Name Citaciones: OFFSET('Citaciones del dia'!$A$4,0,0,COUNTA('Citaciones del dia'!$A$4:$A$27),8)
Name Tesis: 'Tesis y sus tribunales'!$A$4:$E$7

Sheet Citaciones del dia
A1: Citaciones del dia
A3: Dia | B3: Momento | C3: Local | D3: Estudiante | E3: Tutor | F3: Oponente | G3: Presidente | H3: Secretario | I3: Estado | J3: (nivel de las marcas)
A4: lunes | B4: 09:00 | C4: Postgrado | D4: Juan Perez | E4: =IF(AND($A4="",$B4="",$C4=""),"",IF(ISNA(MATCH(1,INDEX(EXACT('Tesis y sus tribunales'!$A$4:$A$7,$D4)*1,0),0)),"",IF(ISBLANK(INDEX('Tesis y sus tribunales'!$B$4:$B$7,MATCH(1,INDEX(EXACT('Tesis y sus tribunales'!$A$4:$A$7,$D4)*1,0),0))),"",INDEX('Tesis y sus tribunales'!$B$4:$B$7,MATCH(1,INDEX(EXACT('Tesis y sus tribunales'!$A$4:$A$7,$D4)*1,0),0))))) | F4: =IF(AND($A4="",$B4="",$C4=""),"",IF(ISNA(MATCH(1,INDEX(EXACT('Tesis y sus tribunales'!$A$4:$A$7,$D4)*1,0),0)),"",IF(ISBLANK(INDEX('Tesis y sus tribunales'!$C$4:$C$7,MATCH(1,INDEX(EXACT('Tesis y sus tribunales'!$A$4:$A$7,$D4)*1,0),0))),"",INDEX('Tesis y sus tribunales'!$C$4:$C$7,MATCH(1,INDEX(EXACT('Tesis y sus tribunales'!$A$4:$A$7,$D4)*1,0),0))))) | G4: =IF(AND($A4="",$B4="",$C4=""),"",IF(ISNA(MATCH(1,INDEX(EXACT('Tesis y sus tribunales'!$A$4:$A$7,$D4)*1,0),0)),"",IF(ISBLANK(INDEX('Tesis y sus tribunales'!$D$4:$D$7,MATCH(1,INDEX(EXACT('Tesis y sus tribunales'!$A$4:$A$7,$D4)*1,0),0))),"",INDEX('Tesis y sus tribunales'!$D$4:$D$7,MATCH(1,INDEX(EXACT('Tesis y sus tribunales'!$A$4:$A$7,$D4)*1,0),0))))) | H4: =IF(AND($A4="",$B4="",$C4=""),"",IF(ISNA(MATCH(1,INDEX(EXACT('Tesis y sus tribunales'!$A$4:$A$7,$D4)*1,0),0)),"",IF(ISBLANK(INDEX('Tesis y sus tribunales'!$E$4:$E$7,MATCH(1,INDEX(EXACT('Tesis y sus tribunales'!$A$4:$A$7,$D4)*1,0),0))),"",INDEX('Tesis y sus tribunales'!$E$4:$E$7,MATCH(1,INDEX(EXACT('Tesis y sus tribunales'!$A$4:$A$7,$D4)*1,0),0))))) | I4: =IF(AND($A4="",$B4="",$C4=""),"",MID(IF((SUMPRODUCT(1*(((('Citaciones del dia'!$A$4:$A$27<>"")+('Citaciones del dia'!$B$4:$B$27<>"")+('Citaciones del dia'!$C$4:$C$27<>""))>0))*((EXACT('Citaciones del dia'!$A$4:$A$27,$A4)))*((EXACT('Citaciones del dia'!$B$4:$B$27,$B4)))*((((('Citaciones del dia'!$E$4:$E$27<>"")*($E4<>"")*EXACT('Citaciones del dia'!$E$4:$E$27,$E4))+(('Citaciones del dia'!$F$4:$F$27<>"")*($E4<>"")*EXACT('Citaciones del dia'!$F$4:$F$27,$E4))+(('Citaciones del dia'!$G$4:$G$27<>"")*($E4<>"")*EXACT('Citaciones del dia'!$G$4:$G$27,$E4))+(('Citaciones del dia'!$H$4:$H$27<>"")*($E4<>"")*EXACT('Citaciones del dia'!$H$4:$H$27,$E4))+(('Citaciones del dia'!$E$4:$E$27<>"")*($F4<>"")*EXACT('Citaciones del dia'!$E$4:$E$27,$F4))+(('Citaciones del dia'!$F$4:$F$27<>"")*($F4<>"")*EXACT('Citaciones del dia'!$F$4:$F$27,$F4))+(('Citaciones del dia'!$G$4:$G$27<>"")*($F4<>"")*EXACT('Citaciones del dia'!$G$4:$G$27,$F4))+(('Citaciones del dia'!$H$4:$H$27<>"")*($F4<>"")*EXACT('Citaciones del dia'!$H$4:$H$27,$F4))+(('Citaciones del dia'!$E$4:$E$27<>"")*($G4<>"")*EXACT('Citaciones del dia'!$E$4:$E$27,$G4))+(('Citaciones del dia'!$F$4:$F$27<>"")*($G4<>"")*EXACT('Citaciones del dia'!$F$4:$F$27,$G4))+(('Citaciones del dia'!$G$4:$G$27<>"")*($G4<>"")*EXACT('Citaciones del dia'!$G$4:$G$27,$G4))+(('Citaciones del dia'!$H$4:$H$27<>"")*($G4<>"")*EXACT('Citaciones del dia'!$H$4:$H$27,$G4))+(('Citaciones del dia'!$E$4:$E$27<>"")*($H4<>"")*EXACT('Citaciones del dia'!$E$4:$E$27,$H4))+(('Citaciones del dia'!$F$4:$F$27<>"")*($H4<>"")*EXACT('Citaciones del dia'!$F$4:$F$27,$H4))+(('Citaciones del dia'!$G$4:$G$27<>"")*($H4<>"")*EXACT('Citaciones del dia'!$G$4:$G$27,$H4))+(('Citaciones del dia'!$H$4:$H$27<>"")*($H4<>"")*EXACT('Citaciones del dia'!$H$4:$H$27,$H4)))>0))*((ROW('Citaciones del dia'!$A$4:$A$27)<>ROW($A4))))>0),"; "&"Este profesor esta citado en dos locales a la vez","")&IF(($D4=""),"; "&"Este hueco todavia no tiene defensa",""),3,32767)) | J4: =IF(OR((SUMPRODUCT(1*(((('Citaciones del dia'!$A$4:$A$27<>"")+('Citaciones del dia'!$B$4:$B$27<>"")+('Citaciones del dia'!$C$4:$C$27<>""))>0))*((EXACT('Citaciones del dia'!$A$4:$A$27,$A4)))*((EXACT('Citaciones del dia'!$B$4:$B$27,$B4)))*((((('Citaciones del dia'!$E$4:$E$27<>"")*($E4<>"")*EXACT('Citaciones del dia'!$E$4:$E$27,$E4))+(('Citaciones del dia'!$F$4:$F$27<>"")*($E4<>"")*EXACT('Citaciones del dia'!$F$4:$F$27,$E4))+(('Citaciones del dia'!$G$4:$G$27<>"")*($E4<>"")*EXACT('Citaciones del dia'!$G$4:$G$27,$E4))+(('Citaciones del dia'!$H$4:$H$27<>"")*($E4<>"")*EXACT('Citaciones del dia'!$H$4:$H$27,$E4))+(('Citaciones del dia'!$E$4:$E$27<>"")*($F4<>"")*EXACT('Citaciones del dia'!$E$4:$E$27,$F4))+(('Citaciones del dia'!$F$4:$F$27<>"")*($F4<>"")*EXACT('Citaciones del dia'!$F$4:$F$27,$F4))+(('Citaciones del dia'!$G$4:$G$27<>"")*($F4<>"")*EXACT('Citaciones del dia'!$G$4:$G$27,$F4))+(('Citaciones del dia'!$H$4:$H$27<>"")*($F4<>"")*EXACT('Citaciones del dia'!$H$4:$H$27,$F4))+(('Citaciones del dia'!$E$4:$E$27<>"")*($G4<>"")*EXACT('Citaciones del dia'!$E$4:$E$27,$G4))+(('Citaciones del dia'!$F$4:$F$27<>"")*($G4<>"")*EXACT('Citaciones del dia'!$F$4:$F$27,$G4))+(('Citaciones del dia'!$G$4:$G$27<>"")*($G4<>"")*EXACT('Citaciones del dia'!$G$4:$G$27,$G4))+(('Citaciones del dia'!$H$4:$H$27<>"")*($G4<>"")*EXACT('Citaciones del dia'!$H$4:$H$27,$G4))+(('Citaciones del dia'!$E$4:$E$27<>"")*($H4<>"")*EXACT('Citaciones del dia'!$E$4:$E$27,$H4))+(('Citaciones del dia'!$F$4:$F$27<>"")*($H4<>"")*EXACT('Citaciones del dia'!$F$4:$F$27,$H4))+(('Citaciones del dia'!$G$4:$G$27<>"")*($H4<>"")*EXACT('Citaciones del dia'!$G$4:$G$27,$H4))+(('Citaciones del dia'!$H$4:$H$27<>"")*($H4<>"")*EXACT('Citaciones del dia'!$H$4:$H$27,$H4)))>0))*((ROW('Citaciones del dia'!$A$4:$A$27)<>ROW($A4))))>0)),3,IF(OR(($D4="")),1,0))
A5: lunes | B5: 09:00 | C5: Decanato | D5: Laura Fernandez | E5: =IF(AND($A5="",$B5="",$C5=""),"",IF(ISNA(MATCH(1,INDEX(EXACT('Tesis y sus tribunales'!$A$4:$A$7,$D5)*1,0),0)),"",IF(ISBLANK(INDEX('Tesis y sus tribunales'!$B$4:$B$7,MATCH(1,INDEX(EXACT('Tesis y sus tribunales'!$A$4:$A$7,$D5)*1,0),0))),"",INDEX('Tesis y sus tribunales'!$B$4:$B$7,MATCH(1,INDEX(EXACT('Tesis y sus tribunales'!$A$4:$A$7,$D5)*1,0),0))))) | F5: =IF(AND($A5="",$B5="",$C5=""),"",IF(ISNA(MATCH(1,INDEX(EXACT('Tesis y sus tribunales'!$A$4:$A$7,$D5)*1,0),0)),"",IF(ISBLANK(INDEX('Tesis y sus tribunales'!$C$4:$C$7,MATCH(1,INDEX(EXACT('Tesis y sus tribunales'!$A$4:$A$7,$D5)*1,0),0))),"",INDEX('Tesis y sus tribunales'!$C$4:$C$7,MATCH(1,INDEX(EXACT('Tesis y sus tribunales'!$A$4:$A$7,$D5)*1,0),0))))) | G5: =IF(AND($A5="",$B5="",$C5=""),"",IF(ISNA(MATCH(1,INDEX(EXACT('Tesis y sus tribunales'!$A$4:$A$7,$D5)*1,0),0)),"",IF(ISBLANK(INDEX('Tesis y sus tribunales'!$D$4:$D$7,MATCH(1,INDEX(EXACT('Tesis y sus tribunales'!$A$4:$A$7,$D5)*1,0),0))),"",INDEX('Tesis y sus tribunales'!$D$4:$D$7,MATCH(1,INDEX(EXACT('Tesis y sus tribunales'!$A$4:$A$7,$D5)*1,0),0))))) | H5: =IF(AND($A5="",$B5="",$C5=""),"",IF(ISNA(MATCH(1,INDEX(EXACT('Tesis y sus tribunales'!$A$4:$A$7,$D5)*1,0),0)),"",IF(ISBLANK(INDEX('Tesis y sus tribunales'!$E$4:$E$7,MATCH(1,INDEX(EXACT('Tesis y sus tribunales'!$A$4:$A$7,$D5)*1,0),0))),"",INDEX('Tesis y sus tribunales'!$E$4:$E$7,MATCH(1,INDEX(EXACT('Tesis y sus tribunales'!$A$4:$A$7,$D5)*1,0),0))))) | I5: =IF(AND($A5="",$B5="",$C5=""),"",MID(IF((SUMPRODUCT(1*(((('Citaciones del dia'!$A$4:$A$27<>"")+('Citaciones del dia'!$B$4:$B$27<>"")+('Citaciones del dia'!$C$4:$C$27<>""))>0))*((EXACT('Citaciones del dia'!$A$4:$A$27,$A5)))*((EXACT('Citaciones del dia'!$B$4:$B$27,$B5)))*((((('Citaciones del dia'!$E$4:$E$27<>"")*($E5<>"")*EXACT('Citaciones del dia'!$E$4:$E$27,$E5))+(('Citaciones del dia'!$F$4:$F$27<>"")*($E5<>"")*EXACT('Citaciones del dia'!$F$4:$F$27,$E5))+(('Citaciones del dia'!$G$4:$G$27<>"")*($E5<>"")*EXACT('Citaciones del dia'!$G$4:$G$27,$E5))+(('Citaciones del dia'!$H$4:$H$27<>"")*($E5<>"")*EXACT('Citaciones del dia'!$H$4:$H$27,$E5))+(('Citaciones del dia'!$E$4:$E$27<>"")*($F5<>"")*EXACT('Citaciones del dia'!$E$4:$E$27,$F5))+(('Citaciones del dia'!$F$4:$F$27<>"")*($F5<>"")*EXACT('Citaciones del dia'!$F$4:$F$27,$F5))+(('Citaciones del dia'!$G$4:$G$27<>"")*($F5<>"")*EXACT('Citaciones del dia'!$G$4:$G$27,$F5))+(('Citaciones del dia'!$H$4:$H$27<>"")*($F5<>"")*EXACT('Citaciones del dia'!$H$4:$H$27,$F5))+(('Citaciones del dia'!$E$4:$E$27<>"")*($G5<>"")*EXACT('Citaciones del dia'!$E$4:$E$27,$G5))+(('Citaciones del dia'!$F$4:$F$27<>"")*($G5<>"")*EXACT('Citaciones del dia'!$F$4:$F$27,$G5))+(('Citaciones del dia'!$G$4:$G$27<>"")*($G5<>"")*EXACT('Citaciones del dia'!$G$4:$G$27,$G5))+(('Citaciones del dia'!$H$4:$H$27<>"")*($G5<>"")*EXACT('Citaciones del dia'!$H$4:$H$27,$G5))+(('Citaciones del dia'!$E$4:$E$27<>"")*($H5<>"")*EXACT('Citaciones del dia'!$E$4:$E$27,$H5))+(('Citaciones del dia'!$F$4:$F$27<>"")*($H5<>"")*EXACT('Citaciones del dia'!$F$4:$F$27,$H5))+(('Citaciones del dia'!$G$4:$G$27<>"")*($H5<>"")*EXACT('Citaciones del dia'!$G$4:$G$27,$H5))+(('Citaciones del dia'!$H$4:$H$27<>"")*($H5<>"")*EXACT('Citaciones del dia'!$H$4:$H$27,$H5)))>0))*((ROW('Citaciones del dia'!$A$4:$A$27)<>ROW($A5))))>0),"; "&"Este profesor esta citado en dos locales a la vez","")&IF(($D5=""),"; "&"Este hueco todavia no tiene defensa",""),3,32767)) | J5: =IF(OR((SUMPRODUCT(1*(((('Citaciones del dia'!$A$4:$A$27<>"")+('Citaciones del dia'!$B$4:$B$27<>"")+('Citaciones del dia'!$C$4:$C$27<>""))>0))*((EXACT('Citaciones del dia'!$A$4:$A$27,$A5)))*((EXACT('Citaciones del dia'!$B$4:$B$27,$B5)))*((((('Citaciones del dia'!$E$4:$E$27<>"")*($E5<>"")*EXACT('Citaciones del dia'!$E$4:$E$27,$E5))+(('Citaciones del dia'!$F$4:$F$27<>"")*($E5<>"")*EXACT('Citaciones del dia'!$F$4:$F$27,$E5))+(('Citaciones del dia'!$G$4:$G$27<>"")*($E5<>"")*EXACT('Citaciones del dia'!$G$4:$G$27,$E5))+(('Citaciones del dia'!$H$4:$H$27<>"")*($E5<>"")*EXACT('Citaciones del dia'!$H$4:$H$27,$E5))+(('Citaciones del dia'!$E$4:$E$27<>"")*($F5<>"")*EXACT('Citaciones del dia'!$E$4:$E$27,$F5))+(('Citaciones del dia'!$F$4:$F$27<>"")*($F5<>"")*EXACT('Citaciones del dia'!$F$4:$F$27,$F5))+(('Citaciones del dia'!$G$4:$G$27<>"")*($F5<>"")*EXACT('Citaciones del dia'!$G$4:$G$27,$F5))+(('Citaciones del dia'!$H$4:$H$27<>"")*($F5<>"")*EXACT('Citaciones del dia'!$H$4:$H$27,$F5))+(('Citaciones del dia'!$E$4:$E$27<>"")*($G5<>"")*EXACT('Citaciones del dia'!$E$4:$E$27,$G5))+(('Citaciones del dia'!$F$4:$F$27<>"")*($G5<>"")*EXACT('Citaciones del dia'!$F$4:$F$27,$G5))+(('Citaciones del dia'!$G$4:$G$27<>"")*($G5<>"")*EXACT('Citaciones del dia'!$G$4:$G$27,$G5))+(('Citaciones del dia'!$H$4:$H$27<>"")*($G5<>"")*EXACT('Citaciones del dia'!$H$4:$H$27,$G5))+(('Citaciones del dia'!$E$4:$E$27<>"")*($H5<>"")*EXACT('Citaciones del dia'!$E$4:$E$27,$H5))+(('Citaciones del dia'!$F$4:$F$27<>"")*($H5<>"")*EXACT('Citaciones del dia'!$F$4:$F$27,$H5))+(('Citaciones del dia'!$G$4:$G$27<>"")*($H5<>"")*EXACT('Citaciones del dia'!$G$4:$G$27,$H5))+(('Citaciones del dia'!$H$4:$H$27<>"")*($H5<>"")*EXACT('Citaciones del dia'!$H$4:$H$27,$H5)))>0))*((ROW('Citaciones del dia'!$A$4:$A$27)<>ROW($A5))))>0)),3,IF(OR(($D5="")),1,0))
A6: lunes | B6: 10:00 | C6: Postgrado | D6: Mario Gomez | E6: =IF(AND($A6="",$B6="",$C6=""),"",IF(ISNA(MATCH(1,INDEX(EXACT('Tesis y sus tribunales'!$A$4:$A$7,$D6)*1,0),0)),"",IF(ISBLANK(INDEX('Tesis y sus tribunales'!$B$4:$B$7,MATCH(1,INDEX(EXACT('Tesis y sus tribunales'!$A$4:$A$7,$D6)*1,0),0))),"",INDEX('Tesis y sus tribunales'!$B$4:$B$7,MATCH(1,INDEX(EXACT('Tesis y sus tribunales'!$A$4:$A$7,$D6)*1,0),0))))) | F6: =IF(AND($A6="",$B6="",$C6=""),"",IF(ISNA(MATCH(1,INDEX(EXACT('Tesis y sus tribunales'!$A$4:$A$7,$D6)*1,0),0)),"",IF(ISBLANK(INDEX('Tesis y sus tribunales'!$C$4:$C$7,MATCH(1,INDEX(EXACT('Tesis y sus tribunales'!$A$4:$A$7,$D6)*1,0),0))),"",INDEX('Tesis y sus tribunales'!$C$4:$C$7,MATCH(1,INDEX(EXACT('Tesis y sus tribunales'!$A$4:$A$7,$D6)*1,0),0))))) | G6: =IF(AND($A6="",$B6="",$C6=""),"",IF(ISNA(MATCH(1,INDEX(EXACT('Tesis y sus tribunales'!$A$4:$A$7,$D6)*1,0),0)),"",IF(ISBLANK(INDEX('Tesis y sus tribunales'!$D$4:$D$7,MATCH(1,INDEX(EXACT('Tesis y sus tribunales'!$A$4:$A$7,$D6)*1,0),0))),"",INDEX('Tesis y sus tribunales'!$D$4:$D$7,MATCH(1,INDEX(EXACT('Tesis y sus tribunales'!$A$4:$A$7,$D6)*1,0),0))))) | H6: =IF(AND($A6="",$B6="",$C6=""),"",IF(ISNA(MATCH(1,INDEX(EXACT('Tesis y sus tribunales'!$A$4:$A$7,$D6)*1,0),0)),"",IF(ISBLANK(INDEX('Tesis y sus tribunales'!$E$4:$E$7,MATCH(1,INDEX(EXACT('Tesis y sus tribunales'!$A$4:$A$7,$D6)*1,0),0))),"",INDEX('Tesis y sus tribunales'!$E$4:$E$7,MATCH(1,INDEX(EXACT('Tesis y sus tribunales'!$A$4:$A$7,$D6)*1,0),0))))) | I6: =IF(AND($A6="",$B6="",$C6=""),"",MID(IF((SUMPRODUCT(1*(((('Citaciones del dia'!$A$4:$A$27<>"")+('Citaciones del dia'!$B$4:$B$27<>"")+('Citaciones del dia'!$C$4:$C$27<>""))>0))*((EXACT('Citaciones del dia'!$A$4:$A$27,$A6)))*((EXACT('Citaciones del dia'!$B$4:$B$27,$B6)))*((((('Citaciones del dia'!$E$4:$E$27<>"")*($E6<>"")*EXACT('Citaciones del dia'!$E$4:$E$27,$E6))+(('Citaciones del dia'!$F$4:$F$27<>"")*($E6<>"")*EXACT('Citaciones del dia'!$F$4:$F$27,$E6))+(('Citaciones del dia'!$G$4:$G$27<>"")*($E6<>"")*EXACT('Citaciones del dia'!$G$4:$G$27,$E6))+(('Citaciones del dia'!$H$4:$H$27<>"")*($E6<>"")*EXACT('Citaciones del dia'!$H$4:$H$27,$E6))+(('Citaciones del dia'!$E$4:$E$27<>"")*($F6<>"")*EXACT('Citaciones del dia'!$E$4:$E$27,$F6))+(('Citaciones del dia'!$F$4:$F$27<>"")*($F6<>"")*EXACT('Citaciones del dia'!$F$4:$F$27,$F6))+(('Citaciones del dia'!$G$4:$G$27<>"")*($F6<>"")*EXACT('Citaciones del dia'!$G$4:$G$27,$F6))+(('Citaciones del dia'!$H$4:$H$27<>"")*($F6<>"")*EXACT('Citaciones del dia'!$H$4:$H$27,$F6))+(('Citaciones del dia'!$E$4:$E$27<>"")*($G6<>"")*EXACT('Citaciones del dia'!$E$4:$E$27,$G6))+(('Citaciones del dia'!$F$4:$F$27<>"")*($G6<>"")*EXACT('Citaciones del dia'!$F$4:$F$27,$G6))+(('Citaciones del dia'!$G$4:$G$27<>"")*($G6<>"")*EXACT('Citaciones del dia'!$G$4:$G$27,$G6))+(('Citaciones del dia'!$H$4:$H$27<>"")*($G6<>"")*EXACT('Citaciones del dia'!$H$4:$H$27,$G6))+(('Citaciones del dia'!$E$4:$E$27<>"")*($H6<>"")*EXACT('Citaciones del dia'!$E$4:$E$27,$H6))+(('Citaciones del dia'!$F$4:$F$27<>"")*($H6<>"")*EXACT('Citaciones del dia'!$F$4:$F$27,$H6))+(('Citaciones del dia'!$G$4:$G$27<>"")*($H6<>"")*EXACT('Citaciones del dia'!$G$4:$G$27,$H6))+(('Citaciones del dia'!$H$4:$H$27<>"")*($H6<>"")*EXACT('Citaciones del dia'!$H$4:$H$27,$H6)))>0))*((ROW('Citaciones del dia'!$A$4:$A$27)<>ROW($A6))))>0),"; "&"Este profesor esta citado en dos locales a la vez","")&IF(($D6=""),"; "&"Este hueco todavia no tiene defensa",""),3,32767)) | J6: =IF(OR((SUMPRODUCT(1*(((('Citaciones del dia'!$A$4:$A$27<>"")+('Citaciones del dia'!$B$4:$B$27<>"")+('Citaciones del dia'!$C$4:$C$27<>""))>0))*((EXACT('Citaciones del dia'!$A$4:$A$27,$A6)))*((EXACT('Citaciones del dia'!$B$4:$B$27,$B6)))*((((('Citaciones del dia'!$E$4:$E$27<>"")*($E6<>"")*EXACT('Citaciones del dia'!$E$4:$E$27,$E6))+(('Citaciones del dia'!$F$4:$F$27<>"")*($E6<>"")*EXACT('Citaciones del dia'!$F$4:$F$27,$E6))+(('Citaciones del dia'!$G$4:$G$27<>"")*($E6<>"")*EXACT('Citaciones del dia'!$G$4:$G$27,$E6))+(('Citaciones del dia'!$H$4:$H$27<>"")*($E6<>"")*EXACT('Citaciones del dia'!$H$4:$H$27,$E6))+(('Citaciones del dia'!$E$4:$E$27<>"")*($F6<>"")*EXACT('Citaciones del dia'!$E$4:$E$27,$F6))+(('Citaciones del dia'!$F$4:$F$27<>"")*($F6<>"")*EXACT('Citaciones del dia'!$F$4:$F$27,$F6))+(('Citaciones del dia'!$G$4:$G$27<>"")*($F6<>"")*EXACT('Citaciones del dia'!$G$4:$G$27,$F6))+(('Citaciones del dia'!$H$4:$H$27<>"")*($F6<>"")*EXACT('Citaciones del dia'!$H$4:$H$27,$F6))+(('Citaciones del dia'!$E$4:$E$27<>"")*($G6<>"")*EXACT('Citaciones del dia'!$E$4:$E$27,$G6))+(('Citaciones del dia'!$F$4:$F$27<>"")*($G6<>"")*EXACT('Citaciones del dia'!$F$4:$F$27,$G6))+(('Citaciones del dia'!$G$4:$G$27<>"")*($G6<>"")*EXACT('Citaciones del dia'!$G$4:$G$27,$G6))+(('Citaciones del dia'!$H$4:$H$27<>"")*($G6<>"")*EXACT('Citaciones del dia'!$H$4:$H$27,$G6))+(('Citaciones del dia'!$E$4:$E$27<>"")*($H6<>"")*EXACT('Citaciones del dia'!$E$4:$E$27,$H6))+(('Citaciones del dia'!$F$4:$F$27<>"")*($H6<>"")*EXACT('Citaciones del dia'!$F$4:$F$27,$H6))+(('Citaciones del dia'!$G$4:$G$27<>"")*($H6<>"")*EXACT('Citaciones del dia'!$G$4:$G$27,$H6))+(('Citaciones del dia'!$H$4:$H$27<>"")*($H6<>"")*EXACT('Citaciones del dia'!$H$4:$H$27,$H6)))>0))*((ROW('Citaciones del dia'!$A$4:$A$27)<>ROW($A6))))>0)),3,IF(OR(($D6="")),1,0))
A7: lunes | B7: 10:00 | C7: Decanato | E7: =IF(AND($A7="",$B7="",$C7=""),"",IF(ISNA(MATCH(1,INDEX(EXACT('Tesis y sus tribunales'!$A$4:$A$7,$D7)*1,0),0)),"",IF(ISBLANK(INDEX('Tesis y sus tribunales'!$B$4:$B$7,MATCH(1,INDEX(EXACT('Tesis y sus tribunales'!$A$4:$A$7,$D7)*1,0),0))),"",INDEX('Tesis y sus tribunales'!$B$4:$B$7,MATCH(1,INDEX(EXACT('Tesis y sus tribunales'!$A$4:$A$7,$D7)*1,0),0))))) | F7: =IF(AND($A7="",$B7="",$C7=""),"",IF(ISNA(MATCH(1,INDEX(EXACT('Tesis y sus tribunales'!$A$4:$A$7,$D7)*1,0),0)),"",IF(ISBLANK(INDEX('Tesis y sus tribunales'!$C$4:$C$7,MATCH(1,INDEX(EXACT('Tesis y sus tribunales'!$A$4:$A$7,$D7)*1,0),0))),"",INDEX('Tesis y sus tribunales'!$C$4:$C$7,MATCH(1,INDEX(EXACT('Tesis y sus tribunales'!$A$4:$A$7,$D7)*1,0),0))))) | G7: =IF(AND($A7="",$B7="",$C7=""),"",IF(ISNA(MATCH(1,INDEX(EXACT('Tesis y sus tribunales'!$A$4:$A$7,$D7)*1,0),0)),"",IF(ISBLANK(INDEX('Tesis y sus tribunales'!$D$4:$D$7,MATCH(1,INDEX(EXACT('Tesis y sus tribunales'!$A$4:$A$7,$D7)*1,0),0))),"",INDEX('Tesis y sus tribunales'!$D$4:$D$7,MATCH(1,INDEX(EXACT('Tesis y sus tribunales'!$A$4:$A$7,$D7)*1,0),0))))) | H7: =IF(AND($A7="",$B7="",$C7=""),"",IF(ISNA(MATCH(1,INDEX(EXACT('Tesis y sus tribunales'!$A$4:$A$7,$D7)*1,0),0)),"",IF(ISBLANK(INDEX('Tesis y sus tribunales'!$E$4:$E$7,MATCH(1,INDEX(EXACT('Tesis y sus tribunales'!$A$4:$A$7,$D7)*1,0),0))),"",INDEX('Tesis y sus tribunales'!$E$4:$E$7,MATCH(1,INDEX(EXACT('Tesis y sus tribunales'!$A$4:$A$7,$D7)*1,0),0))))) | I7: =IF(AND($A7="",$B7="",$C7=""),"",MID(IF((SUMPRODUCT(1*(((('Citaciones del dia'!$A$4:$A$27<>"")+('Citaciones del dia'!$B$4:$B$27<>"")+('Citaciones del dia'!$C$4:$C$27<>""))>0))*((EXACT('Citaciones del dia'!$A$4:$A$27,$A7)))*((EXACT('Citaciones del dia'!$B$4:$B$27,$B7)))*((((('Citaciones del dia'!$E$4:$E$27<>"")*($E7<>"")*EXACT('Citaciones del dia'!$E$4:$E$27,$E7))+(('Citaciones del dia'!$F$4:$F$27<>"")*($E7<>"")*EXACT('Citaciones del dia'!$F$4:$F$27,$E7))+(('Citaciones del dia'!$G$4:$G$27<>"")*($E7<>"")*EXACT('Citaciones del dia'!$G$4:$G$27,$E7))+(('Citaciones del dia'!$H$4:$H$27<>"")*($E7<>"")*EXACT('Citaciones del dia'!$H$4:$H$27,$E7))+(('Citaciones del dia'!$E$4:$E$27<>"")*($F7<>"")*EXACT('Citaciones del dia'!$E$4:$E$27,$F7))+(('Citaciones del dia'!$F$4:$F$27<>"")*($F7<>"")*EXACT('Citaciones del dia'!$F$4:$F$27,$F7))+(('Citaciones del dia'!$G$4:$G$27<>"")*($F7<>"")*EXACT('Citaciones del dia'!$G$4:$G$27,$F7))+(('Citaciones del dia'!$H$4:$H$27<>"")*($F7<>"")*EXACT('Citaciones del dia'!$H$4:$H$27,$F7))+(('Citaciones del dia'!$E$4:$E$27<>"")*($G7<>"")*EXACT('Citaciones del dia'!$E$4:$E$27,$G7))+(('Citaciones del dia'!$F$4:$F$27<>"")*($G7<>"")*EXACT('Citaciones del dia'!$F$4:$F$27,$G7))+(('Citaciones del dia'!$G$4:$G$27<>"")*($G7<>"")*EXACT('Citaciones del dia'!$G$4:$G$27,$G7))+(('Citaciones del dia'!$H$4:$H$27<>"")*($G7<>"")*EXACT('Citaciones del dia'!$H$4:$H$27,$G7))+(('Citaciones del dia'!$E$4:$E$27<>"")*($H7<>"")*EXACT('Citaciones del dia'!$E$4:$E$27,$H7))+(('Citaciones del dia'!$F$4:$F$27<>"")*($H7<>"")*EXACT('Citaciones del dia'!$F$4:$F$27,$H7))+(('Citaciones del dia'!$G$4:$G$27<>"")*($H7<>"")*EXACT('Citaciones del dia'!$G$4:$G$27,$H7))+(('Citaciones del dia'!$H$4:$H$27<>"")*($H7<>"")*EXACT('Citaciones del dia'!$H$4:$H$27,$H7)))>0))*((ROW('Citaciones del dia'!$A$4:$A$27)<>ROW($A7))))>0),"; "&"Este profesor esta citado en dos locales a la vez","")&IF(($D7=""),"; "&"Este hueco todavia no tiene defensa",""),3,32767)) | J7: =IF(OR((SUMPRODUCT(1*(((('Citaciones del dia'!$A$4:$A$27<>"")+('Citaciones del dia'!$B$4:$B$27<>"")+('Citaciones del dia'!$C$4:$C$27<>""))>0))*((EXACT('Citaciones del dia'!$A$4:$A$27,$A7)))*((EXACT('Citaciones del dia'!$B$4:$B$27,$B7)))*((((('Citaciones del dia'!$E$4:$E$27<>"")*($E7<>"")*EXACT('Citaciones del dia'!$E$4:$E$27,$E7))+(('Citaciones del dia'!$F$4:$F$27<>"")*($E7<>"")*EXACT('Citaciones del dia'!$F$4:$F$27,$E7))+(('Citaciones del dia'!$G$4:$G$27<>"")*($E7<>"")*EXACT('Citaciones del dia'!$G$4:$G$27,$E7))+(('Citaciones del dia'!$H$4:$H$27<>"")*($E7<>"")*EXACT('Citaciones del dia'!$H$4:$H$27,$E7))+(('Citaciones del dia'!$E$4:$E$27<>"")*($F7<>"")*EXACT('Citaciones del dia'!$E$4:$E$27,$F7))+(('Citaciones del dia'!$F$4:$F$27<>"")*($F7<>"")*EXACT('Citaciones del dia'!$F$4:$F$27,$F7))+(('Citaciones del dia'!$G$4:$G$27<>"")*($F7<>"")*EXACT('Citaciones del dia'!$G$4:$G$27,$F7))+(('Citaciones del dia'!$H$4:$H$27<>"")*($F7<>"")*EXACT('Citaciones del dia'!$H$4:$H$27,$F7))+(('Citaciones del dia'!$E$4:$E$27<>"")*($G7<>"")*EXACT('Citaciones del dia'!$E$4:$E$27,$G7))+(('Citaciones del dia'!$F$4:$F$27<>"")*($G7<>"")*EXACT('Citaciones del dia'!$F$4:$F$27,$G7))+(('Citaciones del dia'!$G$4:$G$27<>"")*($G7<>"")*EXACT('Citaciones del dia'!$G$4:$G$27,$G7))+(('Citaciones del dia'!$H$4:$H$27<>"")*($G7<>"")*EXACT('Citaciones del dia'!$H$4:$H$27,$G7))+(('Citaciones del dia'!$E$4:$E$27<>"")*($H7<>"")*EXACT('Citaciones del dia'!$E$4:$E$27,$H7))+(('Citaciones del dia'!$F$4:$F$27<>"")*($H7<>"")*EXACT('Citaciones del dia'!$F$4:$F$27,$H7))+(('Citaciones del dia'!$G$4:$G$27<>"")*($H7<>"")*EXACT('Citaciones del dia'!$G$4:$G$27,$H7))+(('Citaciones del dia'!$H$4:$H$27<>"")*($H7<>"")*EXACT('Citaciones del dia'!$H$4:$H$27,$H7)))>0))*((ROW('Citaciones del dia'!$A$4:$A$27)<>ROW($A7))))>0)),3,IF(OR(($D7="")),1,0))
E8: =IF(AND($A8="",$B8="",$C8=""),"",IF(ISNA(MATCH(1,INDEX(EXACT('Tesis y sus tribunales'!$A$4:$A$7,$D8)*1,0),0)),"",IF(ISBLANK(INDEX('Tesis y sus tribunales'!$B$4:$B$7,MATCH(1,INDEX(EXACT('Tesis y sus tribunales'!$A$4:$A$7,$D8)*1,0),0))),"",INDEX('Tesis y sus tribunales'!$B$4:$B$7,MATCH(1,INDEX(EXACT('Tesis y sus tribunales'!$A$4:$A$7,$D8)*1,0),0))))) | F8: =IF(AND($A8="",$B8="",$C8=""),"",IF(ISNA(MATCH(1,INDEX(EXACT('Tesis y sus tribunales'!$A$4:$A$7,$D8)*1,0),0)),"",IF(ISBLANK(INDEX('Tesis y sus tribunales'!$C$4:$C$7,MATCH(1,INDEX(EXACT('Tesis y sus tribunales'!$A$4:$A$7,$D8)*1,0),0))),"",INDEX('Tesis y sus tribunales'!$C$4:$C$7,MATCH(1,INDEX(EXACT('Tesis y sus tribunales'!$A$4:$A$7,$D8)*1,0),0))))) | G8: =IF(AND($A8="",$B8="",$C8=""),"",IF(ISNA(MATCH(1,INDEX(EXACT('Tesis y sus tribunales'!$A$4:$A$7,$D8)*1,0),0)),"",IF(ISBLANK(INDEX('Tesis y sus tribunales'!$D$4:$D$7,MATCH(1,INDEX(EXACT('Tesis y sus tribunales'!$A$4:$A$7,$D8)*1,0),0))),"",INDEX('Tesis y sus tribunales'!$D$4:$D$7,MATCH(1,INDEX(EXACT('Tesis y sus tribunales'!$A$4:$A$7,$D8)*1,0),0))))) | H8: =IF(AND($A8="",$B8="",$C8=""),"",IF(ISNA(MATCH(1,INDEX(EXACT('Tesis y sus tribunales'!$A$4:$A$7,$D8)*1,0),0)),"",IF(ISBLANK(INDEX('Tesis y sus tribunales'!$E$4:$E$7,MATCH(1,INDEX(EXACT('Tesis y sus tribunales'!$A$4:$A$7,$D8)*1,0),0))),"",INDEX('Tesis y sus tribunales'!$E$4:$E$7,MATCH(1,INDEX(EXACT('Tesis y sus tribunales'!$A$4:$A$7,$D8)*1,0),0))))) | I8: =IF(AND($A8="",$B8="",$C8=""),"",MID(IF((SUMPRODUCT(1*(((('Citaciones del dia'!$A$4:$A$27<>"")+('Citaciones del dia'!$B$4:$B$27<>"")+('Citaciones del dia'!$C$4:$C$27<>""))>0))*((EXACT('Citaciones del dia'!$A$4:$A$27,$A8)))*((EXACT('Citaciones del dia'!$B$4:$B$27,$B8)))*((((('Citaciones del dia'!$E$4:$E$27<>"")*($E8<>"")*EXACT('Citaciones del dia'!$E$4:$E$27,$E8))+(('Citaciones del dia'!$F$4:$F$27<>"")*($E8<>"")*EXACT('Citaciones del dia'!$F$4:$F$27,$E8))+(('Citaciones del dia'!$G$4:$G$27<>"")*($E8<>"")*EXACT('Citaciones del dia'!$G$4:$G$27,$E8))+(('Citaciones del dia'!$H$4:$H$27<>"")*($E8<>"")*EXACT('Citaciones del dia'!$H$4:$H$27,$E8))+(('Citaciones del dia'!$E$4:$E$27<>"")*($F8<>"")*EXACT('Citaciones del dia'!$E$4:$E$27,$F8))+(('Citaciones del dia'!$F$4:$F$27<>"")*($F8<>"")*EXACT('Citaciones del dia'!$F$4:$F$27,$F8))+(('Citaciones del dia'!$G$4:$G$27<>"")*($F8<>"")*EXACT('Citaciones del dia'!$G$4:$G$27,$F8))+(('Citaciones del dia'!$H$4:$H$27<>"")*($F8<>"")*EXACT('Citaciones del dia'!$H$4:$H$27,$F8))+(('Citaciones del dia'!$E$4:$E$27<>"")*($G8<>"")*EXACT('Citaciones del dia'!$E$4:$E$27,$G8))+(('Citaciones del dia'!$F$4:$F$27<>"")*($G8<>"")*EXACT('Citaciones del dia'!$F$4:$F$27,$G8))+(('Citaciones del dia'!$G$4:$G$27<>"")*($G8<>"")*EXACT('Citaciones del dia'!$G$4:$G$27,$G8))+(('Citaciones del dia'!$H$4:$H$27<>"")*($G8<>"")*EXACT('Citaciones del dia'!$H$4:$H$27,$G8))+(('Citaciones del dia'!$E$4:$E$27<>"")*($H8<>"")*EXACT('Citaciones del dia'!$E$4:$E$27,$H8))+(('Citaciones del dia'!$F$4:$F$27<>"")*($H8<>"")*EXACT('Citaciones del dia'!$F$4:$F$27,$H8))+(('Citaciones del dia'!$G$4:$G$27<>"")*($H8<>"")*EXACT('Citaciones del dia'!$G$4:$G$27,$H8))+(('Citaciones del dia'!$H$4:$H$27<>"")*($H8<>"")*EXACT('Citaciones del dia'!$H$4:$H$27,$H8)))>0))*((ROW('Citaciones del dia'!$A$4:$A$27)<>ROW($A8))))>0),"; "&"Este profesor esta citado en dos locales a la vez","")&IF(($D8=""),"; "&"Este hueco todavia no tiene defensa",""),3,32767)) | J8: =IF(OR((SUMPRODUCT(1*(((('Citaciones del dia'!$A$4:$A$27<>"")+('Citaciones del dia'!$B$4:$B$27<>"")+('Citaciones del dia'!$C$4:$C$27<>""))>0))*((EXACT('Citaciones del dia'!$A$4:$A$27,$A8)))*((EXACT('Citaciones del dia'!$B$4:$B$27,$B8)))*((((('Citaciones del dia'!$E$4:$E$27<>"")*($E8<>"")*EXACT('Citaciones del dia'!$E$4:$E$27,$E8))+(('Citaciones del dia'!$F$4:$F$27<>"")*($E8<>"")*EXACT('Citaciones del dia'!$F$4:$F$27,$E8))+(('Citaciones del dia'!$G$4:$G$27<>"")*($E8<>"")*EXACT('Citaciones del dia'!$G$4:$G$27,$E8))+(('Citaciones del dia'!$H$4:$H$27<>"")*($E8<>"")*EXACT('Citaciones del dia'!$H$4:$H$27,$E8))+(('Citaciones del dia'!$E$4:$E$27<>"")*($F8<>"")*EXACT('Citaciones del dia'!$E$4:$E$27,$F8))+(('Citaciones del dia'!$F$4:$F$27<>"")*($F8<>"")*EXACT('Citaciones del dia'!$F$4:$F$27,$F8))+(('Citaciones del dia'!$G$4:$G$27<>"")*($F8<>"")*EXACT('Citaciones del dia'!$G$4:$G$27,$F8))+(('Citaciones del dia'!$H$4:$H$27<>"")*($F8<>"")*EXACT('Citaciones del dia'!$H$4:$H$27,$F8))+(('Citaciones del dia'!$E$4:$E$27<>"")*($G8<>"")*EXACT('Citaciones del dia'!$E$4:$E$27,$G8))+(('Citaciones del dia'!$F$4:$F$27<>"")*($G8<>"")*EXACT('Citaciones del dia'!$F$4:$F$27,$G8))+(('Citaciones del dia'!$G$4:$G$27<>"")*($G8<>"")*EXACT('Citaciones del dia'!$G$4:$G$27,$G8))+(('Citaciones del dia'!$H$4:$H$27<>"")*($G8<>"")*EXACT('Citaciones del dia'!$H$4:$H$27,$G8))+(('Citaciones del dia'!$E$4:$E$27<>"")*($H8<>"")*EXACT('Citaciones del dia'!$E$4:$E$27,$H8))+(('Citaciones del dia'!$F$4:$F$27<>"")*($H8<>"")*EXACT('Citaciones del dia'!$F$4:$F$27,$H8))+(('Citaciones del dia'!$G$4:$G$27<>"")*($H8<>"")*EXACT('Citaciones del dia'!$G$4:$G$27,$H8))+(('Citaciones del dia'!$H$4:$H$27<>"")*($H8<>"")*EXACT('Citaciones del dia'!$H$4:$H$27,$H8)))>0))*((ROW('Citaciones del dia'!$A$4:$A$27)<>ROW($A8))))>0)),3,IF(OR(($D8="")),1,0))
E9: =IF(AND($A9="",$B9="",$C9=""),"",IF(ISNA(MATCH(1,INDEX(EXACT('Tesis y sus tribunales'!$A$4:$A$7,$D9)*1,0),0)),"",IF(ISBLANK(INDEX('Tesis y sus tribunales'!$B$4:$B$7,MATCH(1,INDEX(EXACT('Tesis y sus tribunales'!$A$4:$A$7,$D9)*1,0),0))),"",INDEX('Tesis y sus tribunales'!$B$4:$B$7,MATCH(1,INDEX(EXACT('Tesis y sus tribunales'!$A$4:$A$7,$D9)*1,0),0))))) | F9: =IF(AND($A9="",$B9="",$C9=""),"",IF(ISNA(MATCH(1,INDEX(EXACT('Tesis y sus tribunales'!$A$4:$A$7,$D9)*1,0),0)),"",IF(ISBLANK(INDEX('Tesis y sus tribunales'!$C$4:$C$7,MATCH(1,INDEX(EXACT('Tesis y sus tribunales'!$A$4:$A$7,$D9)*1,0),0))),"",INDEX('Tesis y sus tribunales'!$C$4:$C$7,MATCH(1,INDEX(EXACT('Tesis y sus tribunales'!$A$4:$A$7,$D9)*1,0),0))))) | G9: =IF(AND($A9="",$B9="",$C9=""),"",IF(ISNA(MATCH(1,INDEX(EXACT('Tesis y sus tribunales'!$A$4:$A$7,$D9)*1,0),0)),"",IF(ISBLANK(INDEX('Tesis y sus tribunales'!$D$4:$D$7,MATCH(1,INDEX(EXACT('Tesis y sus tribunales'!$A$4:$A$7,$D9)*1,0),0))),"",INDEX('Tesis y sus tribunales'!$D$4:$D$7,MATCH(1,INDEX(EXACT('Tesis y sus tribunales'!$A$4:$A$7,$D9)*1,0),0))))) | H9: =IF(AND($A9="",$B9="",$C9=""),"",IF(ISNA(MATCH(1,INDEX(EXACT('Tesis y sus tribunales'!$A$4:$A$7,$D9)*1,0),0)),"",IF(ISBLANK(INDEX('Tesis y sus tribunales'!$E$4:$E$7,MATCH(1,INDEX(EXACT('Tesis y sus tribunales'!$A$4:$A$7,$D9)*1,0),0))),"",INDEX('Tesis y sus tribunales'!$E$4:$E$7,MATCH(1,INDEX(EXACT('Tesis y sus tribunales'!$A$4:$A$7,$D9)*1,0),0))))) | I9: =IF(AND($A9="",$B9="",$C9=""),"",MID(IF((SUMPRODUCT(1*(((('Citaciones del dia'!$A$4:$A$27<>"")+('Citaciones del dia'!$B$4:$B$27<>"")+('Citaciones del dia'!$C$4:$C$27<>""))>0))*((EXACT('Citaciones del dia'!$A$4:$A$27,$A9)))*((EXACT('Citaciones del dia'!$B$4:$B$27,$B9)))*((((('Citaciones del dia'!$E$4:$E$27<>"")*($E9<>"")*EXACT('Citaciones del dia'!$E$4:$E$27,$E9))+(('Citaciones del dia'!$F$4:$F$27<>"")*($E9<>"")*EXACT('Citaciones del dia'!$F$4:$F$27,$E9))+(('Citaciones del dia'!$G$4:$G$27<>"")*($E9<>"")*EXACT('Citaciones del dia'!$G$4:$G$27,$E9))+(('Citaciones del dia'!$H$4:$H$27<>"")*($E9<>"")*EXACT('Citaciones del dia'!$H$4:$H$27,$E9))+(('Citaciones del dia'!$E$4:$E$27<>"")*($F9<>"")*EXACT('Citaciones del dia'!$E$4:$E$27,$F9))+(('Citaciones del dia'!$F$4:$F$27<>"")*($F9<>"")*EXACT('Citaciones del dia'!$F$4:$F$27,$F9))+(('Citaciones del dia'!$G$4:$G$27<>"")*($F9<>"")*EXACT('Citaciones del dia'!$G$4:$G$27,$F9))+(('Citaciones del dia'!$H$4:$H$27<>"")*($F9<>"")*EXACT('Citaciones del dia'!$H$4:$H$27,$F9))+(('Citaciones del dia'!$E$4:$E$27<>"")*($G9<>"")*EXACT('Citaciones del dia'!$E$4:$E$27,$G9))+(('Citaciones del dia'!$F$4:$F$27<>"")*($G9<>"")*EXACT('Citaciones del dia'!$F$4:$F$27,$G9))+(('Citaciones del dia'!$G$4:$G$27<>"")*($G9<>"")*EXACT('Citaciones del dia'!$G$4:$G$27,$G9))+(('Citaciones del dia'!$H$4:$H$27<>"")*($G9<>"")*EXACT('Citaciones del dia'!$H$4:$H$27,$G9))+(('Citaciones del dia'!$E$4:$E$27<>"")*($H9<>"")*EXACT('Citaciones del dia'!$E$4:$E$27,$H9))+(('Citaciones del dia'!$F$4:$F$27<>"")*($H9<>"")*EXACT('Citaciones del dia'!$F$4:$F$27,$H9))+(('Citaciones del dia'!$G$4:$G$27<>"")*($H9<>"")*EXACT('Citaciones del dia'!$G$4:$G$27,$H9))+(('Citaciones del dia'!$H$4:$H$27<>"")*($H9<>"")*EXACT('Citaciones del dia'!$H$4:$H$27,$H9)))>0))*((ROW('Citaciones del dia'!$A$4:$A$27)<>ROW($A9))))>0),"; "&"Este profesor esta citado en dos locales a la vez","")&IF(($D9=""),"; "&"Este hueco todavia no tiene defensa",""),3,32767)) | J9: =IF(OR((SUMPRODUCT(1*(((('Citaciones del dia'!$A$4:$A$27<>"")+('Citaciones del dia'!$B$4:$B$27<>"")+('Citaciones del dia'!$C$4:$C$27<>""))>0))*((EXACT('Citaciones del dia'!$A$4:$A$27,$A9)))*((EXACT('Citaciones del dia'!$B$4:$B$27,$B9)))*((((('Citaciones del dia'!$E$4:$E$27<>"")*($E9<>"")*EXACT('Citaciones del dia'!$E$4:$E$27,$E9))+(('Citaciones del dia'!$F$4:$F$27<>"")*($E9<>"")*EXACT('Citaciones del dia'!$F$4:$F$27,$E9))+(('Citaciones del dia'!$G$4:$G$27<>"")*($E9<>"")*EXACT('Citaciones del dia'!$G$4:$G$27,$E9))+(('Citaciones del dia'!$H$4:$H$27<>"")*($E9<>"")*EXACT('Citaciones del dia'!$H$4:$H$27,$E9))+(('Citaciones del dia'!$E$4:$E$27<>"")*($F9<>"")*EXACT('Citaciones del dia'!$E$4:$E$27,$F9))+(('Citaciones del dia'!$F$4:$F$27<>"")*($F9<>"")*EXACT('Citaciones del dia'!$F$4:$F$27,$F9))+(('Citaciones del dia'!$G$4:$G$27<>"")*($F9<>"")*EXACT('Citaciones del dia'!$G$4:$G$27,$F9))+(('Citaciones del dia'!$H$4:$H$27<>"")*($F9<>"")*EXACT('Citaciones del dia'!$H$4:$H$27,$F9))+(('Citaciones del dia'!$E$4:$E$27<>"")*($G9<>"")*EXACT('Citaciones del dia'!$E$4:$E$27,$G9))+(('Citaciones del dia'!$F$4:$F$27<>"")*($G9<>"")*EXACT('Citaciones del dia'!$F$4:$F$27,$G9))+(('Citaciones del dia'!$G$4:$G$27<>"")*($G9<>"")*EXACT('Citaciones del dia'!$G$4:$G$27,$G9))+(('Citaciones del dia'!$H$4:$H$27<>"")*($G9<>"")*EXACT('Citaciones del dia'!$H$4:$H$27,$G9))+(('Citaciones del dia'!$E$4:$E$27<>"")*($H9<>"")*EXACT('Citaciones del dia'!$E$4:$E$27,$H9))+(('Citaciones del dia'!$F$4:$F$27<>"")*($H9<>"")*EXACT('Citaciones del dia'!$F$4:$F$27,$H9))+(('Citaciones del dia'!$G$4:$G$27<>"")*($H9<>"")*EXACT('Citaciones del dia'!$G$4:$G$27,$H9))+(('Citaciones del dia'!$H$4:$H$27<>"")*($H9<>"")*EXACT('Citaciones del dia'!$H$4:$H$27,$H9)))>0))*((ROW('Citaciones del dia'!$A$4:$A$27)<>ROW($A9))))>0)),3,IF(OR(($D9="")),1,0))
E10: =IF(AND($A10="",$B10="",$C10=""),"",IF(ISNA(MATCH(1,INDEX(EXACT('Tesis y sus tribunales'!$A$4:$A$7,$D10)*1,0),0)),"",IF(ISBLANK(INDEX('Tesis y sus tribunales'!$B$4:$B$7,MATCH(1,INDEX(EXACT('Tesis y sus tribunales'!$A$4:$A$7,$D10)*1,0),0))),"",INDEX('Tesis y sus tribunales'!$B$4:$B$7,MATCH(1,INDEX(EXACT('Tesis y sus tribunales'!$A$4:$A$7,$D10)*1,0),0))))) | F10: =IF(AND($A10="",$B10="",$C10=""),"",IF(ISNA(MATCH(1,INDEX(EXACT('Tesis y sus tribunales'!$A$4:$A$7,$D10)*1,0),0)),"",IF(ISBLANK(INDEX('Tesis y sus tribunales'!$C$4:$C$7,MATCH(1,INDEX(EXACT('Tesis y sus tribunales'!$A$4:$A$7,$D10)*1,0),0))),"",INDEX('Tesis y sus tribunales'!$C$4:$C$7,MATCH(1,INDEX(EXACT('Tesis y sus tribunales'!$A$4:$A$7,$D10)*1,0),0))))) | G10: =IF(AND($A10="",$B10="",$C10=""),"",IF(ISNA(MATCH(1,INDEX(EXACT('Tesis y sus tribunales'!$A$4:$A$7,$D10)*1,0),0)),"",IF(ISBLANK(INDEX('Tesis y sus tribunales'!$D$4:$D$7,MATCH(1,INDEX(EXACT('Tesis y sus tribunales'!$A$4:$A$7,$D10)*1,0),0))),"",INDEX('Tesis y sus tribunales'!$D$4:$D$7,MATCH(1,INDEX(EXACT('Tesis y sus tribunales'!$A$4:$A$7,$D10)*1,0),0))))) | H10: =IF(AND($A10="",$B10="",$C10=""),"",IF(ISNA(MATCH(1,INDEX(EXACT('Tesis y sus tribunales'!$A$4:$A$7,$D10)*1,0),0)),"",IF(ISBLANK(INDEX('Tesis y sus tribunales'!$E$4:$E$7,MATCH(1,INDEX(EXACT('Tesis y sus tribunales'!$A$4:$A$7,$D10)*1,0),0))),"",INDEX('Tesis y sus tribunales'!$E$4:$E$7,MATCH(1,INDEX(EXACT('Tesis y sus tribunales'!$A$4:$A$7,$D10)*1,0),0))))) | I10: =IF(AND($A10="",$B10="",$C10=""),"",MID(IF((SUMPRODUCT(1*(((('Citaciones del dia'!$A$4:$A$27<>"")+('Citaciones del dia'!$B$4:$B$27<>"")+('Citaciones del dia'!$C$4:$C$27<>""))>0))*((EXACT('Citaciones del dia'!$A$4:$A$27,$A10)))*((EXACT('Citaciones del dia'!$B$4:$B$27,$B10)))*((((('Citaciones del dia'!$E$4:$E$27<>"")*($E10<>"")*EXACT('Citaciones del dia'!$E$4:$E$27,$E10))+(('Citaciones del dia'!$F$4:$F$27<>"")*($E10<>"")*EXACT('Citaciones del dia'!$F$4:$F$27,$E10))+(('Citaciones del dia'!$G$4:$G$27<>"")*($E10<>"")*EXACT('Citaciones del dia'!$G$4:$G$27,$E10))+(('Citaciones del dia'!$H$4:$H$27<>"")*($E10<>"")*EXACT('Citaciones del dia'!$H$4:$H$27,$E10))+(('Citaciones del dia'!$E$4:$E$27<>"")*($F10<>"")*EXACT('Citaciones del dia'!$E$4:$E$27,$F10))+(('Citaciones del dia'!$F$4:$F$27<>"")*($F10<>"")*EXACT('Citaciones del dia'!$F$4:$F$27,$F10))+(('Citaciones del dia'!$G$4:$G$27<>"")*($F10<>"")*EXACT('Citaciones del dia'!$G$4:$G$27,$F10))+(('Citaciones del dia'!$H$4:$H$27<>"")*($F10<>"")*EXACT('Citaciones del dia'!$H$4:$H$27,$F10))+(('Citaciones del dia'!$E$4:$E$27<>"")*($G10<>"")*EXACT('Citaciones del dia'!$E$4:$E$27,$G10))+(('Citaciones del dia'!$F$4:$F$27<>"")*($G10<>"")*EXACT('Citaciones del dia'!$F$4:$F$27,$G10))+(('Citaciones del dia'!$G$4:$G$27<>"")*($G10<>"")*EXACT('Citaciones del dia'!$G$4:$G$27,$G10))+(('Citaciones del dia'!$H$4:$H$27<>"")*($G10<>"")*EXACT('Citaciones del dia'!$H$4:$H$27,$G10))+(('Citaciones del dia'!$E$4:$E$27<>"")*($H10<>"")*EXACT('Citaciones del dia'!$E$4:$E$27,$H10))+(('Citaciones del dia'!$F$4:$F$27<>"")*($H10<>"")*EXACT('Citaciones del dia'!$F$4:$F$27,$H10))+(('Citaciones del dia'!$G$4:$G$27<>"")*($H10<>"")*EXACT('Citaciones del dia'!$G$4:$G$27,$H10))+(('Citaciones del dia'!$H$4:$H$27<>"")*($H10<>"")*EXACT('Citaciones del dia'!$H$4:$H$27,$H10)))>0))*((ROW('Citaciones del dia'!$A$4:$A$27)<>ROW($A10))))>0),"; "&"Este profesor esta citado en dos locales a la vez","")&IF(($D10=""),"; "&"Este hueco todavia no tiene defensa",""),3,32767)) | J10: =IF(OR((SUMPRODUCT(1*(((('Citaciones del dia'!$A$4:$A$27<>"")+('Citaciones del dia'!$B$4:$B$27<>"")+('Citaciones del dia'!$C$4:$C$27<>""))>0))*((EXACT('Citaciones del dia'!$A$4:$A$27,$A10)))*((EXACT('Citaciones del dia'!$B$4:$B$27,$B10)))*((((('Citaciones del dia'!$E$4:$E$27<>"")*($E10<>"")*EXACT('Citaciones del dia'!$E$4:$E$27,$E10))+(('Citaciones del dia'!$F$4:$F$27<>"")*($E10<>"")*EXACT('Citaciones del dia'!$F$4:$F$27,$E10))+(('Citaciones del dia'!$G$4:$G$27<>"")*($E10<>"")*EXACT('Citaciones del dia'!$G$4:$G$27,$E10))+(('Citaciones del dia'!$H$4:$H$27<>"")*($E10<>"")*EXACT('Citaciones del dia'!$H$4:$H$27,$E10))+(('Citaciones del dia'!$E$4:$E$27<>"")*($F10<>"")*EXACT('Citaciones del dia'!$E$4:$E$27,$F10))+(('Citaciones del dia'!$F$4:$F$27<>"")*($F10<>"")*EXACT('Citaciones del dia'!$F$4:$F$27,$F10))+(('Citaciones del dia'!$G$4:$G$27<>"")*($F10<>"")*EXACT('Citaciones del dia'!$G$4:$G$27,$F10))+(('Citaciones del dia'!$H$4:$H$27<>"")*($F10<>"")*EXACT('Citaciones del dia'!$H$4:$H$27,$F10))+(('Citaciones del dia'!$E$4:$E$27<>"")*($G10<>"")*EXACT('Citaciones del dia'!$E$4:$E$27,$G10))+(('Citaciones del dia'!$F$4:$F$27<>"")*($G10<>"")*EXACT('Citaciones del dia'!$F$4:$F$27,$G10))+(('Citaciones del dia'!$G$4:$G$27<>"")*($G10<>"")*EXACT('Citaciones del dia'!$G$4:$G$27,$G10))+(('Citaciones del dia'!$H$4:$H$27<>"")*($G10<>"")*EXACT('Citaciones del dia'!$H$4:$H$27,$G10))+(('Citaciones del dia'!$E$4:$E$27<>"")*($H10<>"")*EXACT('Citaciones del dia'!$E$4:$E$27,$H10))+(('Citaciones del dia'!$F$4:$F$27<>"")*($H10<>"")*EXACT('Citaciones del dia'!$F$4:$F$27,$H10))+(('Citaciones del dia'!$G$4:$G$27<>"")*($H10<>"")*EXACT('Citaciones del dia'!$G$4:$G$27,$H10))+(('Citaciones del dia'!$H$4:$H$27<>"")*($H10<>"")*EXACT('Citaciones del dia'!$H$4:$H$27,$H10)))>0))*((ROW('Citaciones del dia'!$A$4:$A$27)<>ROW($A10))))>0)),3,IF(OR(($D10="")),1,0))
E11: =IF(AND($A11="",$B11="",$C11=""),"",IF(ISNA(MATCH(1,INDEX(EXACT('Tesis y sus tribunales'!$A$4:$A$7,$D11)*1,0),0)),"",IF(ISBLANK(INDEX('Tesis y sus tribunales'!$B$4:$B$7,MATCH(1,INDEX(EXACT('Tesis y sus tribunales'!$A$4:$A$7,$D11)*1,0),0))),"",INDEX('Tesis y sus tribunales'!$B$4:$B$7,MATCH(1,INDEX(EXACT('Tesis y sus tribunales'!$A$4:$A$7,$D11)*1,0),0))))) | F11: =IF(AND($A11="",$B11="",$C11=""),"",IF(ISNA(MATCH(1,INDEX(EXACT('Tesis y sus tribunales'!$A$4:$A$7,$D11)*1,0),0)),"",IF(ISBLANK(INDEX('Tesis y sus tribunales'!$C$4:$C$7,MATCH(1,INDEX(EXACT('Tesis y sus tribunales'!$A$4:$A$7,$D11)*1,0),0))),"",INDEX('Tesis y sus tribunales'!$C$4:$C$7,MATCH(1,INDEX(EXACT('Tesis y sus tribunales'!$A$4:$A$7,$D11)*1,0),0))))) | G11: =IF(AND($A11="",$B11="",$C11=""),"",IF(ISNA(MATCH(1,INDEX(EXACT('Tesis y sus tribunales'!$A$4:$A$7,$D11)*1,0),0)),"",IF(ISBLANK(INDEX('Tesis y sus tribunales'!$D$4:$D$7,MATCH(1,INDEX(EXACT('Tesis y sus tribunales'!$A$4:$A$7,$D11)*1,0),0))),"",INDEX('Tesis y sus tribunales'!$D$4:$D$7,MATCH(1,INDEX(EXACT('Tesis y sus tribunales'!$A$4:$A$7,$D11)*1,0),0))))) | H11: =IF(AND($A11="",$B11="",$C11=""),"",IF(ISNA(MATCH(1,INDEX(EXACT('Tesis y sus tribunales'!$A$4:$A$7,$D11)*1,0),0)),"",IF(ISBLANK(INDEX('Tesis y sus tribunales'!$E$4:$E$7,MATCH(1,INDEX(EXACT('Tesis y sus tribunales'!$A$4:$A$7,$D11)*1,0),0))),"",INDEX('Tesis y sus tribunales'!$E$4:$E$7,MATCH(1,INDEX(EXACT('Tesis y sus tribunales'!$A$4:$A$7,$D11)*1,0),0))))) | I11: =IF(AND($A11="",$B11="",$C11=""),"",MID(IF((SUMPRODUCT(1*(((('Citaciones del dia'!$A$4:$A$27<>"")+('Citaciones del dia'!$B$4:$B$27<>"")+('Citaciones del dia'!$C$4:$C$27<>""))>0))*((EXACT('Citaciones del dia'!$A$4:$A$27,$A11)))*((EXACT('Citaciones del dia'!$B$4:$B$27,$B11)))*((((('Citaciones del dia'!$E$4:$E$27<>"")*($E11<>"")*EXACT('Citaciones del dia'!$E$4:$E$27,$E11))+(('Citaciones del dia'!$F$4:$F$27<>"")*($E11<>"")*EXACT('Citaciones del dia'!$F$4:$F$27,$E11))+(('Citaciones del dia'!$G$4:$G$27<>"")*($E11<>"")*EXACT('Citaciones del dia'!$G$4:$G$27,$E11))+(('Citaciones del dia'!$H$4:$H$27<>"")*($E11<>"")*EXACT('Citaciones del dia'!$H$4:$H$27,$E11))+(('Citaciones del dia'!$E$4:$E$27<>"")*($F11<>"")*EXACT('Citaciones del dia'!$E$4:$E$27,$F11))+(('Citaciones del dia'!$F$4:$F$27<>"")*($F11<>"")*EXACT('Citaciones del dia'!$F$4:$F$27,$F11))+(('Citaciones del dia'!$G$4:$G$27<>"")*($F11<>"")*EXACT('Citaciones del dia'!$G$4:$G$27,$F11))+(('Citaciones del dia'!$H$4:$H$27<>"")*($F11<>"")*EXACT('Citaciones del dia'!$H$4:$H$27,$F11))+(('Citaciones del dia'!$E$4:$E$27<>"")*($G11<>"")*EXACT('Citaciones del dia'!$E$4:$E$27,$G11))+(('Citaciones del dia'!$F$4:$F$27<>"")*($G11<>"")*EXACT('Citaciones del dia'!$F$4:$F$27,$G11))+(('Citaciones del dia'!$G$4:$G$27<>"")*($G11<>"")*EXACT('Citaciones del dia'!$G$4:$G$27,$G11))+(('Citaciones del dia'!$H$4:$H$27<>"")*($G11<>"")*EXACT('Citaciones del dia'!$H$4:$H$27,$G11))+(('Citaciones del dia'!$E$4:$E$27<>"")*($H11<>"")*EXACT('Citaciones del dia'!$E$4:$E$27,$H11))+(('Citaciones del dia'!$F$4:$F$27<>"")*($H11<>"")*EXACT('Citaciones del dia'!$F$4:$F$27,$H11))+(('Citaciones del dia'!$G$4:$G$27<>"")*($H11<>"")*EXACT('Citaciones del dia'!$G$4:$G$27,$H11))+(('Citaciones del dia'!$H$4:$H$27<>"")*($H11<>"")*EXACT('Citaciones del dia'!$H$4:$H$27,$H11)))>0))*((ROW('Citaciones del dia'!$A$4:$A$27)<>ROW($A11))))>0),"; "&"Este profesor esta citado en dos locales a la vez","")&IF(($D11=""),"; "&"Este hueco todavia no tiene defensa",""),3,32767)) | J11: =IF(OR((SUMPRODUCT(1*(((('Citaciones del dia'!$A$4:$A$27<>"")+('Citaciones del dia'!$B$4:$B$27<>"")+('Citaciones del dia'!$C$4:$C$27<>""))>0))*((EXACT('Citaciones del dia'!$A$4:$A$27,$A11)))*((EXACT('Citaciones del dia'!$B$4:$B$27,$B11)))*((((('Citaciones del dia'!$E$4:$E$27<>"")*($E11<>"")*EXACT('Citaciones del dia'!$E$4:$E$27,$E11))+(('Citaciones del dia'!$F$4:$F$27<>"")*($E11<>"")*EXACT('Citaciones del dia'!$F$4:$F$27,$E11))+(('Citaciones del dia'!$G$4:$G$27<>"")*($E11<>"")*EXACT('Citaciones del dia'!$G$4:$G$27,$E11))+(('Citaciones del dia'!$H$4:$H$27<>"")*($E11<>"")*EXACT('Citaciones del dia'!$H$4:$H$27,$E11))+(('Citaciones del dia'!$E$4:$E$27<>"")*($F11<>"")*EXACT('Citaciones del dia'!$E$4:$E$27,$F11))+(('Citaciones del dia'!$F$4:$F$27<>"")*($F11<>"")*EXACT('Citaciones del dia'!$F$4:$F$27,$F11))+(('Citaciones del dia'!$G$4:$G$27<>"")*($F11<>"")*EXACT('Citaciones del dia'!$G$4:$G$27,$F11))+(('Citaciones del dia'!$H$4:$H$27<>"")*($F11<>"")*EXACT('Citaciones del dia'!$H$4:$H$27,$F11))+(('Citaciones del dia'!$E$4:$E$27<>"")*($G11<>"")*EXACT('Citaciones del dia'!$E$4:$E$27,$G11))+(('Citaciones del dia'!$F$4:$F$27<>"")*($G11<>"")*EXACT('Citaciones del dia'!$F$4:$F$27,$G11))+(('Citaciones del dia'!$G$4:$G$27<>"")*($G11<>"")*EXACT('Citaciones del dia'!$G$4:$G$27,$G11))+(('Citaciones del dia'!$H$4:$H$27<>"")*($G11<>"")*EXACT('Citaciones del dia'!$H$4:$H$27,$G11))+(('Citaciones del dia'!$E$4:$E$27<>"")*($H11<>"")*EXACT('Citaciones del dia'!$E$4:$E$27,$H11))+(('Citaciones del dia'!$F$4:$F$27<>"")*($H11<>"")*EXACT('Citaciones del dia'!$F$4:$F$27,$H11))+(('Citaciones del dia'!$G$4:$G$27<>"")*($H11<>"")*EXACT('Citaciones del dia'!$G$4:$G$27,$H11))+(('Citaciones del dia'!$H$4:$H$27<>"")*($H11<>"")*EXACT('Citaciones del dia'!$H$4:$H$27,$H11)))>0))*((ROW('Citaciones del dia'!$A$4:$A$27)<>ROW($A11))))>0)),3,IF(OR(($D11="")),1,0))
E12: =IF(AND($A12="",$B12="",$C12=""),"",IF(ISNA(MATCH(1,INDEX(EXACT('Tesis y sus tribunales'!$A$4:$A$7,$D12)*1,0),0)),"",IF(ISBLANK(INDEX('Tesis y sus tribunales'!$B$4:$B$7,MATCH(1,INDEX(EXACT('Tesis y sus tribunales'!$A$4:$A$7,$D12)*1,0),0))),"",INDEX('Tesis y sus tribunales'!$B$4:$B$7,MATCH(1,INDEX(EXACT('Tesis y sus tribunales'!$A$4:$A$7,$D12)*1,0),0))))) | F12: =IF(AND($A12="",$B12="",$C12=""),"",IF(ISNA(MATCH(1,INDEX(EXACT('Tesis y sus tribunales'!$A$4:$A$7,$D12)*1,0),0)),"",IF(ISBLANK(INDEX('Tesis y sus tribunales'!$C$4:$C$7,MATCH(1,INDEX(EXACT('Tesis y sus tribunales'!$A$4:$A$7,$D12)*1,0),0))),"",INDEX('Tesis y sus tribunales'!$C$4:$C$7,MATCH(1,INDEX(EXACT('Tesis y sus tribunales'!$A$4:$A$7,$D12)*1,0),0))))) | G12: =IF(AND($A12="",$B12="",$C12=""),"",IF(ISNA(MATCH(1,INDEX(EXACT('Tesis y sus tribunales'!$A$4:$A$7,$D12)*1,0),0)),"",IF(ISBLANK(INDEX('Tesis y sus tribunales'!$D$4:$D$7,MATCH(1,INDEX(EXACT('Tesis y sus tribunales'!$A$4:$A$7,$D12)*1,0),0))),"",INDEX('Tesis y sus tribunales'!$D$4:$D$7,MATCH(1,INDEX(EXACT('Tesis y sus tribunales'!$A$4:$A$7,$D12)*1,0),0))))) | H12: =IF(AND($A12="",$B12="",$C12=""),"",IF(ISNA(MATCH(1,INDEX(EXACT('Tesis y sus tribunales'!$A$4:$A$7,$D12)*1,0),0)),"",IF(ISBLANK(INDEX('Tesis y sus tribunales'!$E$4:$E$7,MATCH(1,INDEX(EXACT('Tesis y sus tribunales'!$A$4:$A$7,$D12)*1,0),0))),"",INDEX('Tesis y sus tribunales'!$E$4:$E$7,MATCH(1,INDEX(EXACT('Tesis y sus tribunales'!$A$4:$A$7,$D12)*1,0),0))))) | I12: =IF(AND($A12="",$B12="",$C12=""),"",MID(IF((SUMPRODUCT(1*(((('Citaciones del dia'!$A$4:$A$27<>"")+('Citaciones del dia'!$B$4:$B$27<>"")+('Citaciones del dia'!$C$4:$C$27<>""))>0))*((EXACT('Citaciones del dia'!$A$4:$A$27,$A12)))*((EXACT('Citaciones del dia'!$B$4:$B$27,$B12)))*((((('Citaciones del dia'!$E$4:$E$27<>"")*($E12<>"")*EXACT('Citaciones del dia'!$E$4:$E$27,$E12))+(('Citaciones del dia'!$F$4:$F$27<>"")*($E12<>"")*EXACT('Citaciones del dia'!$F$4:$F$27,$E12))+(('Citaciones del dia'!$G$4:$G$27<>"")*($E12<>"")*EXACT('Citaciones del dia'!$G$4:$G$27,$E12))+(('Citaciones del dia'!$H$4:$H$27<>"")*($E12<>"")*EXACT('Citaciones del dia'!$H$4:$H$27,$E12))+(('Citaciones del dia'!$E$4:$E$27<>"")*($F12<>"")*EXACT('Citaciones del dia'!$E$4:$E$27,$F12))+(('Citaciones del dia'!$F$4:$F$27<>"")*($F12<>"")*EXACT('Citaciones del dia'!$F$4:$F$27,$F12))+(('Citaciones del dia'!$G$4:$G$27<>"")*($F12<>"")*EXACT('Citaciones del dia'!$G$4:$G$27,$F12))+(('Citaciones del dia'!$H$4:$H$27<>"")*($F12<>"")*EXACT('Citaciones del dia'!$H$4:$H$27,$F12))+(('Citaciones del dia'!$E$4:$E$27<>"")*($G12<>"")*EXACT('Citaciones del dia'!$E$4:$E$27,$G12))+(('Citaciones del dia'!$F$4:$F$27<>"")*($G12<>"")*EXACT('Citaciones del dia'!$F$4:$F$27,$G12))+(('Citaciones del dia'!$G$4:$G$27<>"")*($G12<>"")*EXACT('Citaciones del dia'!$G$4:$G$27,$G12))+(('Citaciones del dia'!$H$4:$H$27<>"")*($G12<>"")*EXACT('Citaciones del dia'!$H$4:$H$27,$G12))+(('Citaciones del dia'!$E$4:$E$27<>"")*($H12<>"")*EXACT('Citaciones del dia'!$E$4:$E$27,$H12))+(('Citaciones del dia'!$F$4:$F$27<>"")*($H12<>"")*EXACT('Citaciones del dia'!$F$4:$F$27,$H12))+(('Citaciones del dia'!$G$4:$G$27<>"")*($H12<>"")*EXACT('Citaciones del dia'!$G$4:$G$27,$H12))+(('Citaciones del dia'!$H$4:$H$27<>"")*($H12<>"")*EXACT('Citaciones del dia'!$H$4:$H$27,$H12)))>0))*((ROW('Citaciones del dia'!$A$4:$A$27)<>ROW($A12))))>0),"; "&"Este profesor esta citado en dos locales a la vez","")&IF(($D12=""),"; "&"Este hueco todavia no tiene defensa",""),3,32767)) | J12: =IF(OR((SUMPRODUCT(1*(((('Citaciones del dia'!$A$4:$A$27<>"")+('Citaciones del dia'!$B$4:$B$27<>"")+('Citaciones del dia'!$C$4:$C$27<>""))>0))*((EXACT('Citaciones del dia'!$A$4:$A$27,$A12)))*((EXACT('Citaciones del dia'!$B$4:$B$27,$B12)))*((((('Citaciones del dia'!$E$4:$E$27<>"")*($E12<>"")*EXACT('Citaciones del dia'!$E$4:$E$27,$E12))+(('Citaciones del dia'!$F$4:$F$27<>"")*($E12<>"")*EXACT('Citaciones del dia'!$F$4:$F$27,$E12))+(('Citaciones del dia'!$G$4:$G$27<>"")*($E12<>"")*EXACT('Citaciones del dia'!$G$4:$G$27,$E12))+(('Citaciones del dia'!$H$4:$H$27<>"")*($E12<>"")*EXACT('Citaciones del dia'!$H$4:$H$27,$E12))+(('Citaciones del dia'!$E$4:$E$27<>"")*($F12<>"")*EXACT('Citaciones del dia'!$E$4:$E$27,$F12))+(('Citaciones del dia'!$F$4:$F$27<>"")*($F12<>"")*EXACT('Citaciones del dia'!$F$4:$F$27,$F12))+(('Citaciones del dia'!$G$4:$G$27<>"")*($F12<>"")*EXACT('Citaciones del dia'!$G$4:$G$27,$F12))+(('Citaciones del dia'!$H$4:$H$27<>"")*($F12<>"")*EXACT('Citaciones del dia'!$H$4:$H$27,$F12))+(('Citaciones del dia'!$E$4:$E$27<>"")*($G12<>"")*EXACT('Citaciones del dia'!$E$4:$E$27,$G12))+(('Citaciones del dia'!$F$4:$F$27<>"")*($G12<>"")*EXACT('Citaciones del dia'!$F$4:$F$27,$G12))+(('Citaciones del dia'!$G$4:$G$27<>"")*($G12<>"")*EXACT('Citaciones del dia'!$G$4:$G$27,$G12))+(('Citaciones del dia'!$H$4:$H$27<>"")*($G12<>"")*EXACT('Citaciones del dia'!$H$4:$H$27,$G12))+(('Citaciones del dia'!$E$4:$E$27<>"")*($H12<>"")*EXACT('Citaciones del dia'!$E$4:$E$27,$H12))+(('Citaciones del dia'!$F$4:$F$27<>"")*($H12<>"")*EXACT('Citaciones del dia'!$F$4:$F$27,$H12))+(('Citaciones del dia'!$G$4:$G$27<>"")*($H12<>"")*EXACT('Citaciones del dia'!$G$4:$G$27,$H12))+(('Citaciones del dia'!$H$4:$H$27<>"")*($H12<>"")*EXACT('Citaciones del dia'!$H$4:$H$27,$H12)))>0))*((ROW('Citaciones del dia'!$A$4:$A$27)<>ROW($A12))))>0)),3,IF(OR(($D12="")),1,0))
E13: =IF(AND($A13="",$B13="",$C13=""),"",IF(ISNA(MATCH(1,INDEX(EXACT('Tesis y sus tribunales'!$A$4:$A$7,$D13)*1,0),0)),"",IF(ISBLANK(INDEX('Tesis y sus tribunales'!$B$4:$B$7,MATCH(1,INDEX(EXACT('Tesis y sus tribunales'!$A$4:$A$7,$D13)*1,0),0))),"",INDEX('Tesis y sus tribunales'!$B$4:$B$7,MATCH(1,INDEX(EXACT('Tesis y sus tribunales'!$A$4:$A$7,$D13)*1,0),0))))) | F13: =IF(AND($A13="",$B13="",$C13=""),"",IF(ISNA(MATCH(1,INDEX(EXACT('Tesis y sus tribunales'!$A$4:$A$7,$D13)*1,0),0)),"",IF(ISBLANK(INDEX('Tesis y sus tribunales'!$C$4:$C$7,MATCH(1,INDEX(EXACT('Tesis y sus tribunales'!$A$4:$A$7,$D13)*1,0),0))),"",INDEX('Tesis y sus tribunales'!$C$4:$C$7,MATCH(1,INDEX(EXACT('Tesis y sus tribunales'!$A$4:$A$7,$D13)*1,0),0))))) | G13: =IF(AND($A13="",$B13="",$C13=""),"",IF(ISNA(MATCH(1,INDEX(EXACT('Tesis y sus tribunales'!$A$4:$A$7,$D13)*1,0),0)),"",IF(ISBLANK(INDEX('Tesis y sus tribunales'!$D$4:$D$7,MATCH(1,INDEX(EXACT('Tesis y sus tribunales'!$A$4:$A$7,$D13)*1,0),0))),"",INDEX('Tesis y sus tribunales'!$D$4:$D$7,MATCH(1,INDEX(EXACT('Tesis y sus tribunales'!$A$4:$A$7,$D13)*1,0),0))))) | H13: =IF(AND($A13="",$B13="",$C13=""),"",IF(ISNA(MATCH(1,INDEX(EXACT('Tesis y sus tribunales'!$A$4:$A$7,$D13)*1,0),0)),"",IF(ISBLANK(INDEX('Tesis y sus tribunales'!$E$4:$E$7,MATCH(1,INDEX(EXACT('Tesis y sus tribunales'!$A$4:$A$7,$D13)*1,0),0))),"",INDEX('Tesis y sus tribunales'!$E$4:$E$7,MATCH(1,INDEX(EXACT('Tesis y sus tribunales'!$A$4:$A$7,$D13)*1,0),0))))) | I13: =IF(AND($A13="",$B13="",$C13=""),"",MID(IF((SUMPRODUCT(1*(((('Citaciones del dia'!$A$4:$A$27<>"")+('Citaciones del dia'!$B$4:$B$27<>"")+('Citaciones del dia'!$C$4:$C$27<>""))>0))*((EXACT('Citaciones del dia'!$A$4:$A$27,$A13)))*((EXACT('Citaciones del dia'!$B$4:$B$27,$B13)))*((((('Citaciones del dia'!$E$4:$E$27<>"")*($E13<>"")*EXACT('Citaciones del dia'!$E$4:$E$27,$E13))+(('Citaciones del dia'!$F$4:$F$27<>"")*($E13<>"")*EXACT('Citaciones del dia'!$F$4:$F$27,$E13))+(('Citaciones del dia'!$G$4:$G$27<>"")*($E13<>"")*EXACT('Citaciones del dia'!$G$4:$G$27,$E13))+(('Citaciones del dia'!$H$4:$H$27<>"")*($E13<>"")*EXACT('Citaciones del dia'!$H$4:$H$27,$E13))+(('Citaciones del dia'!$E$4:$E$27<>"")*($F13<>"")*EXACT('Citaciones del dia'!$E$4:$E$27,$F13))+(('Citaciones del dia'!$F$4:$F$27<>"")*($F13<>"")*EXACT('Citaciones del dia'!$F$4:$F$27,$F13))+(('Citaciones del dia'!$G$4:$G$27<>"")*($F13<>"")*EXACT('Citaciones del dia'!$G$4:$G$27,$F13))+(('Citaciones del dia'!$H$4:$H$27<>"")*($F13<>"")*EXACT('Citaciones del dia'!$H$4:$H$27,$F13))+(('Citaciones del dia'!$E$4:$E$27<>"")*($G13<>"")*EXACT('Citaciones del dia'!$E$4:$E$27,$G13))+(('Citaciones del dia'!$F$4:$F$27<>"")*($G13<>"")*EXACT('Citaciones del dia'!$F$4:$F$27,$G13))+(('Citaciones del dia'!$G$4:$G$27<>"")*($G13<>"")*EXACT('Citaciones del dia'!$G$4:$G$27,$G13))+(('Citaciones del dia'!$H$4:$H$27<>"")*($G13<>"")*EXACT('Citaciones del dia'!$H$4:$H$27,$G13))+(('Citaciones del dia'!$E$4:$E$27<>"")*($H13<>"")*EXACT('Citaciones del dia'!$E$4:$E$27,$H13))+(('Citaciones del dia'!$F$4:$F$27<>"")*($H13<>"")*EXACT('Citaciones del dia'!$F$4:$F$27,$H13))+(('Citaciones del dia'!$G$4:$G$27<>"")*($H13<>"")*EXACT('Citaciones del dia'!$G$4:$G$27,$H13))+(('Citaciones del dia'!$H$4:$H$27<>"")*($H13<>"")*EXACT('Citaciones del dia'!$H$4:$H$27,$H13)))>0))*((ROW('Citaciones del dia'!$A$4:$A$27)<>ROW($A13))))>0),"; "&"Este profesor esta citado en dos locales a la vez","")&IF(($D13=""),"; "&"Este hueco todavia no tiene defensa",""),3,32767)) | J13: =IF(OR((SUMPRODUCT(1*(((('Citaciones del dia'!$A$4:$A$27<>"")+('Citaciones del dia'!$B$4:$B$27<>"")+('Citaciones del dia'!$C$4:$C$27<>""))>0))*((EXACT('Citaciones del dia'!$A$4:$A$27,$A13)))*((EXACT('Citaciones del dia'!$B$4:$B$27,$B13)))*((((('Citaciones del dia'!$E$4:$E$27<>"")*($E13<>"")*EXACT('Citaciones del dia'!$E$4:$E$27,$E13))+(('Citaciones del dia'!$F$4:$F$27<>"")*($E13<>"")*EXACT('Citaciones del dia'!$F$4:$F$27,$E13))+(('Citaciones del dia'!$G$4:$G$27<>"")*($E13<>"")*EXACT('Citaciones del dia'!$G$4:$G$27,$E13))+(('Citaciones del dia'!$H$4:$H$27<>"")*($E13<>"")*EXACT('Citaciones del dia'!$H$4:$H$27,$E13))+(('Citaciones del dia'!$E$4:$E$27<>"")*($F13<>"")*EXACT('Citaciones del dia'!$E$4:$E$27,$F13))+(('Citaciones del dia'!$F$4:$F$27<>"")*($F13<>"")*EXACT('Citaciones del dia'!$F$4:$F$27,$F13))+(('Citaciones del dia'!$G$4:$G$27<>"")*($F13<>"")*EXACT('Citaciones del dia'!$G$4:$G$27,$F13))+(('Citaciones del dia'!$H$4:$H$27<>"")*($F13<>"")*EXACT('Citaciones del dia'!$H$4:$H$27,$F13))+(('Citaciones del dia'!$E$4:$E$27<>"")*($G13<>"")*EXACT('Citaciones del dia'!$E$4:$E$27,$G13))+(('Citaciones del dia'!$F$4:$F$27<>"")*($G13<>"")*EXACT('Citaciones del dia'!$F$4:$F$27,$G13))+(('Citaciones del dia'!$G$4:$G$27<>"")*($G13<>"")*EXACT('Citaciones del dia'!$G$4:$G$27,$G13))+(('Citaciones del dia'!$H$4:$H$27<>"")*($G13<>"")*EXACT('Citaciones del dia'!$H$4:$H$27,$G13))+(('Citaciones del dia'!$E$4:$E$27<>"")*($H13<>"")*EXACT('Citaciones del dia'!$E$4:$E$27,$H13))+(('Citaciones del dia'!$F$4:$F$27<>"")*($H13<>"")*EXACT('Citaciones del dia'!$F$4:$F$27,$H13))+(('Citaciones del dia'!$G$4:$G$27<>"")*($H13<>"")*EXACT('Citaciones del dia'!$G$4:$G$27,$H13))+(('Citaciones del dia'!$H$4:$H$27<>"")*($H13<>"")*EXACT('Citaciones del dia'!$H$4:$H$27,$H13)))>0))*((ROW('Citaciones del dia'!$A$4:$A$27)<>ROW($A13))))>0)),3,IF(OR(($D13="")),1,0))
E14: =IF(AND($A14="",$B14="",$C14=""),"",IF(ISNA(MATCH(1,INDEX(EXACT('Tesis y sus tribunales'!$A$4:$A$7,$D14)*1,0),0)),"",IF(ISBLANK(INDEX('Tesis y sus tribunales'!$B$4:$B$7,MATCH(1,INDEX(EXACT('Tesis y sus tribunales'!$A$4:$A$7,$D14)*1,0),0))),"",INDEX('Tesis y sus tribunales'!$B$4:$B$7,MATCH(1,INDEX(EXACT('Tesis y sus tribunales'!$A$4:$A$7,$D14)*1,0),0))))) | F14: =IF(AND($A14="",$B14="",$C14=""),"",IF(ISNA(MATCH(1,INDEX(EXACT('Tesis y sus tribunales'!$A$4:$A$7,$D14)*1,0),0)),"",IF(ISBLANK(INDEX('Tesis y sus tribunales'!$C$4:$C$7,MATCH(1,INDEX(EXACT('Tesis y sus tribunales'!$A$4:$A$7,$D14)*1,0),0))),"",INDEX('Tesis y sus tribunales'!$C$4:$C$7,MATCH(1,INDEX(EXACT('Tesis y sus tribunales'!$A$4:$A$7,$D14)*1,0),0))))) | G14: =IF(AND($A14="",$B14="",$C14=""),"",IF(ISNA(MATCH(1,INDEX(EXACT('Tesis y sus tribunales'!$A$4:$A$7,$D14)*1,0),0)),"",IF(ISBLANK(INDEX('Tesis y sus tribunales'!$D$4:$D$7,MATCH(1,INDEX(EXACT('Tesis y sus tribunales'!$A$4:$A$7,$D14)*1,0),0))),"",INDEX('Tesis y sus tribunales'!$D$4:$D$7,MATCH(1,INDEX(EXACT('Tesis y sus tribunales'!$A$4:$A$7,$D14)*1,0),0))))) | H14: =IF(AND($A14="",$B14="",$C14=""),"",IF(ISNA(MATCH(1,INDEX(EXACT('Tesis y sus tribunales'!$A$4:$A$7,$D14)*1,0),0)),"",IF(ISBLANK(INDEX('Tesis y sus tribunales'!$E$4:$E$7,MATCH(1,INDEX(EXACT('Tesis y sus tribunales'!$A$4:$A$7,$D14)*1,0),0))),"",INDEX('Tesis y sus tribunales'!$E$4:$E$7,MATCH(1,INDEX(EXACT('Tesis y sus tribunales'!$A$4:$A$7,$D14)*1,0),0))))) | I14: =IF(AND($A14="",$B14="",$C14=""),"",MID(IF((SUMPRODUCT(1*(((('Citaciones del dia'!$A$4:$A$27<>"")+('Citaciones del dia'!$B$4:$B$27<>"")+('Citaciones del dia'!$C$4:$C$27<>""))>0))*((EXACT('Citaciones del dia'!$A$4:$A$27,$A14)))*((EXACT('Citaciones del dia'!$B$4:$B$27,$B14)))*((((('Citaciones del dia'!$E$4:$E$27<>"")*($E14<>"")*EXACT('Citaciones del dia'!$E$4:$E$27,$E14))+(('Citaciones del dia'!$F$4:$F$27<>"")*($E14<>"")*EXACT('Citaciones del dia'!$F$4:$F$27,$E14))+(('Citaciones del dia'!$G$4:$G$27<>"")*($E14<>"")*EXACT('Citaciones del dia'!$G$4:$G$27,$E14))+(('Citaciones del dia'!$H$4:$H$27<>"")*($E14<>"")*EXACT('Citaciones del dia'!$H$4:$H$27,$E14))+(('Citaciones del dia'!$E$4:$E$27<>"")*($F14<>"")*EXACT('Citaciones del dia'!$E$4:$E$27,$F14))+(('Citaciones del dia'!$F$4:$F$27<>"")*($F14<>"")*EXACT('Citaciones del dia'!$F$4:$F$27,$F14))+(('Citaciones del dia'!$G$4:$G$27<>"")*($F14<>"")*EXACT('Citaciones del dia'!$G$4:$G$27,$F14))+(('Citaciones del dia'!$H$4:$H$27<>"")*($F14<>"")*EXACT('Citaciones del dia'!$H$4:$H$27,$F14))+(('Citaciones del dia'!$E$4:$E$27<>"")*($G14<>"")*EXACT('Citaciones del dia'!$E$4:$E$27,$G14))+(('Citaciones del dia'!$F$4:$F$27<>"")*($G14<>"")*EXACT('Citaciones del dia'!$F$4:$F$27,$G14))+(('Citaciones del dia'!$G$4:$G$27<>"")*($G14<>"")*EXACT('Citaciones del dia'!$G$4:$G$27,$G14))+(('Citaciones del dia'!$H$4:$H$27<>"")*($G14<>"")*EXACT('Citaciones del dia'!$H$4:$H$27,$G14))+(('Citaciones del dia'!$E$4:$E$27<>"")*($H14<>"")*EXACT('Citaciones del dia'!$E$4:$E$27,$H14))+(('Citaciones del dia'!$F$4:$F$27<>"")*($H14<>"")*EXACT('Citaciones del dia'!$F$4:$F$27,$H14))+(('Citaciones del dia'!$G$4:$G$27<>"")*($H14<>"")*EXACT('Citaciones del dia'!$G$4:$G$27,$H14))+(('Citaciones del dia'!$H$4:$H$27<>"")*($H14<>"")*EXACT('Citaciones del dia'!$H$4:$H$27,$H14)))>0))*((ROW('Citaciones del dia'!$A$4:$A$27)<>ROW($A14))))>0),"; "&"Este profesor esta citado en dos locales a la vez","")&IF(($D14=""),"; "&"Este hueco todavia no tiene defensa",""),3,32767)) | J14: =IF(OR((SUMPRODUCT(1*(((('Citaciones del dia'!$A$4:$A$27<>"")+('Citaciones del dia'!$B$4:$B$27<>"")+('Citaciones del dia'!$C$4:$C$27<>""))>0))*((EXACT('Citaciones del dia'!$A$4:$A$27,$A14)))*((EXACT('Citaciones del dia'!$B$4:$B$27,$B14)))*((((('Citaciones del dia'!$E$4:$E$27<>"")*($E14<>"")*EXACT('Citaciones del dia'!$E$4:$E$27,$E14))+(('Citaciones del dia'!$F$4:$F$27<>"")*($E14<>"")*EXACT('Citaciones del dia'!$F$4:$F$27,$E14))+(('Citaciones del dia'!$G$4:$G$27<>"")*($E14<>"")*EXACT('Citaciones del dia'!$G$4:$G$27,$E14))+(('Citaciones del dia'!$H$4:$H$27<>"")*($E14<>"")*EXACT('Citaciones del dia'!$H$4:$H$27,$E14))+(('Citaciones del dia'!$E$4:$E$27<>"")*($F14<>"")*EXACT('Citaciones del dia'!$E$4:$E$27,$F14))+(('Citaciones del dia'!$F$4:$F$27<>"")*($F14<>"")*EXACT('Citaciones del dia'!$F$4:$F$27,$F14))+(('Citaciones del dia'!$G$4:$G$27<>"")*($F14<>"")*EXACT('Citaciones del dia'!$G$4:$G$27,$F14))+(('Citaciones del dia'!$H$4:$H$27<>"")*($F14<>"")*EXACT('Citaciones del dia'!$H$4:$H$27,$F14))+(('Citaciones del dia'!$E$4:$E$27<>"")*($G14<>"")*EXACT('Citaciones del dia'!$E$4:$E$27,$G14))+(('Citaciones del dia'!$F$4:$F$27<>"")*($G14<>"")*EXACT('Citaciones del dia'!$F$4:$F$27,$G14))+(('Citaciones del dia'!$G$4:$G$27<>"")*($G14<>"")*EXACT('Citaciones del dia'!$G$4:$G$27,$G14))+(('Citaciones del dia'!$H$4:$H$27<>"")*($G14<>"")*EXACT('Citaciones del dia'!$H$4:$H$27,$G14))+(('Citaciones del dia'!$E$4:$E$27<>"")*($H14<>"")*EXACT('Citaciones del dia'!$E$4:$E$27,$H14))+(('Citaciones del dia'!$F$4:$F$27<>"")*($H14<>"")*EXACT('Citaciones del dia'!$F$4:$F$27,$H14))+(('Citaciones del dia'!$G$4:$G$27<>"")*($H14<>"")*EXACT('Citaciones del dia'!$G$4:$G$27,$H14))+(('Citaciones del dia'!$H$4:$H$27<>"")*($H14<>"")*EXACT('Citaciones del dia'!$H$4:$H$27,$H14)))>0))*((ROW('Citaciones del dia'!$A$4:$A$27)<>ROW($A14))))>0)),3,IF(OR(($D14="")),1,0))
