Workbook
Name Asignacion: OFFSET('Asignacion'!$A$4,0,0,COUNTA('Asignacion'!$A$4:$A$34),11)
Name Profesores: OFFSET('Carga por profesor'!$A$4,0,0,COUNTA('Carga por profesor'!$A$4:$A$27),7)
Name Asignaturas: OFFSET('Cobertura por asignatura'!$A$4,0,0,COUNTA('Cobertura por asignatura'!$A$4:$A$27),12)

Sheet Asignacion
A1: Asignacion
A3: No. | B3: Id | C3: Tipo | D3: Grupo | E3: Profesor | F3: Asignatura | G3: Horas | H3: Nombre | I3: Codigo | J3: Primera del par | K3: Cuenta | L3: Estado | M3: (nivel de las marcas)
A4: 1 | B4: EST-CC | C4: Conf | E4: PIAD | F4: =IF(AND($A4=""),"",IF(ISNA(MATCH(1,INDEX(EXACT('Cobertura por asignatura'!$A$4:$A$27,$B4)*1*((('Cobertura por asignatura'!$A$4:$A$27<>""))>0),0),0)),"",IF(ISBLANK(INDEX('Cobertura por asignatura'!$B$4:$B$27,MATCH(1,INDEX(EXACT('Cobertura por asignatura'!$A$4:$A$27,$B4)*1*((('Cobertura por asignatura'!$A$4:$A$27<>""))>0),0),0))),"",INDEX('Cobertura por asignatura'!$B$4:$B$27,MATCH(1,INDEX(EXACT('Cobertura por asignatura'!$A$4:$A$27,$B4)*1*((('Cobertura por asignatura'!$A$4:$A$27<>""))>0),0),0))))) | G4: =IF(AND($A4=""),"",IF(EXACT($C4,"Conf"),IF(ISNA(MATCH(1,INDEX(EXACT('Cobertura por asignatura'!$A$4:$A$27,$B4)*1*((('Cobertura por asignatura'!$A$4:$A$27<>""))>0),0),0)),0,IF(ISBLANK(INDEX('Cobertura por asignatura'!$D$4:$D$27,MATCH(1,INDEX(EXACT('Cobertura por asignatura'!$A$4:$A$27,$B4)*1*((('Cobertura por asignatura'!$A$4:$A$27<>""))>0),0),0))),"",INDEX('Cobertura por asignatura'!$D$4:$D$27,MATCH(1,INDEX(EXACT('Cobertura por asignatura'!$A$4:$A$27,$B4)*1*((('Cobertura por asignatura'!$A$4:$A$27<>""))>0),0),0)))),IF(ISNA(MATCH(1,INDEX(EXACT('Cobertura por asignatura'!$A$4:$A$27,$B4)*1*((('Cobertura por asignatura'!$A$4:$A$27<>""))>0),0),0)),0,IF(ISBLANK(INDEX('Cobertura por asignatura'!$E$4:$E$27,MATCH(1,INDEX(EXACT('Cobertura por asignatura'!$A$4:$A$27,$B4)*1*((('Cobertura por asignatura'!$A$4:$A$27<>""))>0),0),0))),"",INDEX('Cobertura por asignatura'!$E$4:$E$27,MATCH(1,INDEX(EXACT('Cobertura por asignatura'!$A$4:$A$27,$B4)*1*((('Cobertura por asignatura'!$A$4:$A$27<>""))>0),0),0)))))) | H4: =IF(AND($A4=""),"",IF(ISNA(MATCH(1,INDEX(EXACT('Carga por profesor'!$A$4:$A$27,$E4)*1*((('Carga por profesor'!$A$4:$A$27<>""))>0),0),0)),"",IF(ISBLANK(INDEX('Carga por profesor'!$B$4:$B$27,MATCH(1,INDEX(EXACT('Carga por profesor'!$A$4:$A$27,$E4)*1*((('Carga por profesor'!$A$4:$A$27<>""))>0),0),0))),"",INDEX('Carga por profesor'!$B$4:$B$27,MATCH(1,INDEX(EXACT('Carga por profesor'!$A$4:$A$27,$E4)*1*((('Carga por profesor'!$A$4:$A$27<>""))>0),0),0))))) | I4: =IF(AND($A4=""),"",(IF(ISNUMBER($B4),IF($B4=0,"0",ROUND($B4,9-INT(LOG10(ABS($B4))))&""),$B4&"")&" "&IF(ISNUMBER($C4),IF($C4=0,"0",ROUND($C4,9-INT(LOG10(ABS($C4))))&""),$C4&"")&" "&IF(ISNUMBER($D4),IF($D4=0,"0",ROUND($D4,9-INT(LOG10(ABS($D4))))&""),$D4&""))) | J4: =IF(AND($A4=""),"",IF(OR(($E4=""),($B4="")),"",IF(ISNA(MATCH(1,INDEX(1*((('Asignacion'!$A$4:$A$34<>""))>0)*(EXACT('Asignacion'!$E$4:$E$34,$E4))*(EXACT('Asignacion'!$B$4:$B$34,$B4)),0),0)),"",IF(ISBLANK(INDEX('Asignacion'!$I$4:$I$34,MATCH(1,INDEX(1*((('Asignacion'!$A$4:$A$34<>""))>0)*(EXACT('Asignacion'!$E$4:$E$34,$E4))*(EXACT('Asignacion'!$B$4:$B$34,$B4)),0),0))),"",INDEX('Asignacion'!$I$4:$I$34,MATCH(1,INDEX(1*((('Asignacion'!$A$4:$A$34<>""))>0)*(EXACT('Asignacion'!$E$4:$E$34,$E4))*(EXACT('Asignacion'!$B$4:$B$34,$B4)),0),0)))))) | K4: =IF(AND($A4=""),"",IF(AND(NOT(EXACT($J4,"")),EXACT($J4,$I4)),1,0)) | L4: =IF(AND($A4=""),"",MID(IF(AND(NOT(($B4="")),($E4="")),"; "&"Esta fila de carga todavia no tiene profesor",""),3,32767)) | M4: =IF(OR(AND(NOT(($B4="")),($E4=""))),2,0)
A5: 2 | B5: EST-CC | C5: CP | D5: 1 | E5: PIAD | F5: =IF(AND($A5=""),"",IF(ISNA(MATCH(1,INDEX(EXACT('Cobertura por asignatura'!$A$4:$A$27,$B5)*1*((('Cobertura por asignatura'!$A$4:$A$27<>""))>0),0),0)),"",IF(ISBLANK(INDEX('Cobertura por asignatura'!$B$4:$B$27,MATCH(1,INDEX(EXACT('Cobertura por asignatura'!$A$4:$A$27,$B5)*1*((('Cobertura por asignatura'!$A$4:$A$27<>""))>0),0),0))),"",INDEX('Cobertura por asignatura'!$B$4:$B$27,MATCH(1,INDEX(EXACT('Cobertura por asignatura'!$A$4:$A$27,$B5)*1*((('Cobertura por asignatura'!$A$4:$A$27<>""))>0),0),0))))) | G5: =IF(AND($A5=""),"",IF(EXACT($C5,"Conf"),IF(ISNA(MATCH(1,INDEX(EXACT('Cobertura por asignatura'!$A$4:$A$27,$B5)*1*((('Cobertura por asignatura'!$A$4:$A$27<>""))>0),0),0)),0,IF(ISBLANK(INDEX('Cobertura por asignatura'!$D$4:$D$27,MATCH(1,INDEX(EXACT('Cobertura por asignatura'!$A$4:$A$27,$B5)*1*((('Cobertura por asignatura'!$A$4:$A$27<>""))>0),0),0))),"",INDEX('Cobertura por asignatura'!$D$4:$D$27,MATCH(1,INDEX(EXACT('Cobertura por asignatura'!$A$4:$A$27,$B5)*1*((('Cobertura por asignatura'!$A$4:$A$27<>""))>0),0),0)))),IF(ISNA(MATCH(1,INDEX(EXACT('Cobertura por asignatura'!$A$4:$A$27,$B5)*1*((('Cobertura por asignatura'!$A$4:$A$27<>""))>0),0),0)),0,IF(ISBLANK(INDEX('Cobertura por asignatura'!$E$4:$E$27,MATCH(1,INDEX(EXACT('Cobertura por asignatura'!$A$4:$A$27,$B5)*1*((('Cobertura por asignatura'!$A$4:$A$27<>""))>0),0),0))),"",INDEX('Cobertura por asignatura'!$E$4:$E$27,MATCH(1,INDEX(EXACT('Cobertura por asignatura'!$A$4:$A$27,$B5)*1*((('Cobertura por asignatura'!$A$4:$A$27<>""))>0),0),0)))))) | H5: =IF(AND($A5=""),"",IF(ISNA(MATCH(1,INDEX(EXACT('Carga por profesor'!$A$4:$A$27,$E5)*1*((('Carga por profesor'!$A$4:$A$27<>""))>0),0),0)),"",IF(ISBLANK(INDEX('Carga por profesor'!$B$4:$B$27,MATCH(1,INDEX(EXACT('Carga por profesor'!$A$4:$A$27,$E5)*1*((('Carga por profesor'!$A$4:$A$27<>""))>0),0),0))),"",INDEX('Carga por profesor'!$B$4:$B$27,MATCH(1,INDEX(EXACT('Carga por profesor'!$A$4:$A$27,$E5)*1*((('Carga por profesor'!$A$4:$A$27<>""))>0),0),0))))) | I5: =IF(AND($A5=""),"",(IF(ISNUMBER($B5),IF($B5=0,"0",ROUND($B5,9-INT(LOG10(ABS($B5))))&""),$B5&"")&" "&IF(ISNUMBER($C5),IF($C5=0,"0",ROUND($C5,9-INT(LOG10(ABS($C5))))&""),$C5&"")&" "&IF(ISNUMBER($D5),IF($D5=0,"0",ROUND($D5,9-INT(LOG10(ABS($D5))))&""),$D5&""))) | J5: =IF(AND($A5=""),"",IF(OR(($E5=""),($B5="")),"",IF(ISNA(MATCH(1,INDEX(1*((('Asignacion'!$A$4:$A$34<>""))>0)*(EXACT('Asignacion'!$E$4:$E$34,$E5))*(EXACT('Asignacion'!$B$4:$B$34,$B5)),0),0)),"",IF(ISBLANK(INDEX('Asignacion'!$I$4:$I$34,MATCH(1,INDEX(1*((('Asignacion'!$A$4:$A$34<>""))>0)*(EXACT('Asignacion'!$E$4:$E$34,$E5))*(EXACT('Asignacion'!$B$4:$B$34,$B5)),0),0))),"",INDEX('Asignacion'!$I$4:$I$34,MATCH(1,INDEX(1*((('Asignacion'!$A$4:$A$34<>""))>0)*(EXACT('Asignacion'!$E$4:$E$34,$E5))*(EXACT('Asignacion'!$B$4:$B$34,$B5)),0),0)))))) | K5: =IF(AND($A5=""),"",IF(AND(NOT(EXACT($J5,"")),EXACT($J5,$I5)),1,0)) | L5: =IF(AND($A5=""),"",MID(IF(AND(NOT(($B5="")),($E5="")),"; "&"Esta fila de carga todavia no tiene profesor",""),3,32767)) | M5: =IF(OR(AND(NOT(($B5="")),($E5=""))),2,0)
A6: 3 | B6: EST-CC | C6: CP | D6: 2 | E6: PIAD | F6: =IF(AND($A6=""),"",IF(ISNA(MATCH(1,INDEX(EXACT('Cobertura por asignatura'!$A$4:$A$27,$B6)*1*((('Cobertura por asignatura'!$A$4:$A$27<>""))>0),0),0)),"",IF(ISBLANK(INDEX('Cobertura por asignatura'!$B$4:$B$27,MATCH(1,INDEX(EXACT('Cobertura por asignatura'!$A$4:$A$27,$B6)*1*((('Cobertura por asignatura'!$A$4:$A$27<>""))>0),0),0))),"",INDEX('Cobertura por asignatura'!$B$4:$B$27,MATCH(1,INDEX(EXACT('Cobertura por asignatura'!$A$4:$A$27,$B6)*1*((('Cobertura por asignatura'!$A$4:$A$27<>""))>0),0),0))))) | G6: =IF(AND($A6=""),"",IF(EXACT($C6,"Conf"),IF(ISNA(MATCH(1,INDEX(EXACT('Cobertura por asignatura'!$A$4:$A$27,$B6)*1*((('Cobertura por asignatura'!$A$4:$A$27<>""))>0),0),0)),0,IF(ISBLANK(INDEX('Cobertura por asignatura'!$D$4:$D$27,MATCH(1,INDEX(EXACT('Cobertura por asignatura'!$A$4:$A$27,$B6)*1*((('Cobertura por asignatura'!$A$4:$A$27<>""))>0),0),0))),"",INDEX('Cobertura por asignatura'!$D$4:$D$27,MATCH(1,INDEX(EXACT('Cobertura por asignatura'!$A$4:$A$27,$B6)*1*((('Cobertura por asignatura'!$A$4:$A$27<>""))>0),0),0)))),IF(ISNA(MATCH(1,INDEX(EXACT('Cobertura por asignatura'!$A$4:$A$27,$B6)*1*((('Cobertura por asignatura'!$A$4:$A$27<>""))>0),0),0)),0,IF(ISBLANK(INDEX('Cobertura por asignatura'!$E$4:$E$27,MATCH(1,INDEX(EXACT('Cobertura por asignatura'!$A$4:$A$27,$B6)*1*((('Cobertura por asignatura'!$A$4:$A$27<>""))>0),0),0))),"",INDEX('Cobertura por asignatura'!$E$4:$E$27,MATCH(1,INDEX(EXACT('Cobertura por asignatura'!$A$4:$A$27,$B6)*1*((('Cobertura por asignatura'!$A$4:$A$27<>""))>0),0),0)))))) | H6: =IF(AND($A6=""),"",IF(ISNA(MATCH(1,INDEX(EXACT('Carga por profesor'!$A$4:$A$27,$E6)*1*((('Carga por profesor'!$A$4:$A$27<>""))>0),0),0)),"",IF(ISBLANK(INDEX('Carga por profesor'!$B$4:$B$27,MATCH(1,INDEX(EXACT('Carga por profesor'!$A$4:$A$27,$E6)*1*((('Carga por profesor'!$A$4:$A$27<>""))>0),0),0))),"",INDEX('Carga por profesor'!$B$4:$B$27,MATCH(1,INDEX(EXACT('Carga por profesor'!$A$4:$A$27,$E6)*1*((('Carga por profesor'!$A$4:$A$27<>""))>0),0),0))))) | I6: =IF(AND($A6=""),"",(IF(ISNUMBER($B6),IF($B6=0,"0",ROUND($B6,9-INT(LOG10(ABS($B6))))&""),$B6&"")&" "&IF(ISNUMBER($C6),IF($C6=0,"0",ROUND($C6,9-INT(LOG10(ABS($C6))))&""),$C6&"")&" "&IF(ISNUMBER($D6),IF($D6=0,"0",ROUND($D6,9-INT(LOG10(ABS($D6))))&""),$D6&""))) | J6: =IF(AND($A6=""),"",IF(OR(($E6=""),($B6="")),"",IF(ISNA(MATCH(1,INDEX(1*((('Asignacion'!$A$4:$A$34<>""))>0)*(EXACT('Asignacion'!$E$4:$E$34,$E6))*(EXACT('Asignacion'!$B$4:$B$34,$B6)),0),0)),"",IF(ISBLANK(INDEX('Asignacion'!$I$4:$I$34,MATCH(1,INDEX(1*((('Asignacion'!$A$4:$A$34<>""))>0)*(EXACT('Asignacion'!$E$4:$E$34,$E6))*(EXACT('Asignacion'!$B$4:$B$34,$B6)),0),0))),"",INDEX('Asignacion'!$I$4:$I$34,MATCH(1,INDEX(1*((('Asignacion'!$A$4:$A$34<>""))>0)*(EXACT('Asignacion'!$E$4:$E$34,$E6))*(EXACT('Asignacion'!$B$4:$B$34,$B6)),0),0)))))) | K6: =IF(AND($A6=""),"",IF(AND(NOT(EXACT($J6,"")),EXACT($J6,$I6)),1,0)) | L6: =IF(AND($A6=""),"",MID(IF(AND(NOT(($B6="")),($E6="")),"; "&"Esta fila de carga todavia no tiene profesor",""),3,32767)) | M6: =IF(OR(AND(NOT(($B6="")),($E6=""))),2,0)
A7: 4 | B7: EST-MAT | C7: Conf | E7: PIAD | F7: =IF(AND($A7=""),"",IF(ISNA(MATCH(1,INDEX(EXACT('Cobertura por asignatura'!$A$4:$A$27,$B7)*1*((('Cobertura por asignatura'!$A$4:$A$27<>""))>0),0),0)),"",IF(ISBLANK(INDEX('Cobertura por asignatura'!$B$4:$B$27,MATCH(1,INDEX(EXACT('Cobertura por asignatura'!$A$4:$A$27,$B7)*1*((('Cobertura por asignatura'!$A$4:$A$27<>""))>0),0),0))),"",INDEX('Cobertura por asignatura'!$B$4:$B$27,MATCH(1,INDEX(EXACT('Cobertura por asignatura'!$A$4:$A$27,$B7)*1*((('Cobertura por asignatura'!$A$4:$A$27<>""))>0),0),0))))) | G7: =IF(AND($A7=""),"",IF(EXACT($C7,"Conf"),IF(ISNA(MATCH(1,INDEX(EXACT('Cobertura por asignatura'!$A$4:$A$27,$B7)*1*((('Cobertura por asignatura'!$A$4:$A$27<>""))>0),0),0)),0,IF(ISBLANK(INDEX('Cobertura por asignatura'!$D$4:$D$27,MATCH(1,INDEX(EXACT('Cobertura por asignatura'!$A$4:$A$27,$B7)*1*((('Cobertura por asignatura'!$A$4:$A$27<>""))>0),0),0))),"",INDEX('Cobertura por asignatura'!$D$4:$D$27,MATCH(1,INDEX(EXACT('Cobertura por asignatura'!$A$4:$A$27,$B7)*1*((('Cobertura por asignatura'!$A$4:$A$27<>""))>0),0),0)))),IF(ISNA(MATCH(1,INDEX(EXACT('Cobertura por asignatura'!$A$4:$A$27,$B7)*1*((('Cobertura por asignatura'!$A$4:$A$27<>""))>0),0),0)),0,IF(ISBLANK(INDEX('Cobertura por asignatura'!$E$4:$E$27,MATCH(1,INDEX(EXACT('Cobertura por asignatura'!$A$4:$A$27,$B7)*1*((('Cobertura por asignatura'!$A$4:$A$27<>""))>0),0),0))),"",INDEX('Cobertura por asignatura'!$E$4:$E$27,MATCH(1,INDEX(EXACT('Cobertura por asignatura'!$A$4:$A$27,$B7)*1*((('Cobertura por asignatura'!$A$4:$A$27<>""))>0),0),0)))))) | H7: =IF(AND($A7=""),"",IF(ISNA(MATCH(1,INDEX(EXACT('Carga por profesor'!$A$4:$A$27,$E7)*1*((('Carga por profesor'!$A$4:$A$27<>""))>0),0),0)),"",IF(ISBLANK(INDEX('Carga por profesor'!$B$4:$B$27,MATCH(1,INDEX(EXACT('Carga por profesor'!$A$4:$A$27,$E7)*1*((('Carga por profesor'!$A$4:$A$27<>""))>0),0),0))),"",INDEX('Carga por profesor'!$B$4:$B$27,MATCH(1,INDEX(EXACT('Carga por profesor'!$A$4:$A$27,$E7)*1*((('Carga por profesor'!$A$4:$A$27<>""))>0),0),0))))) | I7: =IF(AND($A7=""),"",(IF(ISNUMBER($B7),IF($B7=0,"0",ROUND($B7,9-INT(LOG10(ABS($B7))))&""),$B7&"")&" "&IF(ISNUMBER($C7),IF($C7=0,"0",ROUND($C7,9-INT(LOG10(ABS($C7))))&""),$C7&"")&" "&IF(ISNUMBER($D7),IF($D7=0,"0",ROUND($D7,9-INT(LOG10(ABS($D7))))&""),$D7&""))) | J7: =IF(AND($A7=""),"",IF(OR(($E7=""),($B7="")),"",IF(ISNA(MATCH(1,INDEX(1*((('Asignacion'!$A$4:$A$34<>""))>0)*(EXACT('Asignacion'!$E$4:$E$34,$E7))*(EXACT('Asignacion'!$B$4:$B$34,$B7)),0),0)),"",IF(ISBLANK(INDEX('Asignacion'!$I$4:$I$34,MATCH(1,INDEX(1*((('Asignacion'!$A$4:$A$34<>""))>0)*(EXACT('Asignacion'!$E$4:$E$34,$E7))*(EXACT('Asignacion'!$B$4:$B$34,$B7)),0),0))),"",INDEX('Asignacion'!$I$4:$I$34,MATCH(1,INDEX(1*((('Asignacion'!$A$4:$A$34<>""))>0)*(EXACT('Asignacion'!$E$4:$E$34,$E7))*(EXACT('Asignacion'!$B$4:$B$34,$B7)),0),0)))))) | K7: =IF(AND($A7=""),"",IF(AND(NOT(EXACT($J7,"")),EXACT($J7,$I7)),1,0)) | L7: =IF(AND($A7=""),"",MID(IF(AND(NOT(($B7="")),($E7="")),"; "&"Esta fila de carga todavia no tiene profesor",""),3,32767)) | M7: =IF(OR(AND(NOT(($B7="")),($E7=""))),2,0)
A8: 5 | B8: EST-MAT | C8: CP | D8: 1 | E8: LUGO | F8: =IF(AND($A8=""),"",IF(ISNA(MATCH(1,INDEX(EXACT('Cobertura por asignatura'!$A$4:$A$27,$B8)*1*((('Cobertura por asignatura'!$A$4:$A$27<>""))>0),0),0)),"",IF(ISBLANK(INDEX('Cobertura por asignatura'!$B$4:$B$27,MATCH(1,INDEX(EXACT('Cobertura por asignatura'!$A$4:$A$27,$B8)*1*((('Cobertura por asignatura'!$A$4:$A$27<>""))>0),0),0))),"",INDEX('Cobertura por asignatura'!$B$4:$B$27,MATCH(1,INDEX(EXACT('Cobertura por asignatura'!$A$4:$A$27,$B8)*1*((('Cobertura por asignatura'!$A$4:$A$27<>""))>0),0),0))))) | G8: =IF(AND($A8=""),"",IF(EXACT($C8,"Conf"),IF(ISNA(MATCH(1,INDEX(EXACT('Cobertura por asignatura'!$A$4:$A$27,$B8)*1*((('Cobertura por asignatura'!$A$4:$A$27<>""))>0),0),0)),0,IF(ISBLANK(INDEX('Cobertura por asignatura'!$D$4:$D$27,MATCH(1,INDEX(EXACT('Cobertura por asignatura'!$A$4:$A$27,$B8)*1*((('Cobertura por asignatura'!$A$4:$A$27<>""))>0),0),0))),"",INDEX('Cobertura por asignatura'!$D$4:$D$27,MATCH(1,INDEX(EXACT('Cobertura por asignatura'!$A$4:$A$27,$B8)*1*((('Cobertura por asignatura'!$A$4:$A$27<>""))>0),0),0)))),IF(ISNA(MATCH(1,INDEX(EXACT('Cobertura por asignatura'!$A$4:$A$27,$B8)*1*((('Cobertura por asignatura'!$A$4:$A$27<>""))>0),0),0)),0,IF(ISBLANK(INDEX('Cobertura por asignatura'!$E$4:$E$27,MATCH(1,INDEX(EXACT('Cobertura por asignatura'!$A$4:$A$27,$B8)*1*((('Cobertura por asignatura'!$A$4:$A$27<>""))>0),0),0))),"",INDEX('Cobertura por asignatura'!$E$4:$E$27,MATCH(1,INDEX(EXACT('Cobertura por asignatura'!$A$4:$A$27,$B8)*1*((('Cobertura por asignatura'!$A$4:$A$27<>""))>0),0),0)))))) | H8: =IF(AND($A8=""),"",IF(ISNA(MATCH(1,INDEX(EXACT('Carga por profesor'!$A$4:$A$27,$E8)*1*((('Carga por profesor'!$A$4:$A$27<>""))>0),0),0)),"",IF(ISBLANK(INDEX('Carga por profesor'!$B$4:$B$27,MATCH(1,INDEX(EXACT('Carga por profesor'!$A$4:$A$27,$E8)*1*((('Carga por profesor'!$A$4:$A$27<>""))>0),0),0))),"",INDEX('Carga por profesor'!$B$4:$B$27,MATCH(1,INDEX(EXACT('Carga por profesor'!$A$4:$A$27,$E8)*1*((('Carga por profesor'!$A$4:$A$27<>""))>0),0),0))))) | I8: =IF(AND($A8=""),"",(IF(ISNUMBER($B8),IF($B8=0,"0",ROUND($B8,9-INT(LOG10(ABS($B8))))&""),$B8&"")&" "&IF(ISNUMBER($C8),IF($C8=0,"0",ROUND($C8,9-INT(LOG10(ABS($C8))))&""),$C8&"")&" "&IF(ISNUMBER($D8),IF($D8=0,"0",ROUND($D8,9-INT(LOG10(ABS($D8))))&""),$D8&""))) | J8: =IF(AND($A8=""),"",IF(OR(($E8=""),($B8="")),"",IF(ISNA(MATCH(1,INDEX(1*((('Asignacion'!$A$4:$A$34<>""))>0)*(EXACT('Asignacion'!$E$4:$E$34,$E8))*(EXACT('Asignacion'!$B$4:$B$34,$B8)),0),0)),"",IF(ISBLANK(INDEX('Asignacion'!$I$4:$I$34,MATCH(1,INDEX(1*((('Asignacion'!$A$4:$A$34<>""))>0)*(EXACT('Asignacion'!$E$4:$E$34,$E8))*(EXACT('Asignacion'!$B$4:$B$34,$B8)),0),0))),"",INDEX('Asignacion'!$I$4:$I$34,MATCH(1,INDEX(1*((('Asignacion'!$A$4:$A$34<>""))>0)*(EXACT('Asignacion'!$E$4:$E$34,$E8))*(EXACT('Asignacion'!$B$4:$B$34,$B8)),0),0)))))) | K8: =IF(AND($A8=""),"",IF(AND(NOT(EXACT($J8,"")),EXACT($J8,$I8)),1,0)) | L8: =IF(AND($A8=""),"",MID(IF(AND(NOT(($B8="")),($E8="")),"; "&"Esta fila de carga todavia no tiene profesor",""),3,32767)) | M8: =IF(OR(AND(NOT(($B8="")),($E8=""))),2,0)
A9: 6 | B9: PROB | C9: Conf | E9: MARA | F9: =IF(AND($A9=""),"",IF(ISNA(MATCH(1,INDEX(EXACT('Cobertura por asignatura'!$A$4:$A$27,$B9)*1*((('Cobertura por asignatura'!$A$4:$A$27<>""))>0),0),0)),"",IF(ISBLANK(INDEX('Cobertura por asignatura'!$B$4:$B$27,MATCH(1,INDEX(EXACT('Cobertura por asignatura'!$A$4:$A$27,$B9)*1*((('Cobertura por asignatura'!$A$4:$A$27<>""))>0),0),0))),"",INDEX('Cobertura por asignatura'!$B$4:$B$27,MATCH(1,INDEX(EXACT('Cobertura por asignatura'!$A$4:$A$27,$B9)*1*((('Cobertura por asignatura'!$A$4:$A$27<>""))>0),0),0))))) | G9: =IF(AND($A9=""),"",IF(EXACT($C9,"Conf"),IF(ISNA(MATCH(1,INDEX(EXACT('Cobertura por asignatura'!$A$4:$A$27,$B9)*1*((('Cobertura por asignatura'!$A$4:$A$27<>""))>0),0),0)),0,IF(ISBLANK(INDEX('Cobertura por asignatura'!$D$4:$D$27,MATCH(1,INDEX(EXACT('Cobertura por asignatura'!$A$4:$A$27,$B9)*1*((('Cobertura por asignatura'!$A$4:$A$27<>""))>0),0),0))),"",INDEX('Cobertura por asignatura'!$D$4:$D$27,MATCH(1,INDEX(EXACT('Cobertura por asignatura'!$A$4:$A$27,$B9)*1*((('Cobertura por asignatura'!$A$4:$A$27<>""))>0),0),0)))),IF(ISNA(MATCH(1,INDEX(EXACT('Cobertura por asignatura'!$A$4:$A$27,$B9)*1*((('Cobertura por asignatura'!$A$4:$A$27<>""))>0),0),0)),0,IF(ISBLANK(INDEX('Cobertura por asignatura'!$E$4:$E$27,MATCH(1,INDEX(EXACT('Cobertura por asignatura'!$A$4:$A$27,$B9)*1*((('Cobertura por asignatura'!$A$4:$A$27<>""))>0),0),0))),"",INDEX('Cobertura por asignatura'!$E$4:$E$27,MATCH(1,INDEX(EXACT('Cobertura por asignatura'!$A$4:$A$27,$B9)*1*((('Cobertura por asignatura'!$A$4:$A$27<>""))>0),0),0)))))) | H9: =IF(AND($A9=""),"",IF(ISNA(MATCH(1,INDEX(EXACT('Carga por profesor'!$A$4:$A$27,$E9)*1*((('Carga por profesor'!$A$4:$A$27<>""))>0),0),0)),"",IF(ISBLANK(INDEX('Carga por profesor'!$B$4:$B$27,MATCH(1,INDEX(EXACT('Carga por profesor'!$A$4:$A$27,$E9)*1*((('Carga por profesor'!$A$4:$A$27<>""))>0),0),0))),"",INDEX('Carga por profesor'!$B$4:$B$27,MATCH(1,INDEX(EXACT('Carga por profesor'!$A$4:$A$27,$E9)*1*((('Carga por profesor'!$A$4:$A$27<>""))>0),0),0))))) | I9: =IF(AND($A9=""),"",(IF(ISNUMBER($B9),IF($B9=0,"0",ROUND($B9,9-INT(LOG10(ABS($B9))))&""),$B9&"")&" "&IF(ISNUMBER($C9),IF($C9=0,"0",ROUND($C9,9-INT(LOG10(ABS($C9))))&""),$C9&"")&" "&IF(ISNUMBER($D9),IF($D9=0,"0",ROUND($D9,9-INT(LOG10(ABS($D9))))&""),$D9&""))) | J9: =IF(AND($A9=""),"",IF(OR(($E9=""),($B9="")),"",IF(ISNA(MATCH(1,INDEX(1*((('Asignacion'!$A$4:$A$34<>""))>0)*(EXACT('Asignacion'!$E$4:$E$34,$E9))*(EXACT('Asignacion'!$B$4:$B$34,$B9)),0),0)),"",IF(ISBLANK(INDEX('Asignacion'!$I$4:$I$34,MATCH(1,INDEX(1*((('Asignacion'!$A$4:$A$34<>""))>0)*(EXACT('Asignacion'!$E$4:$E$34,$E9))*(EXACT('Asignacion'!$B$4:$B$34,$B9)),0),0))),"",INDEX('Asignacion'!$I$4:$I$34,MATCH(1,INDEX(1*((('Asignacion'!$A$4:$A$34<>""))>0)*(EXACT('Asignacion'!$E$4:$E$34,$E9))*(EXACT('Asignacion'!$B$4:$B$34,$B9)),0),0)))))) | K9: =IF(AND($A9=""),"",IF(AND(NOT(EXACT($J9,"")),EXACT($J9,$I9)),1,0)) | L9: =IF(AND($A9=""),"",MID(IF(AND(NOT(($B9="")),($E9="")),"; "&"Esta fila de carga todavia no tiene profesor",""),3,32767)) | M9: =IF(OR(AND(NOT(($B9="")),($E9=""))),2,0)
A10: 7 | B10: PROB | C10: CP | D10: 1 | E10: MARA | F10: =IF(AND($A10=""),"",IF(ISNA(MATCH(1,INDEX(EXACT('Cobertura por asignatura'!$A$4:$A$27,$B10)*1*((('Cobertura por asignatura'!$A$4:$A$27<>""))>0),0),0)),"",IF(ISBLANK(INDEX('Cobertura por asignatura'!$B$4:$B$27,MATCH(1,INDEX(EXACT('Cobertura por asignatura'!$A$4:$A$27,$B10)*1*((('Cobertura por asignatura'!$A$4:$A$27<>""))>0),0),0))),"",INDEX('Cobertura por asignatura'!$B$4:$B$27,MATCH(1,INDEX(EXACT('Cobertura por asignatura'!$A$4:$A$27,$B10)*1*((('Cobertura por asignatura'!$A$4:$A$27<>""))>0),0),0))))) | G10: =IF(AND($A10=""),"",IF(EXACT($C10,"Conf"),IF(ISNA(MATCH(1,INDEX(EXACT('Cobertura por asignatura'!$A$4:$A$27,$B10)*1*((('Cobertura por asignatura'!$A$4:$A$27<>""))>0),0),0)),0,IF(ISBLANK(INDEX('Cobertura por asignatura'!$D$4:$D$27,MATCH(1,INDEX(EXACT('Cobertura por asignatura'!$A$4:$A$27,$B10)*1*((('Cobertura por asignatura'!$A$4:$A$27<>""))>0),0),0))),"",INDEX('Cobertura por asignatura'!$D$4:$D$27,MATCH(1,INDEX(EXACT('Cobertura por asignatura'!$A$4:$A$27,$B10)*1*((('Cobertura por asignatura'!$A$4:$A$27<>""))>0),0),0)))),IF(ISNA(MATCH(1,INDEX(EXACT('Cobertura por asignatura'!$A$4:$A$27,$B10)*1*((('Cobertura por asignatura'!$A$4:$A$27<>""))>0),0),0)),0,IF(ISBLANK(INDEX('Cobertura por asignatura'!$E$4:$E$27,MATCH(1,INDEX(EXACT('Cobertura por asignatura'!$A$4:$A$27,$B10)*1*((('Cobertura por asignatura'!$A$4:$A$27<>""))>0),0),0))),"",INDEX('Cobertura por asignatura'!$E$4:$E$27,MATCH(1,INDEX(EXACT('Cobertura por asignatura'!$A$4:$A$27,$B10)*1*((('Cobertura por asignatura'!$A$4:$A$27<>""))>0),0),0)))))) | H10: =IF(AND($A10=""),"",IF(ISNA(MATCH(1,INDEX(EXACT('Carga por profesor'!$A$4:$A$27,$E10)*1*((('Carga por profesor'!$A$4:$A$27<>""))>0),0),0)),"",IF(ISBLANK(INDEX('Carga por profesor'!$B$4:$B$27,MATCH(1,INDEX(EXACT('Carga por profesor'!$A$4:$A$27,$E10)*1*((('Carga por profesor'!$A$4:$A$27<>""))>0),0),0))),"",INDEX('Carga por profesor'!$B$4:$B$27,MATCH(1,INDEX(EXACT('Carga por profesor'!$A$4:$A$27,$E10)*1*((('Carga por profesor'!$A$4:$A$27<>""))>0),0),0))))) | I10: =IF(AND($A10=""),"",(IF(ISNUMBER($B10),IF($B10=0,"0",ROUND($B10,9-INT(LOG10(ABS($B10))))&""),$B10&"")&" "&IF(ISNUMBER($C10),IF($C10=0,"0",ROUND($C10,9-INT(LOG10(ABS($C10))))&""),$C10&"")&" "&IF(ISNUMBER($D10),IF($D10=0,"0",ROUND($D10,9-INT(LOG10(ABS($D10))))&""),$D10&""))) | J10: =IF(AND($A10=""),"",IF(OR(($E10=""),($B10="")),"",IF(ISNA(MATCH(1,INDEX(1*((('Asignacion'!$A$4:$A$34<>""))>0)*(EXACT('Asignacion'!$E$4:$E$34,$E10))*(EXACT('Asignacion'!$B$4:$B$34,$B10)),0),0)),"",IF(ISBLANK(INDEX('Asignacion'!$I$4:$I$34,MATCH(1,INDEX(1*((('Asignacion'!$A$4:$A$34<>""))>0)*(EXACT('Asignacion'!$E$4:$E$34,$E10))*(EXACT('Asignacion'!$B$4:$B$34,$B10)),0),0))),"",INDEX('Asignacion'!$I$4:$I$34,MATCH(1,INDEX(1*((('Asignacion'!$A$4:$A$34<>""))>0)*(EXACT('Asignacion'!$E$4:$E$34,$E10))*(EXACT('Asignacion'!$B$4:$B$34,$B10)),0),0)))))) | K10: =IF(AND($A10=""),"",IF(AND(NOT(EXACT($J10,"")),EXACT($J10,$I10)),1,0)) | L10: =IF(AND($A10=""),"",MID(IF(AND(NOT(($B10="")),($E10="")),"; "&"Esta fila de carga todavia no tiene profesor",""),3,32767)) | M10: =IF(OR(AND(NOT(($B10="")),($E10=""))),2,0)
A11: 8 | B11: PROB | C11: CP | D11: 2 | F11: =IF(AND($A11=""),"",IF(ISNA(MATCH(1,INDEX(EXACT('Cobertura por asignatura'!$A$4:$A$27,$B11)*1*((('Cobertura por asignatura'!$A$4:$A$27<>""))>0),0),0)),"",IF(ISBLANK(INDEX('Cobertura por asignatura'!$B$4:$B$27,MATCH(1,INDEX(EXACT('Cobertura por asignatura'!$A$4:$A$27,$B11)*1*((('Cobertura por asignatura'!$A$4:$A$27<>""))>0),0),0))),"",INDEX('Cobertura por asignatura'!$B$4:$B$27,MATCH(1,INDEX(EXACT('Cobertura por asignatura'!$A$4:$A$27,$B11)*1*((('Cobertura por asignatura'!$A$4:$A$27<>""))>0),0),0))))) | G11: =IF(AND($A11=""),"",IF(EXACT($C11,"Conf"),IF(ISNA(MATCH(1,INDEX(EXACT('Cobertura por asignatura'!$A$4:$A$27,$B11)*1*((('Cobertura por asignatura'!$A$4:$A$27<>""))>0),0),0)),0,IF(ISBLANK(INDEX('Cobertura por asignatura'!$D$4:$D$27,MATCH(1,INDEX(EXACT('Cobertura por asignatura'!$A$4:$A$27,$B11)*1*((('Cobertura por asignatura'!$A$4:$A$27<>""))>0),0),0))),"",INDEX('Cobertura por asignatura'!$D$4:$D$27,MATCH(1,INDEX(EXACT('Cobertura por asignatura'!$A$4:$A$27,$B11)*1*((('Cobertura por asignatura'!$A$4:$A$27<>""))>0),0),0)))),IF(ISNA(MATCH(1,INDEX(EXACT('Cobertura por asignatura'!$A$4:$A$27,$B11)*1*((('Cobertura por asignatura'!$A$4:$A$27<>""))>0),0),0)),0,IF(ISBLANK(INDEX('Cobertura por asignatura'!$E$4:$E$27,MATCH(1,INDEX(EXACT('Cobertura por asignatura'!$A$4:$A$27,$B11)*1*((('Cobertura por asignatura'!$A$4:$A$27<>""))>0),0),0))),"",INDEX('Cobertura por asignatura'!$E$4:$E$27,MATCH(1,INDEX(EXACT('Cobertura por asignatura'!$A$4:$A$27,$B11)*1*((('Cobertura por asignatura'!$A$4:$A$27<>""))>0),0),0)))))) | H11: =IF(AND($A11=""),"",IF(ISNA(MATCH(1,INDEX(EXACT('Carga por profesor'!$A$4:$A$27,$E11)*1*((('Carga por profesor'!$A$4:$A$27<>""))>0),0),0)),"",IF(ISBLANK(INDEX('Carga por profesor'!$B$4:$B$27,MATCH(1,INDEX(EXACT('Carga por profesor'!$A$4:$A$27,$E11)*1*((('Carga por profesor'!$A$4:$A$27<>""))>0),0),0))),"",INDEX('Carga por profesor'!$B$4:$B$27,MATCH(1,INDEX(EXACT('Carga por profesor'!$A$4:$A$27,$E11)*1*((('Carga por profesor'!$A$4:$A$27<>""))>0),0),0))))) | I11: =IF(AND($A11=""),"",(IF(ISNUMBER($B11),IF($B11=0,"0",ROUND($B11,9-INT(LOG10(ABS($B11))))&""),$B11&"")&" "&IF(ISNUMBER($C11),IF($C11=0,"0",ROUND($C11,9-INT(LOG10(ABS($C11))))&""),$C11&"")&" "&IF(ISNUMBER($D11),IF($D11=0,"0",ROUND($D11,9-INT(LOG10(ABS($D11))))&""),$D11&""))) | J11: =IF(AND($A11=""),"",IF(OR(($E11=""),($B11="")),"",IF(ISNA(MATCH(1,INDEX(1*((('Asignacion'!$A$4:$A$34<>""))>0)*(EXACT('Asignacion'!$E$4:$E$34,$E11))*(EXACT('Asignacion'!$B$4:$B$34,$B11)),0),0)),"",IF(ISBLANK(INDEX('Asignacion'!$I$4:$I$34,MATCH(1,INDEX(1*((('Asignacion'!$A$4:$A$34<>""))>0)*(EXACT('Asignacion'!$E$4:$E$34,$E11))*(EXACT('Asignacion'!$B$4:$B$34,$B11)),0),0))),"",INDEX('Asignacion'!$I$4:$I$34,MATCH(1,INDEX(1*((('Asignacion'!$A$4:$A$34<>""))>0)*(EXACT('Asignacion'!$E$4:$E$34,$E11))*(EXACT('Asignacion'!$B$4:$B$34,$B11)),0),0)))))) | K11: =IF(AND($A11=""),"",IF(AND(NOT(EXACT($J11,"")),EXACT($J11,$I11)),1,0)) | L11: =IF(AND($A11=""),"",MID(IF(AND(NOT(($B11="")),($E11="")),"; "&"Esta fila de carga todavia no tiene profesor",""),3,32767)) | M11: =IF(OR(AND(NOT(($B11="")),($E11=""))),2,0)
A12: 9 | B12: MNUM | C12: Conf | E12: MARA | F12: =IF(AND($A12=""),"",IF(ISNA(MATCH(1,INDEX(EXACT('Cobertura por asignatura'!$A$4:$A$27,$B12)*1*((('Cobertura por asignatura'!$A$4:$A$27<>""))>0),0),0)),"",IF(ISBLANK(INDEX('Cobertura por asignatura'!$B$4:$B$27,MATCH(1,INDEX(EXACT('Cobertura por asignatura'!$A$4:$A$27,$B12)*1*((('Cobertura por asignatura'!$A$4:$A$27<>""))>0),0),0))),"",INDEX('Cobertura por asignatura'!$B$4:$B$27,MATCH(1,INDEX(EXACT('Cobertura por asignatura'!$A$4:$A$27,$B12)*1*((('Cobertura por asignatura'!$A$4:$A$27<>""))>0),0),0))))) | G12: =IF(AND($A12=""),"",IF(EXACT($C12,"Conf"),IF(ISNA(MATCH(1,INDEX(EXACT('Cobertura por asignatura'!$A$4:$A$27,$B12)*1*((('Cobertura por asignatura'!$A$4:$A$27<>""))>0),0),0)),0,IF(ISBLANK(INDEX('Cobertura por asignatura'!$D$4:$D$27,MATCH(1,INDEX(EXACT('Cobertura por asignatura'!$A$4:$A$27,$B12)*1*((('Cobertura por asignatura'!$A$4:$A$27<>""))>0),0),0))),"",INDEX('Cobertura por asignatura'!$D$4:$D$27,MATCH(1,INDEX(EXACT('Cobertura por asignatura'!$A$4:$A$27,$B12)*1*((('Cobertura por asignatura'!$A$4:$A$27<>""))>0),0),0)))),IF(ISNA(MATCH(1,INDEX(EXACT('Cobertura por asignatura'!$A$4:$A$27,$B12)*1*((('Cobertura por asignatura'!$A$4:$A$27<>""))>0),0),0)),0,IF(ISBLANK(INDEX('Cobertura por asignatura'!$E$4:$E$27,MATCH(1,INDEX(EXACT('Cobertura por asignatura'!$A$4:$A$27,$B12)*1*((('Cobertura por asignatura'!$A$4:$A$27<>""))>0),0),0))),"",INDEX('Cobertura por asignatura'!$E$4:$E$27,MATCH(1,INDEX(EXACT('Cobertura por asignatura'!$A$4:$A$27,$B12)*1*((('Cobertura por asignatura'!$A$4:$A$27<>""))>0),0),0)))))) | H12: =IF(AND($A12=""),"",IF(ISNA(MATCH(1,INDEX(EXACT('Carga por profesor'!$A$4:$A$27,$E12)*1*((('Carga por profesor'!$A$4:$A$27<>""))>0),0),0)),"",IF(ISBLANK(INDEX('Carga por profesor'!$B$4:$B$27,MATCH(1,INDEX(EXACT('Carga por profesor'!$A$4:$A$27,$E12)*1*((('Carga por profesor'!$A$4:$A$27<>""))>0),0),0))),"",INDEX('Carga por profesor'!$B$4:$B$27,MATCH(1,INDEX(EXACT('Carga por profesor'!$A$4:$A$27,$E12)*1*((('Carga por profesor'!$A$4:$A$27<>""))>0),0),0))))) | I12: =IF(AND($A12=""),"",(IF(ISNUMBER($B12),IF($B12=0,"0",ROUND($B12,9-INT(LOG10(ABS($B12))))&""),$B12&"")&" "&IF(ISNUMBER($C12),IF($C12=0,"0",ROUND($C12,9-INT(LOG10(ABS($C12))))&""),$C12&"")&" "&IF(ISNUMBER($D12),IF($D12=0,"0",ROUND($D12,9-INT(LOG10(ABS($D12))))&""),$D12&""))) | J12: =IF(AND($A12=""),"",IF(OR(($E12=""),($B12="")),"",IF(ISNA(MATCH(1,INDEX(1*((('Asignacion'!$A$4:$A$34<>""))>0)*(EXACT('Asignacion'!$E$4:$E$34,$E12))*(EXACT('Asignacion'!$B$4:$B$34,$B12)),0),0)),"",IF(ISBLANK(INDEX('Asignacion'!$I$4:$I$34,MATCH(1,INDEX(1*((('Asignacion'!$A$4:$A$34<>""))>0)*(EXACT('Asignacion'!$E$4:$E$34,$E12))*(EXACT('Asignacion'!$B$4:$B$34,$B12)),0),0))),"",INDEX('Asignacion'!$I$4:$I$34,MATCH(1,INDEX(1*((('Asignacion'!$A$4:$A$34<>""))>0)*(EXACT('Asignacion'!$E$4:$E$34,$E12))*(EXACT('Asignacion'!$B$4:$B$34,$B12)),0),0)))))) | K12: =IF(AND($A12=""),"",IF(AND(NOT(EXACT($J12,"")),EXACT($J12,$I12)),1,0)) | L12: =IF(AND($A12=""),"",MID(IF(AND(NOT(($B12="")),($E12="")),"; "&"Esta fila de carga todavia no tiene profesor",""),3,32767)) | M12: =IF(OR(AND(NOT(($B12="")),($E12=""))),2,0)
A13: 10 | F13: =IF(AND($A13=""),"",IF(ISNA(MATCH(1,INDEX(EXACT('Cobertura por asignatura'!$A$4:$A$27,$B13)*1*((('Cobertura por asignatura'!$A$4:$A$27<>""))>0),0),0)),"",IF(ISBLANK(INDEX('Cobertura por asignatura'!$B$4:$B$27,MATCH(1,INDEX(EXACT('Cobertura por asignatura'!$A$4:$A$27,$B13)*1*((('Cobertura por asignatura'!$A$4:$A$27<>""))>0),0),0))),"",INDEX('Cobertura por asignatura'!$B$4:$B$27,MATCH(1,INDEX(EXACT('Cobertura por asignatura'!$A$4:$A$27,$B13)*1*((('Cobertura por asignatura'!$A$4:$A$27<>""))>0),0),0))))) | G13: =IF(AND($A13=""),"",IF(EXACT($C13,"Conf"),IF(ISNA(MATCH(1,INDEX(EXACT('Cobertura por asignatura'!$A$4:$A$27,$B13)*1*((('Cobertura por asignatura'!$A$4:$A$27<>""))>0),0),0)),0,IF(ISBLANK(INDEX('Cobertura por asignatura'!$D$4:$D$27,MATCH(1,INDEX(EXACT('Cobertura por asignatura'!$A$4:$A$27,$B13)*1*((('Cobertura por asignatura'!$A$4:$A$27<>""))>0),0),0))),"",INDEX('Cobertura por asignatura'!$D$4:$D$27,MATCH(1,INDEX(EXACT('Cobertura por asignatura'!$A$4:$A$27,$B13)*1*((('Cobertura por asignatura'!$A$4:$A$27<>""))>0),0),0)))),IF(ISNA(MATCH(1,INDEX(EXACT('Cobertura por asignatura'!$A$4:$A$27,$B13)*1*((('Cobertura por asignatura'!$A$4:$A$27<>""))>0),0),0)),0,IF(ISBLANK(INDEX('Cobertura por asignatura'!$E$4:$E$27,MATCH(1,INDEX(EXACT('Cobertura por asignatura'!$A$4:$A$27,$B13)*1*((('Cobertura por asignatura'!$A$4:$A$27<>""))>0),0),0))),"",INDEX('Cobertura por asignatura'!$E$4:$E$27,MATCH(1,INDEX(EXACT('Cobertura por asignatura'!$A$4:$A$27,$B13)*1*((('Cobertura por asignatura'!$A$4:$A$27<>""))>0),0),0)))))) | H13: =IF(AND($A13=""),"",IF(ISNA(MATCH(1,INDEX(EXACT('Carga por profesor'!$A$4:$A$27,$E13)*1*((('Carga por profesor'!$A$4:$A$27<>""))>0),0),0)),"",IF(ISBLANK(INDEX('Carga por profesor'!$B$4:$B$27,MATCH(1,INDEX(EXACT('Carga por profesor'!$A$4:$A$27,$E13)*1*((('Carga por profesor'!$A$4:$A$27<>""))>0),0),0))),"",INDEX('Carga por profesor'!$B$4:$B$27,MATCH(1,INDEX(EXACT('Carga por profesor'!$A$4:$A$27,$E13)*1*((('Carga por profesor'!$A$4:$A$27<>""))>0),0),0))))) | I13: =IF(AND($A13=""),"",(IF(ISNUMBER($B13),IF($B13=0,"0",ROUND($B13,9-INT(LOG10(ABS($B13))))&""),$B13&"")&" "&IF(ISNUMBER($C13),IF($C13=0,"0",ROUND($C13,9-INT(LOG10(ABS($C13))))&""),$C13&"")&" "&IF(ISNUMBER($D13),IF($D13=0,"0",ROUND($D13,9-INT(LOG10(ABS($D13))))&""),$D13&""))) | J13: =IF(AND($A13=""),"",IF(OR(($E13=""),($B13="")),"",IF(ISNA(MATCH(1,INDEX(1*((('Asignacion'!$A$4:$A$34<>""))>0)*(EXACT('Asignacion'!$E$4:$E$34,$E13))*(EXACT('Asignacion'!$B$4:$B$34,$B13)),0),0)),"",IF(ISBLANK(INDEX('Asignacion'!$I$4:$I$34,MATCH(1,INDEX(1*((('Asignacion'!$A$4:$A$34<>""))>0)*(EXACT('Asignacion'!$E$4:$E$34,$E13))*(EXACT('Asignacion'!$B$4:$B$34,$B13)),0),0))),"",INDEX('Asignacion'!$I$4:$I$34,MATCH(1,INDEX(1*((('Asignacion'!$A$4:$A$34<>""))>0)*(EXACT('Asignacion'!$E$4:$E$34,$E13))*(EXACT('Asignacion'!$B$4:$B$34,$B13)),0),0)))))) | K13: =IF(AND($A13=""),"",IF(AND(NOT(EXACT($J13,"")),EXACT($J13,$I13)),1,0)) | L13: =IF(AND($A13=""),"",MID(IF(AND(NOT(($B13="")),($E13="")),"; "&"Esta fila de carga todavia no tiene profesor",""),3,32767)) | M13: =IF(OR(AND(NOT(($B13="")),($E13=""))),2,0)
A14: 11 | F14: =IF(AND($A14=""),"",IF(ISNA(MATCH(1,INDEX(EXACT('Cobertura por asignatura'!$A$4:$A$27,$B14)*1*((('Cobertura por asignatura'!$A$4:$A$27<>""))>0),0),0)),"",IF(ISBLANK(INDEX('Cobertura por asignatura'!$B$4:$B$27,MATCH(1,INDEX(EXACT('Cobertura por asignatura'!$A$4:$A$27,$B14)*1*((('Cobertura por asignatura'!$A$4:$A$27<>""))>0),0),0))),"",INDEX('Cobertura por asignatura'!$B$4:$B$27,MATCH(1,INDEX(EXACT('Cobertura por asignatura'!$A$4:$A$27,$B14)*1*((('Cobertura por asignatura'!$A$4:$A$27<>""))>0),0),0))))) | G14: =IF(AND($A14=""),"",IF(EXACT($C14,"Conf"),IF(ISNA(MATCH(1,INDEX(EXACT('Cobertura por asignatura'!$A$4:$A$27,$B14)*1*((('Cobertura por asignatura'!$A$4:$A$27<>""))>0),0),0)),0,IF(ISBLANK(INDEX('Cobertura por asignatura'!$D$4:$D$27,MATCH(1,INDEX(EXACT('Cobertura por asignatura'!$A$4:$A$27,$B14)*1*((('Cobertura por asignatura'!$A$4:$A$27<>""))>0),0),0))),"",INDEX('Cobertura por asignatura'!$D$4:$D$27,MATCH(1,INDEX(EXACT('Cobertura por asignatura'!$A$4:$A$27,$B14)*1*((('Cobertura por asignatura'!$A$4:$A$27<>""))>0),0),0)))),IF(ISNA(MATCH(1,INDEX(EXACT('Cobertura por asignatura'!$A$4:$A$27,$B14)*1*((('Cobertura por asignatura'!$A$4:$A$27<>""))>0),0),0)),0,IF(ISBLANK(INDEX('Cobertura por asignatura'!$E$4:$E$27,MATCH(1,INDEX(EXACT('Cobertura por asignatura'!$A$4:$A$27,$B14)*1*((('Cobertura por asignatura'!$A$4:$A$27<>""))>0),0),0))),"",INDEX('Cobertura por asignatura'!$E$4:$E$27,MATCH(1,INDEX(EXACT('Cobertura por asignatura'!$A$4:$A$27,$B14)*1*((('Cobertura por asignatura'!$A$4:$A$27<>""))>0),0),0)))))) | H14: =IF(AND($A14=""),"",IF(ISNA(MATCH(1,INDEX(EXACT('Carga por profesor'!$A$4:$A$27,$E14)*1*((('Carga por profesor'!$A$4:$A$27<>""))>0),0),0)),"",IF(ISBLANK(INDEX('Carga por profesor'!$B$4:$B$27,MATCH(1,INDEX(EXACT('Carga por profesor'!$A$4:$A$27,$E14)*1*((('Carga por profesor'!$A$4:$A$27<>""))>0),0),0))),"",INDEX('Carga por profesor'!$B$4:$B$27,MATCH(1,INDEX(EXACT('Carga por profesor'!$A$4:$A$27,$E14)*1*((('Carga por profesor'!$A$4:$A$27<>""))>0),0),0))))) | I14: =IF(AND($A14=""),"",(IF(ISNUMBER($B14),IF($B14=0,"0",ROUND($B14,9-INT(LOG10(ABS($B14))))&""),$B14&"")&" "&IF(ISNUMBER($C14),IF($C14=0,"0",ROUND($C14,9-INT(LOG10(ABS($C14))))&""),$C14&"")&" "&IF(ISNUMBER($D14),IF($D14=0,"0",ROUND($D14,9-INT(LOG10(ABS($D14))))&""),$D14&""))) | J14: =IF(AND($A14=""),"",IF(OR(($E14=""),($B14="")),"",IF(ISNA(MATCH(1,INDEX(1*((('Asignacion'!$A$4:$A$34<>""))>0)*(EXACT('Asignacion'!$E$4:$E$34,$E14))*(EXACT('Asignacion'!$B$4:$B$34,$B14)),0),0)),"",IF(ISBLANK(INDEX('Asignacion'!$I$4:$I$34,MATCH(1,INDEX(1*((('Asignacion'!$A$4:$A$34<>""))>0)*(EXACT('Asignacion'!$E$4:$E$34,$E14))*(EXACT('Asignacion'!$B$4:$B$34,$B14)),0),0))),"",INDEX('Asignacion'!$I$4:$I$34,MATCH(1,INDEX(1*((('Asignacion'!$A$4:$A$34<>""))>0)*(EXACT('Asignacion'!$E$4:$E$34,$E14))*(EXACT('Asignacion'!$B$4:$B$34,$B14)),0),0)))))) | K14: =IF(AND($A14=""),"",IF(AND(NOT(EXACT($J14,"")),EXACT($J14,$I14)),1,0)) | L14: =IF(AND($A14=""),"",MID(IF(AND(NOT(($B14="")),($E14="")),"; "&"Esta fila de carga todavia no tiene profesor",""),3,32767)) | M14: =IF(OR(AND(NOT(($B14="")),($E14=""))),2,0)
F15: =IF(AND($A15=""),"",IF(ISNA(MATCH(1,INDEX(EXACT('Cobertura por asignatura'!$A$4:$A$27,$B15)*1*((('Cobertura por asignatura'!$A$4:$A$27<>""))>0),0),0)),"",IF(ISBLANK(INDEX('Cobertura por asignatura'!$B$4:$B$27,MATCH(1,INDEX(EXACT('Cobertura por asignatura'!$A$4:$A$27,$B15)*1*((('Cobertura por asignatura'!$A$4:$A$27<>""))>0),0),0))),"",INDEX('Cobertura por asignatura'!$B$4:$B$27,MATCH(1,INDEX(EXACT('Cobertura por asignatura'!$A$4:$A$27,$B15)*1*((('Cobertura por asignatura'!$A$4:$A$27<>""))>0),0),0))))) | G15: =IF(AND($A15=""),"",IF(EXACT($C15,"Conf"),IF(ISNA(MATCH(1,INDEX(EXACT('Cobertura por asignatura'!$A$4:$A$27,$B15)*1*((('Cobertura por asignatura'!$A$4:$A$27<>""))>0),0),0)),0,IF(ISBLANK(INDEX('Cobertura por asignatura'!$D$4:$D$27,MATCH(1,INDEX(EXACT('Cobertura por asignatura'!$A$4:$A$27,$B15)*1*((('Cobertura por asignatura'!$A$4:$A$27<>""))>0),0),0))),"",INDEX('Cobertura por asignatura'!$D$4:$D$27,MATCH(1,INDEX(EXACT('Cobertura por asignatura'!$A$4:$A$27,$B15)*1*((('Cobertura por asignatura'!$A$4:$A$27<>""))>0),0),0)))),IF(ISNA(MATCH(1,INDEX(EXACT('Cobertura por asignatura'!$A$4:$A$27,$B15)*1*((('Cobertura por asignatura'!$A$4:$A$27<>""))>0),0),0)),0,IF(ISBLANK(INDEX('Cobertura por asignatura'!$E$4:$E$27,MATCH(1,INDEX(EXACT('Cobertura por asignatura'!$A$4:$A$27,$B15)*1*((('Cobertura por asignatura'!$A$4:$A$27<>""))>0),0),0))),"",INDEX('Cobertura por asignatura'!$E$4:$E$27,MATCH(1,INDEX(EXACT('Cobertura por asignatura'!$A$4:$A$27,$B15)*1*((('Cobertura por asignatura'!$A$4:$A$27<>""))>0),0),0)))))) | H15: =IF(AND($A15=""),"",IF(ISNA(MATCH(1,INDEX(EXACT('Carga por profesor'!$A$4:$A$27,$E15)*1*((('Carga por profesor'!$A$4:$A$27<>""))>0),0),0)),"",IF(ISBLANK(INDEX('Carga por profesor'!$B$4:$B$27,MATCH(1,INDEX(EXACT('Carga por profesor'!$A$4:$A$27,$E15)*1*((('Carga por profesor'!$A$4:$A$27<>""))>0),0),0))),"",INDEX('Carga por profesor'!$B$4:$B$27,MATCH(1,INDEX(EXACT('Carga por profesor'!$A$4:$A$27,$E15)*1*((('Carga por profesor'!$A$4:$A$27<>""))>0),0),0))))) | I15: =IF(AND($A15=""),"",(IF(ISNUMBER($B15),IF($B15=0,"0",ROUND($B15,9-INT(LOG10(ABS($B15))))&""),$B15&"")&" "&IF(ISNUMBER($C15),IF($C15=0,"0",ROUND($C15,9-INT(LOG10(ABS($C15))))&""),$C15&"")&" "&IF(ISNUMBER($D15),IF($D15=0,"0",ROUND($D15,9-INT(LOG10(ABS($D15))))&""),$D15&""))) | J15: =IF(AND($A15=""),"",IF(OR(($E15=""),($B15="")),"",IF(ISNA(MATCH(1,INDEX(1*((('Asignacion'!$A$4:$A$34<>""))>0)*(EXACT('Asignacion'!$E$4:$E$34,$E15))*(EXACT('Asignacion'!$B$4:$B$34,$B15)),0),0)),"",IF(ISBLANK(INDEX('Asignacion'!$I$4:$I$34,MATCH(1,INDEX(1*((('Asignacion'!$A$4:$A$34<>""))>0)*(EXACT('Asignacion'!$E$4:$E$34,$E15))*(EXACT('Asignacion'!$B$4:$B$34,$B15)),0),0))),"",INDEX('Asignacion'!$I$4:$I$34,MATCH(1,INDEX(1*((('Asignacion'!$A$4:$A$34<>""))>0)*(EXACT('Asignacion'!$E$4:$E$34,$E15))*(EXACT('Asignacion'!$B$4:$B$34,$B15)),0),0)))))) | K15: =IF(AND($A15=""),"",IF(AND(NOT(EXACT($J15,"")),EXACT($J15,$I15)),1,0)) | L15: =IF(AND($A15=""),"",MID(IF(AND(NOT(($B15="")),($E15="")),"; "&"Esta fila de carga todavia no tiene profesor",""),3,32767)) | M15: =IF(OR(AND(NOT(($B15="")),($E15=""))),2,0)
F16: =IF(AND($A16=""),"",IF(ISNA(MATCH(1,INDEX(EXACT('Cobertura por asignatura'!$A$4:$A$27,$B16)*1*((('Cobertura por asignatura'!$A$4:$A$27<>""))>0),0),0)),"",IF(ISBLANK(INDEX('Cobertura por asignatura'!$B$4:$B$27,MATCH(1,INDEX(EXACT('Cobertura por asignatura'!$A$4:$A$27,$B16)*1*((('Cobertura por asignatura'!$A$4:$A$27<>""))>0),0),0))),"",INDEX('Cobertura por asignatura'!$B$4:$B$27,MATCH(1,INDEX(EXACT('Cobertura por asignatura'!$A$4:$A$27,$B16)*1*((('Cobertura por asignatura'!$A$4:$A$27<>""))>0),0),0))))) | G16: =IF(AND($A16=""),"",IF(EXACT($C16,"Conf"),IF(ISNA(MATCH(1,INDEX(EXACT('Cobertura por asignatura'!$A$4:$A$27,$B16)*1*((('Cobertura por asignatura'!$A$4:$A$27<>""))>0),0),0)),0,IF(ISBLANK(INDEX('Cobertura por asignatura'!$D$4:$D$27,MATCH(1,INDEX(EXACT('Cobertura por asignatura'!$A$4:$A$27,$B16)*1*((('Cobertura por asignatura'!$A$4:$A$27<>""))>0),0),0))),"",INDEX('Cobertura por asignatura'!$D$4:$D$27,MATCH(1,INDEX(EXACT('Cobertura por asignatura'!$A$4:$A$27,$B16)*1*((('Cobertura por asignatura'!$A$4:$A$27<>""))>0),0),0)))),IF(ISNA(MATCH(1,INDEX(EXACT('Cobertura por asignatura'!$A$4:$A$27,$B16)*1*((('Cobertura por asignatura'!$A$4:$A$27<>""))>0),0),0)),0,IF(ISBLANK(INDEX('Cobertura por asignatura'!$E$4:$E$27,MATCH(1,INDEX(EXACT('Cobertura por asignatura'!$A$4:$A$27,$B16)*1*((('Cobertura por asignatura'!$A$4:$A$27<>""))>0),0),0))),"",INDEX('Cobertura por asignatura'!$E$4:$E$27,MATCH(1,INDEX(EXACT('Cobertura por asignatura'!$A$4:$A$27,$B16)*1*((('Cobertura por asignatura'!$A$4:$A$27<>""))>0),0),0)))))) | H16: =IF(AND($A16=""),"",IF(ISNA(MATCH(1,INDEX(EXACT('Carga por profesor'!$A$4:$A$27,$E16)*1*((('Carga por profesor'!$A$4:$A$27<>""))>0),0),0)),"",IF(ISBLANK(INDEX('Carga por profesor'!$B$4:$B$27,MATCH(1,INDEX(EXACT('Carga por profesor'!$A$4:$A$27,$E16)*1*((('Carga por profesor'!$A$4:$A$27<>""))>0),0),0))),"",INDEX('Carga por profesor'!$B$4:$B$27,MATCH(1,INDEX(EXACT('Carga por profesor'!$A$4:$A$27,$E16)*1*((('Carga por profesor'!$A$4:$A$27<>""))>0),0),0))))) | I16: =IF(AND($A16=""),"",(IF(ISNUMBER($B16),IF($B16=0,"0",ROUND($B16,9-INT(LOG10(ABS($B16))))&""),$B16&"")&" "&IF(ISNUMBER($C16),IF($C16=0,"0",ROUND($C16,9-INT(LOG10(ABS($C16))))&""),$C16&"")&" "&IF(ISNUMBER($D16),IF($D16=0,"0",ROUND($D16,9-INT(LOG10(ABS($D16))))&""),$D16&""))) | J16: =IF(AND($A16=""),"",IF(OR(($E16=""),($B16="")),"",IF(ISNA(MATCH(1,INDEX(1*((('Asignacion'!$A$4:$A$34<>""))>0)*(EXACT('Asignacion'!$E$4:$E$34,$E16))*(EXACT('Asignacion'!$B$4:$B$34,$B16)),0),0)),"",IF(ISBLANK(INDEX('Asignacion'!$I$4:$I$34,MATCH(1,INDEX(1*((('Asignacion'!$A$4:$A$34<>""))>0)*(EXACT('Asignacion'!$E$4:$E$34,$E16))*(EXACT('Asignacion'!$B$4:$B$34,$B16)),0),0))),"",INDEX('Asignacion'!$I$4:$I$34,MATCH(1,INDEX(1*((('Asignacion'!$A$4:$A$34<>""))>0)*(EXACT('Asignacion'!$E$4:$E$34,$E16))*(EXACT('Asignacion'!$B$4:$B$34,$B16)),0),0)))))) | K16: =IF(AND($A16=""),"",IF(AND(NOT(EXACT($J16,"")),EXACT($J16,$I16)),1,0)) | L16: =IF(AND($A16=""),"",MID(IF(AND(NOT(($B16="")),($E16="")),"; "&"Esta fila de carga todavia no tiene profesor",""),3,32767)) | M16: =IF(OR(AND(NOT(($B16="")),($E16=""))),2,0)
F17: =IF(AND($A17=""),"",IF(ISNA(MATCH(1,INDEX(EXACT('Cobertura por asignatura'!$A$4:$A$27,$B17)*1*((('Cobertura por asignatura'!$A$4:$A$27<>""))>0),0),0)),"",IF(ISBLANK(INDEX('Cobertura por asignatura'!$B$4:$B$27,MATCH(1,INDEX(EXACT('Cobertura por asignatura'!$A$4:$A$27,$B17)*1*((('Cobertura por asignatura'!$A$4:$A$27<>""))>0),0),0))),"",INDEX('Cobertura por asignatura'!$B$4:$B$27,MATCH(1,INDEX(EXACT('Cobertura por asignatura'!$A$4:$A$27,$B17)*1*((('Cobertura por asignatura'!$A$4:$A$27<>""))>0),0),0))))) | G17: =IF(AND($A17=""),"",IF(EXACT($C17,"Conf"),IF(ISNA(MATCH(1,INDEX(EXACT('Cobertura por asignatura'!$A$4:$A$27,$B17)*1*((('Cobertura por asignatura'!$A$4:$A$27<>""))>0),0),0)),0,IF(ISBLANK(INDEX('Cobertura por asignatura'!$D$4:$D$27,MATCH(1,INDEX(EXACT('Cobertura por asignatura'!$A$4:$A$27,$B17)*1*((('Cobertura por asignatura'!$A$4:$A$27<>""))>0),0),0))),"",INDEX('Cobertura por asignatura'!$D$4:$D$27,MATCH(1,INDEX(EXACT('Cobertura por asignatura'!$A$4:$A$27,$B17)*1*((('Cobertura por asignatura'!$A$4:$A$27<>""))>0),0),0)))),IF(ISNA(MATCH(1,INDEX(EXACT('Cobertura por asignatura'!$A$4:$A$27,$B17)*1*((('Cobertura por asignatura'!$A$4:$A$27<>""))>0),0),0)),0,IF(ISBLANK(INDEX('Cobertura por asignatura'!$E$4:$E$27,MATCH(1,INDEX(EXACT('Cobertura por asignatura'!$A$4:$A$27,$B17)*1*((('Cobertura por asignatura'!$A$4:$A$27<>""))>0),0),0))),"",INDEX('Cobertura por asignatura'!$E$4:$E$27,MATCH(1,INDEX(EXACT('Cobertura por asignatura'!$A$4:$A$27,$B17)*1*((('Cobertura por asignatura'!$A$4:$A$27<>""))>0),0),0)))))) | H17: =IF(AND($A17=""),"",IF(ISNA(MATCH(1,INDEX(EXACT('Carga por profesor'!$A$4:$A$27,$E17)*1*((('Carga por profesor'!$A$4:$A$27<>""))>0),0),0)),"",IF(ISBLANK(INDEX('Carga por profesor'!$B$4:$B$27,MATCH(1,INDEX(EXACT('Carga por profesor'!$A$4:$A$27,$E17)*1*((('Carga por profesor'!$A$4:$A$27<>""))>0),0),0))),"",INDEX('Carga por profesor'!$B$4:$B$27,MATCH(1,INDEX(EXACT('Carga por profesor'!$A$4:$A$27,$E17)*1*((('Carga por profesor'!$A$4:$A$27<>""))>0),0),0))))) | I17: =IF(AND($A17=""),"",(IF(ISNUMBER($B17),IF($B17=0,"0",ROUND($B17,9-INT(LOG10(ABS($B17))))&""),$B17&"")&" "&IF(ISNUMBER($C17),IF($C17=0,"0",ROUND($C17,9-INT(LOG10(ABS($C17))))&""),$C17&"")&" "&IF(ISNUMBER($D17),IF($D17=0,"0",ROUND($D17,9-INT(LOG10(ABS($D17))))&""),$D17&""))) | J17: =IF(AND($A17=""),"",IF(OR(($E17=""),($B17="")),"",IF(ISNA(MATCH(1,INDEX(1*((('Asignacion'!$A$4:$A$34<>""))>0)*(EXACT('Asignacion'!$E$4:$E$34,$E17))*(EXACT('Asignacion'!$B$4:$B$34,$B17)),0),0)),"",IF(ISBLANK(INDEX('Asignacion'!$I$4:$I$34,MATCH(1,INDEX(1*((('Asignacion'!$A$4:$A$34<>""))>0)*(EXACT('Asignacion'!$E$4:$E$34,$E17))*(EXACT('Asignacion'!$B$4:$B$34,$B17)),0),0))),"",INDEX('Asignacion'!$I$4:$I$34,MATCH(1,INDEX(1*((('Asignacion'!$A$4:$A$34<>""))>0)*(EXACT('Asignacion'!$E$4:$E$34,$E17))*(EXACT('Asignacion'!$B$4:$B$34,$B17)),0),0)))))) | K17: =IF(AND($A17=""),"",IF(AND(NOT(EXACT($J17,"")),EXACT($J17,$I17)),1,0)) | L17: =IF(AND($A17=""),"",MID(IF(AND(NOT(($B17="")),($E17="")),"; "&"Esta fila de carga todavia no tiene profesor",""),3,32767)) | M17: =IF(OR(AND(NOT(($B17="")),($E17=""))),2,0)
F18: =IF(AND($A18=""),"",IF(ISNA(MATCH(1,INDEX(EXACT('Cobertura por asignatura'!$A$4:$A$27,$B18)*1*((('Cobertura por asignatura'!$A$4:$A$27<>""))>0),0),0)),"",IF(ISBLANK(INDEX('Cobertura por asignatura'!$B$4:$B$27,MATCH(1,INDEX(EXACT('Cobertura por asignatura'!$A$4:$A$27,$B18)*1*((('Cobertura por asignatura'!$A$4:$A$27<>""))>0),0),0))),"",INDEX('Cobertura por asignatura'!$B$4:$B$27,MATCH(1,INDEX(EXACT('Cobertura por asignatura'!$A$4:$A$27,$B18)*1*((('Cobertura por asignatura'!$A$4:$A$27<>""))>0),0),0))))) | G18: =IF(AND($A18=""),"",IF(EXACT($C18,"Conf"),IF(ISNA(MATCH(1,INDEX(EXACT('Cobertura por asignatura'!$A$4:$A$27,$B18)*1*((('Cobertura por asignatura'!$A$4:$A$27<>""))>0),0),0)),0,IF(ISBLANK(INDEX('Cobertura por asignatura'!$D$4:$D$27,MATCH(1,INDEX(EXACT('Cobertura por asignatura'!$A$4:$A$27,$B18)*1*((('Cobertura por asignatura'!$A$4:$A$27<>""))>0),0),0))),"",INDEX('Cobertura por asignatura'!$D$4:$D$27,MATCH(1,INDEX(EXACT('Cobertura por asignatura'!$A$4:$A$27,$B18)*1*((('Cobertura por asignatura'!$A$4:$A$27<>""))>0),0),0)))),IF(ISNA(MATCH(1,INDEX(EXACT('Cobertura por asignatura'!$A$4:$A$27,$B18)*1*((('Cobertura por asignatura'!$A$4:$A$27<>""))>0),0),0)),0,IF(ISBLANK(INDEX('Cobertura por asignatura'!$E$4:$E$27,MATCH(1,INDEX(EXACT('Cobertura por asignatura'!$A$4:$A$27,$B18)*1*((('Cobertura por asignatura'!$A$4:$A$27<>""))>0),0),0))),"",INDEX('Cobertura por asignatura'!$E$4:$E$27,MATCH(1,INDEX(EXACT('Cobertura por asignatura'!$A$4:$A$27,$B18)*1*((('Cobertura por asignatura'!$A$4:$A$27<>""))>0),0),0)))))) | H18: =IF(AND($A18=""),"",IF(ISNA(MATCH(1,INDEX(EXACT('Carga por profesor'!$A$4:$A$27,$E18)*1*((('Carga por profesor'!$A$4:$A$27<>""))>0),0),0)),"",IF(ISBLANK(INDEX('Carga por profesor'!$B$4:$B$27,MATCH(1,INDEX(EXACT('Carga por profesor'!$A$4:$A$27,$E18)*1*((('Carga por profesor'!$A$4:$A$27<>""))>0),0),0))),"",INDEX('Carga por profesor'!$B$4:$B$27,MATCH(1,INDEX(EXACT('Carga por profesor'!$A$4:$A$27,$E18)*1*((('Carga por profesor'!$A$4:$A$27<>""))>0),0),0))))) | I18: =IF(AND($A18=""),"",(IF(ISNUMBER($B18),IF($B18=0,"0",ROUND($B18,9-INT(LOG10(ABS($B18))))&""),$B18&"")&" "&IF(ISNUMBER($C18),IF($C18=0,"0",ROUND($C18,9-INT(LOG10(ABS($C18))))&""),$C18&"")&" "&IF(ISNUMBER($D18),IF($D18=0,"0",ROUND($D18,9-INT(LOG10(ABS($D18))))&""),$D18&""))) | J18: =IF(AND($A18=""),"",IF(OR(($E18=""),($B18="")),"",IF(ISNA(MATCH(1,INDEX(1*((('Asignacion'!$A$4:$A$34<>""))>0)*(EXACT('Asignacion'!$E$4:$E$34,$E18))*(EXACT('Asignacion'!$B$4:$B$34,$B18)),0),0)),"",IF(ISBLANK(INDEX('Asignacion'!$I$4:$I$34,MATCH(1,INDEX(1*((('Asignacion'!$A$4:$A$34<>""))>0)*(EXACT('Asignacion'!$E$4:$E$34,$E18))*(EXACT('Asignacion'!$B$4:$B$34,$B18)),0),0))),"",INDEX('Asignacion'!$I$4:$I$34,MATCH(1,INDEX(1*((('Asignacion'!$A$4:$A$34<>""))>0)*(EXACT('Asignacion'!$E$4:$E$34,$E18))*(EXACT('Asignacion'!$B$4:$B$34,$B18)),0),0)))))) | K18: =IF(AND($A18=""),"",IF(AND(NOT(EXACT($J18,"")),EXACT($J18,$I18)),1,0)) | L18: =IF(AND($A18=""),"",MID(IF(AND(NOT(($B18="")),($E18="")),"; "&"Esta fila de carga todavia no tiene profesor",""),3,32767)) | M18: =IF(OR(AND(NOT(($B18="")),($E18=""))),2,0)
F19: =IF(AND($A19=""),"",IF(ISNA(MATCH(1,INDEX(EXACT('Cobertura por asignatura'!$A$4:$A$27,$B19)*1*((('Cobertura por asignatura'!$A$4:$A$27<>""))>0),0),0)),"",IF(ISBLANK(INDEX('Cobertura por asignatura'!$B$4:$B$27,MATCH(1,INDEX(EXACT('Cobertura por asignatura'!$A$4:$A$27,$B19)*1*((('Cobertura por asignatura'!$A$4:$A$27<>""))>0),0),0))),"",INDEX('Cobertura por asignatura'!$B$4:$B$27,MATCH(1,INDEX(EXACT('Cobertura por asignatura'!$A$4:$A$27,$B19)*1*((('Cobertura por asignatura'!$A$4:$A$27<>""))>0),0),0))))) | G19: =IF(AND($A19=""),"",IF(EXACT($C19,"Conf"),IF(ISNA(MATCH(1,INDEX(EXACT('Cobertura por asignatura'!$A$4:$A$27,$B19)*1*((('Cobertura por asignatura'!$A$4:$A$27<>""))>0),0),0)),0,IF(ISBLANK(INDEX('Cobertura por asignatura'!$D$4:$D$27,MATCH(1,INDEX(EXACT('Cobertura por asignatura'!$A$4:$A$27,$B19)*1*((('Cobertura por asignatura'!$A$4:$A$27<>""))>0),0),0))),"",INDEX('Cobertura por asignatura'!$D$4:$D$27,MATCH(1,INDEX(EXACT('Cobertura por asignatura'!$A$4:$A$27,$B19)*1*((('Cobertura por asignatura'!$A$4:$A$27<>""))>0),0),0)))),IF(ISNA(MATCH(1,INDEX(EXACT('Cobertura por asignatura'!$A$4:$A$27,$B19)*1*((('Cobertura por asignatura'!$A$4:$A$27<>""))>0),0),0)),0,IF(ISBLANK(INDEX('Cobertura por asignatura'!$E$4:$E$27,MATCH(1,INDEX(EXACT('Cobertura por asignatura'!$A$4:$A$27,$B19)*1*((('Cobertura por asignatura'!$A$4:$A$27<>""))>0),0),0))),"",INDEX('Cobertura por asignatura'!$E$4:$E$27,MATCH(1,INDEX(EXACT('Cobertura por asignatura'!$A$4:$A$27,$B19)*1*((('Cobertura por asignatura'!$A$4:$A$27<>""))>0),0),0)))))) | H19: =IF(AND($A19=""),"",IF(ISNA(MATCH(1,INDEX(EXACT('Carga por profesor'!$A$4:$A$27,$E19)*1*((('Carga por profesor'!$A$4:$A$27<>""))>0),0),0)),"",IF(ISBLANK(INDEX('Carga por profesor'!$B$4:$B$27,MATCH(1,INDEX(EXACT('Carga por profesor'!$A$4:$A$27,$E19)*1*((('Carga por profesor'!$A$4:$A$27<>""))>0),0),0))),"",INDEX('Carga por profesor'!$B$4:$B$27,MATCH(1,INDEX(EXACT('Carga por profesor'!$A$4:$A$27,$E19)*1*((('Carga por profesor'!$A$4:$A$27<>""))>0),0),0))))) | I19: =IF(AND($A19=""),"",(IF(ISNUMBER($B19),IF($B19=0,"0",ROUND($B19,9-INT(LOG10(ABS($B19))))&""),$B19&"")&" "&IF(ISNUMBER($C19),IF($C19=0,"0",ROUND($C19,9-INT(LOG10(ABS($C19))))&""),$C19&"")&" "&IF(ISNUMBER($D19),IF($D19=0,"0",ROUND($D19,9-INT(LOG10(ABS($D19))))&""),$D19&""))) | J19: =IF(AND($A19=""),"",IF(OR(($E19=""),($B19="")),"",IF(ISNA(MATCH(1,INDEX(1*((('Asignacion'!$A$4:$A$34<>""))>0)*(EXACT('Asignacion'!$E$4:$E$34,$E19))*(EXACT('Asignacion'!$B$4:$B$34,$B19)),0),0)),"",IF(ISBLANK(INDEX('Asignacion'!$I$4:$I$34,MATCH(1,INDEX(1*((('Asignacion'!$A$4:$A$34<>""))>0)*(EXACT('Asignacion'!$E$4:$E$34,$E19))*(EXACT('Asignacion'!$B$4:$B$34,$B19)),0),0))),"",INDEX('Asignacion'!$I$4:$I$34,MATCH(1,INDEX(1*((('Asignacion'!$A$4:$A$34<>""))>0)*(EXACT('Asignacion'!$E$4:$E$34,$E19))*(EXACT('Asignacion'!$B$4:$B$34,$B19)),0),0)))))) | K19: =IF(AND($A19=""),"",IF(AND(NOT(EXACT($J19,"")),EXACT($J19,$I19)),1,0)) | L19: =IF(AND($A19=""),"",MID(IF(AND(NOT(($B19="")),($E19="")),"; "&"Esta fila de carga todavia no tiene profesor",""),3,32767)) | M19: =IF(OR(AND(NOT(($B19="")),($E19=""))),2,0)
F20: =IF(AND($A20=""),"",IF(ISNA(MATCH(1,INDEX(EXACT('Cobertura por asignatura'!$A$4:$A$27,$B20)*1*((('Cobertura por asignatura'!$A$4:$A$27<>""))>0),0),0)),"",IF(ISBLANK(INDEX('Cobertura por asignatura'!$B$4:$B$27,MATCH(1,INDEX(EXACT('Cobertura por asignatura'!$A$4:$A$27,$B20)*1*((('Cobertura por asignatura'!$A$4:$A$27<>""))>0),0),0))),"",INDEX('Cobertura por asignatura'!$B$4:$B$27,MATCH(1,INDEX(EXACT('Cobertura por asignatura'!$A$4:$A$27,$B20)*1*((('Cobertura por asignatura'!$A$4:$A$27<>""))>0),0),0))))) | G20: =IF(AND($A20=""),"",IF(EXACT($C20,"Conf"),IF(ISNA(MATCH(1,INDEX(EXACT('Cobertura por asignatura'!$A$4:$A$27,$B20)*1*((('Cobertura por asignatura'!$A$4:$A$27<>""))>0),0),0)),0,IF(ISBLANK(INDEX('Cobertura por asignatura'!$D$4:$D$27,MATCH(1,INDEX(EXACT('Cobertura por asignatura'!$A$4:$A$27,$B20)*1*((('Cobertura por asignatura'!$A$4:$A$27<>""))>0),0),0))),"",INDEX('Cobertura por asignatura'!$D$4:$D$27,MATCH(1,INDEX(EXACT('Cobertura por asignatura'!$A$4:$A$27,$B20)*1*((('Cobertura por asignatura'!$A$4:$A$27<>""))>0),0),0)))),IF(ISNA(MATCH(1,INDEX(EXACT('Cobertura por asignatura'!$A$4:$A$27,$B20)*1*((('Cobertura por asignatura'!$A$4:$A$27<>""))>0),0),0)),0,IF(ISBLANK(INDEX('Cobertura por asignatura'!$E$4:$E$27,MATCH(1,INDEX(EXACT('Cobertura por asignatura'!$A$4:$A$27,$B20)*1*((('Cobertura por asignatura'!$A$4:$A$27<>""))>0),0),0))),"",INDEX('Cobertura por asignatura'!$E$4:$E$27,MATCH(1,INDEX(EXACT('Cobertura por asignatura'!$A$4:$A$27,$B20)*1*((('Cobertura por asignatura'!$A$4:$A$27<>""))>0),0),0)))))) | H20: =IF(AND($A20=""),"",IF(ISNA(MATCH(1,INDEX(EXACT('Carga por profesor'!$A$4:$A$27,$E20)*1*((('Carga por profesor'!$A$4:$A$27<>""))>0),0),0)),"",IF(ISBLANK(INDEX('Carga por profesor'!$B$4:$B$27,MATCH(1,INDEX(EXACT('Carga por profesor'!$A$4:$A$27,$E20)*1*((('Carga por profesor'!$A$4:$A$27<>""))>0),0),0))),"",INDEX('Carga por profesor'!$B$4:$B$27,MATCH(1,INDEX(EXACT('Carga por profesor'!$A$4:$A$27,$E20)*1*((('Carga por profesor'!$A$4:$A$27<>""))>0),0),0))))) | I20: =IF(AND($A20=""),"",(IF(ISNUMBER($B20),IF($B20=0,"0",ROUND($B20,9-INT(LOG10(ABS($B20))))&""),$B20&"")&" "&IF(ISNUMBER($C20),IF($C20=0,"0",ROUND($C20,9-INT(LOG10(ABS($C20))))&""),$C20&"")&" "&IF(ISNUMBER($D20),IF($D20=0,"0",ROUND($D20,9-INT(LOG10(ABS($D20))))&""),$D20&""))) | J20: =IF(AND($A20=""),"",IF(OR(($E20=""),($B20="")),"",IF(ISNA(MATCH(1,INDEX(1*((('Asignacion'!$A$4:$A$34<>""))>0)*(EXACT('Asignacion'!$E$4:$E$34,$E20))*(EXACT('Asignacion'!$B$4:$B$34,$B20)),0),0)),"",IF(ISBLANK(INDEX('Asignacion'!$I$4:$I$34,MATCH(1,INDEX(1*((('Asignacion'!$A$4:$A$34<>""))>0)*(EXACT('Asignacion'!$E$4:$E$34,$E20))*(EXACT('Asignacion'!$B$4:$B$34,$B20)),0),0))),"",INDEX('Asignacion'!$I$4:$I$34,MATCH(1,INDEX(1*((('Asignacion'!$A$4:$A$34<>""))>0)*(EXACT('Asignacion'!$E$4:$E$34,$E20))*(EXACT('Asignacion'!$B$4:$B$34,$B20)),0),0)))))) | K20: =IF(AND($A20=""),"",IF(AND(NOT(EXACT($J20,"")),EXACT($J20,$I20)),1,0)) | L20: =IF(AND($A20=""),"",MID(IF(AND(NOT(($B20="")),($E20="")),"; "&"Esta fila de carga todavia no tiene profesor",""),3,32767)) | M20: =IF(OR(AND(NOT(($B20="")),($E20=""))),2,0)
F21: =IF(AND($A21=""),"",IF(ISNA(MATCH(1,INDEX(EXACT('Cobertura por asignatura'!$A$4:$A$27,$B21)*1*((('Cobertura por asignatura'!$A$4:$A$27<>""))>0),0),0)),"",IF(ISBLANK(INDEX('Cobertura por asignatura'!$B$4:$B$27,MATCH(1,INDEX(EXACT('Cobertura por asignatura'!$A$4:$A$27,$B21)*1*((('Cobertura por asignatura'!$A$4:$A$27<>""))>0),0),0))),"",INDEX('Cobertura por asignatura'!$B$4:$B$27,MATCH(1,INDEX(EXACT('Cobertura por asignatura'!$A$4:$A$27,$B21)*1*((('Cobertura por asignatura'!$A$4:$A$27<>""))>0),0),0))))) | G21: =IF(AND($A21=""),"",IF(EXACT($C21,"Conf"),IF(ISNA(MATCH(1,INDEX(EXACT('Cobertura por asignatura'!$A$4:$A$27,$B21)*1*((('Cobertura por asignatura'!$A$4:$A$27<>""))>0),0),0)),0,IF(ISBLANK(INDEX('Cobertura por asignatura'!$D$4:$D$27,MATCH(1,INDEX(EXACT('Cobertura por asignatura'!$A$4:$A$27,$B21)*1*((('Cobertura por asignatura'!$A$4:$A$27<>""))>0),0),0))),"",INDEX('Cobertura por asignatura'!$D$4:$D$27,MATCH(1,INDEX(EXACT('Cobertura por asignatura'!$A$4:$A$27,$B21)*1*((('Cobertura por asignatura'!$A$4:$A$27<>""))>0),0),0)))),IF(ISNA(MATCH(1,INDEX(EXACT('Cobertura por asignatura'!$A$4:$A$27,$B21)*1*((('Cobertura por asignatura'!$A$4:$A$27<>""))>0),0),0)),0,IF(ISBLANK(INDEX('Cobertura por asignatura'!$E$4:$E$27,MATCH(1,INDEX(EXACT('Cobertura por asignatura'!$A$4:$A$27,$B21)*1*((('Cobertura por asignatura'!$A$4:$A$27<>""))>0),0),0))),"",INDEX('Cobertura por asignatura'!$E$4:$E$27,MATCH(1,INDEX(EXACT('Cobertura por asignatura'!$A$4:$A$27,$B21)*1*((('Cobertura por asignatura'!$A$4:$A$27<>""))>0),0),0)))))) | H21: =IF(AND($A21=""),"",IF(ISNA(MATCH(1,INDEX(EXACT('Carga por profesor'!$A$4:$A$27,$E21)*1*((('Carga por profesor'!$A$4:$A$27<>""))>0),0),0)),"",IF(ISBLANK(INDEX('Carga por profesor'!$B$4:$B$27,MATCH(1,INDEX(EXACT('Carga por profesor'!$A$4:$A$27,$E21)*1*((('Carga por profesor'!$A$4:$A$27<>""))>0),0),0))),"",INDEX('Carga por profesor'!$B$4:$B$27,MATCH(1,INDEX(EXACT('Carga por profesor'!$A$4:$A$27,$E21)*1*((('Carga por profesor'!$A$4:$A$27<>""))>0),0),0))))) | I21: =IF(AND($A21=""),"",(IF(ISNUMBER($B21),IF($B21=0,"0",ROUND($B21,9-INT(LOG10(ABS($B21))))&""),$B21&"")&" "&IF(ISNUMBER($C21),IF($C21=0,"0",ROUND($C21,9-INT(LOG10(ABS($C21))))&""),$C21&"")&" "&IF(ISNUMBER($D21),IF($D21=0,"0",ROUND($D21,9-INT(LOG10(ABS($D21))))&""),$D21&""))) | J21: =IF(AND($A21=""),"",IF(OR(($E21=""),($B21="")),"",IF(ISNA(MATCH(1,INDEX(1*((('Asignacion'!$A$4:$A$34<>""))>0)*(EXACT('Asignacion'!$E$4:$E$34,$E21))*(EXACT('Asignacion'!$B$4:$B$34,$B21)),0),0)),"",IF(ISBLANK(INDEX('Asignacion'!$I$4:$I$34,MATCH(1,INDEX(1*((('Asignacion'!$A$4:$A$34<>""))>0)*(EXACT('Asignacion'!$E$4:$E$34,$E21))*(EXACT('Asignacion'!$B$4:$B$34,$B21)),0),0))),"",INDEX('Asignacion'!$I$4:$I$34,MATCH(1,INDEX(1*((('Asignacion'!$A$4:$A$34<>""))>0)*(EXACT('Asignacion'!$E$4:$E$34,$E21))*(EXACT('Asignacion'!$B$4:$B$34,$B21)),0),0)))))) | K21: =IF(AND($A21=""),"",IF(AND(NOT(EXACT($J21,"")),EXACT($J21,$I21)),1,0)) | L21: =IF(AND($A21=""),"",MID(IF(AND(NOT(($B21="")),($E21="")),"; "&"Esta fila de carga todavia no tiene profesor",""),3,32767)) | M21: =IF(OR(AND(NOT(($B21="")),($E21=""))),2,0)
F22: =IF(AND($A22=""),"",IF(ISNA(MATCH(1,INDEX(EXACT('Cobertura por asignatura'!$A$4:$A$27,$B22)*1*((('Cobertura por asignatura'!$A$4:$A$27<>""))>0),0),0)),"",IF(ISBLANK(INDEX('Cobertura por asignatura'!$B$4:$B$27,MATCH(1,INDEX(EXACT('Cobertura por asignatura'!$A$4:$A$27,$B22)*1*((('Cobertura por asignatura'!$A$4:$A$27<>""))>0),0),0))),"",INDEX('Cobertura por asignatura'!$B$4:$B$27,MATCH(1,INDEX(EXACT('Cobertura por asignatura'!$A$4:$A$27,$B22)*1*((('Cobertura por asignatura'!$A$4:$A$27<>""))>0),0),0))))) | G22: =IF(AND($A22=""),"",IF(EXACT($C22,"Conf"),IF(ISNA(MATCH(1,INDEX(EXACT('Cobertura por asignatura'!$A$4:$A$27,$B22)*1*((('Cobertura por asignatura'!$A$4:$A$27<>""))>0),0),0)),0,IF(ISBLANK(INDEX('Cobertura por asignatura'!$D$4:$D$27,MATCH(1,INDEX(EXACT('Cobertura por asignatura'!$A$4:$A$27,$B22)*1*((('Cobertura por asignatura'!$A$4:$A$27<>""))>0),0),0))),"",INDEX('Cobertura por asignatura'!$D$4:$D$27,MATCH(1,INDEX(EXACT('Cobertura por asignatura'!$A$4:$A$27,$B22)*1*((('Cobertura por asignatura'!$A$4:$A$27<>""))>0),0),0)))),IF(ISNA(MATCH(1,INDEX(EXACT('Cobertura por asignatura'!$A$4:$A$27,$B22)*1*((('Cobertura por asignatura'!$A$4:$A$27<>""))>0),0),0)),0,IF(ISBLANK(INDEX('Cobertura por asignatura'!$E$4:$E$27,MATCH(1,INDEX(EXACT('Cobertura por asignatura'!$A$4:$A$27,$B22)*1*((('Cobertura por asignatura'!$A$4:$A$27<>""))>0),0),0))),"",INDEX('Cobertura por asignatura'!$E$4:$E$27,MATCH(1,INDEX(EXACT('Cobertura por asignatura'!$A$4:$A$27,$B22)*1*((('Cobertura por asignatura'!$A$4:$A$27<>""))>0),0),0)))))) | H22: =IF(AND($A22=""),"",IF(ISNA(MATCH(1,INDEX(EXACT('Carga por profesor'!$A$4:$A$27,$E22)*1*((('Carga por profesor'!$A$4:$A$27<>""))>0),0),0)),"",IF(ISBLANK(INDEX('Carga por profesor'!$B$4:$B$27,MATCH(1,INDEX(EXACT('Carga por profesor'!$A$4:$A$27,$E22)*1*((('Carga por profesor'!$A$4:$A$27<>""))>0),0),0))),"",INDEX('Carga por profesor'!$B$4:$B$27,MATCH(1,INDEX(EXACT('Carga por profesor'!$A$4:$A$27,$E22)*1*((('Carga por profesor'!$A$4:$A$27<>""))>0),0),0))))) | I22: =IF(AND($A22=""),"",(IF(ISNUMBER($B22),IF($B22=0,"0",ROUND($B22,9-INT(LOG10(ABS($B22))))&""),$B22&"")&" "&IF(ISNUMBER($C22),IF($C22=0,"0",ROUND($C22,9-INT(LOG10(ABS($C22))))&""),$C22&"")&" "&IF(ISNUMBER($D22),IF($D22=0,"0",ROUND($D22,9-INT(LOG10(ABS($D22))))&""),$D22&""))) | J22: =IF(AND($A22=""),"",IF(OR(($E22=""),($B22="")),"",IF(ISNA(MATCH(1,INDEX(1*((('Asignacion'!$A$4:$A$34<>""))>0)*(EXACT('Asignacion'!$E$4:$E$34,$E22))*(EXACT('Asignacion'!$B$4:$B$34,$B22)),0),0)),"",IF(ISBLANK(INDEX('Asignacion'!$I$4:$I$34,MATCH(1,INDEX(1*((('Asignacion'!$A$4:$A$34<>""))>0)*(EXACT('Asignacion'!$E$4:$E$34,$E22))*(EXACT('Asignacion'!$B$4:$B$34,$B22)),0),0))),"",INDEX('Asignacion'!$I$4:$I$34,MATCH(1,INDEX(1*((('Asignacion'!$A$4:$A$34<>""))>0)*(EXACT('Asignacion'!$E$4:$E$34,$E22))*(EXACT('Asignacion'!$B$4:$B$34,$B22)),0),0)))))) | K22: =IF(AND($A22=""),"",IF(AND(NOT(EXACT($J22,"")),EXACT($J22,$I22)),1,0)) | L22: =IF(AND($A22=""),"",MID(IF(AND(NOT(($B22="")),($E22="")),"; "&"Esta fila de carga todavia no tiene profesor",""),3,32767)) | M22: =IF(OR(AND(NOT(($B22="")),($E22=""))),2,0)
