Workbook
Name Casillas: 'Casillas del horario'!$A$4:$Q$73
Name Asignaturas: Asignaturas!$A$4:$G$18
Name PlanPorGrupo: 'Plan por grupo'!$A$4:$H$33
Name Profesores: Profesores!$A$4:$C$33
Name Disponibilidad: 'Dias que asisten los contratados'!$A$4:$D$4
Name CargaDiaria: 'Carga diaria por profesor'!$A$4:$C$153

Sheet Horario del grupo - 10-3
A1: Horario del grupo - 10-3
A3: Turno | B3: L | C3: M | D3: MI | E3: J | F3: V
A4: 1 | B4: =IFERROR(IF(INDEX('Casillas del horario'!$D$4:$D$73,MATCH("10-3"&"|"&$A4&"|"&B$3,'Casillas del horario'!$R$4:$R$73,0))="","",INDEX('Casillas del horario'!$D$4:$D$73,MATCH("10-3"&"|"&$A4&"|"&B$3,'Casillas del horario'!$R$4:$R$73,0))),"") | C4: =IFERROR(IF(INDEX('Casillas del horario'!$D$4:$D$73,MATCH("10-3"&"|"&$A4&"|"&C$3,'Casillas del horario'!$R$4:$R$73,0))="","",INDEX('Casillas del horario'!$D$4:$D$73,MATCH("10-3"&"|"&$A4&"|"&C$3,'Casillas del horario'!$R$4:$R$73,0))),"") | D4: =IFERROR(IF(INDEX('Casillas del horario'!$D$4:$D$73,MATCH("10-3"&"|"&$A4&"|"&D$3,'Casillas del horario'!$R$4:$R$73,0))="","",INDEX('Casillas del horario'!$D$4:$D$73,MATCH("10-3"&"|"&$A4&"|"&D$3,'Casillas del horario'!$R$4:$R$73,0))),"") | E4: =IFERROR(IF(INDEX('Casillas del horario'!$D$4:$D$73,MATCH("10-3"&"|"&$A4&"|"&E$3,'Casillas del horario'!$R$4:$R$73,0))="","",INDEX('Casillas del horario'!$D$4:$D$73,MATCH("10-3"&"|"&$A4&"|"&E$3,'Casillas del horario'!$R$4:$R$73,0))),"") | F4: =IFERROR(IF(INDEX('Casillas del horario'!$D$4:$D$73,MATCH("10-3"&"|"&$A4&"|"&F$3,'Casillas del horario'!$R$4:$R$73,0))="","",INDEX('Casillas del horario'!$D$4:$D$73,MATCH("10-3"&"|"&$A4&"|"&F$3,'Casillas del horario'!$R$4:$R$73,0))),"")
A5: 2 | B5: =IFERROR(IF(INDEX('Casillas del horario'!$D$4:$D$73,MATCH("10-3"&"|"&$A5&"|"&B$3,'Casillas del horario'!$R$4:$R$73,0))="","",INDEX('Casillas del horario'!$D$4:$D$73,MATCH("10-3"&"|"&$A5&"|"&B$3,'Casillas del horario'!$R$4:$R$73,0))),"") | C5: =IFERROR(IF(INDEX('Casillas del horario'!$D$4:$D$73,MATCH("10-3"&"|"&$A5&"|"&C$3,'Casillas del horario'!$R$4:$R$73,0))="","",INDEX('Casillas del horario'!$D$4:$D$73,MATCH("10-3"&"|"&$A5&"|"&C$3,'Casillas del horario'!$R$4:$R$73,0))),"") | D5: =IFERROR(IF(INDEX('Casillas del horario'!$D$4:$D$73,MATCH("10-3"&"|"&$A5&"|"&D$3,'Casillas del horario'!$R$4:$R$73,0))="","",INDEX('Casillas del horario'!$D$4:$D$73,MATCH("10-3"&"|"&$A5&"|"&D$3,'Casillas del horario'!$R$4:$R$73,0))),"") | E5: =IFERROR(IF(INDEX('Casillas del horario'!$D$4:$D$73,MATCH("10-3"&"|"&$A5&"|"&E$3,'Casillas del horario'!$R$4:$R$73,0))="","",INDEX('Casillas del horario'!$D$4:$D$73,MATCH("10-3"&"|"&$A5&"|"&E$3,'Casillas del horario'!$R$4:$R$73,0))),"") | F5: =IFERROR(IF(INDEX('Casillas del horario'!$D$4:$D$73,MATCH("10-3"&"|"&$A5&"|"&F$3,'Casillas del horario'!$R$4:$R$73,0))="","",INDEX('Casillas del horario'!$D$4:$D$73,MATCH("10-3"&"|"&$A5&"|"&F$3,'Casillas del horario'!$R$4:$R$73,0))),"")
A6: 3 | B6: =IFERROR(IF(INDEX('Casillas del horario'!$D$4:$D$73,MATCH("10-3"&"|"&$A6&"|"&B$3,'Casillas del horario'!$R$4:$R$73,0))="","",INDEX('Casillas del horario'!$D$4:$D$73,MATCH("10-3"&"|"&$A6&"|"&B$3,'Casillas del horario'!$R$4:$R$73,0))),"") | C6: =IFERROR(IF(INDEX('Casillas del horario'!$D$4:$D$73,MATCH("10-3"&"|"&$A6&"|"&C$3,'Casillas del horario'!$R$4:$R$73,0))="","",INDEX('Casillas del horario'!$D$4:$D$73,MATCH("10-3"&"|"&$A6&"|"&C$3,'Casillas del horario'!$R$4:$R$73,0))),"") | D6: =IFERROR(IF(INDEX('Casillas del horario'!$D$4:$D$73,MATCH("10-3"&"|"&$A6&"|"&D$3,'Casillas del horario'!$R$4:$R$73,0))="","",INDEX('Casillas del horario'!$D$4:$D$73,MATCH("10-3"&"|"&$A6&"|"&D$3,'Casillas del horario'!$R$4:$R$73,0))),"") | E6: =IFERROR(IF(INDEX('Casillas del horario'!$D$4:$D$73,MATCH("10-3"&"|"&$A6&"|"&E$3,'Casillas del horario'!$R$4:$R$73,0))="","",INDEX('Casillas del horario'!$D$4:$D$73,MATCH("10-3"&"|"&$A6&"|"&E$3,'Casillas del horario'!$R$4:$R$73,0))),"") | F6: =IFERROR(IF(INDEX('Casillas del horario'!$D$4:$D$73,MATCH("10-3"&"|"&$A6&"|"&F$3,'Casillas del horario'!$R$4:$R$73,0))="","",INDEX('Casillas del horario'!$D$4:$D$73,MATCH("10-3"&"|"&$A6&"|"&F$3,'Casillas del horario'!$R$4:$R$73,0))),"")
A7: 4 | B7: =IFERROR(IF(INDEX('Casillas del horario'!$D$4:$D$73,MATCH("10-3"&"|"&$A7&"|"&B$3,'Casillas del horario'!$R$4:$R$73,0))="","",INDEX('Casillas del horario'!$D$4:$D$73,MATCH("10-3"&"|"&$A7&"|"&B$3,'Casillas del horario'!$R$4:$R$73,0))),"") | C7: =IFERROR(IF(INDEX('Casillas del horario'!$D$4:$D$73,MATCH("10-3"&"|"&$A7&"|"&C$3,'Casillas del horario'!$R$4:$R$73,0))="","",INDEX('Casillas del horario'!$D$4:$D$73,MATCH("10-3"&"|"&$A7&"|"&C$3,'Casillas del horario'!$R$4:$R$73,0))),"") | D7: =IFERROR(IF(INDEX('Casillas del horario'!$D$4:$D$73,MATCH("10-3"&"|"&$A7&"|"&D$3,'Casillas del horario'!$R$4:$R$73,0))="","",INDEX('Casillas del horario'!$D$4:$D$73,MATCH("10-3"&"|"&$A7&"|"&D$3,'Casillas del horario'!$R$4:$R$73,0))),"") | E7: =IFERROR(IF(INDEX('Casillas del horario'!$D$4:$D$73,MATCH("10-3"&"|"&$A7&"|"&E$3,'Casillas del horario'!$R$4:$R$73,0))="","",INDEX('Casillas del horario'!$D$4:$D$73,MATCH("10-3"&"|"&$A7&"|"&E$3,'Casillas del horario'!$R$4:$R$73,0))),"") | F7: =IFERROR(IF(INDEX('Casillas del horario'!$D$4:$D$73,MATCH("10-3"&"|"&$A7&"|"&F$3,'Casillas del horario'!$R$4:$R$73,0))="","",INDEX('Casillas del horario'!$D$4:$D$73,MATCH("10-3"&"|"&$A7&"|"&F$3,'Casillas del horario'!$R$4:$R$73,0))),"")
A8: 5 | B8: =IFERROR(IF(INDEX('Casillas del horario'!$D$4:$D$73,MATCH("10-3"&"|"&$A8&"|"&B$3,'Casillas del horario'!$R$4:$R$73,0))="","",INDEX('Casillas del horario'!$D$4:$D$73,MATCH("10-3"&"|"&$A8&"|"&B$3,'Casillas del horario'!$R$4:$R$73,0))),"") | C8: =IFERROR(IF(INDEX('Casillas del horario'!$D$4:$D$73,MATCH("10-3"&"|"&$A8&"|"&C$3,'Casillas del horario'!$R$4:$R$73,0))="","",INDEX('Casillas del horario'!$D$4:$D$73,MATCH("10-3"&"|"&$A8&"|"&C$3,'Casillas del horario'!$R$4:$R$73,0))),"") | D8: =IFERROR(IF(INDEX('Casillas del horario'!$D$4:$D$73,MATCH("10-3"&"|"&$A8&"|"&D$3,'Casillas del horario'!$R$4:$R$73,0))="","",INDEX('Casillas del horario'!$D$4:$D$73,MATCH("10-3"&"|"&$A8&"|"&D$3,'Casillas del horario'!$R$4:$R$73,0))),"") | E8: =IFERROR(IF(INDEX('Casillas del horario'!$D$4:$D$73,MATCH("10-3"&"|"&$A8&"|"&E$3,'Casillas del horario'!$R$4:$R$73,0))="","",INDEX('Casillas del horario'!$D$4:$D$73,MATCH("10-3"&"|"&$A8&"|"&E$3,'Casillas del horario'!$R$4:$R$73,0))),"") | F8: =IFERROR(IF(INDEX('Casillas del horario'!$D$4:$D$73,MATCH("10-3"&"|"&$A8&"|"&F$3,'Casillas del horario'!$R$4:$R$73,0))="","",INDEX('Casillas del horario'!$D$4:$D$73,MATCH("10-3"&"|"&$A8&"|"&F$3,'Casillas del horario'!$R$4:$R$73,0))),"")
A9: 6 | B9: =IFERROR(IF(INDEX('Casillas del horario'!$D$4:$D$73,MATCH("10-3"&"|"&$A9&"|"&B$3,'Casillas del horario'!$R$4:$R$73,0))="","",INDEX('Casillas del horario'!$D$4:$D$73,MATCH("10-3"&"|"&$A9&"|"&B$3,'Casillas del horario'!$R$4:$R$73,0))),"") | C9: =IFERROR(IF(INDEX('Casillas del horario'!$D$4:$D$73,MATCH("10-3"&"|"&$A9&"|"&C$3,'Casillas del horario'!$R$4:$R$73,0))="","",INDEX('Casillas del horario'!$D$4:$D$73,MATCH("10-3"&"|"&$A9&"|"&C$3,'Casillas del horario'!$R$4:$R$73,0))),"") | D9: =IFERROR(IF(INDEX('Casillas del horario'!$D$4:$D$73,MATCH("10-3"&"|"&$A9&"|"&D$3,'Casillas del horario'!$R$4:$R$73,0))="","",INDEX('Casillas del horario'!$D$4:$D$73,MATCH("10-3"&"|"&$A9&"|"&D$3,'Casillas del horario'!$R$4:$R$73,0))),"") | E9: =IFERROR(IF(INDEX('Casillas del horario'!$D$4:$D$73,MATCH("10-3"&"|"&$A9&"|"&E$3,'Casillas del horario'!$R$4:$R$73,0))="","",INDEX('Casillas del horario'!$D$4:$D$73,MATCH("10-3"&"|"&$A9&"|"&E$3,'Casillas del horario'!$R$4:$R$73,0))),"") | F9: =IFERROR(IF(INDEX('Casillas del horario'!$D$4:$D$73,MATCH("10-3"&"|"&$A9&"|"&F$3,'Casillas del horario'!$R$4:$R$73,0))="","",INDEX('Casillas del horario'!$D$4:$D$73,MATCH("10-3"&"|"&$A9&"|"&F$3,'Casillas del horario'!$R$4:$R$73,0))),"")
A10: 7 | B10: =IFERROR(IF(INDEX('Casillas del horario'!$D$4:$D$73,MATCH("10-3"&"|"&$A10&"|"&B$3,'Casillas del horario'!$R$4:$R$73,0))="","",INDEX('Casillas del horario'!$D$4:$D$73,MATCH("10-3"&"|"&$A10&"|"&B$3,'Casillas del horario'!$R$4:$R$73,0))),"") | C10: =IFERROR(IF(INDEX('Casillas del horario'!$D$4:$D$73,MATCH("10-3"&"|"&$A10&"|"&C$3,'Casillas del horario'!$R$4:$R$73,0))="","",INDEX('Casillas del horario'!$D$4:$D$73,MATCH("10-3"&"|"&$A10&"|"&C$3,'Casillas del horario'!$R$4:$R$73,0))),"") | D10: =IFERROR(IF(INDEX('Casillas del horario'!$D$4:$D$73,MATCH("10-3"&"|"&$A10&"|"&D$3,'Casillas del horario'!$R$4:$R$73,0))="","",INDEX('Casillas del horario'!$D$4:$D$73,MATCH("10-3"&"|"&$A10&"|"&D$3,'Casillas del horario'!$R$4:$R$73,0))),"") | E10: =IFERROR(IF(INDEX('Casillas del horario'!$D$4:$D$73,MATCH("10-3"&"|"&$A10&"|"&E$3,'Casillas del horario'!$R$4:$R$73,0))="","",INDEX('Casillas del horario'!$D$4:$D$73,MATCH("10-3"&"|"&$A10&"|"&E$3,'Casillas del horario'!$R$4:$R$73,0))),"") | F10: =IFERROR(IF(INDEX('Casillas del horario'!$D$4:$D$73,MATCH("10-3"&"|"&$A10&"|"&F$3,'Casillas del horario'!$R$4:$R$73,0))="","",INDEX('Casillas del horario'!$D$4:$D$73,MATCH("10-3"&"|"&$A10&"|"&F$3,'Casillas del horario'!$R$4:$R$73,0))),"")

Sheet Horario del grupo - 10-4
A1: Horario del grupo - 10-4
A3: Turno | B3: L | C3: M | D3: MI | E3: J | F3: V
A4: 1 | B4: =IFERROR(IF(INDEX('Casillas del horario'!$D$4:$D$73,MATCH("10-4"&"|"&$A4&"|"&B$3,'Casillas del horario'!$R$4:$R$73,0))="","",INDEX('Casillas del horario'!$D$4:$D$73,MATCH("10-4"&"|"&$A4&"|"&B$3,'Casillas del horario'!$R$4:$R$73,0))),"") | C4: =IFERROR(IF(INDEX('Casillas del horario'!$D$4:$D$73,MATCH("10-4"&"|"&$A4&"|"&C$3,'Casillas del horario'!$R$4:$R$73,0))="","",INDEX('Casillas del horario'!$D$4:$D$73,MATCH("10-4"&"|"&$A4&"|"&C$3,'Casillas del horario'!$R$4:$R$73,0))),"") | D4: =IFERROR(IF(INDEX('Casillas del horario'!$D$4:$D$73,MATCH("10-4"&"|"&$A4&"|"&D$3,'Casillas del horario'!$R$4:$R$73,0))="","",INDEX('Casillas del horario'!$D$4:$D$73,MATCH("10-4"&"|"&$A4&"|"&D$3,'Casillas del horario'!$R$4:$R$73,0))),"") | E4: =IFERROR(IF(INDEX('Casillas del horario'!$D$4:$D$73,MATCH("10-4"&"|"&$A4&"|"&E$3,'Casillas del horario'!$R$4:$R$73,0))="","",INDEX('Casillas del horario'!$D$4:$D$73,MATCH("10-4"&"|"&$A4&"|"&E$3,'Casillas del horario'!$R$4:$R$73,0))),"") | F4: =IFERROR(IF(INDEX('Casillas del horario'!$D$4:$D$73,MATCH("10-4"&"|"&$A4&"|"&F$3,'Casillas del horario'!$R$4:$R$73,0))="","",INDEX('Casillas del horario'!$D$4:$D$73,MATCH("10-4"&"|"&$A4&"|"&F$3,'Casillas del horario'!$R$4:$R$73,0))),"")
A5: 2 | B5: =IFERROR(IF(INDEX('Casillas del horario'!$D$4:$D$73,MATCH("10-4"&"|"&$A5&"|"&B$3,'Casillas del horario'!$R$4:$R$73,0))="","",INDEX('Casillas del horario'!$D$4:$D$73,MATCH("10-4"&"|"&$A5&"|"&B$3,'Casillas del horario'!$R$4:$R$73,0))),"") | C5: =IFERROR(IF(INDEX('Casillas del horario'!$D$4:$D$73,MATCH("10-4"&"|"&$A5&"|"&C$3,'Casillas del horario'!$R$4:$R$73,0))="","",INDEX('Casillas del horario'!$D$4:$D$73,MATCH("10-4"&"|"&$A5&"|"&C$3,'Casillas del horario'!$R$4:$R$73,0))),"") | D5: =IFERROR(IF(INDEX('Casillas del horario'!$D$4:$D$73,MATCH("10-4"&"|"&$A5&"|"&D$3,'Casillas del horario'!$R$4:$R$73,0))="","",INDEX('Casillas del horario'!$D$4:$D$73,MATCH("10-4"&"|"&$A5&"|"&D$3,'Casillas del horario'!$R$4:$R$73,0))),"") | E5: =IFERROR(IF(INDEX('Casillas del horario'!$D$4:$D$73,MATCH("10-4"&"|"&$A5&"|"&E$3,'Casillas del horario'!$R$4:$R$73,0))="","",INDEX('Casillas del horario'!$D$4:$D$73,MATCH("10-4"&"|"&$A5&"|"&E$3,'Casillas del horario'!$R$4:$R$73,0))),"") | F5: =IFERROR(IF(INDEX('Casillas del horario'!$D$4:$D$73,MATCH("10-4"&"|"&$A5&"|"&F$3,'Casillas del horario'!$R$4:$R$73,0))="","",INDEX('Casillas del horario'!$D$4:$D$73,MATCH("10-4"&"|"&$A5&"|"&F$3,'Casillas del horario'!$R$4:$R$73,0))),"")
A6: 3 | B6: =IFERROR(IF(INDEX('Casillas del horario'!$D$4:$D$73,MATCH("10-4"&"|"&$A6&"|"&B$3,'Casillas del horario'!$R$4:$R$73,0))="","",INDEX('Casillas del horario'!$D$4:$D$73,MATCH("10-4"&"|"&$A6&"|"&B$3,'Casillas del horario'!$R$4:$R$73,0))),"") | C6: =IFERROR(IF(INDEX('Casillas del horario'!$D$4:$D$73,MATCH("10-4"&"|"&$A6&"|"&C$3,'Casillas del horario'!$R$4:$R$73,0))="","",INDEX('Casillas del horario'!$D$4:$D$73,MATCH("10-4"&"|"&$A6&"|"&C$3,'Casillas del horario'!$R$4:$R$73,0))),"") | D6: =IFERROR(IF(INDEX('Casillas del horario'!$D$4:$D$73,MATCH("10-4"&"|"&$A6&"|"&D$3,'Casillas del horario'!$R$4:$R$73,0))="","",INDEX('Casillas del horario'!$D$4:$D$73,MATCH("10-4"&"|"&$A6&"|"&D$3,'Casillas del horario'!$R$4:$R$73,0))),"") | E6: =IFERROR(IF(INDEX('Casillas del horario'!$D$4:$D$73,MATCH("10-4"&"|"&$A6&"|"&E$3,'Casillas del horario'!$R$4:$R$73,0))="","",INDEX('Casillas del horario'!$D$4:$D$73,MATCH("10-4"&"|"&$A6&"|"&E$3,'Casillas del horario'!$R$4:$R$73,0))),"") | F6: =IFERROR(IF(INDEX('Casillas del horario'!$D$4:$D$73,MATCH("10-4"&"|"&$A6&"|"&F$3,'Casillas del horario'!$R$4:$R$73,0))="","",INDEX('Casillas del horario'!$D$4:$D$73,MATCH("10-4"&"|"&$A6&"|"&F$3,'Casillas del horario'!$R$4:$R$73,0))),"")
A7: 4 | B7: =IFERROR(IF(INDEX('Casillas del horario'!$D$4:$D$73,MATCH("10-4"&"|"&$A7&"|"&B$3,'Casillas del horario'!$R$4:$R$73,0))="","",INDEX('Casillas del horario'!$D$4:$D$73,MATCH("10-4"&"|"&$A7&"|"&B$3,'Casillas del horario'!$R$4:$R$73,0))),"") | C7: =IFERROR(IF(INDEX('Casillas del horario'!$D$4:$D$73,MATCH("10-4"&"|"&$A7&"|"&C$3,'Casillas del horario'!$R$4:$R$73,0))="","",INDEX('Casillas del horario'!$D$4:$D$73,MATCH("10-4"&"|"&$A7&"|"&C$3,'Casillas del horario'!$R$4:$R$73,0))),"") | D7: =IFERROR(IF(INDEX('Casillas del horario'!$D$4:$D$73,MATCH("10-4"&"|"&$A7&"|"&D$3,'Casillas del horario'!$R$4:$R$73,0))="","",INDEX('Casillas del horario'!$D$4:$D$73,MATCH("10-4"&"|"&$A7&"|"&D$3,'Casillas del horario'!$R$4:$R$73,0))),"") | E7: =IFERROR(IF(INDEX('Casillas del horario'!$D$4:$D$73,MATCH("10-4"&"|"&$A7&"|"&E$3,'Casillas del horario'!$R$4:$R$73,0))="","",INDEX('Casillas del horario'!$D$4:$D$73,MATCH("10-4"&"|"&$A7&"|"&E$3,'Casillas del horario'!$R$4:$R$73,0))),"") | F7: =IFERROR(IF(INDEX('Casillas del horario'!$D$4:$D$73,MATCH("10-4"&"|"&$A7&"|"&F$3,'Casillas del horario'!$R$4:$R$73,0))="","",INDEX('Casillas del horario'!$D$4:$D$73,MATCH("10-4"&"|"&$A7&"|"&F$3,'Casillas del horario'!$R$4:$R$73,0))),"")
A8: 5 | B8: =IFERROR(IF(INDEX('Casillas del horario'!$D$4:$D$73,MATCH("10-4"&"|"&$A8&"|"&B$3,'Casillas del horario'!$R$4:$R$73,0))="","",INDEX('Casillas del horario'!$D$4:$D$73,MATCH("10-4"&"|"&$A8&"|"&B$3,'Casillas del horario'!$R$4:$R$73,0))),"") | C8: =IFERROR(IF(INDEX('Casillas del horario'!$D$4:$D$73,MATCH("10-4"&"|"&$A8&"|"&C$3,'Casillas del horario'!$R$4:$R$73,0))="","",INDEX('Casillas del horario'!$D$4:$D$73,MATCH("10-4"&"|"&$A8&"|"&C$3,'Casillas del horario'!$R$4:$R$73,0))),"") | D8: =IFERROR(IF(INDEX('Casillas del horario'!$D$4:$D$73,MATCH("10-4"&"|"&$A8&"|"&D$3,'Casillas del horario'!$R$4:$R$73,0))="","",INDEX('Casillas del horario'!$D$4:$D$73,MATCH("10-4"&"|"&$A8&"|"&D$3,'Casillas del horario'!$R$4:$R$73,0))),"") | E8: =IFERROR(IF(INDEX('Casillas del horario'!$D$4:$D$73,MATCH("10-4"&"|"&$A8&"|"&E$3,'Casillas del horario'!$R$4:$R$73,0))="","",INDEX('Casillas del horario'!$D$4:$D$73,MATCH("10-4"&"|"&$A8&"|"&E$3,'Casillas del horario'!$R$4:$R$73,0))),"") | F8: =IFERROR(IF(INDEX('Casillas del horario'!$D$4:$D$73,MATCH("10-4"&"|"&$A8&"|"&F$3,'Casillas del horario'!$R$4:$R$73,0))="","",INDEX('Casillas del horario'!$D$4:$D$73,MATCH("10-4"&"|"&$A8&"|"&F$3,'Casillas del horario'!$R$4:$R$73,0))),"")
A9: 6 | B9: =IFERROR(IF(INDEX('Casillas del horario'!$D$4:$D$73,MATCH("10-4"&"|"&$A9&"|"&B$3,'Casillas del horario'!$R$4:$R$73,0))="","",INDEX('Casillas del horario'!$D$4:$D$73,MATCH("10-4"&"|"&$A9&"|"&B$3,'Casillas del horario'!$R$4:$R$73,0))),"") | C9: =IFERROR(IF(INDEX('Casillas del horario'!$D$4:$D$73,MATCH("10-4"&"|"&$A9&"|"&C$3,'Casillas del horario'!$R$4:$R$73,0))="","",INDEX('Casillas del horario'!$D$4:$D$73,MATCH("10-4"&"|"&$A9&"|"&C$3,'Casillas del horario'!$R$4:$R$73,0))),"") | D9: =IFERROR(IF(INDEX('Casillas del horario'!$D$4:$D$73,MATCH("10-4"&"|"&$A9&"|"&D$3,'Casillas del horario'!$R$4:$R$73,0))="","",INDEX('Casillas del horario'!$D$4:$D$73,MATCH("10-4"&"|"&$A9&"|"&D$3,'Casillas del horario'!$R$4:$R$73,0))),"") | E9: =IFERROR(IF(INDEX('Casillas del horario'!$D$4:$D$73,MATCH("10-4"&"|"&$A9&"|"&E$3,'Casillas del horario'!$R$4:$R$73,0))="","",INDEX('Casillas del horario'!$D$4:$D$73,MATCH("10-4"&"|"&$A9&"|"&E$3,'Casillas del horario'!$R$4:$R$73,0))),"") | F9: =IFERROR(IF(INDEX('Casillas del horario'!$D$4:$D$73,MATCH("10-4"&"|"&$A9&"|"&F$3,'Casillas del horario'!$R$4:$R$73,0))="","",INDEX('Casillas del horario'!$D$4:$D$73,MATCH("10-4"&"|"&$A9&"|"&F$3,'Casillas del horario'!$R$4:$R$73,0))),"")
A10: 7 | B10: =IFERROR(IF(INDEX('Casillas del horario'!$D$4:$D$73,MATCH("10-4"&"|"&$A10&"|"&B$3,'Casillas del horario'!$R$4:$R$73,0))="","",INDEX('Casillas del horario'!$D$4:$D$73,MATCH("10-4"&"|"&$A10&"|"&B$3,'Casillas del horario'!$R$4:$R$73,0))),"") | C10: =IFERROR(IF(INDEX('Casillas del horario'!$D$4:$D$73,MATCH("10-4"&"|"&$A10&"|"&C$3,'Casillas del horario'!$R$4:$R$73,0))="","",INDEX('Casillas del horario'!$D$4:$D$73,MATCH("10-4"&"|"&$A10&"|"&C$3,'Casillas del horario'!$R$4:$R$73,0))),"") | D10: =IFERROR(IF(INDEX('Casillas del horario'!$D$4:$D$73,MATCH("10-4"&"|"&$A10&"|"&D$3,'Casillas del horario'!$R$4:$R$73,0))="","",INDEX('Casillas del horario'!$D$4:$D$73,MATCH("10-4"&"|"&$A10&"|"&D$3,'Casillas del horario'!$R$4:$R$73,0))),"") | E10: =IFERROR(IF(INDEX('Casillas del horario'!$D$4:$D$73,MATCH("10-4"&"|"&$A10&"|"&E$3,'Casillas del horario'!$R$4:$R$73,0))="","",INDEX('Casillas del horario'!$D$4:$D$73,MATCH("10-4"&"|"&$A10&"|"&E$3,'Casillas del horario'!$R$4:$R$73,0))),"") | F10: =IFERROR(IF(INDEX('Casillas del horario'!$D$4:$D$73,MATCH("10-4"&"|"&$A10&"|"&F$3,'Casillas del horario'!$R$4:$R$73,0))="","",INDEX('Casillas del horario'!$D$4:$D$73,MATCH("10-4"&"|"&$A10&"|"&F$3,'Casillas del horario'!$R$4:$R$73,0))),"")

Sheet Profesor de EF en 10-3
A1: Profesor de EF en 10-3
A3: Turno | B3: L | C3: MI
A4: 1 | B4: =IF(COUNTIF('Casillas del horario'!$S$4:$S$73,"Profesor de EF en 10-3"&"|"&$A4&"|"&B$3)>1,IFERROR(IF(INDEX('Casillas del horario'!$A$4:$A$73,MATCH("Profesor de EF en 10-3"&"|"&$A4&"|"&B$3,'Casillas del horario'!$S$4:$S$73,0))="","",INDEX('Casillas del horario'!$A$4:$A$73,MATCH("Profesor de EF en 10-3"&"|"&$A4&"|"&B$3,'Casillas del horario'!$S$4:$S$73,0))),"")&" (+"&(COUNTIF('Casillas del horario'!$S$4:$S$73,"Profesor de EF en 10-3"&"|"&$A4&"|"&B$3)-1)&")",IFERROR(IF(INDEX('Casillas del horario'!$A$4:$A$73,MATCH("Profesor de EF en 10-3"&"|"&$A4&"|"&B$3,'Casillas del horario'!$S$4:$S$73,0))="","",INDEX('Casillas del horario'!$A$4:$A$73,MATCH("Profesor de EF en 10-3"&"|"&$A4&"|"&B$3,'Casillas del horario'!$S$4:$S$73,0))),"")) | C4: =IF(COUNTIF('Casillas del horario'!$S$4:$S$73,"Profesor de EF en 10-3"&"|"&$A4&"|"&C$3)>1,IFERROR(IF(INDEX('Casillas del horario'!$A$4:$A$73,MATCH("Profesor de EF en 10-3"&"|"&$A4&"|"&C$3,'Casillas del horario'!$S$4:$S$73,0))="","",INDEX('Casillas del horario'!$A$4:$A$73,MATCH("Profesor de EF en 10-3"&"|"&$A4&"|"&C$3,'Casillas del horario'!$S$4:$S$73,0))),"")&" (+"&(COUNTIF('Casillas del horario'!$S$4:$S$73,"Profesor de EF en 10-3"&"|"&$A4&"|"&C$3)-1)&")",IFERROR(IF(INDEX('Casillas del horario'!$A$4:$A$73,MATCH("Profesor de EF en 10-3"&"|"&$A4&"|"&C$3,'Casillas del horario'!$S$4:$S$73,0))="","",INDEX('Casillas del horario'!$A$4:$A$73,MATCH("Profesor de EF en 10-3"&"|"&$A4&"|"&C$3,'Casillas del horario'!$S$4:$S$73,0))),""))

Sheet Horario - Profesor de H en 10-3
A1: Horario - Profesor de H en 10-3
A3: Turno | B3: M | C3: MI | D3: J
A4: 1 | B4: =IF(COUNTIF('Casillas del horario'!$S$4:$S$73,"Profesor de H en 10-3"&"|"&$A4&"|"&B$3)>1,IFERROR(IF(INDEX('Casillas del horario'!$A$4:$A$73,MATCH("Profesor de H en 10-3"&"|"&$A4&"|"&B$3,'Casillas del horario'!$S$4:$S$73,0))="","",INDEX('Casillas del horario'!$A$4:$A$73,MATCH("Profesor de H en 10-3"&"|"&$A4&"|"&B$3,'Casillas del horario'!$S$4:$S$73,0))),"")&" (+"&(COUNTIF('Casillas del horario'!$S$4:$S$73,"Profesor de H en 10-3"&"|"&$A4&"|"&B$3)-1)&")",IFERROR(IF(INDEX('Casillas del horario'!$A$4:$A$73,MATCH("Profesor de H en 10-3"&"|"&$A4&"|"&B$3,'Casillas del horario'!$S$4:$S$73,0))="","",INDEX('Casillas del horario'!$A$4:$A$73,MATCH("Profesor de H en 10-3"&"|"&$A4&"|"&B$3,'Casillas del horario'!$S$4:$S$73,0))),"")) | C4: =IF(COUNTIF('Casillas del horario'!$S$4:$S$73,"Profesor de H en 10-3"&"|"&$A4&"|"&C$3)>1,IFERROR(IF(INDEX('Casillas del horario'!$A$4:$A$73,MATCH("Profesor de H en 10-3"&"|"&$A4&"|"&C$3,'Casillas del horario'!$S$4:$S$73,0))="","",INDEX('Casillas del horario'!$A$4:$A$73,MATCH("Profesor de H en 10-3"&"|"&$A4&"|"&C$3,'Casillas del horario'!$S$4:$S$73,0))),"")&" (+"&(COUNTIF('Casillas del horario'!$S$4:$S$73,"Profesor de H en 10-3"&"|"&$A4&"|"&C$3)-1)&")",IFERROR(IF(INDEX('Casillas del horario'!$A$4:$A$73,MATCH("Profesor de H en 10-3"&"|"&$A4&"|"&C$3,'Casillas del horario'!$S$4:$S$73,0))="","",INDEX('Casillas del horario'!$A$4:$A$73,MATCH("Profesor de H en 10-3"&"|"&$A4&"|"&C$3,'Casillas del horario'!$S$4:$S$73,0))),"")) | D4: =IF(COUNTIF('Casillas del horario'!$S$4:$S$73,"Profesor de H en 10-3"&"|"&$A4&"|"&D$3)>1,IFERROR(IF(INDEX('Casillas del horario'!$A$4:$A$73,MATCH("Profesor de H en 10-3"&"|"&$A4&"|"&D$3,'Casillas del horario'!$S$4:$S$73,0))="","",INDEX('Casillas del horario'!$A$4:$A$73,MATCH("Profesor de H en 10-3"&"|"&$A4&"|"&D$3,'Casillas del horario'!$S$4:$S$73,0))),"")&" (+"&(COUNTIF('Casillas del horario'!$S$4:$S$73,"Profesor de H en 10-3"&"|"&$A4&"|"&D$3)-1)&")",IFERROR(IF(INDEX('Casillas del horario'!$A$4:$A$73,MATCH("Profesor de H en 10-3"&"|"&$A4&"|"&D$3,'Casillas del horario'!$S$4:$S$73,0))="","",INDEX('Casillas del horario'!$A$4:$A$73,MATCH("Profesor de H en 10-3"&"|"&$A4&"|"&D$3,'Casillas del horario'!$S$4:$S$73,0))),""))
A5: 4 | B5: =IF(COUNTIF('Casillas del horario'!$S$4:$S$73,"Profesor de H en 10-3"&"|"&$A5&"|"&B$3)>1,IFERROR(IF(INDEX('Casillas del horario'!$A$4:$A$73,MATCH("Profesor de H en 10-3"&"|"&$A5&"|"&B$3,'Casillas del horario'!$S$4:$S$73,0))="","",INDEX('Casillas del horario'!$A$4:$A$73,MATCH("Profesor de H en 10-3"&"|"&$A5&"|"&B$3,'Casillas del horario'!$S$4:$S$73,0))),"")&" (+"&(COUNTIF('Casillas del horario'!$S$4:$S$73,"Profesor de H en 10-3"&"|"&$A5&"|"&B$3)-1)&")",IFERROR(IF(INDEX('Casillas del horario'!$A$4:$A$73,MATCH("Profesor de H en 10-3"&"|"&$A5&"|"&B$3,'Casillas del horario'!$S$4:$S$73,0))="","",INDEX('Casillas del horario'!$A$4:$A$73,MATCH("Profesor de H en 10-3"&"|"&$A5&"|"&B$3,'Casillas del horario'!$S$4:$S$73,0))),"")) | C5: =IF(COUNTIF('Casillas del horario'!$S$4:$S$73,"Profesor de H en 10-3"&"|"&$A5&"|"&C$3)>1,IFERROR(IF(INDEX('Casillas del horario'!$A$4:$A$73,MATCH("Profesor de H en 10-3"&"|"&$A5&"|"&C$3,'Casillas del horario'!$S$4:$S$73,0))="","",INDEX('Casillas del horario'!$A$4:$A$73,MATCH("Profesor de H en 10-3"&"|"&$A5&"|"&C$3,'Casillas del horario'!$S$4:$S$73,0))),"")&" (+"&(COUNTIF('Casillas del horario'!$S$4:$S$73,"Profesor de H en 10-3"&"|"&$A5&"|"&C$3)-1)&")",IFERROR(IF(INDEX('Casillas del horario'!$A$4:$A$73,MATCH("Profesor de H en 10-3"&"|"&$A5&"|"&C$3,'Casillas del horario'!$S$4:$S$73,0))="","",INDEX('Casillas del horario'!$A$4:$A$73,MATCH("Profesor de H en 10-3"&"|"&$A5&"|"&C$3,'Casillas del horario'!$S$4:$S$73,0))),"")) | D5: =IF(COUNTIF('Casillas del horario'!$S$4:$S$73,"Profesor de H en 10-3"&"|"&$A5&"|"&D$3)>1,IFERROR(IF(INDEX('Casillas del horario'!$A$4:$A$73,MATCH("Profesor de H en 10-3"&"|"&$A5&"|"&D$3,'Casillas del horario'!$S$4:$S$73,0))="","",INDEX('Casillas del horario'!$A$4:$A$73,MATCH("Profesor de H en 10-3"&"|"&$A5&"|"&D$3,'Casillas del horario'!$S$4:$S$73,0))),"")&" (+"&(COUNTIF('Casillas del horario'!$S$4:$S$73,"Profesor de H en 10-3"&"|"&$A5&"|"&D$3)-1)&")",IFERROR(IF(INDEX('Casillas del horario'!$A$4:$A$73,MATCH("Profesor de H en 10-3"&"|"&$A5&"|"&D$3,'Casillas del horario'!$S$4:$S$73,0))="","",INDEX('Casillas del horario'!$A$4:$A$73,MATCH("Profesor de H en 10-3"&"|"&$A5&"|"&D$3,'Casillas del horario'!$S$4:$S$73,0))),""))
A6: 6 | B6: =IF(COUNTIF('Casillas del horario'!$S$4:$S$73,"Profesor de H en 10-3"&"|"&$A6&"|"&B$3)>1,IFERROR(IF(INDEX('Casillas del horario'!$A$4:$A$73,MATCH("Profesor de H en 10-3"&"|"&$A6&"|"&B$3,'Casillas del horario'!$S$4:$S$73,0))="","",INDEX('Casillas del horario'!$A$4:$A$73,MATCH("Profesor de H en 10-3"&"|"&$A6&"|"&B$3,'Casillas del horario'!$S$4:$S$73,0))),"")&" (+"&(COUNTIF('Casillas del horario'!$S$4:$S$73,"Profesor de H en 10-3"&"|"&$A6&"|"&B$3)-1)&")",IFERROR(IF(INDEX('Casillas del horario'!$A$4:$A$73,MATCH("Profesor de H en 10-3"&"|"&$A6&"|"&B$3,'Casillas del horario'!$S$4:$S$73,0))="","",INDEX('Casillas del horario'!$A$4:$A$73,MATCH("Profesor de H en 10-3"&"|"&$A6&"|"&B$3,'Casillas del horario'!$S$4:$S$73,0))),"")) | C6: =IF(COUNTIF('Casillas del horario'!$S$4:$S$73,"Profesor de H en 10-3"&"|"&$A6&"|"&C$3)>1,IFERROR(IF(INDEX('Casillas del horario'!$A$4:$A$73,MATCH("Profesor de H en 10-3"&"|"&$A6&"|"&C$3,'Casillas del horario'!$S$4:$S$73,0))="","",INDEX('Casillas del horario'!$A$4:$A$73,MATCH("Profesor de H en 10-3"&"|"&$A6&"|"&C$3,'Casillas del horario'!$S$4:$S$73,0))),"")&" (+"&(COUNTIF('Casillas del horario'!$S$4:$S$73,"Profesor de H en 10-3"&"|"&$A6&"|"&C$3)-1)&")",IFERROR(IF(INDEX('Casillas del horario'!$A$4:$A$73,MATCH("Profesor de H en 10-3"&"|"&$A6&"|"&C$3,'Casillas del horario'!$S$4:$S$73,0))="","",INDEX('Casillas del horario'!$A$4:$A$73,MATCH("Profesor de H en 10-3"&"|"&$A6&"|"&C$3,'Casillas del horario'!$S$4:$S$73,0))),"")) | D6: =IF(COUNTIF('Casillas del horario'!$S$4:$S$73,"Profesor de H en 10-3"&"|"&$A6&"|"&D$3)>1,IFERROR(IF(INDEX('Casillas del horario'!$A$4:$A$73,MATCH("Profesor de H en 10-3"&"|"&$A6&"|"&D$3,'Casillas del horario'!$S$4:$S$73,0))="","",INDEX('Casillas del horario'!$A$4:$A$73,MATCH("Profesor de H en 10-3"&"|"&$A6&"|"&D$3,'Casillas del horario'!$S$4:$S$73,0))),"")&" (+"&(COUNTIF('Casillas del horario'!$S$4:$S$73,"Profesor de H en 10-3"&"|"&$A6&"|"&D$3)-1)&")",IFERROR(IF(INDEX('Casillas del horario'!$A$4:$A$73,MATCH("Profesor de H en 10-3"&"|"&$A6&"|"&D$3,'Casillas del horario'!$S$4:$S$73,0))="","",INDEX('Casillas del horario'!$A$4:$A$73,MATCH("Profesor de H en 10-3"&"|"&$A6&"|"&D$3,'Casillas del horario'!$S$4:$S$73,0))),""))

Sheet Profesor de INF en 10-3
A1: Profesor de INF en 10-3
A3: Turno | B3: J
A4: 1 | B4: =IF(COUNTIF('Casillas del horario'!$S$4:$S$73,"Profesor de INF en 10-3"&"|"&$A4&"|"&B$3)>1,IFERROR(IF(INDEX('Casillas del horario'!$A$4:$A$73,MATCH("Profesor de INF en 10-3"&"|"&$A4&"|"&B$3,'Casillas del horario'!$S$4:$S$73,0))="","",INDEX('Casillas del horario'!$A$4:$A$73,MATCH("Profesor de INF en 10-3"&"|"&$A4&"|"&B$3,'Casillas del horario'!$S$4:$S$73,0))),"")&" (+"&(COUNTIF('Casillas del horario'!$S$4:$S$73,"Profesor de INF en 10-3"&"|"&$A4&"|"&B$3)-1)&")",IFERROR(IF(INDEX('Casillas del horario'!$A$4:$A$73,MATCH("Profesor de INF en 10-3"&"|"&$A4&"|"&B$3,'Casillas del horario'!$S$4:$S$73,0))="","",INDEX('Casillas del horario'!$A$4:$A$73,MATCH("Profesor de INF en 10-3"&"|"&$A4&"|"&B$3,'Casillas del horario'!$S$4:$S$73,0))),""))

Sheet Horario - Profesor de F en 10-3
A1: Horario - Profesor de F en 10-3
A3: Turno | B3: V | C3: J | D3: MI
A4: 1 | B4: =IF(COUNTIF('Casillas del horario'!$S$4:$S$73,"Profesor de F en 10-3"&"|"&$A4&"|"&B$3)>1,IFERROR(IF(INDEX('Casillas del horario'!$A$4:$A$73,MATCH("Profesor de F en 10-3"&"|"&$A4&"|"&B$3,'Casillas del horario'!$S$4:$S$73,0))="","",INDEX('Casillas del horario'!$A$4:$A$73,MATCH("Profesor de F en 10-3"&"|"&$A4&"|"&B$3,'Casillas del horario'!$S$4:$S$73,0))),"")&" (+"&(COUNTIF('Casillas del horario'!$S$4:$S$73,"Profesor de F en 10-3"&"|"&$A4&"|"&B$3)-1)&")",IFERROR(IF(INDEX('Casillas del horario'!$A$4:$A$73,MATCH("Profesor de F en 10-3"&"|"&$A4&"|"&B$3,'Casillas del horario'!$S$4:$S$73,0))="","",INDEX('Casillas del horario'!$A$4:$A$73,MATCH("Profesor de F en 10-3"&"|"&$A4&"|"&B$3,'Casillas del horario'!$S$4:$S$73,0))),"")) | C4: =IF(COUNTIF('Casillas del horario'!$S$4:$S$73,"Profesor de F en 10-3"&"|"&$A4&"|"&C$3)>1,IFERROR(IF(INDEX('Casillas del horario'!$A$4:$A$73,MATCH("Profesor de F en 10-3"&"|"&$A4&"|"&C$3,'Casillas del horario'!$S$4:$S$73,0))="","",INDEX('Casillas del horario'!$A$4:$A$73,MATCH("Profesor de F en 10-3"&"|"&$A4&"|"&C$3,'Casillas del horario'!$S$4:$S$73,0))),"")&" (+"&(COUNTIF('Casillas del horario'!$S$4:$S$73,"Profesor de F en 10-3"&"|"&$A4&"|"&C$3)-1)&")",IFERROR(IF(INDEX('Casillas del horario'!$A$4:$A$73,MATCH("Profesor de F en 10-3"&"|"&$A4&"|"&C$3,'Casillas del horario'!$S$4:$S$73,0))="","",INDEX('Casillas del horario'!$A$4:$A$73,MATCH("Profesor de F en 10-3"&"|"&$A4&"|"&C$3,'Casillas del horario'!$S$4:$S$73,0))),"")) | D4: =IF(COUNTIF('Casillas del horario'!$S$4:$S$73,"Profesor de F en 10-3"&"|"&$A4&"|"&D$3)>1,IFERROR(IF(INDEX('Casillas del horario'!$A$4:$A$73,MATCH("Profesor de F en 10-3"&"|"&$A4&"|"&D$3,'Casillas del horario'!$S$4:$S$73,0))="","",INDEX('Casillas del horario'!$A$4:$A$73,MATCH("Profesor de F en 10-3"&"|"&$A4&"|"&D$3,'Casillas del horario'!$S$4:$S$73,0))),"")&" (+"&(COUNTIF('Casillas del horario'!$S$4:$S$73,"Profesor de F en 10-3"&"|"&$A4&"|"&D$3)-1)&")",IFERROR(IF(INDEX('Casillas del horario'!$A$4:$A$73,MATCH("Profesor de F en 10-3"&"|"&$A4&"|"&D$3,'Casillas del horario'!$S$4:$S$73,0))="","",INDEX('Casillas del horario'!$A$4:$A$73,MATCH("Profesor de F en 10-3"&"|"&$A4&"|"&D$3,'Casillas del horario'!$S$4:$S$73,0))),""))
A5: 2 | B5: =IF(COUNTIF('Casillas del horario'!$S$4:$S$73,"Profesor de F en 10-3"&"|"&$A5&"|"&B$3)>1,IFERROR(IF(INDEX('Casillas del horario'!$A$4:$A$73,MATCH("Profesor de F en 10-3"&"|"&$A5&"|"&B$3,'Casillas del horario'!$S$4:$S$73,0))="","",INDEX('Casillas del horario'!$A$4:$A$73,MATCH("Profesor de F en 10-3"&"|"&$A5&"|"&B$3,'Casillas del horario'!$S$4:$S$73,0))),"")&" (+"&(COUNTIF('Casillas del horario'!$S$4:$S$73,"Profesor de F en 10-3"&"|"&$A5&"|"&B$3)-1)&")",IFERROR(IF(INDEX('Casillas del horario'!$A$4:$A$73,MATCH("Profesor de F en 10-3"&"|"&$A5&"|"&B$3,'Casillas del horario'!$S$4:$S$73,0))="","",INDEX('Casillas del horario'!$A$4:$A$73,MATCH("Profesor de F en 10-3"&"|"&$A5&"|"&B$3,'Casillas del horario'!$S$4:$S$73,0))),"")) | C5: =IF(COUNTIF('Casillas del horario'!$S$4:$S$73,"Profesor de F en 10-3"&"|"&$A5&"|"&C$3)>1,IFERROR(IF(INDEX('Casillas del horario'!$A$4:$A$73,MATCH("Profesor de F en 10-3"&"|"&$A5&"|"&C$3,'Casillas del horario'!$S$4:$S$73,0))="","",INDEX('Casillas del horario'!$A$4:$A$73,MATCH("Profesor de F en 10-3"&"|"&$A5&"|"&C$3,'Casillas del horario'!$S$4:$S$73,0))),"")&" (+"&(COUNTIF('Casillas del horario'!$S$4:$S$73,"Profesor de F en 10-3"&"|"&$A5&"|"&C$3)-1)&")",IFERROR(IF(INDEX('Casillas del horario'!$A$4:$A$73,MATCH("Profesor de F en 10-3"&"|"&$A5&"|"&C$3,'Casillas del horario'!$S$4:$S$73,0))="","",INDEX('Casillas del horario'!$A$4:$A$73,MATCH("Profesor de F en 10-3"&"|"&$A5&"|"&C$3,'Casillas del horario'!$S$4:$S$73,0))),"")) | D5: =IF(COUNTIF('Casillas del horario'!$S$4:$S$73,"Profesor de F en 10-3"&"|"&$A5&"|"&D$3)>1,IFERROR(IF(INDEX('Casillas del horario'!$A$4:$A$73,MATCH("Profesor de F en 10-3"&"|"&$A5&"|"&D$3,'Casillas del horario'!$S$4:$S$73,0))="","",INDEX('Casillas del horario'!$A$4:$A$73,MATCH("Profesor de F en 10-3"&"|"&$A5&"|"&D$3,'Casillas del horario'!$S$4:$S$73,0))),"")&" (+"&(COUNTIF('Casillas del horario'!$S$4:$S$73,"Profesor de F en 10-3"&"|"&$A5&"|"&D$3)-1)&")",IFERROR(IF(INDEX('Casillas del horario'!$A$4:$A$73,MATCH("Profesor de F en 10-3"&"|"&$A5&"|"&D$3,'Casillas del horario'!$S$4:$S$73,0))="","",INDEX('Casillas del horario'!$A$4:$A$73,MATCH("Profesor de F en 10-3"&"|"&$A5&"|"&D$3,'Casillas del horario'!$S$4:$S$73,0))),""))
A6: 6 | B6: =IF(COUNTIF('Casillas del horario'!$S$4:$S$73,"Profesor de F en 10-3"&"|"&$A6&"|"&B$3)>1,IFERROR(IF(INDEX('Casillas del horario'!$A$4:$A$73,MATCH("Profesor de F en 10-3"&"|"&$A6&"|"&B$3,'Casillas del horario'!$S$4:$S$73,0))="","",INDEX('Casillas del horario'!$A$4:$A$73,MATCH("Profesor de F en 10-3"&"|"&$A6&"|"&B$3,'Casillas del horario'!$S$4:$S$73,0))),"")&" (+"&(COUNTIF('Casillas del horario'!$S$4:$S$73,"Profesor de F en 10-3"&"|"&$A6&"|"&B$3)-1)&")",IFERROR(IF(INDEX('Casillas del horario'!$A$4:$A$73,MATCH("Profesor de F en 10-3"&"|"&$A6&"|"&B$3,'Casillas del horario'!$S$4:$S$73,0))="","",INDEX('Casillas del horario'!$A$4:$A$73,MATCH("Profesor de F en 10-3"&"|"&$A6&"|"&B$3,'Casillas del horario'!$S$4:$S$73,0))),"")) | C6: =IF(COUNTIF('Casillas del horario'!$S$4:$S$73,"Profesor de F en 10-3"&"|"&$A6&"|"&C$3)>1,IFERROR(IF(INDEX('Casillas del horario'!$A$4:$A$73,MATCH("Profesor de F en 10-3"&"|"&$A6&"|"&C$3,'Casillas del horario'!$S$4:$S$73,0))="","",INDEX('Casillas del horario'!$A$4:$A$73,MATCH("Profesor de F en 10-3"&"|"&$A6&"|"&C$3,'Casillas del horario'!$S$4:$S$73,0))),"")&" (+"&(COUNTIF('Casillas del horario'!$S$4:$S$73,"Profesor de F en 10-3"&"|"&$A6&"|"&C$3)-1)&")",IFERROR(IF(INDEX('Casillas del horario'!$A$4:$A$73,MATCH("Profesor de F en 10-3"&"|"&$A6&"|"&C$3,'Casillas del horario'!$S$4:$S$73,0))="","",INDEX('Casillas del horario'!$A$4:$A$73,MATCH("Profesor de F en 10-3"&"|"&$A6&"|"&C$3,'Casillas del horario'!$S$4:$S$73,0))),"")) | D6: =IF(COUNTIF('Casillas del horario'!$S$4:$S$73,"Profesor de F en 10-3"&"|"&$A6&"|"&D$3)>1,IFERROR(IF(INDEX('Casillas del horario'!$A$4:$A$73,MATCH("Profesor de F en 10-3"&"|"&$A6&"|"&D$3,'Casillas del horario'!$S$4:$S$73,0))="","",INDEX('Casillas del horario'!$A$4:$A$73,MATCH("Profesor de F en 10-3"&"|"&$A6&"|"&D$3,'Casillas del horario'!$S$4:$S$73,0))),"")&" (+"&(COUNTIF('Casillas del horario'!$S$4:$S$73,"Profesor de F en 10-3"&"|"&$A6&"|"&D$3)-1)&")",IFERROR(IF(INDEX('Casillas del horario'!$A$4:$A$73,MATCH("Profesor de F en 10-3"&"|"&$A6&"|"&D$3,'Casillas del horario'!$S$4:$S$73,0))="","",INDEX('Casillas del horario'!$A$4:$A$73,MATCH("Profesor de F en 10-3"&"|"&$A6&"|"&D$3,'Casillas del horario'!$S$4:$S$73,0))),""))

Sheet Horario - Profesor de M en 10-4
A1: Horario - Profesor de M en 10-4
A3: Turno | B3: L | C3: MI | D3: J | E3: V
A4: 1 | B4: =IF(COUNTIF('Casillas del horario'!$S$4:$S$73,"Profesor de M en 10-4"&"|"&$A4&"|"&B$3)>1,IFERROR(IF(INDEX('Casillas del horario'!$A$4:$A$73,MATCH("Profesor de M en 10-4"&"|"&$A4&"|"&B$3,'Casillas del horario'!$S$4:$S$73,0))="","",INDEX('Casillas del horario'!$A$4:$A$73,MATCH("Profesor de M en 10-4"&"|"&$A4&"|"&B$3,'Casillas del horario'!$S$4:$S$73,0))),"")&" (+"&(COUNTIF('Casillas del horario'!$S$4:$S$73,"Profesor de M en 10-4"&"|"&$A4&"|"&B$3)-1)&")",IFERROR(IF(INDEX('Casillas del horario'!$A$4:$A$73,MATCH("Profesor de M en 10-4"&"|"&$A4&"|"&B$3,'Casillas del horario'!$S$4:$S$73,0))="","",INDEX('Casillas del horario'!$A$4:$A$73,MATCH("Profesor de M en 10-4"&"|"&$A4&"|"&B$3,'Casillas del horario'!$S$4:$S$73,0))),"")) | C4: =IF(COUNTIF('Casillas del horario'!$S$4:$S$73,"Profesor de M en 10-4"&"|"&$A4&"|"&C$3)>1,IFERROR(IF(INDEX('Casillas del horario'!$A$4:$A$73,MATCH("Profesor de M en 10-4"&"|"&$A4&"|"&C$3,'Casillas del horario'!$S$4:$S$73,0))="","",INDEX('Casillas del horario'!$A$4:$A$73,MATCH("Profesor de M en 10-4"&"|"&$A4&"|"&C$3,'Casillas del horario'!$S$4:$S$73,0))),"")&" (+"&(COUNTIF('Casillas del horario'!$S$4:$S$73,"Profesor de M en 10-4"&"|"&$A4&"|"&C$3)-1)&")",IFERROR(IF(INDEX('Casillas del horario'!$A$4:$A$73,MATCH("Profesor de M en 10-4"&"|"&$A4&"|"&C$3,'Casillas del horario'!$S$4:$S$73,0))="","",INDEX('Casillas del horario'!$A$4:$A$73,MATCH("Profesor de M en 10-4"&"|"&$A4&"|"&C$3,'Casillas del horario'!$S$4:$S$73,0))),"")) | D4: =IF(COUNTIF('Casillas del horario'!$S$4:$S$73,"Profesor de M en 10-4"&"|"&$A4&"|"&D$3)>1,IFERROR(IF(INDEX('Casillas del horario'!$A$4:$A$73,MATCH("Profesor de M en 10-4"&"|"&$A4&"|"&D$3,'Casillas del horario'!$S$4:$S$73,0))="","",INDEX('Casillas del horario'!$A$4:$A$73,MATCH("Profesor de M en 10-4"&"|"&$A4&"|"&D$3,'Casillas del horario'!$S$4:$S$73,0))),"")&" (+"&(COUNTIF('Casillas del horario'!$S$4:$S$73,"Profesor de M en 10-4"&"|"&$A4&"|"&D$3)-1)&")",IFERROR(IF(INDEX('Casillas del horario'!$A$4:$A$73,MATCH("Profesor de M en 10-4"&"|"&$A4&"|"&D$3,'Casillas del horario'!$S$4:$S$73,0))="","",INDEX('Casillas del horario'!$A$4:$A$73,MATCH("Profesor de M en 10-4"&"|"&$A4&"|"&D$3,'Casillas del horario'!$S$4:$S$73,0))),"")) | E4: =IF(COUNTIF('Casillas del horario'!$S$4:$S$73,"Profesor de M en 10-4"&"|"&$A4&"|"&E$3)>1,IFERROR(IF(INDEX('Casillas del horario'!$A$4:$A$73,MATCH("Profesor de M en 10-4"&"|"&$A4&"|"&E$3,'Casillas del horario'!$S$4:$S$73,0))="","",INDEX('Casillas del horario'!$A$4:$A$73,MATCH("Profesor de M en 10-4"&"|"&$A4&"|"&E$3,'Casillas del horario'!$S$4:$S$73,0))),"")&" (+"&(COUNTIF('Casillas del horario'!$S$4:$S$73,"Profesor de M en 10-4"&"|"&$A4&"|"&E$3)-1)&")",IFERROR(IF(INDEX('Casillas del horario'!$A$4:$A$73,MATCH("Profesor de M en 10-4"&"|"&$A4&"|"&E$3,'Casillas del horario'!$S$4:$S$73,0))="","",INDEX('Casillas del horario'!$A$4:$A$73,MATCH("Profesor de M en 10-4"&"|"&$A4&"|"&E$3,'Casillas del horario'!$S$4:$S$73,0))),""))
A5: 2 | B5: =IF(COUNTIF('Casillas del horario'!$S$4:$S$73,"Profesor de M en 10-4"&"|"&$A5&"|"&B$3)>1,IFERROR(IF(INDEX('Casillas del horario'!$A$4:$A$73,MATCH("Profesor de M en 10-4"&"|"&$A5&"|"&B$3,'Casillas del horario'!$S$4:$S$73,0))="","",INDEX('Casillas del horario'!$A$4:$A$73,MATCH("Profesor de M en 10-4"&"|"&$A5&"|"&B$3,'Casillas del horario'!$S$4:$S$73,0))),"")&" (+"&(COUNTIF('Casillas del horario'!$S$4:$S$73,"Profesor de M en 10-4"&"|"&$A5&"|"&B$3)-1)&")",IFERROR(IF(INDEX('Casillas del horario'!$A$4:$A$73,MATCH("Profesor de M en 10-4"&"|"&$A5&"|"&B$3,'Casillas del horario'!$S$4:$S$73,0))="","",INDEX('Casillas del horario'!$A$4:$A$73,MATCH("Profesor de M en 10-4"&"|"&$A5&"|"&B$3,'Casillas del horario'!$S$4:$S$73,0))),"")) | C5: =IF(COUNTIF('Casillas del horario'!$S$4:$S$73,"Profesor de M en 10-4"&"|"&$A5&"|"&C$3)>1,IFERROR(IF(INDEX('Casillas del horario'!$A$4:$A$73,MATCH("Profesor de M en 10-4"&"|"&$A5&"|"&C$3,'Casillas del horario'!$S$4:$S$73,0))="","",INDEX('Casillas del horario'!$A$4:$A$73,MATCH("Profesor de M en 10-4"&"|"&$A5&"|"&C$3,'Casillas del horario'!$S$4:$S$73,0))),"")&" (+"&(COUNTIF('Casillas del horario'!$S$4:$S$73,"Profesor de M en 10-4"&"|"&$A5&"|"&C$3)-1)&")",IFERROR(IF(INDEX('Casillas del horario'!$A$4:$A$73,MATCH("Profesor de M en 10-4"&"|"&$A5&"|"&C$3,'Casillas del horario'!$S$4:$S$73,0))="","",INDEX('Casillas del horario'!$A$4:$A$73,MATCH("Profesor de M en 10-4"&"|"&$A5&"|"&C$3,'Casillas del horario'!$S$4:$S$73,0))),"")) | D5: =IF(COUNTIF('Casillas del horario'!$S$4:$S$73,"Profesor de M en 10-4"&"|"&$A5&"|"&D$3)>1,IFERROR(IF(INDEX('Casillas del horario'!$A$4:$A$73,MATCH("Profesor de M en 10-4"&"|"&$A5&"|"&D$3,'Casillas del horario'!$S$4:$S$73,0))="","",INDEX('Casillas del horario'!$A$4:$A$73,MATCH("Profesor de M en 10-4"&"|"&$A5&"|"&D$3,'Casillas del horario'!$S$4:$S$73,0))),"")&" (+"&(COUNTIF('Casillas del horario'!$S$4:$S$73,"Profesor de M en 10-4"&"|"&$A5&"|"&D$3)-1)&")",IFERROR(IF(INDEX('Casillas del horario'!$A$4:$A$73,MATCH("Profesor de M en 10-4"&"|"&$A5&"|"&D$3,'Casillas del horario'!$S$4:$S$73,0))="","",INDEX('Casillas del horario'!$A$4:$A$73,MATCH("Profesor de M en 10-4"&"|"&$A5&"|"&D$3,'Casillas del horario'!$S$4:$S$73,0))),"")) | E5: =IF(COUNTIF('Casillas del horario'!$S$4:$S$73,"Profesor de M en 10-4"&"|"&$A5&"|"&E$3)>1,IFERROR(IF(INDEX('Casillas del horario'!$A$4:$A$73,MATCH("Profesor de M en 10-4"&"|"&$A5&"|"&E$3,'Casillas del horario'!$S$4:$S$73,0))="","",INDEX('Casillas del horario'!$A$4:$A$73,MATCH("Profesor de M en 10-4"&"|"&$A5&"|"&E$3,'Casillas del horario'!$S$4:$S$73,0))),"")&" (+"&(COUNTIF('Casillas del horario'!$S$4:$S$73,"Profesor de M en 10-4"&"|"&$A5&"|"&E$3)-1)&")",IFERROR(IF(INDEX('Casillas del horario'!$A$4:$A$73,MATCH("Profesor de M en 10-4"&"|"&$A5&"|"&E$3,'Casillas del horario'!$S$4:$S$73,0))="","",INDEX('Casillas del horario'!$A$4:$A$73,MATCH("Profesor de M en 10-4"&"|"&$A5&"|"&E$3,'Casillas del horario'!$S$4:$S$73,0))),""))
A6: 3 | B6: =IF(COUNTIF('Casillas del horario'!$S$4:$S$73,"Profesor de M en 10-4"&"|"&$A6&"|"&B$3)>1,IFERROR(IF(INDEX('Casillas del horario'!$A$4:$A$73,MATCH("Profesor de M en 10-4"&"|"&$A6&"|"&B$3,'Casillas del horario'!$S$4:$S$73,0))="","",INDEX('Casillas del horario'!$A$4:$A$73,MATCH("Profesor de M en 10-4"&"|"&$A6&"|"&B$3,'Casillas del horario'!$S$4:$S$73,0))),"")&" (+"&(COUNTIF('Casillas del horario'!$S$4:$S$73,"Profesor de M en 10-4"&"|"&$A6&"|"&B$3)-1)&")",IFERROR(IF(INDEX('Casillas del horario'!$A$4:$A$73,MATCH("Profesor de M en 10-4"&"|"&$A6&"|"&B$3,'Casillas del horario'!$S$4:$S$73,0))="","",INDEX('Casillas del horario'!$A$4:$A$73,MATCH("Profesor de M en 10-4"&"|"&$A6&"|"&B$3,'Casillas del horario'!$S$4:$S$73,0))),"")) | C6: =IF(COUNTIF('Casillas del horario'!$S$4:$S$73,"Profesor de M en 10-4"&"|"&$A6&"|"&C$3)>1,IFERROR(IF(INDEX('Casillas del horario'!$A$4:$A$73,MATCH("Profesor de M en 10-4"&"|"&$A6&"|"&C$3,'Casillas del horario'!$S$4:$S$73,0))="","",INDEX('Casillas del horario'!$A$4:$A$73,MATCH("Profesor de M en 10-4"&"|"&$A6&"|"&C$3,'Casillas del horario'!$S$4:$S$73,0))),"")&" (+"&(COUNTIF('Casillas del horario'!$S$4:$S$73,"Profesor de M en 10-4"&"|"&$A6&"|"&C$3)-1)&")",IFERROR(IF(INDEX('Casillas del horario'!$A$4:$A$73,MATCH("Profesor de M en 10-4"&"|"&$A6&"|"&C$3,'Casillas del horario'!$S$4:$S$73,0))="","",INDEX('Casillas del horario'!$A$4:$A$73,MATCH("Profesor de M en 10-4"&"|"&$A6&"|"&C$3,'Casillas del horario'!$S$4:$S$73,0))),"")) | D6: =IF(COUNTIF('Casillas del horario'!$S$4:$S$73,"Profesor de M en 10-4"&"|"&$A6&"|"&D$3)>1,IFERROR(IF(INDEX('Casillas del horario'!$A$4:$A$73,MATCH("Profesor de M en 10-4"&"|"&$A6&"|"&D$3,'Casillas del horario'!$S$4:$S$73,0))="","",INDEX('Casillas del horario'!$A$4:$A$73,MATCH("Profesor de M en 10-4"&"|"&$A6&"|"&D$3,'Casillas del horario'!$S$4:$S$73,0))),"")&" (+"&(COUNTIF('Casillas del horario'!$S$4:$S$73,"Profesor de M en 10-4"&"|"&$A6&"|"&D$3)-1)&")",IFERROR(IF(INDEX('Casillas del horario'!$A$4:$A$73,MATCH("Profesor de M en 10-4"&"|"&$A6&"|"&D$3,'Casillas del horario'!$S$4:$S$73,0))="","",INDEX('Casillas del horario'!$A$4:$A$73,MATCH("Profesor de M en 10-4"&"|"&$A6&"|"&D$3,'Casillas del horario'!$S$4:$S$73,0))),"")) | E6: =IF(COUNTIF('Casillas del horario'!$S$4:$S$73,"Profesor de M en 10-4"&"|"&$A6&"|"&E$3)>1,IFERROR(IF(INDEX('Casillas del horario'!$A$4:$A$73,MATCH("Profesor de M en 10-4"&"|"&$A6&"|"&E$3,'Casillas del horario'!$S$4:$S$73,0))="","",INDEX('Casillas del horario'!$A$4:$A$73,MATCH("Profesor de M en 10-4"&"|"&$A6&"|"&E$3,'Casillas del horario'!$S$4:$S$73,0))),"")&" (+"&(COUNTIF('Casillas del horario'!$S$4:$S$73,"Profesor de M en 10-4"&"|"&$A6&"|"&E$3)-1)&")",IFERROR(IF(INDEX('Casillas del horario'!$A$4:$A$73,MATCH("Profesor de M en 10-4"&"|"&$A6&"|"&E$3,'Casillas del horario'!$S$4:$S$73,0))="","",INDEX('Casillas del horario'!$A$4:$A$73,MATCH("Profesor de M en 10-4"&"|"&$A6&"|"&E$3,'Casillas del horario'!$S$4:$S$73,0))),""))
A7: 6 | B7: =IF(COUNTIF('Casillas del horario'!$S$4:$S$73,"Profesor de M en 10-4"&"|"&$A7&"|"&B$3)>1,IFERROR(IF(INDEX('Casillas del horario'!$A$4:$A$73,MATCH("Profesor de M en 10-4"&"|"&$A7&"|"&B$3,'Casillas del horario'!$S$4:$S$73,0))="","",INDEX('Casillas del horario'!$A$4:$A$73,MATCH("Profesor de M en 10-4"&"|"&$A7&"|"&B$3,'Casillas del horario'!$S$4:$S$73,0))),"")&" (+"&(COUNTIF('Casillas del horario'!$S$4:$S$73,"Profesor de M en 10-4"&"|"&$A7&"|"&B$3)-1)&")",IFERROR(IF(INDEX('Casillas del horario'!$A$4:$A$73,MATCH("Profesor de M en 10-4"&"|"&$A7&"|"&B$3,'Casillas del horario'!$S$4:$S$73,0))="","",INDEX('Casillas del horario'!$A$4:$A$73,MATCH("Profesor de M en 10-4"&"|"&$A7&"|"&B$3,'Casillas del horario'!$S$4:$S$73,0))),"")) | C7: =IF(COUNTIF('Casillas del horario'!$S$4:$S$73,"Profesor de M en 10-4"&"|"&$A7&"|"&C$3)>1,IFERROR(IF(INDEX('Casillas del horario'!$A$4:$A$73,MATCH("Profesor de M en 10-4"&"|"&$A7&"|"&C$3,'Casillas del horario'!$S$4:$S$73,0))="","",INDEX('Casillas del horario'!$A$4:$A$73,MATCH("Profesor de M en 10-4"&"|"&$A7&"|"&C$3,'Casillas del horario'!$S$4:$S$73,0))),"")&" (+"&(COUNTIF('Casillas del horario'!$S$4:$S$73,"Profesor de M en 10-4"&"|"&$A7&"|"&C$3)-1)&")",IFERROR(IF(INDEX('Casillas del horario'!$A$4:$A$73,MATCH("Profesor de M en 10-4"&"|"&$A7&"|"&C$3,'Casillas del horario'!$S$4:$S$73,0))="","",INDEX('Casillas del horario'!$A$4:$A$73,MATCH("Profesor de M en 10-4"&"|"&$A7&"|"&C$3,'Casillas del horario'!$S$4:$S$73,0))),"")) | D7: =IF(COUNTIF('Casillas del horario'!$S$4:$S$73,"Profesor de M en 10-4"&"|"&$A7&"|"&D$3)>1,IFERROR(IF(INDEX('Casillas del horario'!$A$4:$A$73,MATCH("Profesor de M en 10-4"&"|"&$A7&"|"&D$3,'Casillas del horario'!$S$4:$S$73,0))="","",INDEX('Casillas del horario'!$A$4:$A$73,MATCH("Profesor de M en 10-4"&"|"&$A7&"|"&D$3,'Casillas del horario'!$S$4:$S$73,0))),"")&" (+"&(COUNTIF('Casillas del horario'!$S$4:$S$73,"Profesor de M en 10-4"&"|"&$A7&"|"&D$3)-1)&")",IFERROR(IF(INDEX('Casillas del horario'!$A$4:$A$73,MATCH("Profesor de M en 10-4"&"|"&$A7&"|"&D$3,'Casillas del horario'!$S$4:$S$73,0))="","",INDEX('Casillas del horario'!$A$4:$A$73,MATCH("Profesor de M en 10-4"&"|"&$A7&"|"&D$3,'Casillas del horario'!$S$4:$S$73,0))),"")) | E7: =IF(COUNTIF('Casillas del horario'!$S$4:$S$73,"Profesor de M en 10-4"&"|"&$A7&"|"&E$3)>1,IFERROR(IF(INDEX('Casillas del horario'!$A$4:$A$73,MATCH("Profesor de M en 10-4"&"|"&$A7&"|"&E$3,'Casillas del horario'!$S$4:$S$73,0))="","",INDEX('Casillas del horario'!$A$4:$A$73,MATCH("Profesor de M en 10-4"&"|"&$A7&"|"&E$3,'Casillas del horario'!$S$4:$S$73,0))),"")&" (+"&(COUNTIF('Casillas del horario'!$S$4:$S$73,"Profesor de M en 10-4"&"|"&$A7&"|"&E$3)-1)&")",IFERROR(IF(INDEX('Casillas del horario'!$A$4:$A$73,MATCH("Profesor de M en 10-4"&"|"&$A7&"|"&E$3,'Casillas del horario'!$S$4:$S$73,0))="","",INDEX('Casillas del horario'!$A$4:$A$73,MATCH("Profesor de M en 10-4"&"|"&$A7&"|"&E$3,'Casillas del horario'!$S$4:$S$73,0))),""))

Sheet Profesor de Lit-L en 10-4
A1: Profesor de Lit-L en 10-4
A3: Turno | B3: M | C3: V | D3: J
A4: 1 | B4: =IF(COUNTIF('Casillas del horario'!$S$4:$S$73,"Profesor de Lit-L en 10-4"&"|"&$A4&"|"&B$3)>1,IFERROR(IF(INDEX('Casillas del horario'!$A$4:$A$73,MATCH("Profesor de Lit-L en 10-4"&"|"&$A4&"|"&B$3,'Casillas del horario'!$S$4:$S$73,0))="","",INDEX('Casillas del horario'!$A$4:$A$73,MATCH("Profesor de Lit-L en 10-4"&"|"&$A4&"|"&B$3,'Casillas del horario'!$S$4:$S$73,0))),"")&" (+"&(COUNTIF('Casillas del horario'!$S$4:$S$73,"Profesor de Lit-L en 10-4"&"|"&$A4&"|"&B$3)-1)&")",IFERROR(IF(INDEX('Casillas del horario'!$A$4:$A$73,MATCH("Profesor de Lit-L en 10-4"&"|"&$A4&"|"&B$3,'Casillas del horario'!$S$4:$S$73,0))="","",INDEX('Casillas del horario'!$A$4:$A$73,MATCH("Profesor de Lit-L en 10-4"&"|"&$A4&"|"&B$3,'Casillas del horario'!$S$4:$S$73,0))),"")) | C4: =IF(COUNTIF('Casillas del horario'!$S$4:$S$73,"Profesor de Lit-L en 10-4"&"|"&$A4&"|"&C$3)>1,IFERROR(IF(INDEX('Casillas del horario'!$A$4:$A$73,MATCH("Profesor de Lit-L en 10-4"&"|"&$A4&"|"&C$3,'Casillas del horario'!$S$4:$S$73,0))="","",INDEX('Casillas del horario'!$A$4:$A$73,MATCH("Profesor de Lit-L en 10-4"&"|"&$A4&"|"&C$3,'Casillas del horario'!$S$4:$S$73,0))),"")&" (+"&(COUNTIF('Casillas del horario'!$S$4:$S$73,"Profesor de Lit-L en 10-4"&"|"&$A4&"|"&C$3)-1)&")",IFERROR(IF(INDEX('Casillas del horario'!$A$4:$A$73,MATCH("Profesor de Lit-L en 10-4"&"|"&$A4&"|"&C$3,'Casillas del horario'!$S$4:$S$73,0))="","",INDEX('Casillas del horario'!$A$4:$A$73,MATCH("Profesor de Lit-L en 10-4"&"|"&$A4&"|"&C$3,'Casillas del horario'!$S$4:$S$73,0))),"")) | D4: =IF(COUNTIF('Casillas del horario'!$S$4:$S$73,"Profesor de Lit-L en 10-4"&"|"&$A4&"|"&D$3)>1,IFERROR(IF(INDEX('Casillas del horario'!$A$4:$A$73,MATCH("Profesor de Lit-L en 10-4"&"|"&$A4&"|"&D$3,'Casillas del horario'!$S$4:$S$73,0))="","",INDEX('Casillas del horario'!$A$4:$A$73,MATCH("Profesor de Lit-L en 10-4"&"|"&$A4&"|"&D$3,'Casillas del horario'!$S$4:$S$73,0))),"")&" (+"&(COUNTIF('Casillas del horario'!$S$4:$S$73,"Profesor de Lit-L en 10-4"&"|"&$A4&"|"&D$3)-1)&")",IFERROR(IF(INDEX('Casillas del horario'!$A$4:$A$73,MATCH("Profesor de Lit-L en 10-4"&"|"&$A4&"|"&D$3,'Casillas del horario'!$S$4:$S$73,0))="","",INDEX('Casillas del horario'!$A$4:$A$73,MATCH("Profesor de Lit-L en 10-4"&"|"&$A4&"|"&D$3,'Casillas del horario'!$S$4:$S$73,0))),""))
A5: 2 | B5: =IF(COUNTIF('Casillas del horario'!$S$4:$S$73,"Profesor de Lit-L en 10-4"&"|"&$A5&"|"&B$3)>1,IFERROR(IF(INDEX('Casillas del horario'!$A$4:$A$73,MATCH("Profesor de Lit-L en 10-4"&"|"&$A5&"|"&B$3,'Casillas del horario'!$S$4:$S$73,0))="","",INDEX('Casillas del horario'!$A$4:$A$73,MATCH("Profesor de Lit-L en 10-4"&"|"&$A5&"|"&B$3,'Casillas del horario'!$S$4:$S$73,0))),"")&" (+"&(COUNTIF('Casillas del horario'!$S$4:$S$73,"Profesor de Lit-L en 10-4"&"|"&$A5&"|"&B$3)-1)&")",IFERROR(IF(INDEX('Casillas del horario'!$A$4:$A$73,MATCH("Profesor de Lit-L en 10-4"&"|"&$A5&"|"&B$3,'Casillas del horario'!$S$4:$S$73,0))="","",INDEX('Casillas del horario'!$A$4:$A$73,MATCH("Profesor de Lit-L en 10-4"&"|"&$A5&"|"&B$3,'Casillas del horario'!$S$4:$S$73,0))),"")) | C5: =IF(COUNTIF('Casillas del horario'!$S$4:$S$73,"Profesor de Lit-L en 10-4"&"|"&$A5&"|"&C$3)>1,IFERROR(IF(INDEX('Casillas del horario'!$A$4:$A$73,MATCH("Profesor de Lit-L en 10-4"&"|"&$A5&"|"&C$3,'Casillas del horario'!$S$4:$S$73,0))="","",INDEX('Casillas del horario'!$A$4:$A$73,MATCH("Profesor de Lit-L en 10-4"&"|"&$A5&"|"&C$3,'Casillas del horario'!$S$4:$S$73,0))),"")&" (+"&(COUNTIF('Casillas del horario'!$S$4:$S$73,"Profesor de Lit-L en 10-4"&"|"&$A5&"|"&C$3)-1)&")",IFERROR(IF(INDEX('Casillas del horario'!$A$4:$A$73,MATCH("Profesor de Lit-L en 10-4"&"|"&$A5&"|"&C$3,'Casillas del horario'!$S$4:$S$73,0))="","",INDEX('Casillas del horario'!$A$4:$A$73,MATCH("Profesor de Lit-L en 10-4"&"|"&$A5&"|"&C$3,'Casillas del horario'!$S$4:$S$73,0))),"")) | D5: =IF(COUNTIF('Casillas del horario'!$S$4:$S$73,"Profesor de Lit-L en 10-4"&"|"&$A5&"|"&D$3)>1,IFERROR(IF(INDEX('Casillas del horario'!$A$4:$A$73,MATCH("Profesor de Lit-L en 10-4"&"|"&$A5&"|"&D$3,'Casillas del horario'!$S$4:$S$73,0))="","",INDEX('Casillas del horario'!$A$4:$A$73,MATCH("Profesor de Lit-L en 10-4"&"|"&$A5&"|"&D$3,'Casillas del horario'!$S$4:$S$73,0))),"")&" (+"&(COUNTIF('Casillas del horario'!$S$4:$S$73,"Profesor de Lit-L en 10-4"&"|"&$A5&"|"&D$3)-1)&")",IFERROR(IF(INDEX('Casillas del horario'!$A$4:$A$73,MATCH("Profesor de Lit-L en 10-4"&"|"&$A5&"|"&D$3,'Casillas del horario'!$S$4:$S$73,0))="","",INDEX('Casillas del horario'!$A$4:$A$73,MATCH("Profesor de Lit-L en 10-4"&"|"&$A5&"|"&D$3,'Casillas del horario'!$S$4:$S$73,0))),""))
A6: 6 | B6: =IF(COUNTIF('Casillas del horario'!$S$4:$S$73,"Profesor de Lit-L en 10-4"&"|"&$A6&"|"&B$3)>1,IFERROR(IF(INDEX('Casillas del horario'!$A$4:$A$73,MATCH("Profesor de Lit-L en 10-4"&"|"&$A6&"|"&B$3,'Casillas del horario'!$S$4:$S$73,0))="","",INDEX('Casillas del horario'!$A$4:$A$73,MATCH("Profesor de Lit-L en 10-4"&"|"&$A6&"|"&B$3,'Casillas del horario'!$S$4:$S$73,0))),"")&" (+"&(COUNTIF('Casillas del horario'!$S$4:$S$73,"Profesor de Lit-L en 10-4"&"|"&$A6&"|"&B$3)-1)&")",IFERROR(IF(INDEX('Casillas del horario'!$A$4:$A$73,MATCH("Profesor de Lit-L en 10-4"&"|"&$A6&"|"&B$3,'Casillas del horario'!$S$4:$S$73,0))="","",INDEX('Casillas del horario'!$A$4:$A$73,MATCH("Profesor de Lit-L en 10-4"&"|"&$A6&"|"&B$3,'Casillas del horario'!$S$4:$S$73,0))),"")) | C6: =IF(COUNTIF('Casillas del horario'!$S$4:$S$73,"Profesor de Lit-L en 10-4"&"|"&$A6&"|"&C$3)>1,IFERROR(IF(INDEX('Casillas del horario'!$A$4:$A$73,MATCH("Profesor de Lit-L en 10-4"&"|"&$A6&"|"&C$3,'Casillas del horario'!$S$4:$S$73,0))="","",INDEX('Casillas del horario'!$A$4:$A$73,MATCH("Profesor de Lit-L en 10-4"&"|"&$A6&"|"&C$3,'Casillas del horario'!$S$4:$S$73,0))),"")&" (+"&(COUNTIF('Casillas del horario'!$S$4:$S$73,"Profesor de Lit-L en 10-4"&"|"&$A6&"|"&C$3)-1)&")",IFERROR(IF(INDEX('Casillas del horario'!$A$4:$A$73,MATCH("Profesor de Lit-L en 10-4"&"|"&$A6&"|"&C$3,'Casillas del horario'!$S$4:$S$73,0))="","",INDEX('Casillas del horario'!$A$4:$A$73,MATCH("Profesor de Lit-L en 10-4"&"|"&$A6&"|"&C$3,'Casillas del horario'!$S$4:$S$73,0))),"")) | D6: =IF(COUNTIF('Casillas del horario'!$S$4:$S$73,"Profesor de Lit-L en 10-4"&"|"&$A6&"|"&D$3)>1,IFERROR(IF(INDEX('Casillas del horario'!$A$4:$A$73,MATCH("Profesor de Lit-L en 10-4"&"|"&$A6&"|"&D$3,'Casillas del horario'!$S$4:$S$73,0))="","",INDEX('Casillas del horario'!$A$4:$A$73,MATCH("Profesor de Lit-L en 10-4"&"|"&$A6&"|"&D$3,'Casillas del horario'!$S$4:$S$73,0))),"")&" (+"&(COUNTIF('Casillas del horario'!$S$4:$S$73,"Profesor de Lit-L en 10-4"&"|"&$A6&"|"&D$3)-1)&")",IFERROR(IF(INDEX('Casillas del horario'!$A$4:$A$73,MATCH("Profesor de Lit-L en 10-4"&"|"&$A6&"|"&D$3,'Casillas del horario'!$S$4:$S$73,0))="","",INDEX('Casillas del horario'!$A$4:$A$73,MATCH("Profesor de Lit-L en 10-4"&"|"&$A6&"|"&D$3,'Casillas del horario'!$S$4:$S$73,0))),""))

Sheet Profesor de CP en 10-4
A1: Profesor de CP en 10-4
A3: Turno | B3: MI
A4: 1 | B4: =IF(COUNTIF('Casillas del horario'!$S$4:$S$73,"Profesor de CP en 10-4"&"|"&$A4&"|"&B$3)>1,IFERROR(IF(INDEX('Casillas del horario'!$A$4:$A$73,MATCH("Profesor de CP en 10-4"&"|"&$A4&"|"&B$3,'Casillas del horario'!$S$4:$S$73,0))="","",INDEX('Casillas del horario'!$A$4:$A$73,MATCH("Profesor de CP en 10-4"&"|"&$A4&"|"&B$3,'Casillas del horario'!$S$4:$S$73,0))),"")&" (+"&(COUNTIF('Casillas del horario'!$S$4:$S$73,"Profesor de CP en 10-4"&"|"&$A4&"|"&B$3)-1)&")",IFERROR(IF(INDEX('Casillas del horario'!$A$4:$A$73,MATCH("Profesor de CP en 10-4"&"|"&$A4&"|"&B$3,'Casillas del horario'!$S$4:$S$73,0))="","",INDEX('Casillas del horario'!$A$4:$A$73,MATCH("Profesor de CP en 10-4"&"|"&$A4&"|"&B$3,'Casillas del horario'!$S$4:$S$73,0))),""))

Sheet Horario - Profesor de F en 10-4
A1: Horario - Profesor de F en 10-4
A3: Turno | B3: J | C3: V | D3: MI
A4: 1 | B4: =IF(COUNTIF('Casillas del horario'!$S$4:$S$73,"Profesor de F en 10-4"&"|"&$A4&"|"&B$3)>1,IFERROR(IF(INDEX('Casillas del horario'!$A$4:$A$73,MATCH("Profesor de F en 10-4"&"|"&$A4&"|"&B$3,'Casillas del horario'!$S$4:$S$73,0))="","",INDEX('Casillas del horario'!$A$4:$A$73,MATCH("Profesor de F en 10-4"&"|"&$A4&"|"&B$3,'Casillas del horario'!$S$4:$S$73,0))),"")&" (+"&(COUNTIF('Casillas del horario'!$S$4:$S$73,"Profesor de F en 10-4"&"|"&$A4&"|"&B$3)-1)&")",IFERROR(IF(INDEX('Casillas del horario'!$A$4:$A$73,MATCH("Profesor de F en 10-4"&"|"&$A4&"|"&B$3,'Casillas del horario'!$S$4:$S$73,0))="","",INDEX('Casillas del horario'!$A$4:$A$73,MATCH("Profesor de F en 10-4"&"|"&$A4&"|"&B$3,'Casillas del horario'!$S$4:$S$73,0))),"")) | C4: =IF(COUNTIF('Casillas del horario'!$S$4:$S$73,"Profesor de F en 10-4"&"|"&$A4&"|"&C$3)>1,IFERROR(IF(INDEX('Casillas del horario'!$A$4:$A$73,MATCH("Profesor de F en 10-4"&"|"&$A4&"|"&C$3,'Casillas del horario'!$S$4:$S$73,0))="","",INDEX('Casillas del horario'!$A$4:$A$73,MATCH("Profesor de F en 10-4"&"|"&$A4&"|"&C$3,'Casillas del horario'!$S$4:$S$73,0))),"")&" (+"&(COUNTIF('Casillas del horario'!$S$4:$S$73,"Profesor de F en 10-4"&"|"&$A4&"|"&C$3)-1)&")",IFERROR(IF(INDEX('Casillas del horario'!$A$4:$A$73,MATCH("Profesor de F en 10-4"&"|"&$A4&"|"&C$3,'Casillas del horario'!$S$4:$S$73,0))="","",INDEX('Casillas del horario'!$A$4:$A$73,MATCH("Profesor de F en 10-4"&"|"&$A4&"|"&C$3,'Casillas del horario'!$S$4:$S$73,0))),"")) | D4: =IF(COUNTIF('Casillas del horario'!$S$4:$S$73,"Profesor de F en 10-4"&"|"&$A4&"|"&D$3)>1,IFERROR(IF(INDEX('Casillas del horario'!$A$4:$A$73,MATCH("Profesor de F en 10-4"&"|"&$A4&"|"&D$3,'Casillas del horario'!$S$4:$S$73,0))="","",INDEX('Casillas del horario'!$A$4:$A$73,MATCH("Profesor de F en 10-4"&"|"&$A4&"|"&D$3,'Casillas del horario'!$S$4:$S$73,0))),"")&" (+"&(COUNTIF('Casillas del horario'!$S$4:$S$73,"Profesor de F en 10-4"&"|"&$A4&"|"&D$3)-1)&")",IFERROR(IF(INDEX('Casillas del horario'!$A$4:$A$73,MATCH("Profesor de F en 10-4"&"|"&$A4&"|"&D$3,'Casillas del horario'!$S$4:$S$73,0))="","",INDEX('Casillas del horario'!$A$4:$A$73,MATCH("Profesor de F en 10-4"&"|"&$A4&"|"&D$3,'Casillas del horario'!$S$4:$S$73,0))),""))
A5: 3 | B5: =IF(COUNTIF('Casillas del horario'!$S$4:$S$73,"Profesor de F en 10-4"&"|"&$A5&"|"&B$3)>1,IFERROR(IF(INDEX('Casillas del horario'!$A$4:$A$73,MATCH("Profesor de F en 10-4"&"|"&$A5&"|"&B$3,'Casillas del horario'!$S$4:$S$73,0))="","",INDEX('Casillas del horario'!$A$4:$A$73,MATCH("Profesor de F en 10-4"&"|"&$A5&"|"&B$3,'Casillas del horario'!$S$4:$S$73,0))),"")&" (+"&(COUNTIF('Casillas del horario'!$S$4:$S$73,"Profesor de F en 10-4"&"|"&$A5&"|"&B$3)-1)&")",IFERROR(IF(INDEX('Casillas del horario'!$A$4:$A$73,MATCH("Profesor de F en 10-4"&"|"&$A5&"|"&B$3,'Casillas del horario'!$S$4:$S$73,0))="","",INDEX('Casillas del horario'!$A$4:$A$73,MATCH("Profesor de F en 10-4"&"|"&$A5&"|"&B$3,'Casillas del horario'!$S$4:$S$73,0))),"")) | C5: =IF(COUNTIF('Casillas del horario'!$S$4:$S$73,"Profesor de F en 10-4"&"|"&$A5&"|"&C$3)>1,IFERROR(IF(INDEX('Casillas del horario'!$A$4:$A$73,MATCH("Profesor de F en 10-4"&"|"&$A5&"|"&C$3,'Casillas del horario'!$S$4:$S$73,0))="","",INDEX('Casillas del horario'!$A$4:$A$73,MATCH("Profesor de F en 10-4"&"|"&$A5&"|"&C$3,'Casillas del horario'!$S$4:$S$73,0))),"")&" (+"&(COUNTIF('Casillas del horario'!$S$4:$S$73,"Profesor de F en 10-4"&"|"&$A5&"|"&C$3)-1)&")",IFERROR(IF(INDEX('Casillas del horario'!$A$4:$A$73,MATCH("Profesor de F en 10-4"&"|"&$A5&"|"&C$3,'Casillas del horario'!$S$4:$S$73,0))="","",INDEX('Casillas del horario'!$A$4:$A$73,MATCH("Profesor de F en 10-4"&"|"&$A5&"|"&C$3,'Casillas del horario'!$S$4:$S$73,0))),"")) | D5: =IF(COUNTIF('Casillas del horario'!$S$4:$S$73,"Profesor de F en 10-4"&"|"&$A5&"|"&D$3)>1,IFERROR(IF(INDEX('Casillas del horario'!$A$4:$A$73,MATCH("Profesor de F en 10-4"&"|"&$A5&"|"&D$3,'Casillas del horario'!$S$4:$S$73,0))="","",INDEX('Casillas del horario'!$A$4:$A$73,MATCH("Profesor de F en 10-4"&"|"&$A5&"|"&D$3,'Casillas del horario'!$S$4:$S$73,0))),"")&" (+"&(COUNTIF('Casillas del horario'!$S$4:$S$73,"Profesor de F en 10-4"&"|"&$A5&"|"&D$3)-1)&")",IFERROR(IF(INDEX('Casillas del horario'!$A$4:$A$73,MATCH("Profesor de F en 10-4"&"|"&$A5&"|"&D$3,'Casillas del horario'!$S$4:$S$73,0))="","",INDEX('Casillas del horario'!$A$4:$A$73,MATCH("Profesor de F en 10-4"&"|"&$A5&"|"&D$3,'Casillas del horario'!$S$4:$S$73,0))),""))
A6: 5 | B6: =IF(COUNTIF('Casillas del horario'!$S$4:$S$73,"Profesor de F en 10-4"&"|"&$A6&"|"&B$3)>1,IFERROR(IF(INDEX('Casillas del horario'!$A$4:$A$73,MATCH("Profesor de F en 10-4"&"|"&$A6&"|"&B$3,'Casillas del horario'!$S$4:$S$73,0))="","",INDEX('Casillas del horario'!$A$4:$A$73,MATCH("Profesor de F en 10-4"&"|"&$A6&"|"&B$3,'Casillas del horario'!$S$4:$S$73,0))),"")&" (+"&(COUNTIF('Casillas del horario'!$S$4:$S$73,"Profesor de F en 10-4"&"|"&$A6&"|"&B$3)-1)&")",IFERROR(IF(INDEX('Casillas del horario'!$A$4:$A$73,MATCH("Profesor de F en 10-4"&"|"&$A6&"|"&B$3,'Casillas del horario'!$S$4:$S$73,0))="","",INDEX('Casillas del horario'!$A$4:$A$73,MATCH("Profesor de F en 10-4"&"|"&$A6&"|"&B$3,'Casillas del horario'!$S$4:$S$73,0))),"")) | C6: =IF(COUNTIF('Casillas del horario'!$S$4:$S$73,"Profesor de F en 10-4"&"|"&$A6&"|"&C$3)>1,IFERROR(IF(INDEX('Casillas del horario'!$A$4:$A$73,MATCH("Profesor de F en 10-4"&"|"&$A6&"|"&C$3,'Casillas del horario'!$S$4:$S$73,0))="","",INDEX('Casillas del horario'!$A$4:$A$73,MATCH("Profesor de F en 10-4"&"|"&$A6&"|"&C$3,'Casillas del horario'!$S$4:$S$73,0))),"")&" (+"&(COUNTIF('Casillas del horario'!$S$4:$S$73,"Profesor de F en 10-4"&"|"&$A6&"|"&C$3)-1)&")",IFERROR(IF(INDEX('Casillas del horario'!$A$4:$A$73,MATCH("Profesor de F en 10-4"&"|"&$A6&"|"&C$3,'Casillas del horario'!$S$4:$S$73,0))="","",INDEX('Casillas del horario'!$A$4:$A$73,MATCH("Profesor de F en 10-4"&"|"&$A6&"|"&C$3,'Casillas del horario'!$S$4:$S$73,0))),"")) | D6: =IF(COUNTIF('Casillas del horario'!$S$4:$S$73,"Profesor de F en 10-4"&"|"&$A6&"|"&D$3)>1,IFERROR(IF(INDEX('Casillas del horario'!$A$4:$A$73,MATCH("Profesor de F en 10-4"&"|"&$A6&"|"&D$3,'Casillas del horario'!$S$4:$S$73,0))="","",INDEX('Casillas del horario'!$A$4:$A$73,MATCH("Profesor de F en 10-4"&"|"&$A6&"|"&D$3,'Casillas del horario'!$S$4:$S$73,0))),"")&" (+"&(COUNTIF('Casillas del horario'!$S$4:$S$73,"Profesor de F en 10-4"&"|"&$A6&"|"&D$3)-1)&")",IFERROR(IF(INDEX('Casillas del horario'!$A$4:$A$73,MATCH("Profesor de F en 10-4"&"|"&$A6&"|"&D$3,'Casillas del horario'!$S$4:$S$73,0))="","",INDEX('Casillas del horario'!$A$4:$A$73,MATCH("Profesor de F en 10-4"&"|"&$A6&"|"&D$3,'Casillas del horario'!$S$4:$S$73,0))),""))

Sheet Horario - Profesor de I en 10-3
A1: Horario - Profesor de I en 10-3
A3: Turno | B3: L | C3: V | D3: J
