Workbook
Name Brigadas: OFFSET('Reparto de brigadas'!$A$4,0,0,COUNTA('Reparto de brigadas'!$A$4:$A$31),9)
Name Instalaciones: OFFSET('Instalaciones'!$A$4,0,0,COUNTA('Instalaciones'!$A$4:$A$27),4)
Name Anos: OFFSET('Anos de carrera'!$A$4,0,0,COUNTA('Anos de carrera'!$A$4:$A$29),3)
Name Disponibles: OFFSET('Horarios disponibles por ano'!$A$4,0,0,COUNTA('Horarios disponibles por ano'!$A$4:$A$34),2)
Name Franja: 'Brigadas por horario'!$A$4:$D$9

Sheet OI - par
A1: Ocupacion de instalaciones - par
A3: Instalacion | B3: 10 a.m. | C3: 11 a.m. | D3: 3 p.m.
A4: Pista 1 | B4: =IF(SUMPRODUCT(1*EXACT('Reparto de brigadas'!$L$4:$L$31,"par"&CHAR(31)&$A4&CHAR(31)&B$3))>1,IF(ISNA(MATCH(1,INDEX(EXACT('Reparto de brigadas'!$L$4:$L$31,"par"&CHAR(31)&$A4&CHAR(31)&B$3)*1,0),0)),"",IF(ISBLANK(INDEX('Reparto de brigadas'!$A$4:$A$31,MATCH(1,INDEX(EXACT('Reparto de brigadas'!$L$4:$L$31,"par"&CHAR(31)&$A4&CHAR(31)&B$3)*1,0),0))),"",INDEX('Reparto de brigadas'!$A$4:$A$31,MATCH(1,INDEX(EXACT('Reparto de brigadas'!$L$4:$L$31,"par"&CHAR(31)&$A4&CHAR(31)&B$3)*1,0),0))))&" / "&IF(ISBLANK(INDEX('Reparto de brigadas'!$A$4:$A$31,(MATCH(1,INDEX(EXACT('Reparto de brigadas'!$L$4:$L$31,"par"&CHAR(31)&$A4&CHAR(31)&B$3)*1,0),0)+MATCH(1,INDEX(EXACT(INDEX('Reparto de brigadas'!$L$4:$L$31,MATCH(1,INDEX(EXACT('Reparto de brigadas'!$L$4:$L$31,"par"&CHAR(31)&$A4&CHAR(31)&B$3)*1,0),0)+1):INDEX('Reparto de brigadas'!$L$4:$L$31,ROWS('Reparto de brigadas'!$L$4:$L$31)),"par"&CHAR(31)&$A4&CHAR(31)&B$3)*1,0),0)))),"",INDEX('Reparto de brigadas'!$A$4:$A$31,(MATCH(1,INDEX(EXACT('Reparto de brigadas'!$L$4:$L$31,"par"&CHAR(31)&$A4&CHAR(31)&B$3)*1,0),0)+MATCH(1,INDEX(EXACT(INDEX('Reparto de brigadas'!$L$4:$L$31,MATCH(1,INDEX(EXACT('Reparto de brigadas'!$L$4:$L$31,"par"&CHAR(31)&$A4&CHAR(31)&B$3)*1,0),0)+1):INDEX('Reparto de brigadas'!$L$4:$L$31,ROWS('Reparto de brigadas'!$L$4:$L$31)),"par"&CHAR(31)&$A4&CHAR(31)&B$3)*1,0),0))))&IF(SUMPRODUCT(1*EXACT('Reparto de brigadas'!$L$4:$L$31,"par"&CHAR(31)&$A4&CHAR(31)&B$3))>2," (+"&(SUMPRODUCT(1*EXACT('Reparto de brigadas'!$L$4:$L$31,"par"&CHAR(31)&$A4&CHAR(31)&B$3))-2)&")",""),IF(ISNA(MATCH(1,INDEX(EXACT('Reparto de brigadas'!$L$4:$L$31,"par"&CHAR(31)&$A4&CHAR(31)&B$3)*1,0),0)),"",IF(ISBLANK(INDEX('Reparto de brigadas'!$A$4:$A$31,MATCH(1,INDEX(EXACT('Reparto de brigadas'!$L$4:$L$31,"par"&CHAR(31)&$A4&CHAR(31)&B$3)*1,0),0))),"",INDEX('Reparto de brigadas'!$A$4:$A$31,MATCH(1,INDEX(EXACT('Reparto de brigadas'!$L$4:$L$31,"par"&CHAR(31)&$A4&CHAR(31)&B$3)*1,0),0))))) | C4: =IF(SUMPRODUCT(1*EXACT('Reparto de brigadas'!$L$4:$L$31,"par"&CHAR(31)&$A4&CHAR(31)&C$3))>1,IF(ISNA(MATCH(1,INDEX(EXACT('Reparto de brigadas'!$L$4:$L$31,"par"&CHAR(31)&$A4&CHAR(31)&C$3)*1,0),0)),"",IF(ISBLANK(INDEX('Reparto de brigadas'!$A$4:$A$31,MATCH(1,INDEX(EXACT('Reparto de brigadas'!$L$4:$L$31,"par"&CHAR(31)&$A4&CHAR(31)&C$3)*1,0),0))),"",INDEX('Reparto de brigadas'!$A$4:$A$31,MATCH(1,INDEX(EXACT('Reparto de brigadas'!$L$4:$L$31,"par"&CHAR(31)&$A4&CHAR(31)&C$3)*1,0),0))))&" / "&IF(ISBLANK(INDEX('Reparto de brigadas'!$A$4:$A$31,(MATCH(1,INDEX(EXACT('Reparto de brigadas'!$L$4:$L$31,"par"&CHAR(31)&$A4&CHAR(31)&C$3)*1,0),0)+MATCH(1,INDEX(EXACT(INDEX('Reparto de brigadas'!$L$4:$L$31,MATCH(1,INDEX(EXACT('Reparto de brigadas'!$L$4:$L$31,"par"&CHAR(31)&$A4&CHAR(31)&C$3)*1,0),0)+1):INDEX('Reparto de brigadas'!$L$4:$L$31,ROWS('Reparto de brigadas'!$L$4:$L$31)),"par"&CHAR(31)&$A4&CHAR(31)&C$3)*1,0),0)))),"",INDEX('Reparto de brigadas'!$A$4:$A$31,(MATCH(1,INDEX(EXACT('Reparto de brigadas'!$L$4:$L$31,"par"&CHAR(31)&$A4&CHAR(31)&C$3)*1,0),0)+MATCH(1,INDEX(EXACT(INDEX('Reparto de brigadas'!$L$4:$L$31,MATCH(1,INDEX(EXACT('Reparto de brigadas'!$L$4:$L$31,"par"&CHAR(31)&$A4&CHAR(31)&C$3)*1,0),0)+1):INDEX('Reparto de brigadas'!$L$4:$L$31,ROWS('Reparto de brigadas'!$L$4:$L$31)),"par"&CHAR(31)&$A4&CHAR(31)&C$3)*1,0),0))))&IF(SUMPRODUCT(1*EXACT('Reparto de brigadas'!$L$4:$L$31,"par"&CHAR(31)&$A4&CHAR(31)&C$3))>2," (+"&(SUMPRODUCT(1*EXACT('Reparto de brigadas'!$L$4:$L$31,"par"&CHAR(31)&$A4&CHAR(31)&C$3))-2)&")",""),IF(ISNA(MATCH(1,INDEX(EXACT('Reparto de brigadas'!$L$4:$L$31,"par"&CHAR(31)&$A4&CHAR(31)&C$3)*1,0),0)),"",IF(ISBLANK(INDEX('Reparto de brigadas'!$A$4:$A$31,MATCH(1,INDEX(EXACT('Reparto de brigadas'!$L$4:$L$31,"par"&CHAR(31)&$A4&CHAR(31)&C$3)*1,0),0))),"",INDEX('Reparto de brigadas'!$A$4:$A$31,MATCH(1,INDEX(EXACT('Reparto de brigadas'!$L$4:$L$31,"par"&CHAR(31)&$A4&CHAR(31)&C$3)*1,0),0))))) | D4: =IF(SUMPRODUCT(1*EXACT('Reparto de brigadas'!$L$4:$L$31,"par"&CHAR(31)&$A4&CHAR(31)&D$3))>1,IF(ISNA(MATCH(1,INDEX(EXACT('Reparto de brigadas'!$L$4:$L$31,"par"&CHAR(31)&$A4&CHAR(31)&D$3)*1,0),0)),"",IF(ISBLANK(INDEX('Reparto de brigadas'!$A$4:$A$31,MATCH(1,INDEX(EXACT('Reparto de brigadas'!$L$4:$L$31,"par"&CHAR(31)&$A4&CHAR(31)&D$3)*1,0),0))),"",INDEX('Reparto de brigadas'!$A$4:$A$31,MATCH(1,INDEX(EXACT('Reparto de brigadas'!$L$4:$L$31,"par"&CHAR(31)&$A4&CHAR(31)&D$3)*1,0),0))))&" / "&IF(ISBLANK(INDEX('Reparto de brigadas'!$A$4:$A$31,(MATCH(1,INDEX(EXACT('Reparto de brigadas'!$L$4:$L$31,"par"&CHAR(31)&$A4&CHAR(31)&D$3)*1,0),0)+MATCH(1,INDEX(EXACT(INDEX('Reparto de brigadas'!$L$4:$L$31,MATCH(1,INDEX(EXACT('Reparto de brigadas'!$L$4:$L$31,"par"&CHAR(31)&$A4&CHAR(31)&D$3)*1,0),0)+1):INDEX('Reparto de brigadas'!$L$4:$L$31,ROWS('Reparto de brigadas'!$L$4:$L$31)),"par"&CHAR(31)&$A4&CHAR(31)&D$3)*1,0),0)))),"",INDEX('Reparto de brigadas'!$A$4:$A$31,(MATCH(1,INDEX(EXACT('Reparto de brigadas'!$L$4:$L$31,"par"&CHAR(31)&$A4&CHAR(31)&D$3)*1,0),0)+MATCH(1,INDEX(EXACT(INDEX('Reparto de brigadas'!$L$4:$L$31,MATCH(1,INDEX(EXACT('Reparto de brigadas'!$L$4:$L$31,"par"&CHAR(31)&$A4&CHAR(31)&D$3)*1,0),0)+1):INDEX('Reparto de brigadas'!$L$4:$L$31,ROWS('Reparto de brigadas'!$L$4:$L$31)),"par"&CHAR(31)&$A4&CHAR(31)&D$3)*1,0),0))))&IF(SUMPRODUCT(1*EXACT('Reparto de brigadas'!$L$4:$L$31,"par"&CHAR(31)&$A4&CHAR(31)&D$3))>2," (+"&(SUMPRODUCT(1*EXACT('Reparto de brigadas'!$L$4:$L$31,"par"&CHAR(31)&$A4&CHAR(31)&D$3))-2)&")",""),IF(ISNA(MATCH(1,INDEX(EXACT('Reparto de brigadas'!$L$4:$L$31,"par"&CHAR(31)&$A4&CHAR(31)&D$3)*1,0),0)),"",IF(ISBLANK(INDEX('Reparto de brigadas'!$A$4:$A$31,MATCH(1,INDEX(EXACT('Reparto de brigadas'!$L$4:$L$31,"par"&CHAR(31)&$A4&CHAR(31)&D$3)*1,0),0))),"",INDEX('Reparto de brigadas'!$A$4:$A$31,MATCH(1,INDEX(EXACT('Reparto de brigadas'!$L$4:$L$31,"par"&CHAR(31)&$A4&CHAR(31)&D$3)*1,0),0)))))
A5: Pista 2 | B5: =IF(SUMPRODUCT(1*EXACT('Reparto de brigadas'!$L$4:$L$31,"par"&CHAR(31)&$A5&CHAR(31)&B$3))>1,IF(ISNA(MATCH(1,INDEX(EXACT('Reparto de brigadas'!$L$4:$L$31,"par"&CHAR(31)&$A5&CHAR(31)&B$3)*1,0),0)),"",IF(ISBLANK(INDEX('Reparto de brigadas'!$A$4:$A$31,MATCH(1,INDEX(EXACT('Reparto de brigadas'!$L$4:$L$31,"par"&CHAR(31)&$A5&CHAR(31)&B$3)*1,0),0))),"",INDEX('Reparto de brigadas'!$A$4:$A$31,MATCH(1,INDEX(EXACT('Reparto de brigadas'!$L$4:$L$31,"par"&CHAR(31)&$A5&CHAR(31)&B$3)*1,0),0))))&" / "&IF(ISBLANK(INDEX('Reparto de brigadas'!$A$4:$A$31,(MATCH(1,INDEX(EXACT('Reparto de brigadas'!$L$4:$L$31,"par"&CHAR(31)&$A5&CHAR(31)&B$3)*1,0),0)+MATCH(1,INDEX(EXACT(INDEX('Reparto de brigadas'!$L$4:$L$31,MATCH(1,INDEX(EXACT('Reparto de brigadas'!$L$4:$L$31,"par"&CHAR(31)&$A5&CHAR(31)&B$3)*1,0),0)+1):INDEX('Reparto de brigadas'!$L$4:$L$31,ROWS('Reparto de brigadas'!$L$4:$L$31)),"par"&CHAR(31)&$A5&CHAR(31)&B$3)*1,0),0)))),"",INDEX('Reparto de brigadas'!$A$4:$A$31,(MATCH(1,INDEX(EXACT('Reparto de brigadas'!$L$4:$L$31,"par"&CHAR(31)&$A5&CHAR(31)&B$3)*1,0),0)+MATCH(1,INDEX(EXACT(INDEX('Reparto de brigadas'!$L$4:$L$31,MATCH(1,INDEX(EXACT('Reparto de brigadas'!$L$4:$L$31,"par"&CHAR(31)&$A5&CHAR(31)&B$3)*1,0),0)+1):INDEX('Reparto de brigadas'!$L$4:$L$31,ROWS('Reparto de brigadas'!$L$4:$L$31)),"par"&CHAR(31)&$A5&CHAR(31)&B$3)*1,0),0))))&IF(SUMPRODUCT(1*EXACT('Reparto de brigadas'!$L$4:$L$31,"par"&CHAR(31)&$A5&CHAR(31)&B$3))>2," (+"&(SUMPRODUCT(1*EXACT('Reparto de brigadas'!$L$4:$L$31,"par"&CHAR(31)&$A5&CHAR(31)&B$3))-2)&")",""),IF(ISNA(MATCH(1,INDEX(EXACT('Reparto de brigadas'!$L$4:$L$31,"par"&CHAR(31)&$A5&CHAR(31)&B$3)*1,0),0)),"",IF(ISBLANK(INDEX('Reparto de brigadas'!$A$4:$A$31,MATCH(1,INDEX(EXACT('Reparto de brigadas'!$L$4:$L$31,"par"&CHAR(31)&$A5&CHAR(31)&B$3)*1,0),0))),"",INDEX('Reparto de brigadas'!$A$4:$A$31,MATCH(1,INDEX(EXACT('Reparto de brigadas'!$L$4:$L$31,"par"&CHAR(31)&$A5&CHAR(31)&B$3)*1,0),0))))) | C5: =IF(SUMPRODUCT(1*EXACT('Reparto de brigadas'!$L$4:$L$31,"par"&CHAR(31)&$A5&CHAR(31)&C$3))>1,IF(ISNA(MATCH(1,INDEX(EXACT('Reparto de brigadas'!$L$4:$L$31,"par"&CHAR(31)&$A5&CHAR(31)&C$3)*1,0),0)),"",IF(ISBLANK(INDEX('Reparto de brigadas'!$A$4:$A$31,MATCH(1,INDEX(EXACT('Reparto de brigadas'!$L$4:$L$31,"par"&CHAR(31)&$A5&CHAR(31)&C$3)*1,0),0))),"",INDEX('Reparto de brigadas'!$A$4:$A$31,MATCH(1,INDEX(EXACT('Reparto de brigadas'!$L$4:$L$31,"par"&CHAR(31)&$A5&CHAR(31)&C$3)*1,0),0))))&" / "&IF(ISBLANK(INDEX('Reparto de brigadas'!$A$4:$A$31,(MATCH(1,INDEX(EXACT('Reparto de brigadas'!$L$4:$L$31,"par"&CHAR(31)&$A5&CHAR(31)&C$3)*1,0),0)+MATCH(1,INDEX(EXACT(INDEX('Reparto de brigadas'!$L$4:$L$31,MATCH(1,INDEX(EXACT('Reparto de brigadas'!$L$4:$L$31,"par"&CHAR(31)&$A5&CHAR(31)&C$3)*1,0),0)+1):INDEX('Reparto de brigadas'!$L$4:$L$31,ROWS('Reparto de brigadas'!$L$4:$L$31)),"par"&CHAR(31)&$A5&CHAR(31)&C$3)*1,0),0)))),"",INDEX('Reparto de brigadas'!$A$4:$A$31,(MATCH(1,INDEX(EXACT('Reparto de brigadas'!$L$4:$L$31,"par"&CHAR(31)&$A5&CHAR(31)&C$3)*1,0),0)+MATCH(1,INDEX(EXACT(INDEX('Reparto de brigadas'!$L$4:$L$31,MATCH(1,INDEX(EXACT('Reparto de brigadas'!$L$4:$L$31,"par"&CHAR(31)&$A5&CHAR(31)&C$3)*1,0),0)+1):INDEX('Reparto de brigadas'!$L$4:$L$31,ROWS('Reparto de brigadas'!$L$4:$L$31)),"par"&CHAR(31)&$A5&CHAR(31)&C$3)*1,0),0))))&IF(SUMPRODUCT(1*EXACT('Reparto de brigadas'!$L$4:$L$31,"par"&CHAR(31)&$A5&CHAR(31)&C$3))>2," (+"&(SUMPRODUCT(1*EXACT('Reparto de brigadas'!$L$4:$L$31,"par"&CHAR(31)&$A5&CHAR(31)&C$3))-2)&")",""),IF(ISNA(MATCH(1,INDEX(EXACT('Reparto de brigadas'!$L$4:$L$31,"par"&CHAR(31)&$A5&CHAR(31)&C$3)*1,0),0)),"",IF(ISBLANK(INDEX('Reparto de brigadas'!$A$4:$A$31,MATCH(1,INDEX(EXACT('Reparto de brigadas'!$L$4:$L$31,"par"&CHAR(31)&$A5&CHAR(31)&C$3)*1,0),0))),"",INDEX('Reparto de brigadas'!$A$4:$A$31,MATCH(1,INDEX(EXACT('Reparto de brigadas'!$L$4:$L$31,"par"&CHAR(31)&$A5&CHAR(31)&C$3)*1,0),0))))) | D5: =IF(SUMPRODUCT(1*EXACT('Reparto de brigadas'!$L$4:$L$31,"par"&CHAR(31)&$A5&CHAR(31)&D$3))>1,IF(ISNA(MATCH(1,INDEX(EXACT('Reparto de brigadas'!$L$4:$L$31,"par"&CHAR(31)&$A5&CHAR(31)&D$3)*1,0),0)),"",IF(ISBLANK(INDEX('Reparto de brigadas'!$A$4:$A$31,MATCH(1,INDEX(EXACT('Reparto de brigadas'!$L$4:$L$31,"par"&CHAR(31)&$A5&CHAR(31)&D$3)*1,0),0))),"",INDEX('Reparto de brigadas'!$A$4:$A$31,MATCH(1,INDEX(EXACT('Reparto de brigadas'!$L$4:$L$31,"par"&CHAR(31)&$A5&CHAR(31)&D$3)*1,0),0))))&" / "&IF(ISBLANK(INDEX('Reparto de brigadas'!$A$4:$A$31,(MATCH(1,INDEX(EXACT('Reparto de brigadas'!$L$4:$L$31,"par"&CHAR(31)&$A5&CHAR(31)&D$3)*1,0),0)+MATCH(1,INDEX(EXACT(INDEX('Reparto de brigadas'!$L$4:$L$31,MATCH(1,INDEX(EXACT('Reparto de brigadas'!$L$4:$L$31,"par"&CHAR(31)&$A5&CHAR(31)&D$3)*1,0),0)+1):INDEX('Reparto de brigadas'!$L$4:$L$31,ROWS('Reparto de brigadas'!$L$4:$L$31)),"par"&CHAR(31)&$A5&CHAR(31)&D$3)*1,0),0)))),"",INDEX('Reparto de brigadas'!$A$4:$A$31,(MATCH(1,INDEX(EXACT('Reparto de brigadas'!$L$4:$L$31,"par"&CHAR(31)&$A5&CHAR(31)&D$3)*1,0),0)+MATCH(1,INDEX(EXACT(INDEX('Reparto de brigadas'!$L$4:$L$31,MATCH(1,INDEX(EXACT('Reparto de brigadas'!$L$4:$L$31,"par"&CHAR(31)&$A5&CHAR(31)&D$3)*1,0),0)+1):INDEX('Reparto de brigadas'!$L$4:$L$31,ROWS('Reparto de brigadas'!$L$4:$L$31)),"par"&CHAR(31)&$A5&CHAR(31)&D$3)*1,0),0))))&IF(SUMPRODUCT(1*EXACT('Reparto de brigadas'!$L$4:$L$31,"par"&CHAR(31)&$A5&CHAR(31)&D$3))>2," (+"&(SUMPRODUCT(1*EXACT('Reparto de brigadas'!$L$4:$L$31,"par"&CHAR(31)&$A5&CHAR(31)&D$3))-2)&")",""),IF(ISNA(MATCH(1,INDEX(EXACT('Reparto de brigadas'!$L$4:$L$31,"par"&CHAR(31)&$A5&CHAR(31)&D$3)*1,0),0)),"",IF(ISBLANK(INDEX('Reparto de brigadas'!$A$4:$A$31,MATCH(1,INDEX(EXACT('Reparto de brigadas'!$L$4:$L$31,"par"&CHAR(31)&$A5&CHAR(31)&D$3)*1,0),0))),"",INDEX('Reparto de brigadas'!$A$4:$A$31,MATCH(1,INDEX(EXACT('Reparto de brigadas'!$L$4:$L$31,"par"&CHAR(31)&$A5&CHAR(31)&D$3)*1,0),0)))))
A6: Gimnasio | B6: =IF(SUMPRODUCT(1*EXACT('Reparto de brigadas'!$L$4:$L$31,"par"&CHAR(31)&$A6&CHAR(31)&B$3))>1,IF(ISNA(MATCH(1,INDEX(EXACT('Reparto de brigadas'!$L$4:$L$31,"par"&CHAR(31)&$A6&CHAR(31)&B$3)*1,0),0)),"",IF(ISBLANK(INDEX('Reparto de brigadas'!$A$4:$A$31,MATCH(1,INDEX(EXACT('Reparto de brigadas'!$L$4:$L$31,"par"&CHAR(31)&$A6&CHAR(31)&B$3)*1,0),0))),"",INDEX('Reparto de brigadas'!$A$4:$A$31,MATCH(1,INDEX(EXACT('Reparto de brigadas'!$L$4:$L$31,"par"&CHAR(31)&$A6&CHAR(31)&B$3)*1,0),0))))&" / "&IF(ISBLANK(INDEX('Reparto de brigadas'!$A$4:$A$31,(MATCH(1,INDEX(EXACT('Reparto de brigadas'!$L$4:$L$31,"par"&CHAR(31)&$A6&CHAR(31)&B$3)*1,0),0)+MATCH(1,INDEX(EXACT(INDEX('Reparto de brigadas'!$L$4:$L$31,MATCH(1,INDEX(EXACT('Reparto de brigadas'!$L$4:$L$31,"par"&CHAR(31)&$A6&CHAR(31)&B$3)*1,0),0)+1):INDEX('Reparto de brigadas'!$L$4:$L$31,ROWS('Reparto de brigadas'!$L$4:$L$31)),"par"&CHAR(31)&$A6&CHAR(31)&B$3)*1,0),0)))),"",INDEX('Reparto de brigadas'!$A$4:$A$31,(MATCH(1,INDEX(EXACT('Reparto de brigadas'!$L$4:$L$31,"par"&CHAR(31)&$A6&CHAR(31)&B$3)*1,0),0)+MATCH(1,INDEX(EXACT(INDEX('Reparto de brigadas'!$L$4:$L$31,MATCH(1,INDEX(EXACT('Reparto de brigadas'!$L$4:$L$31,"par"&CHAR(31)&$A6&CHAR(31)&B$3)*1,0),0)+1):INDEX('Reparto de brigadas'!$L$4:$L$31,ROWS('Reparto de brigadas'!$L$4:$L$31)),"par"&CHAR(31)&$A6&CHAR(31)&B$3)*1,0),0))))&IF(SUMPRODUCT(1*EXACT('Reparto de brigadas'!$L$4:$L$31,"par"&CHAR(31)&$A6&CHAR(31)&B$3))>2," (+"&(SUMPRODUCT(1*EXACT('Reparto de brigadas'!$L$4:$L$31,"par"&CHAR(31)&$A6&CHAR(31)&B$3))-2)&")",""),IF(ISNA(MATCH(1,INDEX(EXACT('Reparto de brigadas'!$L$4:$L$31,"par"&CHAR(31)&$A6&CHAR(31)&B$3)*1,0),0)),"",IF(ISBLANK(INDEX('Reparto de brigadas'!$A$4:$A$31,MATCH(1,INDEX(EXACT('Reparto de brigadas'!$L$4:$L$31,"par"&CHAR(31)&$A6&CHAR(31)&B$3)*1,0),0))),"",INDEX('Reparto de brigadas'!$A$4:$A$31,MATCH(1,INDEX(EXACT('Reparto de brigadas'!$L$4:$L$31,"par"&CHAR(31)&$A6&CHAR(31)&B$3)*1,0),0))))) | C6: =IF(SUMPRODUCT(1*EXACT('Reparto de brigadas'!$L$4:$L$31,"par"&CHAR(31)&$A6&CHAR(31)&C$3))>1,IF(ISNA(MATCH(1,INDEX(EXACT('Reparto de brigadas'!$L$4:$L$31,"par"&CHAR(31)&$A6&CHAR(31)&C$3)*1,0),0)),"",IF(ISBLANK(INDEX('Reparto de brigadas'!$A$4:$A$31,MATCH(1,INDEX(EXACT('Reparto de brigadas'!$L$4:$L$31,"par"&CHAR(31)&$A6&CHAR(31)&C$3)*1,0),0))),"",INDEX('Reparto de brigadas'!$A$4:$A$31,MATCH(1,INDEX(EXACT('Reparto de brigadas'!$L$4:$L$31,"par"&CHAR(31)&$A6&CHAR(31)&C$3)*1,0),0))))&" / "&IF(ISBLANK(INDEX('Reparto de brigadas'!$A$4:$A$31,(MATCH(1,INDEX(EXACT('Reparto de brigadas'!$L$4:$L$31,"par"&CHAR(31)&$A6&CHAR(31)&C$3)*1,0),0)+MATCH(1,INDEX(EXACT(INDEX('Reparto de brigadas'!$L$4:$L$31,MATCH(1,INDEX(EXACT('Reparto de brigadas'!$L$4:$L$31,"par"&CHAR(31)&$A6&CHAR(31)&C$3)*1,0),0)+1):INDEX('Reparto de brigadas'!$L$4:$L$31,ROWS('Reparto de brigadas'!$L$4:$L$31)),"par"&CHAR(31)&$A6&CHAR(31)&C$3)*1,0),0)))),"",INDEX('Reparto de brigadas'!$A$4:$A$31,(MATCH(1,INDEX(EXACT('Reparto de brigadas'!$L$4:$L$31,"par"&CHAR(31)&$A6&CHAR(31)&C$3)*1,0),0)+MATCH(1,INDEX(EXACT(INDEX('Reparto de brigadas'!$L$4:$L$31,MATCH(1,INDEX(EXACT('Reparto de brigadas'!$L$4:$L$31,"par"&CHAR(31)&$A6&CHAR(31)&C$3)*1,0),0)+1):INDEX('Reparto de brigadas'!$L$4:$L$31,ROWS('Reparto de brigadas'!$L$4:$L$31)),"par"&CHAR(31)&$A6&CHAR(31)&C$3)*1,0),0))))&IF(SUMPRODUCT(1*EXACT('Reparto de brigadas'!$L$4:$L$31,"par"&CHAR(31)&$A6&CHAR(31)&C$3))>2," (+"&(SUMPRODUCT(1*EXACT('Reparto de brigadas'!$L$4:$L$31,"par"&CHAR(31)&$A6&CHAR(31)&C$3))-2)&")",""),IF(ISNA(MATCH(1,INDEX(EXACT('Reparto de brigadas'!$L$4:$L$31,"par"&CHAR(31)&$A6&CHAR(31)&C$3)*1,0),0)),"",IF(ISBLANK(INDEX('Reparto de brigadas'!$A$4:$A$31,MATCH(1,INDEX(EXACT('Reparto de brigadas'!$L$4:$L$31,"par"&CHAR(31)&$A6&CHAR(31)&C$3)*1,0),0))),"",INDEX('Reparto de brigadas'!$A$4:$A$31,MATCH(1,INDEX(EXACT('Reparto de brigadas'!$L$4:$L$31,"par"&CHAR(31)&$A6&CHAR(31)&C$3)*1,0),0))))) | D6: =IF(SUMPRODUCT(1*EXACT('Reparto de brigadas'!$L$4:$L$31,"par"&CHAR(31)&$A6&CHAR(31)&D$3))>1,IF(ISNA(MATCH(1,INDEX(EXACT('Reparto de brigadas'!$L$4:$L$31,"par"&CHAR(31)&$A6&CHAR(31)&D$3)*1,0),0)),"",IF(ISBLANK(INDEX('Reparto de brigadas'!$A$4:$A$31,MATCH(1,INDEX(EXACT('Reparto de brigadas'!$L$4:$L$31,"par"&CHAR(31)&$A6&CHAR(31)&D$3)*1,0),0))),"",INDEX('Reparto de brigadas'!$A$4:$A$31,MATCH(1,INDEX(EXACT('Reparto de brigadas'!$L$4:$L$31,"par"&CHAR(31)&$A6&CHAR(31)&D$3)*1,0),0))))&" / "&IF(ISBLANK(INDEX('Reparto de brigadas'!$A$4:$A$31,(MATCH(1,INDEX(EXACT('Reparto de brigadas'!$L$4:$L$31,"par"&CHAR(31)&$A6&CHAR(31)&D$3)*1,0),0)+MATCH(1,INDEX(EXACT(INDEX('Reparto de brigadas'!$L$4:$L$31,MATCH(1,INDEX(EXACT('Reparto de brigadas'!$L$4:$L$31,"par"&CHAR(31)&$A6&CHAR(31)&D$3)*1,0),0)+1):INDEX('Reparto de brigadas'!$L$4:$L$31,ROWS('Reparto de brigadas'!$L$4:$L$31)),"par"&CHAR(31)&$A6&CHAR(31)&D$3)*1,0),0)))),"",INDEX('Reparto de brigadas'!$A$4:$A$31,(MATCH(1,INDEX(EXACT('Reparto de brigadas'!$L$4:$L$31,"par"&CHAR(31)&$A6&CHAR(31)&D$3)*1,0),0)+MATCH(1,INDEX(EXACT(INDEX('Reparto de brigadas'!$L$4:$L$31,MATCH(1,INDEX(EXACT('Reparto de brigadas'!$L$4:$L$31,"par"&CHAR(31)&$A6&CHAR(31)&D$3)*1,0),0)+1):INDEX('Reparto de brigadas'!$L$4:$L$31,ROWS('Reparto de brigadas'!$L$4:$L$31)),"par"&CHAR(31)&$A6&CHAR(31)&D$3)*1,0),0))))&IF(SUMPRODUCT(1*EXACT('Reparto de brigadas'!$L$4:$L$31,"par"&CHAR(31)&$A6&CHAR(31)&D$3))>2," (+"&(SUMPRODUCT(1*EXACT('Reparto de brigadas'!$L$4:$L$31,"par"&CHAR(31)&$A6&CHAR(31)&D$3))-2)&")",""),IF(ISNA(MATCH(1,INDEX(EXACT('Reparto de brigadas'!$L$4:$L$31,"par"&CHAR(31)&$A6&CHAR(31)&D$3)*1,0),0)),"",IF(ISBLANK(INDEX('Reparto de brigadas'!$A$4:$A$31,MATCH(1,INDEX(EXACT('Reparto de brigadas'!$L$4:$L$31,"par"&CHAR(31)&$A6&CHAR(31)&D$3)*1,0),0))),"",INDEX('Reparto de brigadas'!$A$4:$A$31,MATCH(1,INDEX(EXACT('Reparto de brigadas'!$L$4:$L$31,"par"&CHAR(31)&$A6&CHAR(31)&D$3)*1,0),0)))))
A7: Piscina | B7: =IF(SUMPRODUCT(1*EXACT('Reparto de brigadas'!$L$4:$L$31,"par"&CHAR(31)&$A7&CHAR(31)&B$3))>1,IF(ISNA(MATCH(1,INDEX(EXACT('Reparto de brigadas'!$L$4:$L$31,"par"&CHAR(31)&$A7&CHAR(31)&B$3)*1,0),0)),"",IF(ISBLANK(INDEX('Reparto de brigadas'!$A$4:$A$31,MATCH(1,INDEX(EXACT('Reparto de brigadas'!$L$4:$L$31,"par"&CHAR(31)&$A7&CHAR(31)&B$3)*1,0),0))),"",INDEX('Reparto de brigadas'!$A$4:$A$31,MATCH(1,INDEX(EXACT('Reparto de brigadas'!$L$4:$L$31,"par"&CHAR(31)&$A7&CHAR(31)&B$3)*1,0),0))))&" / "&IF(ISBLANK(INDEX('Reparto de brigadas'!$A$4:$A$31,(MATCH(1,INDEX(EXACT('Reparto de brigadas'!$L$4:$L$31,"par"&CHAR(31)&$A7&CHAR(31)&B$3)*1,0),0)+MATCH(1,INDEX(EXACT(INDEX('Reparto de brigadas'!$L$4:$L$31,MATCH(1,INDEX(EXACT('Reparto de brigadas'!$L$4:$L$31,"par"&CHAR(31)&$A7&CHAR(31)&B$3)*1,0),0)+1):INDEX('Reparto de brigadas'!$L$4:$L$31,ROWS('Reparto de brigadas'!$L$4:$L$31)),"par"&CHAR(31)&$A7&CHAR(31)&B$3)*1,0),0)))),"",INDEX('Reparto de brigadas'!$A$4:$A$31,(MATCH(1,INDEX(EXACT('Reparto de brigadas'!$L$4:$L$31,"par"&CHAR(31)&$A7&CHAR(31)&B$3)*1,0),0)+MATCH(1,INDEX(EXACT(INDEX('Reparto de brigadas'!$L$4:$L$31,MATCH(1,INDEX(EXACT('Reparto de brigadas'!$L$4:$L$31,"par"&CHAR(31)&$A7&CHAR(31)&B$3)*1,0),0)+1):INDEX('Reparto de brigadas'!$L$4:$L$31,ROWS('Reparto de brigadas'!$L$4:$L$31)),"par"&CHAR(31)&$A7&CHAR(31)&B$3)*1,0),0))))&IF(SUMPRODUCT(1*EXACT('Reparto de brigadas'!$L$4:$L$31,"par"&CHAR(31)&$A7&CHAR(31)&B$3))>2," (+"&(SUMPRODUCT(1*EXACT('Reparto de brigadas'!$L$4:$L$31,"par"&CHAR(31)&$A7&CHAR(31)&B$3))-2)&")",""),IF(ISNA(MATCH(1,INDEX(EXACT('Reparto de brigadas'!$L$4:$L$31,"par"&CHAR(31)&$A7&CHAR(31)&B$3)*1,0),0)),"",IF(ISBLANK(INDEX('Reparto de brigadas'!$A$4:$A$31,MATCH(1,INDEX(EXACT('Reparto de brigadas'!$L$4:$L$31,"par"&CHAR(31)&$A7&CHAR(31)&B$3)*1,0),0))),"",INDEX('Reparto de brigadas'!$A$4:$A$31,MATCH(1,INDEX(EXACT('Reparto de brigadas'!$L$4:$L$31,"par"&CHAR(31)&$A7&CHAR(31)&B$3)*1,0),0))))) | C7: =IF(SUMPRODUCT(1*EXACT('Reparto de brigadas'!$L$4:$L$31,"par"&CHAR(31)&$A7&CHAR(31)&C$3))>1,IF(ISNA(MATCH(1,INDEX(EXACT('Reparto de brigadas'!$L$4:$L$31,"par"&CHAR(31)&$A7&CHAR(31)&C$3)*1,0),0)),"",IF(ISBLANK(INDEX('Reparto de brigadas'!$A$4:$A$31,MATCH(1,INDEX(EXACT('Reparto de brigadas'!$L$4:$L$31,"par"&CHAR(31)&$A7&CHAR(31)&C$3)*1,0),0))),"",INDEX('Reparto de brigadas'!$A$4:$A$31,MATCH(1,INDEX(EXACT('Reparto de brigadas'!$L$4:$L$31,"par"&CHAR(31)&$A7&CHAR(31)&C$3)*1,0),0))))&" / "&IF(ISBLANK(INDEX('Reparto de brigadas'!$A$4:$A$31,(MATCH(1,INDEX(EXACT('Reparto de brigadas'!$L$4:$L$31,"par"&CHAR(31)&$A7&CHAR(31)&C$3)*1,0),0)+MATCH(1,INDEX(EXACT(INDEX('Reparto de brigadas'!$L$4:$L$31,MATCH(1,INDEX(EXACT('Reparto de brigadas'!$L$4:$L$31,"par"&CHAR(31)&$A7&CHAR(31)&C$3)*1,0),0)+1):INDEX('Reparto de brigadas'!$L$4:$L$31,ROWS('Reparto de brigadas'!$L$4:$L$31)),"par"&CHAR(31)&$A7&CHAR(31)&C$3)*1,0),0)))),"",INDEX('Reparto de brigadas'!$A$4:$A$31,(MATCH(1,INDEX(EXACT('Reparto de brigadas'!$L$4:$L$31,"par"&CHAR(31)&$A7&CHAR(31)&C$3)*1,0),0)+MATCH(1,INDEX(EXACT(INDEX('Reparto de brigadas'!$L$4:$L$31,MATCH(1,INDEX(EXACT('Reparto de brigadas'!$L$4:$L$31,"par"&CHAR(31)&$A7&CHAR(31)&C$3)*1,0),0)+1):INDEX('Reparto de brigadas'!$L$4:$L$31,ROWS('Reparto de brigadas'!$L$4:$L$31)),"par"&CHAR(31)&$A7&CHAR(31)&C$3)*1,0),0))))&IF(SUMPRODUCT(1*EXACT('Reparto de brigadas'!$L$4:$L$31,"par"&CHAR(31)&$A7&CHAR(31)&C$3))>2," (+"&(SUMPRODUCT(1*EXACT('Reparto de brigadas'!$L$4:$L$31,"par"&CHAR(31)&$A7&CHAR(31)&C$3))-2)&")",""),IF(ISNA(MATCH(1,INDEX(EXACT('Reparto de brigadas'!$L$4:$L$31,"par"&CHAR(31)&$A7&CHAR(31)&C$3)*1,0),0)),"",IF(ISBLANK(INDEX('Reparto de brigadas'!$A$4:$A$31,MATCH(1,INDEX(EXACT('Reparto de brigadas'!$L$4:$L$31,"par"&CHAR(31)&$A7&CHAR(31)&C$3)*1,0),0))),"",INDEX('Reparto de brigadas'!$A$4:$A$31,MATCH(1,INDEX(EXACT('Reparto de brigadas'!$L$4:$L$31,"par"&CHAR(31)&$A7&CHAR(31)&C$3)*1,0),0))))) | D7: =IF(SUMPRODUCT(1*EXACT('Reparto de brigadas'!$L$4:$L$31,"par"&CHAR(31)&$A7&CHAR(31)&D$3))>1,IF(ISNA(MATCH(1,INDEX(EXACT('Reparto de brigadas'!$L$4:$L$31,"par"&CHAR(31)&$A7&CHAR(31)&D$3)*1,0),0)),"",IF(ISBLANK(INDEX('Reparto de brigadas'!$A$4:$A$31,MATCH(1,INDEX(EXACT('Reparto de brigadas'!$L$4:$L$31,"par"&CHAR(31)&$A7&CHAR(31)&D$3)*1,0),0))),"",INDEX('Reparto de brigadas'!$A$4:$A$31,MATCH(1,INDEX(EXACT('Reparto de brigadas'!$L$4:$L$31,"par"&CHAR(31)&$A7&CHAR(31)&D$3)*1,0),0))))&" / "&IF(ISBLANK(INDEX('Reparto de brigadas'!$A$4:$A$31,(MATCH(1,INDEX(EXACT('Reparto de brigadas'!$L$4:$L$31,"par"&CHAR(31)&$A7&CHAR(31)&D$3)*1,0),0)+MATCH(1,INDEX(EXACT(INDEX('Reparto de brigadas'!$L$4:$L$31,MATCH(1,INDEX(EXACT('Reparto de brigadas'!$L$4:$L$31,"par"&CHAR(31)&$A7&CHAR(31)&D$3)*1,0),0)+1):INDEX('Reparto de brigadas'!$L$4:$L$31,ROWS('Reparto de brigadas'!$L$4:$L$31)),"par"&CHAR(31)&$A7&CHAR(31)&D$3)*1,0),0)))),"",INDEX('Reparto de brigadas'!$A$4:$A$31,(MATCH(1,INDEX(EXACT('Reparto de brigadas'!$L$4:$L$31,"par"&CHAR(31)&$A7&CHAR(31)&D$3)*1,0),0)+MATCH(1,INDEX(EXACT(INDEX('Reparto de brigadas'!$L$4:$L$31,MATCH(1,INDEX(EXACT('Reparto de brigadas'!$L$4:$L$31,"par"&CHAR(31)&$A7&CHAR(31)&D$3)*1,0),0)+1):INDEX('Reparto de brigadas'!$L$4:$L$31,ROWS('Reparto de brigadas'!$L$4:$L$31)),"par"&CHAR(31)&$A7&CHAR(31)&D$3)*1,0),0))))&IF(SUMPRODUCT(1*EXACT('Reparto de brigadas'!$L$4:$L$31,"par"&CHAR(31)&$A7&CHAR(31)&D$3))>2," (+"&(SUMPRODUCT(1*EXACT('Reparto de brigadas'!$L$4:$L$31,"par"&CHAR(31)&$A7&CHAR(31)&D$3))-2)&")",""),IF(ISNA(MATCH(1,INDEX(EXACT('Reparto de brigadas'!$L$4:$L$31,"par"&CHAR(31)&$A7&CHAR(31)&D$3)*1,0),0)),"",IF(ISBLANK(INDEX('Reparto de brigadas'!$A$4:$A$31,MATCH(1,INDEX(EXACT('Reparto de brigadas'!$L$4:$L$31,"par"&CHAR(31)&$A7&CHAR(31)&D$3)*1,0),0))),"",INDEX('Reparto de brigadas'!$A$4:$A$31,MATCH(1,INDEX(EXACT('Reparto de brigadas'!$L$4:$L$31,"par"&CHAR(31)&$A7&CHAR(31)&D$3)*1,0),0)))))

Sheet OI - impar
A1: Ocupacion de instalaciones - impar
A3: Instalacion | B3: 10 a.m. | C3: 11 a.m. | D3: 3 p.m.
A4: Pista 1 | B4: =IF(SUMPRODUCT(1*EXACT('Reparto de brigadas'!$L$4:$L$31,"impar"&CHAR(31)&$A4&CHAR(31)&B$3))>1,IF(ISNA(MATCH(1,INDEX(EXACT('Reparto de brigadas'!$L$4:$L$31,"impar"&CHAR(31)&$A4&CHAR(31)&B$3)*1,0),0)),"",IF(ISBLANK(INDEX('Reparto de brigadas'!$A$4:$A$31,MATCH(1,INDEX(EXACT('Reparto de brigadas'!$L$4:$L$31,"impar"&CHAR(31)&$A4&CHAR(31)&B$3)*1,0),0))),"",INDEX('Reparto de brigadas'!$A$4:$A$31,MATCH(1,INDEX(EXACT('Reparto de brigadas'!$L$4:$L$31,"impar"&CHAR(31)&$A4&CHAR(31)&B$3)*1,0),0))))&" / "&IF(ISBLANK(INDEX('Reparto de brigadas'!$A$4:$A$31,(MATCH(1,INDEX(EXACT('Reparto de brigadas'!$L$4:$L$31,"impar"&CHAR(31)&$A4&CHAR(31)&B$3)*1,0),0)+MATCH(1,INDEX(EXACT(INDEX('Reparto de brigadas'!$L$4:$L$31,MATCH(1,INDEX(EXACT('Reparto de brigadas'!$L$4:$L$31,"impar"&CHAR(31)&$A4&CHAR(31)&B$3)*1,0),0)+1):INDEX('Reparto de brigadas'!$L$4:$L$31,ROWS('Reparto de brigadas'!$L$4:$L$31)),"impar"&CHAR(31)&$A4&CHAR(31)&B$3)*1,0),0)))),"",INDEX('Reparto de brigadas'!$A$4:$A$31,(MATCH(1,INDEX(EXACT('Reparto de brigadas'!$L$4:$L$31,"impar"&CHAR(31)&$A4&CHAR(31)&B$3)*1,0),0)+MATCH(1,INDEX(EXACT(INDEX('Reparto de brigadas'!$L$4:$L$31,MATCH(1,INDEX(EXACT('Reparto de brigadas'!$L$4:$L$31,"impar"&CHAR(31)&$A4&CHAR(31)&B$3)*1,0),0)+1):INDEX('Reparto de brigadas'!$L$4:$L$31,ROWS('Reparto de brigadas'!$L$4:$L$31)),"impar"&CHAR(31)&$A4&CHAR(31)&B$3)*1,0),0))))&IF(SUMPRODUCT(1*EXACT('Reparto de brigadas'!$L$4:$L$31,"impar"&CHAR(31)&$A4&CHAR(31)&B$3))>2," (+"&(SUMPRODUCT(1*EXACT('Reparto de brigadas'!$L$4:$L$31,"impar"&CHAR(31)&$A4&CHAR(31)&B$3))-2)&")",""),IF(ISNA(MATCH(1,INDEX(EXACT('Reparto de brigadas'!$L$4:$L$31,"impar"&CHAR(31)&$A4&CHAR(31)&B$3)*1,0),0)),"",IF(ISBLANK(INDEX('Reparto de brigadas'!$A$4:$A$31,MATCH(1,INDEX(EXACT('Reparto de brigadas'!$L$4:$L$31,"impar"&CHAR(31)&$A4&CHAR(31)&B$3)*1,0),0))),"",INDEX('Reparto de brigadas'!$A$4:$A$31,MATCH(1,INDEX(EXACT('Reparto de brigadas'!$L$4:$L$31,"impar"&CHAR(31)&$A4&CHAR(31)&B$3)*1,0),0))))) | C4: =IF(SUMPRODUCT(1*EXACT('Reparto de brigadas'!$L$4:$L$31,"impar"&CHAR(31)&$A4&CHAR(31)&C$3))>1,IF(ISNA(MATCH(1,INDEX(EXACT('Reparto de brigadas'!$L$4:$L$31,"impar"&CHAR(31)&$A4&CHAR(31)&C$3)*1,0),0)),"",IF(ISBLANK(INDEX('Reparto de brigadas'!$A$4:$A$31,MATCH(1,INDEX(EXACT('Reparto de brigadas'!$L$4:$L$31,"impar"&CHAR(31)&$A4&CHAR(31)&C$3)*1,0),0))),"",INDEX('Reparto de brigadas'!$A$4:$A$31,MATCH(1,INDEX(EXACT('Reparto de brigadas'!$L$4:$L$31,"impar"&CHAR(31)&$A4&CHAR(31)&C$3)*1,0),0))))&" / "&IF(ISBLANK(INDEX('Reparto de brigadas'!$A$4:$A$31,(MATCH(1,INDEX(EXACT('Reparto de brigadas'!$L$4:$L$31,"impar"&CHAR(31)&$A4&CHAR(31)&C$3)*1,0),0)+MATCH(1,INDEX(EXACT(INDEX('Reparto de brigadas'!$L$4:$L$31,MATCH(1,INDEX(EXACT('Reparto de brigadas'!$L$4:$L$31,"impar"&CHAR(31)&$A4&CHAR(31)&C$3)*1,0),0)+1):INDEX('Reparto de brigadas'!$L$4:$L$31,ROWS('Reparto de brigadas'!$L$4:$L$31)),"impar"&CHAR(31)&$A4&CHAR(31)&C$3)*1,0),0)))),"",INDEX('Reparto de brigadas'!$A$4:$A$31,(MATCH(1,INDEX(EXACT('Reparto de brigadas'!$L$4:$L$31,"impar"&CHAR(31)&$A4&CHAR(31)&C$3)*1,0),0)+MATCH(1,INDEX(EXACT(INDEX('Reparto de brigadas'!$L$4:$L$31,MATCH(1,INDEX(EXACT('Reparto de brigadas'!$L$4:$L$31,"impar"&CHAR(31)&$A4&CHAR(31)&C$3)*1,0),0)+1):INDEX('Reparto de brigadas'!$L$4:$L$31,ROWS('Reparto de brigadas'!$L$4:$L$31)),"impar"&CHAR(31)&$A4&CHAR(31)&C$3)*1,0),0))))&IF(SUMPRODUCT(1*EXACT('Reparto de brigadas'!$L$4:$L$31,"impar"&CHAR(31)&$A4&CHAR(31)&C$3))>2," (+"&(SUMPRODUCT(1*EXACT('Reparto de brigadas'!$L$4:$L$31,"impar"&CHAR(31)&$A4&CHAR(31)&C$3))-2)&")",""),IF(ISNA(MATCH(1,INDEX(EXACT('Reparto de brigadas'!$L$4:$L$31,"impar"&CHAR(31)&$A4&CHAR(31)&C$3)*1,0),0)),"",IF(ISBLANK(INDEX('Reparto de brigadas'!$A$4:$A$31,MATCH(1,INDEX(EXACT('Reparto de brigadas'!$L$4:$L$31,"impar"&CHAR(31)&$A4&CHAR(31)&C$3)*1,0),0))),"",INDEX('Reparto de brigadas'!$A$4:$A$31,MATCH(1,INDEX(EXACT('Reparto de brigadas'!$L$4:$L$31,"impar"&CHAR(31)&$A4&CHAR(31)&C$3)*1,0),0))))) | D4: =IF(SUMPRODUCT(1*EXACT('Reparto de brigadas'!$L$4:$L$31,"impar"&CHAR(31)&$A4&CHAR(31)&D$3))>1,IF(ISNA(MATCH(1,INDEX(EXACT('Reparto de brigadas'!$L$4:$L$31,"impar"&CHAR(31)&$A4&CHAR(31)&D$3)*1,0),0)),"",IF(ISBLANK(INDEX('Reparto de brigadas'!$A$4:$A$31,MATCH(1,INDEX(EXACT('Reparto de brigadas'!$L$4:$L$31,"impar"&CHAR(31)&$A4&CHAR(31)&D$3)*1,0),0))),"",INDEX('Reparto de brigadas'!$A$4:$A$31,MATCH(1,INDEX(EXACT('Reparto de brigadas'!$L$4:$L$31,"impar"&CHAR(31)&$A4&CHAR(31)&D$3)*1,0),0))))&" / "&IF(ISBLANK(INDEX('Reparto de brigadas'!$A$4:$A$31,(MATCH(1,INDEX(EXACT('Reparto de brigadas'!$L$4:$L$31,"impar"&CHAR(31)&$A4&CHAR(31)&D$3)*1,0),0)+MATCH(1,INDEX(EXACT(INDEX('Reparto de brigadas'!$L$4:$L$31,MATCH(1,INDEX(EXACT('Reparto de brigadas'!$L$4:$L$31,"impar"&CHAR(31)&$A4&CHAR(31)&D$3)*1,0),0)+1):INDEX('Reparto de brigadas'!$L$4:$L$31,ROWS('Reparto de brigadas'!$L$4:$L$31)),"impar"&CHAR(31)&$A4&CHAR(31)&D$3)*1,0),0)))),"",INDEX('Reparto de brigadas'!$A$4:$A$31,(MATCH(1,INDEX(EXACT('Reparto de brigadas'!$L$4:$L$31,"impar"&CHAR(31)&$A4&CHAR(31)&D$3)*1,0),0)+MATCH(1,INDEX(EXACT(INDEX('Reparto de brigadas'!$L$4:$L$31,MATCH(1,INDEX(EXACT('Reparto de brigadas'!$L$4:$L$31,"impar"&CHAR(31)&$A4&CHAR(31)&D$3)*1,0),0)+1):INDEX('Reparto de brigadas'!$L$4:$L$31,ROWS('Reparto de brigadas'!$L$4:$L$31)),"impar"&CHAR(31)&$A4&CHAR(31)&D$3)*1,0),0))))&IF(SUMPRODUCT(1*EXACT('Reparto de brigadas'!$L$4:$L$31,"impar"&CHAR(31)&$A4&CHAR(31)&D$3))>2," (+"&(SUMPRODUCT(1*EXACT('Reparto de brigadas'!$L$4:$L$31,"impar"&CHAR(31)&$A4&CHAR(31)&D$3))-2)&")",""),IF(ISNA(MATCH(1,INDEX(EXACT('Reparto de brigadas'!$L$4:$L$31,"impar"&CHAR(31)&$A4&CHAR(31)&D$3)*1,0),0)),"",IF(ISBLANK(INDEX('Reparto de brigadas'!$A$4:$A$31,MATCH(1,INDEX(EXACT('Reparto de brigadas'!$L$4:$L$31,"impar"&CHAR(31)&$A4&CHAR(31)&D$3)*1,0),0))),"",INDEX('Reparto de brigadas'!$A$4:$A$31,MATCH(1,INDEX(EXACT('Reparto de brigadas'!$L$4:$L$31,"impar"&CHAR(31)&$A4&CHAR(31)&D$3)*1,0),0)))))
A5: Pista 2 | B5: =IF(SUMPRODUCT(1*EXACT('Reparto de brigadas'!$L$4:$L$31,"impar"&CHAR(31)&$A5&CHAR(31)&B$3))>1,IF(ISNA(MATCH(1,INDEX(EXACT('Reparto de brigadas'!$L$4:$L$31,"impar"&CHAR(31)&$A5&CHAR(31)&B$3)*1,0),0)),"",IF(ISBLANK(INDEX('Reparto de brigadas'!$A$4:$A$31,MATCH(1,INDEX(EXACT('Reparto de brigadas'!$L$4:$L$31,"impar"&CHAR(31)&$A5&CHAR(31)&B$3)*1,0),0))),"",INDEX('Reparto de brigadas'!$A$4:$A$31,MATCH(1,INDEX(EXACT('Reparto de brigadas'!$L$4:$L$31,"impar"&CHAR(31)&$A5&CHAR(31)&B$3)*1,0),0))))&" / "&IF(ISBLANK(INDEX('Reparto de brigadas'!$A$4:$A$31,(MATCH(1,INDEX(EXACT('Reparto de brigadas'!$L$4:$L$31,"impar"&CHAR(31)&$A5&CHAR(31)&B$3)*1,0),0)+MATCH(1,INDEX(EXACT(INDEX('Reparto de brigadas'!$L$4:$L$31,MATCH(1,INDEX(EXACT('Reparto de brigadas'!$L$4:$L$31,"impar"&CHAR(31)&$A5&CHAR(31)&B$3)*1,0),0)+1):INDEX('Reparto de brigadas'!$L$4:$L$31,ROWS('Reparto de brigadas'!$L$4:$L$31)),"impar"&CHAR(31)&$A5&CHAR(31)&B$3)*1,0),0)))),"",INDEX('Reparto de brigadas'!$A$4:$A$31,(MATCH(1,INDEX(EXACT('Reparto de brigadas'!$L$4:$L$31,"impar"&CHAR(31)&$A5&CHAR(31)&B$3)*1,0),0)+MATCH(1,INDEX(EXACT(INDEX('Reparto de brigadas'!$L$4:$L$31,MATCH(1,INDEX(EXACT('Reparto de brigadas'!$L$4:$L$31,"impar"&CHAR(31)&$A5&CHAR(31)&B$3)*1,0),0)+1):INDEX('Reparto de brigadas'!$L$4:$L$31,ROWS('Reparto de brigadas'!$L$4:$L$31)),"impar"&CHAR(31)&$A5&CHAR(31)&B$3)*1,0),0))))&IF(SUMPRODUCT(1*EXACT('Reparto de brigadas'!$L$4:$L$31,"impar"&CHAR(31)&$A5&CHAR(31)&B$3))>2," (+"&(SUMPRODUCT(1*EXACT('Reparto de brigadas'!$L$4:$L$31,"impar"&CHAR(31)&$A5&CHAR(31)&B$3))-2)&")",""),IF(ISNA(MATCH(1,INDEX(EXACT('Reparto de brigadas'!$L$4:$L$31,"impar"&CHAR(31)&$A5&CHAR(31)&B$3)*1,0),0)),"",IF(ISBLANK(INDEX('Reparto de brigadas'!$A$4:$A$31,MATCH(1,INDEX(EXACT('Reparto de brigadas'!$L$4:$L$31,"impar"&CHAR(31)&$A5&CHAR(31)&B$3)*1,0),0))),"",INDEX('Reparto de brigadas'!$A$4:$A$31,MATCH(1,INDEX(EXACT('Reparto de brigadas'!$L$4:$L$31,"impar"&CHAR(31)&$A5&CHAR(31)&B$3)*1,0),0))))) | C5: =IF(SUMPRODUCT(1*EXACT('Reparto de brigadas'!$L$4:$L$31,"impar"&CHAR(31)&$A5&CHAR(31)&C$3))>1,IF(ISNA(MATCH(1,INDEX(EXACT('Reparto de brigadas'!$L$4:$L$31,"impar"&CHAR(31)&$A5&CHAR(31)&C$3)*1,0),0)),"",IF(ISBLANK(INDEX('Reparto de brigadas'!$A$4:$A$31,MATCH(1,INDEX(EXACT('Reparto de brigadas'!$L$4:$L$31,"impar"&CHAR(31)&$A5&CHAR(31)&C$3)*1,0),0))),"",INDEX('Reparto de brigadas'!$A$4:$A$31,MATCH(1,INDEX(EXACT('Reparto de brigadas'!$L$4:$L$31,"impar"&CHAR(31)&$A5&CHAR(31)&C$3)*1,0),0))))&" / "&IF(ISBLANK(INDEX('Reparto de brigadas'!$A$4:$A$31,(MATCH(1,INDEX(EXACT('Reparto de brigadas'!$L$4:$L$31,"impar"&CHAR(31)&$A5&CHAR(31)&C$3)*1,0),0)+MATCH(1,INDEX(EXACT(INDEX('Reparto de brigadas'!$L$4:$L$31,MATCH(1,INDEX(EXACT('Reparto de brigadas'!$L$4:$L$31,"impar"&CHAR(31)&$A5&CHAR(31)&C$3)*1,0),0)+1):INDEX('Reparto de brigadas'!$L$4:$L$31,ROWS('Reparto de brigadas'!$L$4:$L$31)),"impar"&CHAR(31)&$A5&CHAR(31)&C$3)*1,0),0)))),"",INDEX('Reparto de brigadas'!$A$4:$A$31,(MATCH(1,INDEX(EXACT('Reparto de brigadas'!$L$4:$L$31,"impar"&CHAR(31)&$A5&CHAR(31)&C$3)*1,0),0)+MATCH(1,INDEX(EXACT(INDEX('Reparto de brigadas'!$L$4:$L$31,MATCH(1,INDEX(EXACT('Reparto de brigadas'!$L$4:$L$31,"impar"&CHAR(31)&$A5&CHAR(31)&C$3)*1,0),0)+1):INDEX('Reparto de brigadas'!$L$4:$L$31,ROWS('Reparto de brigadas'!$L$4:$L$31)),"impar"&CHAR(31)&$A5&CHAR(31)&C$3)*1,0),0))))&IF(SUMPRODUCT(1*EXACT('Reparto de brigadas'!$L$4:$L$31,"impar"&CHAR(31)&$A5&CHAR(31)&C$3))>2," (+"&(SUMPRODUCT(1*EXACT('Reparto de brigadas'!$L$4:$L$31,"impar"&CHAR(31)&$A5&CHAR(31)&C$3))-2)&")",""),IF(ISNA(MATCH(1,INDEX(EXACT('Reparto de brigadas'!$L$4:$L$31,"impar"&CHAR(31)&$A5&CHAR(31)&C$3)*1,0),0)),"",IF(ISBLANK(INDEX('Reparto de brigadas'!$A$4:$A$31,MATCH(1,INDEX(EXACT('Reparto de brigadas'!$L$4:$L$31,"impar"&CHAR(31)&$A5&CHAR(31)&C$3)*1,0),0))),"",INDEX('Reparto de brigadas'!$A$4:$A$31,MATCH(1,INDEX(EXACT('Reparto de brigadas'!$L$4:$L$31,"impar"&CHAR(31)&$A5&CHAR(31)&C$3)*1,0),0))))) | D5: =IF(SUMPRODUCT(1*EXACT('Reparto de brigadas'!$L$4:$L$31,"impar"&CHAR(31)&$A5&CHAR(31)&D$3))>1,IF(ISNA(MATCH(1,INDEX(EXACT('Reparto de brigadas'!$L$4:$L$31,"impar"&CHAR(31)&$A5&CHAR(31)&D$3)*1,0),0)),"",IF(ISBLANK(INDEX('Reparto de brigadas'!$A$4:$A$31,MATCH(1,INDEX(EXACT('Reparto de brigadas'!$L$4:$L$31,"impar"&CHAR(31)&$A5&CHAR(31)&D$3)*1,0),0))),"",INDEX('Reparto de brigadas'!$A$4:$A$31,MATCH(1,INDEX(EXACT('Reparto de brigadas'!$L$4:$L$31,"impar"&CHAR(31)&$A5&CHAR(31)&D$3)*1,0),0))))&" / "&IF(ISBLANK(INDEX('Reparto de brigadas'!$A$4:$A$31,(MATCH(1,INDEX(EXACT('Reparto de brigadas'!$L$4:$L$31,"impar"&CHAR(31)&$A5&CHAR(31)&D$3)*1,0),0)+MATCH(1,INDEX(EXACT(INDEX('Reparto de brigadas'!$L$4:$L$31,MATCH(1,INDEX(EXACT('Reparto de brigadas'!$L$4:$L$31,"impar"&CHAR(31)&$A5&CHAR(31)&D$3)*1,0),0)+1):INDEX('Reparto de brigadas'!$L$4:$L$31,ROWS('Reparto de brigadas'!$L$4:$L$31)),"impar"&CHAR(31)&$A5&CHAR(31)&D$3)*1,0),0)))),"",INDEX('Reparto de brigadas'!$A$4:$A$31,(MATCH(1,INDEX(EXACT('Reparto de brigadas'!$L$4:$L$31,"impar"&CHAR(31)&$A5&CHAR(31)&D$3)*1,0),0)+MATCH(1,INDEX(EXACT(INDEX('Reparto de brigadas'!$L$4:$L$31,MATCH(1,INDEX(EXACT('Reparto de brigadas'!$L$4:$L$31,"impar"&CHAR(31)&$A5&CHAR(31)&D$3)*1,0),0)+1):INDEX('Reparto de brigadas'!$L$4:$L$31,ROWS('Reparto de brigadas'!$L$4:$L$31)),"impar"&CHAR(31)&$A5&CHAR(31)&D$3)*1,0),0))))&IF(SUMPRODUCT(1*EXACT('Reparto de brigadas'!$L$4:$L$31,"impar"&CHAR(31)&$A5&CHAR(31)&D$3))>2," (+"&(SUMPRODUCT(1*EXACT('Reparto de brigadas'!$L$4:$L$31,"impar"&CHAR(31)&$A5&CHAR(31)&D$3))-2)&")",""),IF(ISNA(MATCH(1,INDEX(EXACT('Reparto de brigadas'!$L$4:$L$31,"impar"&CHAR(31)&$A5&CHAR(31)&D$3)*1,0),0)),"",IF(ISBLANK(INDEX('Reparto de brigadas'!$A$4:$A$31,MATCH(1,INDEX(EXACT('Reparto de brigadas'!$L$4:$L$31,"impar"&CHAR(31)&$A5&CHAR(31)&D$3)*1,0),0))),"",INDEX('Reparto de brigadas'!$A$4:$A$31,MATCH(1,INDEX(EXACT('Reparto de brigadas'!$L$4:$L$31,"impar"&CHAR(31)&$A5&CHAR(31)&D$3)*1,0),0)))))
A6: Gimnasio | B6: =IF(SUMPRODUCT(1*EXACT('Reparto de brigadas'!$L$4:$L$31,"impar"&CHAR(31)&$A6&CHAR(31)&B$3))>1,IF(ISNA(MATCH(1,INDEX(EXACT('Reparto de brigadas'!$L$4:$L$31,"impar"&CHAR(31)&$A6&CHAR(31)&B$3)*1,0),0)),"",IF(ISBLANK(INDEX('Reparto de brigadas'!$A$4:$A$31,MATCH(1,INDEX(EXACT('Reparto de brigadas'!$L$4:$L$31,"impar"&CHAR(31)&$A6&CHAR(31)&B$3)*1,0),0))),"",INDEX('Reparto de brigadas'!$A$4:$A$31,MATCH(1,INDEX(EXACT('Reparto de brigadas'!$L$4:$L$31,"impar"&CHAR(31)&$A6&CHAR(31)&B$3)*1,0),0))))&" / "&IF(ISBLANK(INDEX('Reparto de brigadas'!$A$4:$A$31,(MATCH(1,INDEX(EXACT('Reparto de brigadas'!$L$4:$L$31,"impar"&CHAR(31)&$A6&CHAR(31)&B$3)*1,0),0)+MATCH(1,INDEX(EXACT(INDEX('Reparto de brigadas'!$L$4:$L$31,MATCH(1,INDEX(EXACT('Reparto de brigadas'!$L$4:$L$31,"impar"&CHAR(31)&$A6&CHAR(31)&B$3)*1,0),0)+1):INDEX('Reparto de brigadas'!$L$4:$L$31,ROWS('Reparto de brigadas'!$L$4:$L$31)),"impar"&CHAR(31)&$A6&CHAR(31)&B$3)*1,0),0)))),"",INDEX('Reparto de brigadas'!$A$4:$A$31,(MATCH(1,INDEX(EXACT('Reparto de brigadas'!$L$4:$L$31,"impar"&CHAR(31)&$A6&CHAR(31)&B$3)*1,0),0)+MATCH(1,INDEX(EXACT(INDEX('Reparto de brigadas'!$L$4:$L$31,MATCH(1,INDEX(EXACT('Reparto de brigadas'!$L$4:$L$31,"impar"&CHAR(31)&$A6&CHAR(31)&B$3)*1,0),0)+1):INDEX('Reparto de brigadas'!$L$4:$L$31,ROWS('Reparto de brigadas'!$L$4:$L$31)),"impar"&CHAR(31)&$A6&CHAR(31)&B$3)*1,0),0))))&IF(SUMPRODUCT(1*EXACT('Reparto de brigadas'!$L$4:$L$31,"impar"&CHAR(31)&$A6&CHAR(31)&B$3))>2," (+"&(SUMPRODUCT(1*EXACT('Reparto de brigadas'!$L$4:$L$31,"impar"&CHAR(31)&$A6&CHAR(31)&B$3))-2)&")",""),IF(ISNA(MATCH(1,INDEX(EXACT('Reparto de brigadas'!$L$4:$L$31,"impar"&CHAR(31)&$A6&CHAR(31)&B$3)*1,0),0)),"",IF(ISBLANK(INDEX('Reparto de brigadas'!$A$4:$A$31,MATCH(1,INDEX(EXACT('Reparto de brigadas'!$L$4:$L$31,"impar"&CHAR(31)&$A6&CHAR(31)&B$3)*1,0),0))),"",INDEX('Reparto de brigadas'!$A$4:$A$31,MATCH(1,INDEX(EXACT('Reparto de brigadas'!$L$4:$L$31,"impar"&CHAR(31)&$A6&CHAR(31)&B$3)*1,0),0))))) | C6: =IF(SUMPRODUCT(1*EXACT('Reparto de brigadas'!$L$4:$L$31,"impar"&CHAR(31)&$A6&CHAR(31)&C$3))>1,IF(ISNA(MATCH(1,INDEX(EXACT('Reparto de brigadas'!$L$4:$L$31,"impar"&CHAR(31)&$A6&CHAR(31)&C$3)*1,0),0)),"",IF(ISBLANK(INDEX('Reparto de brigadas'!$A$4:$A$31,MATCH(1,INDEX(EXACT('Reparto de brigadas'!$L$4:$L$31,"impar"&CHAR(31)&$A6&CHAR(31)&C$3)*1,0),0))),"",INDEX('Reparto de brigadas'!$A$4:$A$31,MATCH(1,INDEX(EXACT('Reparto de brigadas'!$L$4:$L$31,"impar"&CHAR(31)&$A6&CHAR(31)&C$3)*1,0),0))))&" / "&IF(ISBLANK(INDEX('Reparto de brigadas'!$A$4:$A$31,(MATCH(1,INDEX(EXACT('Reparto de brigadas'!$L$4:$L$31,"impar"&CHAR(31)&$A6&CHAR(31)&C$3)*1,0),0)+MATCH(1,INDEX(EXACT(INDEX('Reparto de brigadas'!$L$4:$L$31,MATCH(1,INDEX(EXACT('Reparto de brigadas'!$L$4:$L$31,"impar"&CHAR(31)&$A6&CHAR(31)&C$3)*1,0),0)+1):INDEX('Reparto de brigadas'!$L$4:$L$31,ROWS('Reparto de brigadas'!$L$4:$L$31)),"impar"&CHAR(31)&$A6&CHAR(31)&C$3)*1,0),0)))),"",INDEX('Reparto de brigadas'!$A$4:$A$31,(MATCH(1,INDEX(EXACT('Reparto de brigadas'!$L$4:$L$31,"impar"&CHAR(31)&$A6&CHAR(31)&C$3)*1,0),0)+MATCH(1,INDEX(EXACT(INDEX('Reparto de brigadas'!$L$4:$L$31,MATCH(1,INDEX(EXACT('Reparto de brigadas'!$L$4:$L$31,"impar"&CHAR(31)&$A6&CHAR(31)&C$3)*1,0),0)+1):INDEX('Reparto de brigadas'!$L$4:$L$31,ROWS('Reparto de brigadas'!$L$4:$L$31)),"impar"&CHAR(31)&$A6&CHAR(31)&C$3)*1,0),0))))&IF(SUMPRODUCT(1*EXACT('Reparto de brigadas'!$L$4:$L$31,"impar"&CHAR(31)&$A6&CHAR(31)&C$3))>2," (+"&(SUMPRODUCT(1*EXACT('Reparto de brigadas'!$L$4:$L$31,"impar"&CHAR(31)&$A6&CHAR(31)&C$3))-2)&")",""),IF(ISNA(MATCH(1,INDEX(EXACT('Reparto de brigadas'!$L$4:$L$31,"impar"&CHAR(31)&$A6&CHAR(31)&C$3)*1,0),0)),"",IF(ISBLANK(INDEX('Reparto de brigadas'!$A$4:$A$31,MATCH(1,INDEX(EXACT('Reparto de brigadas'!$L$4:$L$31,"impar"&CHAR(31)&$A6&CHAR(31)&C$3)*1,0),0))),"",INDEX('Reparto de brigadas'!$A$4:$A$31,MATCH(1,INDEX(EXACT('Reparto de brigadas'!$L$4:$L$31,"impar"&CHAR(31)&$A6&CHAR(31)&C$3)*1,0),0))))) | D6: =IF(SUMPRODUCT(1*EXACT('Reparto de brigadas'!$L$4:$L$31,"impar"&CHAR(31)&$A6&CHAR(31)&D$3))>1,IF(ISNA(MATCH(1,INDEX(EXACT('Reparto de brigadas'!$L$4:$L$31,"impar"&CHAR(31)&$A6&CHAR(31)&D$3)*1,0),0)),"",IF(ISBLANK(INDEX('Reparto de brigadas'!$A$4:$A$31,MATCH(1,INDEX(EXACT('Reparto de brigadas'!$L$4:$L$31,"impar"&CHAR(31)&$A6&CHAR(31)&D$3)*1,0),0))),"",INDEX('Reparto de brigadas'!$A$4:$A$31,MATCH(1,INDEX(EXACT('Reparto de brigadas'!$L$4:$L$31,"impar"&CHAR(31)&$A6&CHAR(31)&D$3)*1,0),0))))&" / "&IF(ISBLANK(INDEX('Reparto de brigadas'!$A$4:$A$31,(MATCH(1,INDEX(EXACT('Reparto de brigadas'!$L$4:$L$31,"impar"&CHAR(31)&$A6&CHAR(31)&D$3)*1,0),0)+MATCH(1,INDEX(EXACT(INDEX('Reparto de brigadas'!$L$4:$L$31,MATCH(1,INDEX(EXACT('Reparto de brigadas'!$L$4:$L$31,"impar"&CHAR(31)&$A6&CHAR(31)&D$3)*1,0),0)+1):INDEX('Reparto de brigadas'!$L$4:$L$31,ROWS('Reparto de brigadas'!$L$4:$L$31)),"impar"&CHAR(31)&$A6&CHAR(31)&D$3)*1,0),0)))),"",INDEX('Reparto de brigadas'!$A$4:$A$31,(MATCH(1,INDEX(EXACT('Reparto de brigadas'!$L$4:$L$31,"impar"&CHAR(31)&$A6&CHAR(31)&D$3)*1,0),0)+MATCH(1,INDEX(EXACT(INDEX('Reparto de brigadas'!$L$4:$L$31,MATCH(1,INDEX(EXACT('Reparto de brigadas'!$L$4:$L$31,"impar"&CHAR(31)&$A6&CHAR(31)&D$3)*1,0),0)+1):INDEX('Reparto de brigadas'!$L$4:$L$31,ROWS('Reparto de brigadas'!$L$4:$L$31)),"impar"&CHAR(31)&$A6&CHAR(31)&D$3)*1,0),0))))&IF(SUMPRODUCT(1*EXACT('Reparto de brigadas'!$L$4:$L$31,"impar"&CHAR(31)&$A6&CHAR(31)&D$3))>2," (+"&(SUMPRODUCT(1*EXACT('Reparto de brigadas'!$L$4:$L$31,"impar"&CHAR(31)&$A6&CHAR(31)&D$3))-2)&")",""),IF(ISNA(MATCH(1,INDEX(EXACT('Reparto de brigadas'!$L$4:$L$31,"impar"&CHAR(31)&$A6&CHAR(31)&D$3)*1,0),0)),"",IF(ISBLANK(INDEX('Reparto de brigadas'!$A$4:$A$31,MATCH(1,INDEX(EXACT('Reparto de brigadas'!$L$4:$L$31,"impar"&CHAR(31)&$A6&CHAR(31)&D$3)*1,0),0))),"",INDEX('Reparto de brigadas'!$A$4:$A$31,MATCH(1,INDEX(EXACT('Reparto de brigadas'!$L$4:$L$31,"impar"&CHAR(31)&$A6&CHAR(31)&D$3)*1,0),0)))))
A7: Piscina | B7: =IF(SUMPRODUCT(1*EXACT('Reparto de brigadas'!$L$4:$L$31,"impar"&CHAR(31)&$A7&CHAR(31)&B$3))>1,IF(ISNA(MATCH(1,INDEX(EXACT('Reparto de brigadas'!$L$4:$L$31,"impar"&CHAR(31)&$A7&CHAR(31)&B$3)*1,0),0)),"",IF(ISBLANK(INDEX('Reparto de brigadas'!$A$4:$A$31,MATCH(1,INDEX(EXACT('Reparto de brigadas'!$L$4:$L$31,"impar"&CHAR(31)&$A7&CHAR(31)&B$3)*1,0),0))),"",INDEX('Reparto de brigadas'!$A$4:$A$31,MATCH(1,INDEX(EXACT('Reparto de brigadas'!$L$4:$L$31,"impar"&CHAR(31)&$A7&CHAR(31)&B$3)*1,0),0))))&" / "&IF(ISBLANK(INDEX('Reparto de brigadas'!$A$4:$A$31,(MATCH(1,INDEX(EXACT('Reparto de brigadas'!$L$4:$L$31,"impar"&CHAR(31)&$A7&CHAR(31)&B$3)*1,0),0)+MATCH(1,INDEX(EXACT(INDEX('Reparto de brigadas'!$L$4:$L$31,MATCH(1,INDEX(EXACT('Reparto de brigadas'!$L$4:$L$31,"impar"&CHAR(31)&$A7&CHAR(31)&B$3)*1,0),0)+1):INDEX('Reparto de brigadas'!$L$4:$L$31,ROWS('Reparto de brigadas'!$L$4:$L$31)),"impar"&CHAR(31)&$A7&CHAR(31)&B$3)*1,0),0)))),"",INDEX('Reparto de brigadas'!$A$4:$A$31,(MATCH(1,INDEX(EXACT('Reparto de brigadas'!$L$4:$L$31,"impar"&CHAR(31)&$A7&CHAR(31)&B$3)*1,0),0)+MATCH(1,INDEX(EXACT(INDEX('Reparto de brigadas'!$L$4:$L$31,MATCH(1,INDEX(EXACT('Reparto de brigadas'!$L$4:$L$31,"impar"&CHAR(31)&$A7&CHAR(31)&B$3)*1,0),0)+1):INDEX('Reparto de brigadas'!$L$4:$L$31,ROWS('Reparto de brigadas'!$L$4:$L$31)),"impar"&CHAR(31)&$A7&CHAR(31)&B$3)*1,0),0))))&IF(SUMPRODUCT(1*EXACT('Reparto de brigadas'!$L$4:$L$31,"impar"&CHAR(31)&$A7&CHAR(31)&B$3))>2," (+"&(SUMPRODUCT(1*EXACT('Reparto de brigadas'!$L$4:$L$31,"impar"&CHAR(31)&$A7&CHAR(31)&B$3))-2)&")",""),IF(ISNA(MATCH(1,INDEX(EXACT('Reparto de brigadas'!$L$4:$L$31,"impar"&CHAR(31)&$A7&CHAR(31)&B$3)*1,0),0)),"",IF(ISBLANK(INDEX('Reparto de brigadas'!$A$4:$A$31,MATCH(1,INDEX(EXACT('Reparto de brigadas'!$L$4:$L$31,"impar"&CHAR(31)&$A7&CHAR(31)&B$3)*1,0),0))),"",INDEX('Reparto de brigadas'!$A$4:$A$31,MATCH(1,INDEX(EXACT('Reparto de brigadas'!$L$4:$L$31,"impar"&CHAR(31)&$A7&CHAR(31)&B$3)*1,0),0))))) | C7: =IF(SUMPRODUCT(1*EXACT('Reparto de brigadas'!$L$4:$L$31,"impar"&CHAR(31)&$A7&CHAR(31)&C$3))>1,IF(ISNA(MATCH(1,INDEX(EXACT('Reparto de brigadas'!$L$4:$L$31,"impar"&CHAR(31)&$A7&CHAR(31)&C$3)*1,0),0)),"",IF(ISBLANK(INDEX('Reparto de brigadas'!$A$4:$A$31,MATCH(1,INDEX(EXACT('Reparto de brigadas'!$L$4:$L$31,"impar"&CHAR(31)&$A7&CHAR(31)&C$3)*1,0),0))),"",INDEX('Reparto de brigadas'!$A$4:$A$31,MATCH(1,INDEX(EXACT('Reparto de brigadas'!$L$4:$L$31,"impar"&CHAR(31)&$A7&CHAR(31)&C$3)*1,0),0))))&" / "&IF(ISBLANK(INDEX('Reparto de brigadas'!$A$4:$A$31,(MATCH(1,INDEX(EXACT('Reparto de brigadas'!$L$4:$L$31,"impar"&CHAR(31)&$A7&CHAR(31)&C$3)*1,0),0)+MATCH(1,INDEX(EXACT(INDEX('Reparto de brigadas'!$L$4:$L$31,MATCH(1,INDEX(EXACT('Reparto de brigadas'!$L$4:$L$31,"impar"&CHAR(31)&$A7&CHAR(31)&C$3)*1,0),0)+1):INDEX('Reparto de brigadas'!$L$4:$L$31,ROWS('Reparto de brigadas'!$L$4:$L$31)),"impar"&CHAR(31)&$A7&CHAR(31)&C$3)*1,0),0)))),"",INDEX('Reparto de brigadas'!$A$4:$A$31,(MATCH(1,INDEX(EXACT('Reparto de brigadas'!$L$4:$L$31,"impar"&CHAR(31)&$A7&CHAR(31)&C$3)*1,0),0)+MATCH(1,INDEX(EXACT(INDEX('Reparto de brigadas'!$L$4:$L$31,MATCH(1,INDEX(EXACT('Reparto de brigadas'!$L$4:$L$31,"impar"&CHAR(31)&$A7&CHAR(31)&C$3)*1,0),0)+1):INDEX('Reparto de brigadas'!$L$4:$L$31,ROWS('Reparto de brigadas'!$L$4:$L$31)),"impar"&CHAR(31)&$A7&CHAR(31)&C$3)*1,0),0))))&IF(SUMPRODUCT(1*EXACT('Reparto de brigadas'!$L$4:$L$31,"impar"&CHAR(31)&$A7&CHAR(31)&C$3))>2," (+"&(SUMPRODUCT(1*EXACT('Reparto de brigadas'!$L$4:$L$31,"impar"&CHAR(31)&$A7&CHAR(31)&C$3))-2)&")",""),IF(ISNA(MATCH(1,INDEX(EXACT('Reparto de brigadas'!$L$4:$L$31,"impar"&CHAR(31)&$A7&CHAR(31)&C$3)*1,0),0)),"",IF(ISBLANK(INDEX('Reparto de brigadas'!$A$4:$A$31,MATCH(1,INDEX(EXACT('Reparto de brigadas'!$L$4:$L$31,"impar"&CHAR(31)&$A7&CHAR(31)&C$3)*1,0),0))),"",INDEX('Reparto de brigadas'!$A$4:$A$31,MATCH(1,INDEX(EXACT('Reparto de brigadas'!$L$4:$L$31,"impar"&CHAR(31)&$A7&CHAR(31)&C$3)*1,0),0))))) | D7: =IF(SUMPRODUCT(1*EXACT('Reparto de brigadas'!$L$4:$L$31,"impar"&CHAR(31)&$A7&CHAR(31)&D$3))>1,IF(ISNA(MATCH(1,INDEX(EXACT('Reparto de brigadas'!$L$4:$L$31,"impar"&CHAR(31)&$A7&CHAR(31)&D$3)*1,0),0)),"",IF(ISBLANK(INDEX('Reparto de brigadas'!$A$4:$A$31,MATCH(1,INDEX(EXACT('Reparto de brigadas'!$L$4:$L$31,"impar"&CHAR(31)&$A7&CHAR(31)&D$3)*1,0),0))),"",INDEX('Reparto de brigadas'!$A$4:$A$31,MATCH(1,INDEX(EXACT('Reparto de brigadas'!$L$4:$L$31,"impar"&CHAR(31)&$A7&CHAR(31)&D$3)*1,0),0))))&" / "&IF(ISBLANK(INDEX('Reparto de brigadas'!$A$4:$A$31,(MATCH(1,INDEX(EXACT('Reparto de brigadas'!$L$4:$L$31,"impar"&CHAR(31)&$A7&CHAR(31)&D$3)*1,0),0)+MATCH(1,INDEX(EXACT(INDEX('Reparto de brigadas'!$L$4:$L$31,MATCH(1,INDEX(EXACT('Reparto de brigadas'!$L$4:$L$31,"impar"&CHAR(31)&$A7&CHAR(31)&D$3)*1,0),0)+1):INDEX('Reparto de brigadas'!$L$4:$L$31,ROWS('Reparto de brigadas'!$L$4:$L$31)),"impar"&CHAR(31)&$A7&CHAR(31)&D$3)*1,0),0)))),"",INDEX('Reparto de brigadas'!$A$4:$A$31,(MATCH(1,INDEX(EXACT('Reparto de brigadas'!$L$4:$L$31,"impar"&CHAR(31)&$A7&CHAR(31)&D$3)*1,0),0)+MATCH(1,INDEX(EXACT(INDEX('Reparto de brigadas'!$L$4:$L$31,MATCH(1,INDEX(EXACT('Reparto de brigadas'!$L$4:$L$31,"impar"&CHAR(31)&$A7&CHAR(31)&D$3)*1,0),0)+1):INDEX('Reparto de brigadas'!$L$4:$L$31,ROWS('Reparto de brigadas'!$L$4:$L$31)),"impar"&CHAR(31)&$A7&CHAR(31)&D$3)*1,0),0))))&IF(SUMPRODUCT(1*EXACT('Reparto de brigadas'!$L$4:$L$31,"impar"&CHAR(31)&$A7&CHAR(31)&D$3))>2," (+"&(SUMPRODUCT(1*EXACT('Reparto de brigadas'!$L$4:$L$31,"impar"&CHAR(31)&$A7&CHAR(31)&D$3))-2)&")",""),IF(ISNA(MATCH(1,INDEX(EXACT('Reparto de brigadas'!$L$4:$L$31,"impar"&CHAR(31)&$A7&CHAR(31)&D$3)*1,0),0)),"",IF(ISBLANK(INDEX('Reparto de brigadas'!$A$4:$A$31,MATCH(1,INDEX(EXACT('Reparto de brigadas'!$L$4:$L$31,"impar"&CHAR(31)&$A7&CHAR(31)&D$3)*1,0),0))),"",INDEX('Reparto de brigadas'!$A$4:$A$31,MATCH(1,INDEX(EXACT('Reparto de brigadas'!$L$4:$L$31,"impar"&CHAR(31)&$A7&CHAR(31)&D$3)*1,0),0)))))

Sheet HP - Prof. Alvarez
A1: Horario del profesor - Prof. Alvarez
A3: Horario | B3: par | C3: impar
A4: 10 a.m. | B4: =IF(SUMPRODUCT(1*EXACT('Reparto de brigadas'!$M$4:$M$31,"Prof. Alvarez"&CHAR(31)&$A4&CHAR(31)&B$3))>1,IF(ISNA(MATCH(1,INDEX(EXACT('Reparto de brigadas'!$M$4:$M$31,"Prof. Alvarez"&CHAR(31)&$A4&CHAR(31)&B$3)*1,0),0)),"",IF(ISBLANK(INDEX('Reparto de brigadas'!$A$4:$A$31,MATCH(1,INDEX(EXACT('Reparto de brigadas'!$M$4:$M$31,"Prof. Alvarez"&CHAR(31)&$A4&CHAR(31)&B$3)*1,0),0))),"",INDEX('Reparto de brigadas'!$A$4:$A$31,MATCH(1,INDEX(EXACT('Reparto de brigadas'!$M$4:$M$31,"Prof. Alvarez"&CHAR(31)&$A4&CHAR(31)&B$3)*1,0),0))))&" / "&IF(ISBLANK(INDEX('Reparto de brigadas'!$A$4:$A$31,(MATCH(1,INDEX(EXACT('Reparto de brigadas'!$M$4:$M$31,"Prof. Alvarez"&CHAR(31)&$A4&CHAR(31)&B$3)*1,0),0)+MATCH(1,INDEX(EXACT(INDEX('Reparto de brigadas'!$M$4:$M$31,MATCH(1,INDEX(EXACT('Reparto de brigadas'!$M$4:$M$31,"Prof. Alvarez"&CHAR(31)&$A4&CHAR(31)&B$3)*1,0),0)+1):INDEX('Reparto de brigadas'!$M$4:$M$31,ROWS('Reparto de brigadas'!$M$4:$M$31)),"Prof. Alvarez"&CHAR(31)&$A4&CHAR(31)&B$3)*1,0),0)))),"",INDEX('Reparto de brigadas'!$A$4:$A$31,(MATCH(1,INDEX(EXACT('Reparto de brigadas'!$M$4:$M$31,"Prof. Alvarez"&CHAR(31)&$A4&CHAR(31)&B$3)*1,0),0)+MATCH(1,INDEX(EXACT(INDEX('Reparto de brigadas'!$M$4:$M$31,MATCH(1,INDEX(EXACT('Reparto de brigadas'!$M$4:$M$31,"Prof. Alvarez"&CHAR(31)&$A4&CHAR(31)&B$3)*1,0),0)+1):INDEX('Reparto de brigadas'!$M$4:$M$31,ROWS('Reparto de brigadas'!$M$4:$M$31)),"Prof. Alvarez"&CHAR(31)&$A4&CHAR(31)&B$3)*1,0),0))))&IF(SUMPRODUCT(1*EXACT('Reparto de brigadas'!$M$4:$M$31,"Prof. Alvarez"&CHAR(31)&$A4&CHAR(31)&B$3))>2," (+"&(SUMPRODUCT(1*EXACT('Reparto de brigadas'!$M$4:$M$31,"Prof. Alvarez"&CHAR(31)&$A4&CHAR(31)&B$3))-2)&")",""),IF(ISNA(MATCH(1,INDEX(EXACT('Reparto de brigadas'!$M$4:$M$31,"Prof. Alvarez"&CHAR(31)&$A4&CHAR(31)&B$3)*1,0),0)),"",IF(ISBLANK(INDEX('Reparto de brigadas'!$A$4:$A$31,MATCH(1,INDEX(EXACT('Reparto de brigadas'!$M$4:$M$31,"Prof. Alvarez"&CHAR(31)&$A4&CHAR(31)&B$3)*1,0),0))),"",INDEX('Reparto de brigadas'!$A$4:$A$31,MATCH(1,INDEX(EXACT('Reparto de brigadas'!$M$4:$M$31,"Prof. Alvarez"&CHAR(31)&$A4&CHAR(31)&B$3)*1,0),0))))) | C4: =IF(SUMPRODUCT(1*EXACT('Reparto de brigadas'!$M$4:$M$31,"Prof. Alvarez"&CHAR(31)&$A4&CHAR(31)&C$3))>1,IF(ISNA(MATCH(1,INDEX(EXACT('Reparto de brigadas'!$M$4:$M$31,"Prof. Alvarez"&CHAR(31)&$A4&CHAR(31)&C$3)*1,0),0)),"",IF(ISBLANK(INDEX('Reparto de brigadas'!$A$4:$A$31,MATCH(1,INDEX(EXACT('Reparto de brigadas'!$M$4:$M$31,"Prof. Alvarez"&CHAR(31)&$A4&CHAR(31)&C$3)*1,0),0))),"",INDEX('Reparto de brigadas'!$A$4:$A$31,MATCH(1,INDEX(EXACT('Reparto de brigadas'!$M$4:$M$31,"Prof. Alvarez"&CHAR(31)&$A4&CHAR(31)&C$3)*1,0),0))))&" / "&IF(ISBLANK(INDEX('Reparto de brigadas'!$A$4:$A$31,(MATCH(1,INDEX(EXACT('Reparto de brigadas'!$M$4:$M$31,"Prof. Alvarez"&CHAR(31)&$A4&CHAR(31)&C$3)*1,0),0)+MATCH(1,INDEX(EXACT(INDEX('Reparto de brigadas'!$M$4:$M$31,MATCH(1,INDEX(EXACT('Reparto de brigadas'!$M$4:$M$31,"Prof. Alvarez"&CHAR(31)&$A4&CHAR(31)&C$3)*1,0),0)+1):INDEX('Reparto de brigadas'!$M$4:$M$31,ROWS('Reparto de brigadas'!$M$4:$M$31)),"Prof. Alvarez"&CHAR(31)&$A4&CHAR(31)&C$3)*1,0),0)))),"",INDEX('Reparto de brigadas'!$A$4:$A$31,(MATCH(1,INDEX(EXACT('Reparto de brigadas'!$M$4:$M$31,"Prof. Alvarez"&CHAR(31)&$A4&CHAR(31)&C$3)*1,0),0)+MATCH(1,INDEX(EXACT(INDEX('Reparto de brigadas'!$M$4:$M$31,MATCH(1,INDEX(EXACT('Reparto de brigadas'!$M$4:$M$31,"Prof. Alvarez"&CHAR(31)&$A4&CHAR(31)&C$3)*1,0),0)+1):INDEX('Reparto de brigadas'!$M$4:$M$31,ROWS('Reparto de brigadas'!$M$4:$M$31)),"Prof. Alvarez"&CHAR(31)&$A4&CHAR(31)&C$3)*1,0),0))))&IF(SUMPRODUCT(1*EXACT('Reparto de brigadas'!$M$4:$M$31,"Prof. Alvarez"&CHAR(31)&$A4&CHAR(31)&C$3))>2," (+"&(SUMPRODUCT(1*EXACT('Reparto de brigadas'!$M$4:$M$31,"Prof. Alvarez"&CHAR(31)&$A4&CHAR(31)&C$3))-2)&")",""),IF(ISNA(MATCH(1,INDEX(EXACT('Reparto de brigadas'!$M$4:$M$31,"Prof. Alvarez"&CHAR(31)&$A4&CHAR(31)&C$3)*1,0),0)),"",IF(ISBLANK(INDEX('Reparto de brigadas'!$A$4:$A$31,MATCH(1,INDEX(EXACT('Reparto de brigadas'!$M$4:$M$31,"Prof. Alvarez"&CHAR(31)&$A4&CHAR(31)&C$3)*1,0),0))),"",INDEX('Reparto de brigadas'!$A$4:$A$31,MATCH(1,INDEX(EXACT('Reparto de brigadas'!$M$4:$M$31,"Prof. Alvarez"&CHAR(31)&$A4&CHAR(31)&C$3)*1,0),0)))))
A5: 11 a.m. | B5: =IF(SUMPRODUCT(1*EXACT('Reparto de brigadas'!$M$4:$M$31,"Prof. Alvarez"&CHAR(31)&$A5&CHAR(31)&B$3))>1,IF(ISNA(MATCH(1,INDEX(EXACT('Reparto de brigadas'!$M$4:$M$31,"Prof. Alvarez"&CHAR(31)&$A5&CHAR(31)&B$3)*1,0),0)),"",IF(ISBLANK(INDEX('Reparto de brigadas'!$A$4:$A$31,MATCH(1,INDEX(EXACT('Reparto de brigadas'!$M$4:$M$31,"Prof. Alvarez"&CHAR(31)&$A5&CHAR(31)&B$3)*1,0),0))),"",INDEX('Reparto de brigadas'!$A$4:$A$31,MATCH(1,INDEX(EXACT('Reparto de brigadas'!$M$4:$M$31,"Prof. Alvarez"&CHAR(31)&$A5&CHAR(31)&B$3)*1,0),0))))&" / "&IF(ISBLANK(INDEX('Reparto de brigadas'!$A$4:$A$31,(MATCH(1,INDEX(EXACT('Reparto de brigadas'!$M$4:$M$31,"Prof. Alvarez"&CHAR(31)&$A5&CHAR(31)&B$3)*1,0),0)+MATCH(1,INDEX(EXACT(INDEX('Reparto de brigadas'!$M$4:$M$31,MATCH(1,INDEX(EXACT('Reparto de brigadas'!$M$4:$M$31,"Prof. Alvarez"&CHAR(31)&$A5&CHAR(31)&B$3)*1,0),0)+1):INDEX('Reparto de brigadas'!$M$4:$M$31,ROWS('Reparto de brigadas'!$M$4:$M$31)),"Prof. Alvarez"&CHAR(31)&$A5&CHAR(31)&B$3)*1,0),0)))),"",INDEX('Reparto de brigadas'!$A$4:$A$31,(MATCH(1,INDEX(EXACT('Reparto de brigadas'!$M$4:$M$31,"Prof. Alvarez"&CHAR(31)&$A5&CHAR(31)&B$3)*1,0),0)+MATCH(1,INDEX(EXACT(INDEX('Reparto de brigadas'!$M$4:$M$31,MATCH(1,INDEX(EXACT('Reparto de brigadas'!$M$4:$M$31,"Prof. Alvarez"&CHAR(31)&$A5&CHAR(31)&B$3)*1,0),0)+1):INDEX('Reparto de brigadas'!$M$4:$M$31,ROWS('Reparto de brigadas'!$M$4:$M$31)),"Prof. Alvarez"&CHAR(31)&$A5&CHAR(31)&B$3)*1,0),0))))&IF(SUMPRODUCT(1*EXACT('Reparto de brigadas'!$M$4:$M$31,"Prof. Alvarez"&CHAR(31)&$A5&CHAR(31)&B$3))>2," (+"&(SUMPRODUCT(1*EXACT('Reparto de brigadas'!$M$4:$M$31,"Prof. Alvarez"&CHAR(31)&$A5&CHAR(31)&B$3))-2)&")",""),IF(ISNA(MATCH(1,INDEX(EXACT('Reparto de brigadas'!$M$4:$M$31,"Prof. Alvarez"&CHAR(31)&$A5&CHAR(31)&B$3)*1,0),0)),"",IF(ISBLANK(INDEX('Reparto de brigadas'!$A$4:$A$31,MATCH(1,INDEX(EXACT('Reparto de brigadas'!$M$4:$M$31,"Prof. Alvarez"&CHAR(31)&$A5&CHAR(31)&B$3)*1,0),0))),"",INDEX('Reparto de brigadas'!$A$4:$A$31,MATCH(1,INDEX(EXACT('Reparto de brigadas'!$M$4:$M$31,"Prof. Alvarez"&CHAR(31)&$A5&CHAR(31)&B$3)*1,0),0))))) | C5: =IF(SUMPRODUCT(1*EXACT('Reparto de brigadas'!$M$4:$M$31,"Prof. Alvarez"&CHAR(31)&$A5&CHAR(31)&C$3))>1,IF(ISNA(MATCH(1,INDEX(EXACT('Reparto de brigadas'!$M$4:$M$31,"Prof. Alvarez"&CHAR(31)&$A5&CHAR(31)&C$3)*1,0),0)),"",IF(ISBLANK(INDEX('Reparto de brigadas'!$A$4:$A$31,MATCH(1,INDEX(EXACT('Reparto de brigadas'!$M$4:$M$31,"Prof. Alvarez"&CHAR(31)&$A5&CHAR(31)&C$3)*1,0),0))),"",INDEX('Reparto de brigadas'!$A$4:$A$31,MATCH(1,INDEX(EXACT('Reparto de brigadas'!$M$4:$M$31,"Prof. Alvarez"&CHAR(31)&$A5&CHAR(31)&C$3)*1,0),0))))&" / "&IF(ISBLANK(INDEX('Reparto de brigadas'!$A$4:$A$31,(MATCH(1,INDEX(EXACT('Reparto de brigadas'!$M$4:$M$31,"Prof. Alvarez"&CHAR(31)&$A5&CHAR(31)&C$3)*1,0),0)+MATCH(1,INDEX(EXACT(INDEX('Reparto de brigadas'!$M$4:$M$31,MATCH(1,INDEX(EXACT('Reparto de brigadas'!$M$4:$M$31,"Prof. Alvarez"&CHAR(31)&$A5&CHAR(31)&C$3)*1,0),0)+1):INDEX('Reparto de brigadas'!$M$4:$M$31,ROWS('Reparto de brigadas'!$M$4:$M$31)),"Prof. Alvarez"&CHAR(31)&$A5&CHAR(31)&C$3)*1,0),0)))),"",INDEX('Reparto de brigadas'!$A$4:$A$31,(MATCH(1,INDEX(EXACT('Reparto de brigadas'!$M$4:$M$31,"Prof. Alvarez"&CHAR(31)&$A5&CHAR(31)&C$3)*1,0),0)+MATCH(1,INDEX(EXACT(INDEX('Reparto de brigadas'!$M$4:$M$31,MATCH(1,INDEX(EXACT('Reparto de brigadas'!$M$4:$M$31,"Prof. Alvarez"&CHAR(31)&$A5&CHAR(31)&C$3)*1,0),0)+1):INDEX('Reparto de brigadas'!$M$4:$M$31,ROWS('Reparto de brigadas'!$M$4:$M$31)),"Prof. Alvarez"&CHAR(31)&$A5&CHAR(31)&C$3)*1,0),0))))&IF(SUMPRODUCT(1*EXACT('Reparto de brigadas'!$M$4:$M$31,"Prof. Alvarez"&CHAR(31)&$A5&CHAR(31)&C$3))>2," (+"&(SUMPRODUCT(1*EXACT('Reparto de brigadas'!$M$4:$M$31,"Prof. Alvarez"&CHAR(31)&$A5&CHAR(31)&C$3))-2)&")",""),IF(ISNA(MATCH(1,INDEX(EXACT('Reparto de brigadas'!$M$4:$M$31,"Prof. Alvarez"&CHAR(31)&$A5&CHAR(31)&C$3)*1,0),0)),"",IF(ISBLANK(INDEX('Reparto de brigadas'!$A$4:$A$31,MATCH(1,INDEX(EXACT('Reparto de brigadas'!$M$4:$M$31,"Prof. Alvarez"&CHAR(31)&$A5&CHAR(31)&C$3)*1,0),0))),"",INDEX('Reparto de brigadas'!$A$4:$A$31,MATCH(1,INDEX(EXACT('Reparto de brigadas'!$M$4:$M$31,"Prof. Alvarez"&CHAR(31)&$A5&CHAR(31)&C$3)*1,0),0)))))
A6: 3 p.m. | B6: =IF(SUMPRODUCT(1*EXACT('Reparto de brigadas'!$M$4:$M$31,"Prof. Alvarez"&CHAR(31)&$A6&CHAR(31)&B$3))>1,IF(ISNA(MATCH(1,INDEX(EXACT('Reparto de brigadas'!$M$4:$M$31,"Prof. Alvarez"&CHAR(31)&$A6&CHAR(31)&B$3)*1,0),0)),"",IF(ISBLANK(INDEX('Reparto de brigadas'!$A$4:$A$31,MATCH(1,INDEX(EXACT('Reparto de brigadas'!$M$4:$M$31,"Prof. Alvarez"&CHAR(31)&$A6&CHAR(31)&B$3)*1,0),0))),"",INDEX('Reparto de brigadas'!$A$4:$A$31,MATCH(1,INDEX(EXACT('Reparto de brigadas'!$M$4:$M$31,"Prof. Alvarez"&CHAR(31)&$A6&CHAR(31)&B$3)*1,0),0))))&" / "&IF(ISBLANK(INDEX('Reparto de brigadas'!$A$4:$A$31,(MATCH(1,INDEX(EXACT('Reparto de brigadas'!$M$4:$M$31,"Prof. Alvarez"&CHAR(31)&$A6&CHAR(31)&B$3)*1,0),0)+MATCH(1,INDEX(EXACT(INDEX('Reparto de brigadas'!$M$4:$M$31,MATCH(1,INDEX(EXACT('Reparto de brigadas'!$M$4:$M$31,"Prof. Alvarez"&CHAR(31)&$A6&CHAR(31)&B$3)*1,0),0)+1):INDEX('Reparto de brigadas'!$M$4:$M$31,ROWS('Reparto de brigadas'!$M$4:$M$31)),"Prof. Alvarez"&CHAR(31)&$A6&CHAR(31)&B$3)*1,0),0)))),"",INDEX('Reparto de brigadas'!$A$4:$A$31,(MATCH(1,INDEX(EXACT('Reparto de brigadas'!$M$4:$M$31,"Prof. Alvarez"&CHAR(31)&$A6&CHAR(31)&B$3)*1,0),0)+MATCH(1,INDEX(EXACT(INDEX('Reparto de brigadas'!$M$4:$M$31,MATCH(1,INDEX(EXACT('Reparto de brigadas'!$M$4:$M$31,"Prof. Alvarez"&CHAR(31)&$A6&CHAR(31)&B$3)*1,0),0)+1):INDEX('Reparto de brigadas'!$M$4:$M$31,ROWS('Reparto de brigadas'!$M$4:$M$31)),"Prof. Alvarez"&CHAR(31)&$A6&CHAR(31)&B$3)*1,0),0))))&IF(SUMPRODUCT(1*EXACT('Reparto de brigadas'!$M$4:$M$31,"Prof. Alvarez"&CHAR(31)&$A6&CHAR(31)&B$3))>2," (+"&(SUMPRODUCT(1*EXACT('Reparto de brigadas'!$M$4:$M$31,"Prof. Alvarez"&CHAR(31)&$A6&CHAR(31)&B$3))-2)&")",""),IF(ISNA(MATCH(1,INDEX(EXACT('Reparto de brigadas'!$M$4:$M$31,"Prof. Alvarez"&CHAR(31)&$A6&CHAR(31)&B$3)*1,0),0)),"",IF(ISBLANK(INDEX('Reparto de brigadas'!$A$4:$A$31,MATCH(1,INDEX(EXACT('Reparto de brigadas'!$M$4:$M$31,"Prof. Alvarez"&CHAR(31)&$A6&CHAR(31)&B$3)*1,0),0))),"",INDEX('Reparto de brigadas'!$A$4:$A$31,MATCH(1,INDEX(EXACT('Reparto de brigadas'!$M$4:$M$31,"Prof. Alvarez"&CHAR(31)&$A6&CHAR(31)&B$3)*1,0),0))))) | C6: =IF(SUMPRODUCT(1*EXACT('Reparto de brigadas'!$M$4:$M$31,"Prof. Alvarez"&CHAR(31)&$A6&CHAR(31)&C$3))>1,IF(ISNA(MATCH(1,INDEX(EXACT('Reparto de brigadas'!$M$4:$M$31,"Prof. Alvarez"&CHAR(31)&$A6&CHAR(31)&C$3)*1,0),0)),"",IF(ISBLANK(INDEX('Reparto de brigadas'!$A$4:$A$31,MATCH(1,INDEX(EXACT('Reparto de brigadas'!$M$4:$M$31,"Prof. Alvarez"&CHAR(31)&$A6&CHAR(31)&C$3)*1,0),0))),"",INDEX('Reparto de brigadas'!$A$4:$A$31,MATCH(1,INDEX(EXACT('Reparto de brigadas'!$M$4:$M$31,"Prof. Alvarez"&CHAR(31)&$A6&CHAR(31)&C$3)*1,0),0))))&" / "&IF(ISBLANK(INDEX('Reparto de brigadas'!$A$4:$A$31,(MATCH(1,INDEX(EXACT('Reparto de brigadas'!$M$4:$M$31,"Prof. Alvarez"&CHAR(31)&$A6&CHAR(31)&C$3)*1,0),0)+MATCH(1,INDEX(EXACT(INDEX('Reparto de brigadas'!$M$4:$M$31,MATCH(1,INDEX(EXACT('Reparto de brigadas'!$M$4:$M$31,"Prof. Alvarez"&CHAR(31)&$A6&CHAR(31)&C$3)*1,0),0)+1):INDEX('Reparto de brigadas'!$M$4:$M$31,ROWS('Reparto de brigadas'!$M$4:$M$31)),"Prof. Alvarez"&CHAR(31)&$A6&CHAR(31)&C$3)*1,0),0)))),"",INDEX('Reparto de brigadas'!$A$4:$A$31,(MATCH(1,INDEX(EXACT('Reparto de brigadas'!$M$4:$M$31,"Prof. Alvarez"&CHAR(31)&$A6&CHAR(31)&C$3)*1,0),0)+MATCH(1,INDEX(EXACT(INDEX('Reparto de brigadas'!$M$4:$M$31,MATCH(1,INDEX(EXACT('Reparto de brigadas'!$M$4:$M$31,"Prof. Alvarez"&CHAR(31)&$A6&CHAR(31)&C$3)*1,0),0)+1):INDEX('Reparto de brigadas'!$M$4:$M$31,ROWS('Reparto de brigadas'!$M$4:$M$31)),"Prof. Alvarez"&CHAR(31)&$A6&CHAR(31)&C$3)*1,0),0))))&IF(SUMPRODUCT(1*EXACT('Reparto de brigadas'!$M$4:$M$31,"Prof. Alvarez"&CHAR(31)&$A6&CHAR(31)&C$3))>2," (+"&(SUMPRODUCT(1*EXACT('Reparto de brigadas'!$M$4:$M$31,"Prof. Alvarez"&CHAR(31)&$A6&CHAR(31)&C$3))-2)&")",""),IF(ISNA(MATCH(1,INDEX(EXACT('Reparto de brigadas'!$M$4:$M$31,"Prof. Alvarez"&CHAR(31)&$A6&CHAR(31)&C$3)*1,0),0)),"",IF(ISBLANK(INDEX('Reparto de brigadas'!$A$4:$A$31,MATCH(1,INDEX(EXACT('Reparto de brigadas'!$M$4:$M$31,"Prof. Alvarez"&CHAR(31)&$A6&CHAR(31)&C$3)*1,0),0))),"",INDEX('Reparto de brigadas'!$A$4:$A$31,MATCH(1,INDEX(EXACT('Reparto de brigadas'!$M$4:$M$31,"Prof. Alvarez"&CHAR(31)&$A6&CHAR(31)&C$3)*1,0),0)))))

Sheet HP - Prof. Benitez
A1: Horario del profesor - Prof. Benitez
A3: Horario | B3: par | C3: impar
